Workbook

Sheet Pallet Historica
H3: Jun | I3: Jul | J3: Aug | K3: Sep | L3: Oct | M3: Nov | N3: Dec
H4: 77322 | I4: 76033 | J4: 75910 | K4: 78987 | L4: 86443 | M4: 86754.259 | N4: 92916
H5: 99036 | I5: 94823 | J5: 93799.415 | K5: 101405.92 | L5: 104000 | M5: 111889.15 | N5: 97481.642
H6: 105009.66 | I6: 97809.843 | J6: 91717.211 | K6: 90605.004 | L6: 93188.756 | M6: 91337.265 | N6: 78772.592
U9: 3 week
S10: 2000000 | U10: =S10*3 -> 6000000
S11: =S10/7 -> 285714.29 | U11: =U10*0.1 -> 600000
S12: =S11*2 -> 571428.57 | U12: =U11/185 -> 3243.2432
S13: =S12/180 -> 3174.6032
S22: 113
S23: 137
S24: =S23/S22-1 -> 0.21238938
S27: 800000
S28: =S27/190 -> 4210.5263

Sheet Pivt-Data for Recap
B3: Sum of 2024 Cs | C3: Sum of 2025 Cs | D3: Sum of 2026 Cs | E3: Sum of 2024 Pal | F3: Sum of 2025 Pal | G3: Sum of 2026 Pal | H3: Sum of 2024 Liton | I3: Sum of 2025 Liton | J3: Sum of 2026 Liton
B4: 108959143 | C4: 1.109478e+08 | D4: 1.1383678e+08 | E4: 573128.32 | F4: 582739.05 | G4: 591647.72 | H4: 538348.48 | I4: 542471.65 | J4: 529258.81
C9: Cases | D9: Pallets | E9: Litons
B10: 2024 | C10: =B4 -> 108959143 | D10: =E4 -> 573128.32 | E10: =H4 -> 538348.48
B11: 2025 | C11: =C4 -> 1.109478e+08 | D11: =F4 -> 582739.05 | E11: =I4 -> 542471.65
B12: 2026 | C12: =D4 -> 1.1383678e+08 | D12: =G4 -> 591647.72 | E12: =J4 -> 529258.81
B13: 25' vs 24' | C13: =C11/C10-1 -> 0.01825139 | D13: =D11/D10-1 -> 0.0167689 | E13: =E11/E10-1 -> 0.007658916
B14: 26' vs 25' | C14: =C12/C11-1 -> 0.026039106 | D14: =D12/D11-1 -> 0.015287583 | E14: =E12/E11-1 -> -0.024356737
B20: Sum of 1/1/20252 | C20: Sum of 2/1/20252 | D20: Sum of 3/1/20252 | E20: Sum of 4/1/20252 | F20: Sum of 5/1/20252 | G20: Sum of 6/1/20252 | H20: Sum of 7/1/20252 | I20: Sum of 8/1/20252 | J20: Sum of 9/1/20252 | K20: Sum of 10/1/20252 | L20: Sum of 11/1/20252 | M20: Sum of 12/1/20252 | N20: Sum of 1/1/20262 | O20: Sum of 2/1/20262 | P20: Sum of 3/1/20262 | Q20: Sum of 4/1/20262 | R20: Sum of 5/1/20262 | S20: Sum of 6/1/20262 | T20: Sum of 7/1/20262 | U20: Sum of 8/1/20262 | V20: Sum of 9/1/20262 | W20: Sum of 10/1/20262 | X20: Sum of 11/1/20262 | Y20: Sum of 12/1/20262
B21: 33640.894 | C21: 43191.344 | D21: 53402.149 | E21: 53848.265 | F21: 58102.001 | G21: 64787.241 | H21: 57731.382 | I21: 53033.48 | J21: 43843.61 | K21: 40308.255 | L21: 41783.711 | M21: 39066.717 | N21: 33229.587 | O21: 39333.599 | P21: 52241.354 | Q21: 53935.169 | R21: 61902.74 | S21: 66306.636 | T21: 62759.358 | U21: 59199.701 | V21: 43717.032 | W21: 42130.274 | X21: 41935.602 | Y21: 34956.668
B23: Jan | C23: Feb | D23: Mar | E23: Apr | F23: May | G23: Jun | H23: Jul | I23: Aug | J23: Sep | K23: Oct | L23: Nov | M23: Dec
A24: Vs YAG | B24: =B26/B25-1 -> -0.012226391 | C24: =C26/C25-1 -> -0.089317544 | D24: =D26/D25-1 -> -0.021736873 | E24: =E26/E25-1 -> 0.0016138684 | F24: =F26/F25-1 -> 0.065414946 | G24: =G26/G25-1 -> 0.023452073 | H24: =H26/H25-1 -> 0.08709261 | I24: =I26/I25-1 -> 0.11627033 | ... M24: =M26/M25-1 -> -0.1052059
A25: 2025 | B25: =B21 -> 33640.894 | C25: =C21 -> 43191.344 | D25: =D21 -> 53402.149 | E25: =E21 -> 53848.265 | F25: =F21 -> 58102.001 | G25: =G21 -> 64787.241 | H25: =H21 -> 57731.382 | I25: =I21 -> 53033.48 | ... M25: =M21 -> 39066.717
A26: 2026 | B26: =N21 -> 33229.587 | C26: =O21 -> 39333.599 | D26: =P21 -> 52241.354 | E26: =Q21 -> 53935.169 | F26: =R21 -> 61902.74 | G26: =S21 -> 66306.636 | H26: =T21 -> 62759.358 | I26: =U21 -> 59199.701 | ... M26: =Y21 -> 34956.668
B28: =SUM(B26:I26)/SUM(B25:I25)-1 -> 0.026742651
B50: Sum of 2024 Cs | C50: Sum of 2025 Cs | D50: Sum of 2026 Cs | E50: Sum of 2024 Pal | F50: Sum of 2025 Pal | G50: Sum of 2026 Pal | H50: Sum of 2024 Liton | I50: Sum of 2025 Liton | J50: Sum of 2026 Liton
B51: 108959143 | C51: 1.109478e+08 | D51: 1.1383678e+08 | E51: 573128.32 | F51: 582739.05 | G51: 591647.72 | H51: 538348.48 | I51: 542471.65 | J51: 529258.81
C56: Cases | D56: Pallets | E56: Litons
B57: 2024 | C57: =B51 -> 108959143 | D57: =E51 -> 573128.32 | E57: =H51 -> 538348.48
B58: 2025 | C58: =C51 -> 1.109478e+08 | D58: =F51 -> 582739.05 | E58: =I51 -> 542471.65
B59: 2026 | C59: =D51 -> 1.1383678e+08 | D59: =G51 -> 591647.72 | E59: =J51 -> 529258.81
B60: 25' vs 24' | C60: =C58/C57-1 -> 0.01825139 | D60: =D58/D57-1 -> 0.0167689 | E60: =E58/E57-1 -> 0.007658916
B61: 26' vs 25' | C61: =C59/C58-1 -> 0.026039106 | D61: =D59/D58-1 -> 0.015287583 | E61: =E59/E58-1 -> -0.024356737

Sheet Tech Pivot
M2: Cases | O2: Pallets | Q2: Litons
B3: Row Labels | C3: Sum of 2024 Cs | D3: Sum of 2025 Cs | E3: Sum of 2026 Cs | F3: Sum of 2024 Pal | G3: Sum of 2025 Pal | H3: Sum of 2026 Pal | I3: Sum of 2024 Liton | J3: Sum of 2025 Liton | K3: Sum of 2026 Liton | M3: 25 vs 24 | N3: 26 vs 25 | O3: 25 vs 24 | P3: 26 vs 25 | Q3: 25 vs 24 | R3: 26 vs 25
B4: 48oz | C4: 25396425 | D4: 25060811 | E4: 24044104 | F4: 150897.12 | G4: 148714.01 | H4: 142498.75 | I4: 216356.33 | J4: 213497.99 | K4: 204831.13 | M4: =D4/C4-1 -> -0.01321501 | N4: =E4/D4-1 -> -0.04056959 | O4: =G4/F4-1 -> -0.014467574 | P4: =H4/G4-1 -> -0.041793316 | Q4: =J4/I4-1 -> -0.013211269 | R4: =K4/J4-1 -> -0.040594553
B5: BJ PTS | C5: 25550832 | D5: 25012056 | E5: 21872361 | F5: 106461.8 | G5: 104216.9 | H5: 91134.836 | I5: 96555.293 | J5: 94515.43 | K5: 82650.477 | M5: =D5/C5-1 -> -0.021086437 | N5: =E5/D5-1 -> -0.12552728 | O5: =G5/F5-1 -> -0.021086437 | P5: =H5/G5-1 -> -0.12552728 | Q5: =J5/I5-1 -> -0.021126372 | R5: =K5/J5-1 -> -0.12553456
B6: TALENTI | C6: 10628715 | D6: 10951250 | E6: 10580440 | F6: 41754.775 | G6: 42946.078 | H6: 41491.92 | I6: 39705.174 | J6: 40849.702 | K6: 39489.978 | M6: =D6/C6-1 -> 0.030345625 | N6: =E6/D6-1 -> -0.033860099 | O6: =G6/F6-1 -> 0.028530958 | P6: =H6/G6-1 -> -0.033860099 | Q6: =J6/I6-1 -> 0.028825665 | R6: =K6/J6-1 -> -0.033286011
B7: Yasso Sticks | C7: 7019764 | D7: 8572346.2 | E7: 8872371.3 | F7: 37538.845 | G7: 45841.424 | H7: 47445.836 | I7: 21738.457 | J7: 26287.136 | K7: 27117.355 | M7: =D7/C7-1 -> 0.22117299 | N7: =E7/D7-1 -> 0.034999174 | O7: =G7/F7-1 -> 0.22117299 | P7: =H7/G7-1 -> 0.034999174 | Q7: =J7/I7-1 -> 0.20924571 | R7: =K7/J7-1 -> 0.0315827
B8: PG | C8: 7645042 | D8: 7539347 | E8: 6688729.5 | F8: 58676.603 | G8: 57994.977 | H8: 51053.304 | I8: 39007.967 | J8: 38919.673 | K8: 34004.875 | M8: =D8/C8-1 -> -0.0138253 | N8: =E8/D8-1 -> -0.11282377 | O8: =G8/F8-1 -> -0.011616663 | P8: =H8/G8-1 -> -0.11969439 | Q8: =J8/I8-1 -> -0.0022634934 | R8: =K8/J8-1 -> -0.12628056
B9: MG Sticks | C9: 5989760 | D9: 5932375.3 | E9: 5619297.9 | F9: 31055.606 | G9: 30662.95 | H9: 29083.369 | I9: 15121.639 | J9: 15174.466 | K9: 14559.86 | M9: =D9/C9-1 -> -0.0095804706 | N9: =E9/D9-1 -> -0.052774378 | O9: =G9/F9-1 -> -0.012643653 | P9: =H9/G9-1 -> -0.051514312 | Q9: =J9/I9-1 -> 0.0034934362 | R9: =K9/J9-1 -> -0.040502627
B10: EDF | C10: 4551097 | D10: 4792941 | E10: 4699483.1 | F10: 34478.008 | G10: 36310.159 | H10: 35602.145 | I10: 41068.026 | J10: 43267.691 | K10: 42385.989 | M10: =D10/C10-1 -> 0.053139716 | N10: =E10/D10-1 -> -0.01949907 | O10: =G10/F10-1 -> 0.053139716 | P10: =H10/G10-1 -> -0.01949907 | Q10: =J10/I10-1 -> 0.053561502 | R10: =K10/J10-1 -> -0.020377836
B11: Facepieces | C11: 2994317 | D11: 3663497 | E11: 4448982.1 | F11: 14754.224 | G11: 18362.003 | H11: 23083.45 | I11: 6588.9085 | J11: 7984.4064 | K11: 9611.1826 | M11: =D11/C11-1 -> 0.22348335 | N11: =E11/D11-1 -> 0.21440855 | O11: =G11/F11-1 -> 0.24452518 | P11: =H11/G11-1 -> 0.2571314 | Q11: =J11/I11-1 -> 0.21179501 | R11: =K11/J11-1 -> 0.20374416
B12: MBG | C12: 3518874 | D12: 3662117 | E12: 3014678.2 | F12: 20215.765 | G12: 21043.997 | H12: 17181.367 | I12: 12698.509 | J12: 13241.988 | K12: 10892.046 | M12: =D12/C12-1 -> 0.040707062 | N12: =E12/D12-1 -> -0.17679359 | O12: =G12/F12-1 -> 0.040969611 | P12: =H12/G12-1 -> -0.18355021 | Q12: =J12/I12-1 -> 0.042798597 | R12: =K12/J12-1 -> -0.17746139
B13: Yasso Club | C13: 1931563 | D13: 3542519 | E13: 5281339 | F13: 8048.1792 | G13: 14760.496 | H13: 22005.579 | I13: 2925.8367 | J13: 5399.1829 | K13: 8177.1729 | M13: =D13/C13-1 -> 0.8340168 | N13: =E13/D13-1 -> 0.49084282 | O13: =G13/F13-1 -> 0.8340168 | P13: =H13/G13-1 -> 0.49084282 | Q13: =J13/I13-1 -> 0.84534662 | R13: =K13/J13-1 -> 0.51452043
B14: Topped | C14: 2333363 | D14: 2160214 | E14: 1917552.2 | F14: 9722.3458 | G14: 9000.8917 | H14: 7989.8008 | I14: 8400.1068 | J14: 7776.7704 | K14: 6903.1879 | M14: =D14/C14-1 -> -0.074205771 | N14: =E14/D14-1 -> -0.1123323 | O14: =G14/F14-1 -> -0.074205771 | P14: =H14/G14-1 -> -0.1123323 | Q14: =J14/I14-1 -> -0.074205771 | R14: =K14/J14-1 -> -0.1123323
B15: ESS | C15: 1922867 | D15: 1904254 | E15: 1782634.5 | F15: 13091.75 | G15: 13517.484 | H15: 12952.771 | I15: 8047.6951 | J15: 8291.79 | K15: 8102.4717 | M15: =D15/C15-1 -> -0.0096798166 | N15: =E15/D15-1 -> -0.063867247 | O15: =G15/F15-1 -> 0.032519182 | P15: =H15/G15-1 -> -0.041776456 | Q15: =J15/I15-1 -> 0.030331037 | R15: =K15/J15-1 -> -0.022832017
... B38: Viennetta | C38: 62 | D38: 0 | E38: 0 | F38: 0.28181818 | G38: 0 | H38: 0 | I38: 0.2418 | J38: 0 | K38: 0 | M38: =D38/C38-1 -> -1 | N38: =E38/D38-1 -> #DIV/0! | O38: =G38/F38-1 -> -1 | P38: =H38/G38-1 -> #DIV/0! | Q38: =J38/I38-1 -> -1 | R38: =K38/J38-1 -> #DIV/0!
B39: (blank) | M39: =D39/C39-1 -> #DIV/0! | N39: =E39/D39-1 -> #DIV/0! | O39: =G39/F39-1 -> #DIV/0! | P39: =H39/G39-1 -> #DIV/0! | Q39: =J39/I39-1 -> #DIV/0! | R39: =K39/J39-1 -> #DIV/0!
B40: MG PTS | C40: 5322 | D40: 0 | E40: 0 | F40: 15.652941 | G40: 0 | H40: 0 | I40: 14.05008 | J40: 0 | K40: 0 | M40: =D40/C40-1 -> -1 | N40: =E40/D40-1 -> #DIV/0! | O40: =G40/F40-1 -> -1 | P40: =H40/G40-1 -> #DIV/0! | Q40: =J40/I40-1 -> -1 | R40: =K40/J40-1 -> #DIV/0!
B41: CS PTS | C41: 1590 | D41: 0 | E41: 0 | F41: 6.625 | G41: 0 | H41: 0 | I41: 6.01656 | J41: 0 | K41: 0 | M41: =D41/C41-1 -> -1 | N41: =E41/D41-1 -> #DIV/0! | O41: =G41/F41-1 -> -1 | P41: =H41/G41-1 -> #DIV/0! | Q41: =J41/I41-1 -> -1 | R41: =K41/J41-1 -> #DIV/0!
B42: Grand Total | C42: 108959143 | D42: 1.109478e+08 | E42: 1.1383678e+08 | F42: 573128.32 | G42: 582739.05 | H42: 591647.72 | I42: 538348.48 | J42: 542471.65 | K42: 529258.81 | M42: =D42/C42-1 -> 0.01825139 | N42: =E42/D42-1 -> 0.026039106 | O42: =G42/F42-1 -> 0.0167689 | P42: =H42/G42-1 -> 0.015287583 | Q42: =J42/I42-1 -> 0.007658916 | R42: =K42/J42-1 -> -0.024356737
M43: =D43/C43-1 -> #DIV/0! | N43: =E43/D43-1 -> #DIV/0! | O43: =G43/F43-1 -> #DIV/0! | P43: =H43/G43-1 -> #DIV/0! | Q43: =J43/I43-1 -> #DIV/0! | R43: =K43/J43-1 -> #DIV/0!
A46: Packaged | C46: =SUM(C4:C6,C14,C21,C24,C27,C31:C32,C35,C40:C41) -> 65165150 | D46: =SUM(D4:D6,D14,D21,D24,D27,D31:D32,D35,D40:D41) -> 64795458 | E46: =SUM(E4:E6,E14,E21,E24,E27,E31:E32,E35,E40:E41) -> 61769931 | F46: =SUM(F4:F6,F14,F21,F24,F27,F31:F32,F35,F40:F41) -> 316543.54 | G46: =SUM(G4:G6,G14,G21,G24,G27,G31:G32,G35,G40:G41) -> 313778.54 | H46: =SUM(H4:H6,H14,H21,H24,H27,H31:H32,H35,H40:H41) -> 299043.31 | I46: =SUM(I4:I6,I14,I21,I24,I27,I31:I32,I35,I40:I41) -> 368484.75 | J46: =SUM(J4:J6,J14,J21,J24,J27,J31:J32,J35,J40:J41) -> 365380.58 | K46: =SUM(K4:K6,K14,K21,K24,K27,K31:K32,K35,K40:K41) -> 348212.19 | M46: =D46/C46-1 -> -0.0056731534 | N46: =E46/D46-1 -> -0.046693513 | O46: =G46/F46-1 -> -0.0087349747 | P46: =H46/G46-1 -> -0.046960623 | Q46: =J46/I46-1 -> -0.0084241625 | R46: =K46/J46-1 -> -0.046987688
A47: Nov | C47: =SUM(C7:C13,C15:C20,C22:C23,C25:C26,C28:C30,C33:C34,C36:C39) -> 43793993 | D47: =SUM(D7:D13,D15:D20,D22:D23,D25:D26,D28:D30,D33:D34,D36:D39) -> 46152341 | E47: =SUM(E7:E13,E15:E20,E22:E23,E25:E26,E28:E30,E33:E34,E36:E39) -> 52066850 | F47: =SUM(F7:F13,F15:F20,F22:F23,F25:F26,F28:F30,F33:F34,F36:F39) -> 256584.77 | G47: =SUM(G7:G13,G15:G20,G22:G23,G25:G26,G28:G30,G33:G34,G36:G39) -> 268960.51 | H47: =SUM(H7:H13,H15:H20,H22:H23,H25:H26,H28:H30,H33:H34,H36:H39) -> 292604.41 | I47: =SUM(I7:I13,I15:I20,I22:I23,I25:I26,I28:I30,I33:I34,I36:I39) -> 169863.73 | J47: =SUM(J7:J13,J15:J20,J22:J23,J25:J26,J28:J30,J33:J34,J36:J39) -> 177091.07 | K47: =SUM(K7:K13,K15:K20,K22:K23,K25:K26,K28:K30,K33:K34,K36:K39) -> 181046.62 | M47: =D47/C47-1 -> 0.05385094 | N47: =E47/D47-1 -> 0.12815188 | O47: =G47/F47-1 -> 0.048232525 | P47: =H47/G47-1 -> 0.087908472 | Q47: =J47/I47-1 -> 0.042547878 | R47: =K47/J47-1 -> 0.022336243

Sheet Sheet2
A3: Row Labels | B3: Sum of 2024 Liton | C3: Sum of 2025 Liton | D3: Sum of 2026 Liton
A4: NOV | B4: 170315.08 | C4: 174866.82 | D4: 176753.08 | G4: =C4/B4-1 -> 0.026725401 | H4: =D4/C4-1 -> 0.010786834
A5: PIC | B5: 368033.4 | C5: 367604.83 | D5: 352505.73 | G5: =C5/B5-1 -> -0.001164495 | H5: =D5/C5-1 -> -0.041074266
A6: Grand Total | B6: 538348.48 | C6: 542471.65 | D6: 529258.81 | G6: =C6/B6-1 -> 0.007658916 | H6: =D6/C6-1 -> -0.024356737

Sheet Recap
B3: Sum of 2024 Cs | C3: Sum of 2025 Cs | D3: Sum of 2026 Cs | E3: Sum of 2024 Pal | F3: Sum of 2025 Pal | G3: Sum of 2026 Pal | H3: Sum of 2024 Liton | I3: Sum of 2025 Liton | J3: Sum of 2026 Liton
B4: 108959143 | C4: 1.109478e+08 | D4: 1.1161604e+08 | E4: 573128.32 | F4: 582739.05 | G4: 583573.09 | H4: 538348.48 | I4: 542471.65 | J4: 527253.9
C8: Cases | D8: Pallets | E8: Litons
B9: 2024 | C9: =B4 -> 108959143 | D9: =E4 -> 573128.32 | E9: =H4 -> 538348.48
B10: 2025 | C10: =C4 -> 1.109478e+08 | D10: =F4 -> 582739.05 | E10: =I4 -> 542471.65
B11: 2026 | C11: =D4 -> 1.1161604e+08 | D11: =G4 -> 583573.09 | E11: =J4 -> 527253.9
B12: 25' vs 24' | C12: =C10/C9-1 -> 0.01825139 | D12: =D10/D9-1 -> 0.0167689 | E12: =E10/E9-1 -> 0.007658916
B13: 26' vs 25' | C13: =C11/C10-1 -> 0.0060230129 | D13: =D11/D10-1 -> 0.0014312447 | E13: =E11/E10-1 -> -0.028052617
B15: MRF2 | C15: 0.0062657043 | D15: 3.9252106e-05 | E15: -0.027288237
B16: MRF1 | C16: 0.026 | D16: 0.015 | E16: -0.024
B17: MRF12 | C17: 0.04 | D17: 0.023 | E17: 0.011

Sheet Sheet3
A3: Row Labels | B3: Sum of Total
A4: 2.4 Gal | B4: 1325371.7 | D4: =B4/$B$43 -> 0.0039978805
A5: 48oz | B5: 74284997 | D5: =B5/$B$43 -> 0.22407491
A6: B&J Cups | B6: 3557186 | D6: =B6/$B$43 -> 0.010729975
A7: BJ Bars | B7: 2012712 | D7: =B7/$B$43 -> 0.0060711891
A8: BJ PTS | B8: 72701613 | D8: =B8/$B$43 -> 0.21929876
A9: BR Minicups | B9: 698571.72 | D9: =B9/$B$43 -> 0.0021071872
A10: CS PTS | B10: 1590 | D10: =B10/$B$43 -> 4.7961112e-06
A11: Dough Bites | B11: 1335527.3 | D11: =B11/$B$43 -> 0.0040285142
A12: EDF | B12: 14091317 | D12: =B12/$B$43 -> 0.04250536
A13: EFW | B13: 2553318.3 | D13: =B13/$B$43 -> 0.0077018859
A14: ESS | B14: 5536511.1 | D14: =B14/$B$43 -> 0.016700455
A15: Facepieces | B15: 11488792 | D15: =B15/$B$43 -> 0.034655046
... A41: YS PTS | B41: 2219034.8 | D41: =B41/$B$43 -> 0.0066935458
A42: (blank)
A43: Grand Total | B43: 3.3151858e+08

Sheet Sheet4
E1: FG WAC
D2: 2.4 Gal | E2: 31.07
D3: Quarts | E3: 23.46
D4: EDF | E4: 22.75
D5: BR Minicups | E5: 22.51
D6: Yasso Poppables | E6: 18.16
D7: ESS | E7: 17.21
D8: BJ Bars | E8: 17.05
D9: KL Mini Cones | E9: 16.65
D10: Dough Bites | E10: 14.65
D11: GH "Candy" | E11: 13.95
D12: EFW | E12: 13.78
D13: Other | E13: 13.38
... D31: Facepieces | E31: 6.04

Sheet MRF2
AM1: =SUBTOTAL(9,AM3:AM411) -> 33348.393 | AN1: =SUBTOTAL(9,AN3:AN411) -> 42875.663 | AO1: =SUBTOTAL(9,AO3:AO411) -> 53073.398 | AP1: =SUBTOTAL(9,AP3:AP411) -> 53478.837 | AQ1: =SUBTOTAL(9,AQ3:AQ411) -> 57759.776 | AR1: =SUBTOTAL(9,AR3:AR411) -> 64384.378 | AS1: =SUBTOTAL(9,AS3:AS411) -> 57347.943 | AT1: =SUBTOTAL(9,AT3:AT411) -> 52715.679 | ... BJ1: =SUBTOTAL(9,BJ3:BJ411) -> 0 | BN1: =SUBTOTAL(9,BN3:BN411) -> 31403.896 | BO1: =SUBTOTAL(9,BO3:BO411) -> 39381.387 | BP1: =SUBTOTAL(9,BP3:BP411) -> 48902.088 | BQ1: =SUBTOTAL(9,BQ3:BQ411) -> 50769.829 | BR1: =SUBTOTAL(9,BR3:BR411) -> 52213.028 | BS1: =SUBTOTAL(9,BS3:BS411) -> 59749.815 | BT1: =SUBTOTAL(9,BT3:BT411) -> 52811.484 | BU1: =SUBTOTAL(9,BU3:BU411) -> 49265.469 | ... CK1: =SUBTOTAL(9,CK3:CK411) -> 0
A2: Segment | B2: Tech | C2: DU | D2: UCC | E2: Description | F2: 2024 Cs | G2: 45658 | H2: 45689 | I2: 45717 | J2: 45748 | K2: 45778 | L2: 45809 | M2: 45839 | N2: 45870 | O2: 45901 | P2: 45931 | Q2: 45962 | R2: 45992 | S2: 46023 | T2: 46054 | U2: 46082 | V2: 46113 | W2: 46143 | X2: 46174 | Y2: 46204 | Z2: 46235 | AA2: 46266 | AB2: 46296 | AC2: 46327 | AD2: 46357 | AE2: Total | AF2: Per Pallet | AG2: Litons Per | AH2: 2025 Cs | AI2: 2026 Cs | AJ2: 2024 Pal | AK2: 2025 Pal | AL2: 2026 Pal | AM2: 45658 | AN2: 45689 | AO2: 45717 | AP2: 45748 | AQ2: 45778 | AR2: 45809 | AS2: 45839 | AT2: 45870 | AU2: 45901 | AV2: 45931 | AW2: 45962 | AX2: 45992 | AY2: 46023 | AZ2: 46054 | BA2: 46082 | BB2: 46113 | BC2: 46143 | BD2: 46174 | BE2: 46204 | BF2: 46235 | BG2: 46266 | BH2: 46296 | BI2: 46327 | BJ2: 46357 | BK2: 2024 Liton | BL2: 2025 Liton | BM2: 2026 Liton | BN2: 45658 | BO2: 45689 | BP2: 45717 | BQ2: 45748 | BR2: 45778 | BS2: 45809 | BT2: 45839 | BU2: 45870 | BV2: 45901 | BW2: 45931 | BX2: 45962 | BY2: 45992 | BZ2: 46023 | CA2: 46054 | CB2: 46082 | CC2: 46113 | CD2: 46143 | CE2: 46174 | CF2: 46204 | CG2: 46235 | CH2: 46266 | CI2: 46296 | CJ2: 46327 | CK2: 46357
A3: =VLOOKUP($C3,'Tech Pallet'!$A:$J,10,0) -> PIC | B3: =VLOOKUP(C3,'Tech Pallet'!A:I,3,0) -> 48oz | C3: =VLOOKUP($D3,'DU -UCC'!B:C,2,0) -> 68851106 | D3: 10077567254235 | E3: BR HA NAT Vanilla 6 1.5 QT | F3: 3095817 | G3: 176369 | H3: 209154 | I3: 274473 | J3: 314920 | K3: 238908 | L3: 292984 | M3: 307087 | N3: 268290 | O3: 218080 | P3: 311240 | Q3: 307505 | R3: 251820 | AE3: =SUM(F3:AD3) -> 6266647 | AF3: =VLOOKUP($C3,'Tech Pallet'!$A:$I,9,0) -> 154 | AG3: =VLOOKUP($C3,'Tech Pallet'!$A:$H,8,0) -> 0.00852 | AH3: =SUM(G3:R3) -> 3170830 | AI3: =SUM(S3:AD3) -> 0 | AJ3: =F3/AF3 -> 20102.708 | AK3: =SUM(G3:R3)/AF3 -> 20589.805 | AL3: =SUM(S3:AD3)/AF3 -> 0 | AM3: =G3/$AF3 -> 1145.2532 | AN3: =H3/$AF3 -> 1358.1429 | AO3: =I3/$AF3 -> 1782.2922 | AP3: =J3/$AF3 -> 2044.9351 | AQ3: =K3/$AF3 -> 1551.3506 | AR3: =L3/$AF3 -> 1902.4935 | AS3: =M3/$AF3 -> 1994.0714 | AT3: =N3/$AF3 -> 1742.1429 | ... BJ3: =AD3/$AF3 -> 0 | BK3: =F3*AG3 -> 26376.361 | BL3: =SUM(G3:R3)*AG3 -> 27015.472 | BM3: =SUM(S3:AD3)*AG3 -> 0 | BN3: =G3*$AG3 -> 1502.6639 | BO3: =H3*$AG3 -> 1781.9921 | BP3: =I3*$AG3 -> 2338.51 | BQ3: =J3*$AG3 -> 2683.1184 | BR3: =K3*$AG3 -> 2035.4962 | BS3: =L3*$AG3 -> 2496.2237 | BT3: =M3*$AG3 -> 2616.3812 | BU3: =N3*$AG3 -> 2285.8308 | ... CK3: =AD3*$AG3 -> 0
A4: =VLOOKUP($C4,'Tech Pallet'!$A:$J,10,0) -> NOV | B4: =VLOOKUP(C4,'Tech Pallet'!A:I,3,0) -> Yasso Club | C4: =VLOOKUP($D4,'DU -UCC'!B:C,2,0) -> 64376316 | D4: 10851035003057 | E4: Yasso Cookies n Cream Club 1-15pk | F4: 345783 | G4: 151920 | H4: 548640 | I4: 563989 | J4: 0 | K4: 0 | L4: 0 | M4: 53040 | N4: 11460 | O4: 0 | P4: 219600 | Q4: 864144 | R4: 266736 | AE4: =SUM(F4:AD4) -> 3025312 | AF4: =VLOOKUP($C4,'Tech Pallet'!$A:$I,9,0) -> 240 | AG4: =VLOOKUP($C4,'Tech Pallet'!$A:$H,8,0) -> 0.001545 | AH4: =SUM(G4:R4) -> 2679529 | AI4: =SUM(S4:AD4) -> 0 | AJ4: =F4/AF4 -> 1440.7625 | AK4: =SUM(G4:R4)/AF4 -> 11164.704 | AL4: =SUM(S4:AD4)/AF4 -> 0 | AM4: =G4/$AF4 -> 633 | AN4: =H4/$AF4 -> 2286 | AO4: =I4/$AF4 -> 2349.9542 | AP4: =J4/$AF4 -> 0 | AQ4: =K4/$AF4 -> 0 | AR4: =L4/$AF4 -> 0 | AS4: =M4/$AF4 -> 221 | AT4: =N4/$AF4 -> 47.75 | ... BJ4: =AD4/$AF4 -> 0 | BK4: =F4*AG4 -> 534.23474 | BL4: =SUM(G4:R4)*AG4 -> 4139.8723 | BM4: =SUM(S4:AD4)*AG4 -> 0 | BN4: =G4*$AG4 -> 234.7164 | BO4: =H4*$AG4 -> 847.6488 | BP4: =I4*$AG4 -> 871.363 | BQ4: =J4*$AG4 -> 0 | BR4: =K4*$AG4 -> 0 | BS4: =L4*$AG4 -> 0 | BT4: =M4*$AG4 -> 81.9468 | BU4: =N4*$AG4 -> 17.7057 | ... CK4: =AD4*$AG4 -> 0
A5: =VLOOKUP($C5,'Tech Pallet'!$A:$J,10,0) -> PIC | B5: =VLOOKUP(C5,'Tech Pallet'!A:I,3,0) -> BJ PTS | C5: =VLOOKUP($D5,'DU -UCC'!B:C,2,0) -> 84141103 | D5: 10076840101327 | E5: BJ US-IC-HalfBaked-FH-8 1PT | F5: 2262483 | G5: 121598 | H5: 194662 | I5: 225100 | J5: 197679 | K5: 205476 | L5: 242164 | M5: 205277 | N5: 209550 | O5: 207720 | P5: 185262 | Q5: 166605 | R5: 180038 | AE5: =SUM(F5:AD5) -> 4603614 | AF5: =VLOOKUP($C5,'Tech Pallet'!$A:$I,9,0) -> 240 | AG5: =VLOOKUP($C5,'Tech Pallet'!$A:$H,8,0) -> 0.003785344 | AH5: =SUM(G5:R5) -> 2341131 | AI5: =SUM(S5:AD5) -> 0 | AJ5: =F5/AF5 -> 9427.0125 | AK5: =SUM(G5:R5)/AF5 -> 9754.7125 | AL5: =SUM(S5:AD5)/AF5 -> 0 | AM5: =G5/$AF5 -> 506.65833 | AN5: =H5/$AF5 -> 811.09167 | AO5: =I5/$AF5 -> 937.91667 | AP5: =J5/$AF5 -> 823.6625 | AQ5: =K5/$AF5 -> 856.15 | AR5: =L5/$AF5 -> 1009.0167 | AS5: =M5/$AF5 -> 855.32083 | AT5: =N5/$AF5 -> 873.125 | ... BJ5: =AD5/$AF5 -> 0 | BK5: =F5*AG5 -> 8564.2764 | BL5: =SUM(G5:R5)*AG5 -> 8861.9862 | BM5: =SUM(S5:AD5)*AG5 -> 0 | BN5: =G5*$AG5 -> 460.29026 | BO5: =H5*$AG5 -> 736.86263 | BP5: =I5*$AG5 -> 852.08093 | BQ5: =J5*$AG5 -> 748.28302 | BR5: =K5*$AG5 -> 777.79734 | BS5: =L5*$AG5 -> 916.67404 | BT5: =M5*$AG5 -> 777.04406 | BU5: =N5*$AG5 -> 793.21884 | ... CK5: =AD5*$AG5 -> 0
A6: =VLOOKUP($C6,'Tech Pallet'!$A:$J,10,0) -> PIC | B6: =VLOOKUP(C6,'Tech Pallet'!A:I,3,0) -> BJ PTS | C6: =VLOOKUP($D6,'DU -UCC'!B:C,2,0) -> 84137725 | D6: 10076840100153 | E6: BJ US-IC-CherryGarcia-FH-8 1PT | F6: 1899510 | G6: 109637 | H6: 159659 | I6: 184592 | J6: 167614 | K6: 170688 | L6: 208686 | M6: 162318 | N6: 175516 | O6: 158647 | P6: 129691 | Q6: 142159 | R6: 131248 | AE6: =SUM(F6:AD6) -> 3799965 | AF6: =VLOOKUP($C6,'Tech Pallet'!$A:$I,9,0) -> 240 | AG6: =VLOOKUP($C6,'Tech Pallet'!$A:$H,8,0) -> 0.003785344 | AH6: =SUM(G6:R6) -> 1900455 | AI6: =SUM(S6:AD6) -> 0 | AJ6: =F6/AF6 -> 7914.625 | AK6: =SUM(G6:R6)/AF6 -> 7918.5625 | AL6: =SUM(S6:AD6)/AF6 -> 0 | AM6: =G6/$AF6 -> 456.82083 | AN6: =H6/$AF6 -> 665.24583 | AO6: =I6/$AF6 -> 769.13333 | AP6: =J6/$AF6 -> 698.39167 | AQ6: =K6/$AF6 -> 711.2 | AR6: =L6/$AF6 -> 869.525 | AS6: =M6/$AF6 -> 676.325 | AT6: =N6/$AF6 -> 731.31667 | ... BJ6: =AD6/$AF6 -> 0 | BK6: =F6*AG6 -> 7190.2988 | BL6: =SUM(G6:R6)*AG6 -> 7193.8759 | BM6: =SUM(S6:AD6)*AG6 -> 0 | BN6: =G6*$AG6 -> 415.01376 | BO6: =H6*$AG6 -> 604.36424 | BP6: =I6*$AG6 -> 698.74422 | BQ6: =J6*$AG6 -> 634.47665 | BR6: =K6*$AG6 -> 646.1128 | BS6: =L6*$AG6 -> 789.9483 | BT6: =M6*$AG6 -> 614.42947 | BU6: =N6*$AG6 -> 664.38844 | ... CK6: =AD6*$AG6 -> 0
A7: =VLOOKUP($C7,'Tech Pallet'!$A:$J,10,0) -> NOV | B7: =VLOOKUP(C7,'Tech Pallet'!A:I,3,0) -> EDF | C7: =VLOOKUP($D7,'DU -UCC'!B:C,2,0) -> 68689251 | D7: 10075856001102 | E7: KL ORIGINAL VANILLA BAR 12-6PK | F7: 1549848 | G7: 85296 | H7: 93432 | I7: 169990 | J7: 165889 | K7: 171240 | L7: 203899 | M7: 181652 | N7: 145980 | O7: 113404 | P7: 107220 | Q7: 95636 | R7: 93336 | AE7: =SUM(F7:AD7) -> 3176822 | AF7: =VLOOKUP($C7,'Tech Pallet'!$A:$I,9,0) -> 132 | AG7: =VLOOKUP($C7,'Tech Pallet'!$A:$H,8,0) -> 0.009576 | AH7: =SUM(G7:R7) -> 1626974 | AI7: =SUM(S7:AD7) -> 0 | AJ7: =F7/AF7 -> 11741.273 | AK7: =SUM(G7:R7)/AF7 -> 12325.561 | AL7: =SUM(S7:AD7)/AF7 -> 0 | AM7: =G7/$AF7 -> 646.18182 | AN7: =H7/$AF7 -> 707.81818 | AO7: =I7/$AF7 -> 1287.803 | AP7: =J7/$AF7 -> 1256.7348 | AQ7: =K7/$AF7 -> 1297.2727 | AR7: =L7/$AF7 -> 1544.6894 | AS7: =M7/$AF7 -> 1376.1515 | AT7: =N7/$AF7 -> 1105.9091 | ... BJ7: =AD7/$AF7 -> 0 | BK7: =F7*AG7 -> 14841.344 | BL7: =SUM(G7:R7)*AG7 -> 15579.903 | BM7: =SUM(S7:AD7)*AG7 -> 0 | BN7: =G7*$AG7 -> 816.7945 | BO7: =H7*$AG7 -> 894.70483 | BP7: =I7*$AG7 -> 1627.8242 | BQ7: =J7*$AG7 -> 1588.5531 | BR7: =K7*$AG7 -> 1639.7942 | BS7: =L7*$AG7 -> 1952.5368 | BT7: =M7*$AG7 -> 1739.4996 | BU7: =N7*$AG7 -> 1397.9045 | ... CK7: =AD7*$AG7 -> 0
A8: =VLOOKUP($C8,'Tech Pallet'!$A:$J,10,0) -> NOV | B8: =VLOOKUP(C8,'Tech Pallet'!A:I,3,0) -> PG | C8: =VLOOKUP($D8,'DU -UCC'!B:C,2,0) -> 62714126 | D8: 10077567001563 | E8: PS OCG SF 6-18PK | F8: 1831869 | G8: 112123 | H8: 140508 | I8: 151382 | J8: 170972 | K8: 252105 | L8: 213156 | M8: 205788 | N8: 201630 | O8: 134130 | P8: 102659 | Q8: 113126 | R8: 116881 | AE8: =SUM(F8:AD8) -> 3746329 | AF8: =VLOOKUP($C8,'Tech Pallet'!$A:$I,9,0) -> 130 | AG8: =VLOOKUP($C8,'Tech Pallet'!$A:$H,8,0) -> 0.005268 | AH8: =SUM(G8:R8) -> 1914460 | AI8: =SUM(S8:AD8) -> 0 | AJ8: =F8/AF8 -> 14091.3 | AK8: =SUM(G8:R8)/AF8 -> 14726.615 | AL8: =SUM(S8:AD8)/AF8 -> 0 | AM8: =G8/$AF8 -> 862.48462 | AN8: =H8/$AF8 -> 1080.8308 | AO8: =I8/$AF8 -> 1164.4769 | AP8: =J8/$AF8 -> 1315.1692 | AQ8: =K8/$AF8 -> 1939.2692 | AR8: =L8/$AF8 -> 1639.6615 | AS8: =M8/$AF8 -> 1582.9846 | AT8: =N8/$AF8 -> 1551 | ... BJ8: =AD8/$AF8 -> 0 | BK8: =F8*AG8 -> 9650.2859 | BL8: =SUM(G8:R8)*AG8 -> 10085.375 | BM8: =SUM(S8:AD8)*AG8 -> 0 | BN8: =G8*$AG8 -> 590.66396 | BO8: =H8*$AG8 -> 740.19614 | BP8: =I8*$AG8 -> 797.48038 | BQ8: =J8*$AG8 -> 900.6805 | BR8: =K8*$AG8 -> 1328.0891 | BS8: =L8*$AG8 -> 1122.9058 | BT8: =M8*$AG8 -> 1084.0912 | BU8: =N8*$AG8 -> 1062.1868 | ... CK8: =AD8*$AG8 -> 0
A9: =VLOOKUP($C9,'Tech Pallet'!$A:$J,10,0) -> PIC | B9: =VLOOKUP(C9,'Tech Pallet'!A:I,3,0) -> BJ PTS | C9: =VLOOKUP($D9,'DU -UCC'!B:C,2,0) -> 69716748 | D9: 10076840100474 | E9: BJ US-IC-ChocFudgBrownie-FH-8 1PT | F9: 1632918 | G9: 96574 | H9: 139276 | I9: 169154 | J9: 148509 | K9: 146329 | L9: 179572 | M9: 148318 | N9: 154210 | O9: 131381 | P9: 134601 | Q9: 123632 | R9: 128066 | AE9: =SUM(F9:AD9) -> 3332540 | AF9: =VLOOKUP($C9,'Tech Pallet'!$A:$I,9,0) -> 240 | AG9: =VLOOKUP($C9,'Tech Pallet'!$A:$H,8,0) -> 0.003784 | AH9: =SUM(G9:R9) -> 1699622 | AI9: =SUM(S9:AD9) -> 0 | AJ9: =F9/AF9 -> 6803.825 | AK9: =SUM(G9:R9)/AF9 -> 7081.7583 | AL9: =SUM(S9:AD9)/AF9 -> 0 | AM9: =G9/$AF9 -> 402.39167 | AN9: =H9/$AF9 -> 580.31667 | AO9: =I9/$AF9 -> 704.80833 | AP9: =J9/$AF9 -> 618.7875 | AQ9: =K9/$AF9 -> 609.70417 | AR9: =L9/$AF9 -> 748.21667 | AS9: =M9/$AF9 -> 617.99167 | AT9: =N9/$AF9 -> 642.54167 | ... BJ9: =AD9/$AF9 -> 0 | BK9: =F9*AG9 -> 6178.9617 | BL9: =SUM(G9:R9)*AG9 -> 6431.3696 | BM9: =SUM(S9:AD9)*AG9 -> 0 | BN9: =G9*$AG9 -> 365.43602 | BO9: =H9*$AG9 -> 527.02038 | BP9: =I9*$AG9 -> 640.07874 | BQ9: =J9*$AG9 -> 561.95806 | BR9: =K9*$AG9 -> 553.70894 | BS9: =L9*$AG9 -> 679.50045 | BT9: =M9*$AG9 -> 561.23531 | BU9: =N9*$AG9 -> 583.53064 | ... CK9: =AD9*$AG9 -> 0
A10: =VLOOKUP($C10,'Tech Pallet'!$A:$J,10,0) -> PIC | B10: =VLOOKUP(C10,'Tech Pallet'!A:I,3,0) -> BJ PTS | C10: =VLOOKUP($D10,'DU -UCC'!B:C,2,0) -> 69999269 | D10: 10076840400215 | E10: BJ US IC-STRWBRY CHSCK 8 1 PT w/REC CUP | F10: 1664842 | G10: 84369 | H10: 139113 | I10: 153581 | J10: 141544 | K10: 144377 | L10: 175107 | M10: 148770 | N10: 153279 | O10: 141030 | P10: 111682 | Q10: 128760 | R10: 113815 | AE10: =SUM(F10:AD10) -> 3300269 | AF10: =VLOOKUP($C10,'Tech Pallet'!$A:$I,9,0) -> 240 | AG10: =VLOOKUP($C10,'Tech Pallet'!$A:$H,8,0) -> 0.003784 | AH10: =SUM(G10:R10) -> 1635427 | AI10: =SUM(S10:AD10) -> 0 | AJ10: =F10/AF10 -> 6936.8417 | AK10: =SUM(G10:R10)/AF10 -> 6814.2792 | AL10: =SUM(S10:AD10)/AF10 -> 0 | AM10: =G10/$AF10 -> 351.5375 | AN10: =H10/$AF10 -> 579.6375 | AO10: =I10/$AF10 -> 639.92083 | AP10: =J10/$AF10 -> 589.76667 | AQ10: =K10/$AF10 -> 601.57083 | AR10: =L10/$AF10 -> 729.6125 | AS10: =M10/$AF10 -> 619.875 | AT10: =N10/$AF10 -> 638.6625 | ... BJ10: =AD10/$AF10 -> 0 | BK10: =F10*AG10 -> 6299.7621 | BL10: =SUM(G10:R10)*AG10 -> 6188.4558 | BM10: =SUM(S10:AD10)*AG10 -> 0 | BN10: =G10*$AG10 -> 319.2523 | BO10: =H10*$AG10 -> 526.40359 | BP10: =I10*$AG10 -> 581.1505 | BQ10: =J10*$AG10 -> 535.6025 | BR10: =K10*$AG10 -> 546.32257 | BS10: =L10*$AG10 -> 662.60489 | BT10: =M10*$AG10 -> 562.94568 | BU10: =N10*$AG10 -> 580.00774 | ... CK10: =AD10*$AG10 -> 0
A11: =VLOOKUP($C11,'Tech Pallet'!$A:$J,10,0) -> PIC | B11: =VLOOKUP(C11,'Tech Pallet'!A:I,3,0) -> BJ PTS | C11: =VLOOKUP($D11,'DU -UCC'!B:C,2,0) -> 84135718 | D11: 10076840100580 | E11: BJ US-IC-ChocChpCookDgh-FH-8 1PT | F11: 1639854 | G11: 95231 | H11: 131625 | I11: 156920 | J11: 139328 | K11: 141551 | L11: 176745 | M11: 126399 | N11: 139939 | O11: 136547 | P11: 111172 | Q11: 115528 | R11: 122881 | AE11: =SUM(F11:AD11) -> 3233720 | AF11: =VLOOKUP($C11,'Tech Pallet'!$A:$I,9,0) -> 240 | AG11: =VLOOKUP($C11,'Tech Pallet'!$A:$H,8,0) -> 0.003785344 | AH11: =SUM(G11:R11) -> 1593866 | AI11: =SUM(S11:AD11) -> 0 | AJ11: =F11/AF11 -> 6832.725 | AK11: =SUM(G11:R11)/AF11 -> 6641.1083 | AL11: =SUM(S11:AD11)/AF11 -> 0 | AM11: =G11/$AF11 -> 396.79583 | AN11: =H11/$AF11 -> 548.4375 | AO11: =I11/$AF11 -> 653.83333 | AP11: =J11/$AF11 -> 580.53333 | AQ11: =K11/$AF11 -> 589.79583 | AR11: =L11/$AF11 -> 736.4375 | AS11: =M11/$AF11 -> 526.6625 | AT11: =N11/$AF11 -> 583.07917 | ... BJ11: =AD11/$AF11 -> 0 | BK11: =F11*AG11 -> 6207.4115 | BL11: =SUM(G11:R11)*AG11 -> 6033.3311 | BM11: =SUM(S11:AD11)*AG11 -> 0 | BN11: =G11*$AG11 -> 360.48209 | BO11: =H11*$AG11 -> 498.2459 | BP11: =I11*$AG11 -> 593.99618 | BQ11: =J11*$AG11 -> 527.40441 | BR11: =K11*$AG11 -> 535.81923 | BS11: =L11*$AG11 -> 669.04063 | BT11: =M11*$AG11 -> 478.4637 | BU11: =N11*$AG11 -> 529.71725 | ... CK11: =AD11*$AG11 -> 0
A12: =VLOOKUP($C12,'Tech Pallet'!$A:$J,10,0) -> PIC | B12: =VLOOKUP(C12,'Tech Pallet'!A:I,3,0) -> 48oz | C12: =VLOOKUP($D12,'DU -UCC'!B:C,2,0) -> 68851105 | D12: 10077567254266 | E12: BR HA VAN CHOC STRAW 6 1.5QT | F12: 1530765 | G12: 92028 | H12: 112884 | I12: 154385 | J12: 156312 | K12: 136576 | L12: 173728 | M12: 145424 | N12: 138630 | O12: 130971 | P12: 126687 | Q12: 123036 | R12: 118736 | AE12: =SUM(F12:AD12) -> 3140162 | AF12: =VLOOKUP($C12,'Tech Pallet'!$A:$I,9,0) -> 154 | AG12: =VLOOKUP($C12,'Tech Pallet'!$A:$H,8,0) -> 0.00852 | AH12: =SUM(G12:R12) -> 1609397 | AI12: =SUM(S12:AD12) -> 0 | AJ12: =F12/AF12 -> 9940.0325 | AK12: =SUM(G12:R12)/AF12 -> 10450.63 | AL12: =SUM(S12:AD12)/AF12 -> 0 | AM12: =G12/$AF12 -> 597.58442 | AN12: =H12/$AF12 -> 733.01299 | AO12: =I12/$AF12 -> 1002.5 | AP12: =J12/$AF12 -> 1015.013 | AQ12: =K12/$AF12 -> 886.85714 | AR12: =L12/$AF12 -> 1128.1039 | AS12: =M12/$AF12 -> 944.31169 | AT12: =N12/$AF12 -> 900.19481 | ... BJ12: =AD12/$AF12 -> 0 | BK12: =F12*AG12 -> 13042.118 | BL12: =SUM(G12:R12)*AG12 -> 13712.062 | BM12: =SUM(S12:AD12)*AG12 -> 0 | BN12: =G12*$AG12 -> 784.07856 | BO12: =H12*$AG12 -> 961.77168 | BP12: =I12*$AG12 -> 1315.3602 | BQ12: =J12*$AG12 -> 1331.7782 | BR12: =K12*$AG12 -> 1163.6275 | BS12: =L12*$AG12 -> 1480.1626 | BT12: =M12*$AG12 -> 1239.0125 | BU12: =N12*$AG12 -> 1181.1276 | ... CK12: =AD12*$AG12 -> 0
A13: =VLOOKUP($C13,'Tech Pallet'!$A:$J,10,0) -> NOV | B13: =VLOOKUP(C13,'Tech Pallet'!A:I,3,0) -> PG | C13: =VLOOKUP($D13,'DU -UCC'!B:C,2,0) -> 69629468 | D13: 10077567001587 | E13: PS Fudgesicle NSA 6-18PK | F13: 1691084 | G13: 75593 | H13: 121711 | I13: 117287 | J13: 147537 | K13: 245987 | L13: 180677 | M13: 186867 | N13: 162111 | O13: 104846 | P13: 83732 | Q13: 85475 | R13: 84176 | AE13: =SUM(F13:AD13) -> 3287083 | AF13: =VLOOKUP($C13,'Tech Pallet'!$A:$I,9,0) -> 130 | AG13: =VLOOKUP($C13,'Tech Pallet'!$A:$H,8,0) -> 0.005268 | AH13: =SUM(G13:R13) -> 1595999 | AI13: =SUM(S13:AD13) -> 0 | AJ13: =F13/AF13 -> 13008.338 | AK13: =SUM(G13:R13)/AF13 -> 12276.915 | AL13: =SUM(S13:AD13)/AF13 -> 0 | AM13: =G13/$AF13 -> 581.48462 | AN13: =H13/$AF13 -> 936.23846 | AO13: =I13/$AF13 -> 902.20769 | AP13: =J13/$AF13 -> 1134.9 | AQ13: =K13/$AF13 -> 1892.2077 | AR13: =L13/$AF13 -> 1389.8231 | AS13: =M13/$AF13 -> 1437.4385 | AT13: =N13/$AF13 -> 1247.0077 | ... BJ13: =AD13/$AF13 -> 0 | BK13: =F13*AG13 -> 8908.6305 | BL13: =SUM(G13:R13)*AG13 -> 8407.7227 | BM13: =SUM(S13:AD13)*AG13 -> 0 | BN13: =G13*$AG13 -> 398.22392 | BO13: =H13*$AG13 -> 641.17355 | BP13: =I13*$AG13 -> 617.86792 | BQ13: =J13*$AG13 -> 777.22492 | BR13: =K13*$AG13 -> 1295.8595 | BS13: =L13*$AG13 -> 951.80644 | BT13: =M13*$AG13 -> 984.41536 | BU13: =N13*$AG13 -> 854.00075 | ... CK13: =AD13*$AG13 -> 0
A14: =VLOOKUP($C14,'Tech Pallet'!$A:$J,10,0) -> PIC | B14: =VLOOKUP(C14,'Tech Pallet'!A:I,3,0) -> BJ PTS | C14: =VLOOKUP($D14,'DU -UCC'!B:C,2,0) -> 67794169 | D14: 10076840485113 | E14: BJ US-IC-TonightDough-FH-8 1PT | F14: 1422102 | G14: 80535 | H14: 120462 | I14: 140689 | J14: 114752 | K14: 117166 | L14: 144132 | M14: 113027 | N14: 121408 | O14: 122163 | P14: 101388 | Q14: 97052 | R14: 97922 | AE14: =SUM(F14:AD14) -> 2792798 | AF14: =VLOOKUP($C14,'Tech Pallet'!$A:$I,9,0) -> 240 | AG14: =VLOOKUP($C14,'Tech Pallet'!$A:$H,8,0) -> 0.003785344 | AH14: =SUM(G14:R14) -> 1370696 | AI14: =SUM(S14:AD14) -> 0 | AJ14: =F14/AF14 -> 5925.425 | AK14: =SUM(G14:R14)/AF14 -> 5711.2333 | AL14: =SUM(S14:AD14)/AF14 -> 0 | AM14: =G14/$AF14 -> 335.5625 | AN14: =H14/$AF14 -> 501.925 | AO14: =I14/$AF14 -> 586.20417 | AP14: =J14/$AF14 -> 478.13333 | AQ14: =K14/$AF14 -> 488.19167 | AR14: =L14/$AF14 -> 600.55 | AS14: =M14/$AF14 -> 470.94583 | AT14: =N14/$AF14 -> 505.86667 | ... BJ14: =AD14/$AF14 -> 0 | BK14: =F14*AG14 -> 5383.1453 | BL14: =SUM(G14:R14)*AG14 -> 5188.5559 | BM14: =SUM(S14:AD14)*AG14 -> 0 | BN14: =G14*$AG14 -> 304.85268 | BO14: =H14*$AG14 -> 455.99011 | BP14: =I14*$AG14 -> 532.55626 | BQ14: =J14*$AG14 -> 434.37579 | BR14: =K14*$AG14 -> 443.51362 | BS14: =L14*$AG14 -> 545.5892 | BT14: =M14*$AG14 -> 427.84608 | BU14: =N14*$AG14 -> 459.57104 | ... CK14: =AD14*$AG14 -> 0
... A51: =VLOOKUP($C51,'Tech Pallet'!$A:$J,10,0) -> PIC | B51: =VLOOKUP(C51,'Tech Pallet'!A:I,3,0) -> 48oz | C51: =VLOOKUP($D51,'DU -UCC'!B:C,2,0) -> 68821735 | D51: 10077567227000 | E51: BR LACTOSE FR VAN 6 1.5QT | F51: 733012 | G51: 38859 | H51: 50166 | I51: 58322 | J51: 68783 | K51: 56191 | L51: 74767 | M51: 61120 | N51: 68857 | O51: 51271 | P51: 50894 | Q51: 61898 | R51: 58923 | AE51: =SUM(F51:AD51) -> 1433063 | AF51: =VLOOKUP($C51,'Tech Pallet'!$A:$I,9,0) -> 176 | AG51: =VLOOKUP($C51,'Tech Pallet'!$A:$H,8,0) -> 0.00852 | AH51: =SUM(G51:R51) -> 700051 | AI51: =SUM(S51:AD51) -> 0 | AJ51: =F51/AF51 -> 4164.8409 | AK51: =SUM(G51:R51)/AF51 -> 3977.5625 | AL51: =SUM(S51:AD51)/AF51 -> 0 | AM51: =G51/$AF51 -> 220.78977 | AN51: =H51/$AF51 -> 285.03409 | AO51: =I51/$AF51 -> 331.375 | AP51: =J51/$AF51 -> 390.8125 | AQ51: =K51/$AF51 -> 319.26705 | AR51: =L51/$AF51 -> 424.8125 | AS51: =M51/$AF51 -> 347.27273 | AT51: =N51/$AF51 -> 391.23295 | ... BJ51: =AD51/$AF51 -> 0 | BK51: =F51*AG51 -> 6245.2622 | BL51: =SUM(G51:R51)*AG51 -> 5964.4345 | BM51: =SUM(S51:AD51)*AG51 -> 0 | BN51: =G51*$AG51 -> 331.07868 | BO51: =H51*$AG51 -> 427.41432 | BP51: =I51*$AG51 -> 496.90344 | BQ51: =J51*$AG51 -> 586.03116 | BR51: =K51*$AG51 -> 478.74732 | BS51: =L51*$AG51 -> 637.01484 | BT51: =M51*$AG51 -> 520.7424 | BU51: =N51*$AG51 -> 586.66164 | ... CK51: =AD51*$AG51 -> 0
A52: =VLOOKUP($C52,'Tech Pallet'!$A:$J,10,0) -> NOV | B52: =VLOOKUP(C52,'Tech Pallet'!A:I,3,0) -> MG Sticks | C52: =VLOOKUP($D52,'DU -UCC'!B:C,2,0) -> 65594416 | D52: 10077567004953 | E52: MG Bars Dubai Chocolate 1-12pk | G52: 0 | H52: 0 | I52: 0 | J52: 0 | K52: 0 | L52: 0 | M52: 0 | N52: 0 | O52: 0 | P52: 0 | Q52: 0 | R52: 0 | AE52: =SUM(F52:AD52) -> 0 | AF52: =VLOOKUP($C52,'Tech Pallet'!$A:$I,9,0) -> 432 | AG52: =VLOOKUP($C52,'Tech Pallet'!$A:$H,8,0) -> 0.00096 | AH52: =SUM(G52:R52) -> 0 | AI52: =SUM(S52:AD52) -> 0 | AJ52: =F52/AF52 -> 0 | AK52: =SUM(G52:R52)/AF52 -> 0 | AL52: =SUM(S52:AD52)/AF52 -> 0 | AM52: =G52/$AF52 -> 0 | AN52: =H52/$AF52 -> 0 | AO52: =I52/$AF52 -> 0 | AP52: =J52/$AF52 -> 0 | AQ52: =K52/$AF52 -> 0 | AR52: =L52/$AF52 -> 0 | AS52: =M52/$AF52 -> 0 | AT52: =N52/$AF52 -> 0 | ... BJ52: =AD52/$AF52 -> 0 | BK52: =F52*AG52 -> 0 | BL52: =SUM(G52:R52)*AG52 -> 0 | BM52: =SUM(S52:AD52)*AG52 -> 0 | BN52: =G52*$AG52 -> 0 | BO52: =H52*$AG52 -> 0 | BP52: =I52*$AG52 -> 0 | BQ52: =J52*$AG52 -> 0 | BR52: =K52*$AG52 -> 0 | BS52: =L52*$AG52 -> 0 | BT52: =M52*$AG52 -> 0 | BU52: =N52*$AG52 -> 0 | ... CK52: =AD52*$AG52 -> 0
A53: =VLOOKUP($C53,'Tech Pallet'!$A:$J,10,0) -> PIC | B53: =VLOOKUP(C53,'Tech Pallet'!A:I,3,0) -> Talenti | C53: =VLOOKUP($D53,'DU -UCC'!B:C,2,0) -> 68860059 | D53: 20186852000093 | E53: Talenti Pacific Coast Pistachio 8-1PT | F53: 623979 | G53: 43532 | H53: 47775 | I53: 54683 | J53: 60090 | K53: 65286 | L53: 66486 | M53: 56295 | N53: 48730 | O53: 50812 | P53: 45105 | Q53: 43170 | R53: 43290 | AE53: =SUM(F53:AD53) -> 1249233 | AF53: =VLOOKUP($C53,'Tech Pallet'!$A:$I,9,0) -> 255 | AG53: =VLOOKUP($C53,'Tech Pallet'!$A:$H,8,0) -> 0.003784 | AH53: =SUM(G53:R53) -> 625254 | AI53: =SUM(S53:AD53) -> 0 | AJ53: =F53/AF53 -> 2446.9765 | AK53: =SUM(G53:R53)/AF53 -> 2451.9765 | AL53: =SUM(S53:AD53)/AF53 -> 0 | AM53: =G53/$AF53 -> 170.71373 | AN53: =H53/$AF53 -> 187.35294 | AO53: =I53/$AF53 -> 214.44314 | AP53: =J53/$AF53 -> 235.64706 | AQ53: =K53/$AF53 -> 256.02353 | AR53: =L53/$AF53 -> 260.72941 | AS53: =M53/$AF53 -> 220.76471 | AT53: =N53/$AF53 -> 191.09804 | ... BJ53: =AD53/$AF53 -> 0 | BK53: =F53*AG53 -> 2361.1365 | BL53: =SUM(G53:R53)*AG53 -> 2365.9611 | BM53: =SUM(S53:AD53)*AG53 -> 0 | BN53: =G53*$AG53 -> 164.72509 | BO53: =H53*$AG53 -> 180.7806 | BP53: =I53*$AG53 -> 206.92047 | BQ53: =J53*$AG53 -> 227.38056 | BR53: =K53*$AG53 -> 247.04222 | BS53: =L53*$AG53 -> 251.58302 | BT53: =M53*$AG53 -> 213.02028 | BU53: =N53*$AG53 -> 184.39432 | ... CK53: =AD53*$AG53 -> 0
A54: =VLOOKUP($C54,'Tech Pallet'!$A:$J,10,0) -> PIC | B54: =VLOOKUP(C54,'Tech Pallet'!A:I,3,0) -> 48oz | C54: =VLOOKUP($D54,'DU -UCC'!B:C,2,0) -> 68821734 | D54: 10077567254259 | E54: BR Vanilla Chocolate 6 1.5QT | F54: 595254 | G54: 39050 | H54: 43575 | I54: 49237 | J54: 60866 | K54: 55214 | L54: 70378 | M54: 51893 | N54: 52625 | O54: 44695 | P54: 44901 | Q54: 55638 | R54: 50655 | AE54: =SUM(F54:AD54) -> 1213981 | AF54: =VLOOKUP($C54,'Tech Pallet'!$A:$I,9,0) -> 176 | AG54: =VLOOKUP($C54,'Tech Pallet'!$A:$H,8,0) -> 0.00852 | AH54: =SUM(G54:R54) -> 618727 | AI54: =SUM(S54:AD54) -> 0 | AJ54: =F54/AF54 -> 3382.125 | AK54: =SUM(G54:R54)/AF54 -> 3515.4943 | AL54: =SUM(S54:AD54)/AF54 -> 0 | AM54: =G54/$AF54 -> 221.875 | AN54: =H54/$AF54 -> 247.58523 | AO54: =I54/$AF54 -> 279.75568 | AP54: =J54/$AF54 -> 345.82955 | AQ54: =K54/$AF54 -> 313.71591 | AR54: =L54/$AF54 -> 399.875 | AS54: =M54/$AF54 -> 294.84659 | AT54: =N54/$AF54 -> 299.00568 | ... BJ54: =AD54/$AF54 -> 0 | BK54: =F54*AG54 -> 5071.5641 | BL54: =SUM(G54:R54)*AG54 -> 5271.554 | BM54: =SUM(S54:AD54)*AG54 -> 0 | BN54: =G54*$AG54 -> 332.706 | BO54: =H54*$AG54 -> 371.259 | BP54: =I54*$AG54 -> 419.49924 | BQ54: =J54*$AG54 -> 518.57832 | BR54: =K54*$AG54 -> 470.42328 | BS54: =L54*$AG54 -> 599.62056 | BT54: =M54*$AG54 -> 442.12836 | BU54: =N54*$AG54 -> 448.365 | ... CK54: =AD54*$AG54 -> 0
A55: =VLOOKUP($C55,'Tech Pallet'!$A:$J,10,0) -> NOV | B55: =VLOOKUP(C55,'Tech Pallet'!A:I,3,0) -> MG Sticks | C55: =VLOOKUP($D55,'DU -UCC'!B:C,2,0) -> 64331550 | D55: 10077567158939 | E55: MG Double Caramel RFA 1-12BK | F55: 629824 | G55: 15946 | H55: 29948 | I55: 45506 | J55: 64237 | K55: 34196 | L55: 104478.09 | M55: 42788 | N55: 59612 | O55: 45374 | P55: 62933 | Q55: 39962 | R55: 24911 | AE55: =SUM(F55:AD55) -> 1199715.1 | AF55: =VLOOKUP($C55,'Tech Pallet'!$A:$I,9,0) -> 493 | AG55: =VLOOKUP($C55,'Tech Pallet'!$A:$H,8,0) -> 0.00108 | AH55: =SUM(G55:R55) -> 569891.09 | AI55: =SUM(S55:AD55) -> 0 | AJ55: =F55/AF55 -> 1277.5335 | AK55: =SUM(G55:R55)/AF55 -> 1155.9657 | AL55: =SUM(S55:AD55)/AF55 -> 0 | AM55: =G55/$AF55 -> 32.344828 | AN55: =H55/$AF55 -> 60.74645 | AO55: =I55/$AF55 -> 92.30426 | AP55: =J55/$AF55 -> 130.29817 | AQ55: =K55/$AF55 -> 69.363083 | AR55: =L55/$AF55 -> 211.9231 | AS55: =M55/$AF55 -> 86.791075 | AT55: =N55/$AF55 -> 120.91684 | ... BJ55: =AD55/$AF55 -> 0 | BK55: =F55*AG55 -> 680.20992 | BL55: =SUM(G55:R55)*AG55 -> 615.48238 | BM55: =SUM(S55:AD55)*AG55 -> 0 | BN55: =G55*$AG55 -> 17.22168 | BO55: =H55*$AG55 -> 32.34384 | BP55: =I55*$AG55 -> 49.14648 | BQ55: =J55*$AG55 -> 69.37596 | BR55: =K55*$AG55 -> 36.93168 | BS55: =L55*$AG55 -> 112.83634 | BT55: =M55*$AG55 -> 46.21104 | BU55: =N55*$AG55 -> 64.38096 | ... CK55: =AD55*$AG55 -> 0
A56: =VLOOKUP($C56,'Tech Pallet'!$A:$J,10,0) -> NOV | B56: =VLOOKUP(C56,'Tech Pallet'!A:I,3,0) -> MBG | C56: =VLOOKUP($D56,'DU -UCC'!B:C,2,0) -> 68741714 | D56: 10041000054140 | E56: GH STRAW Shortcake Bar 1-24PK OOH | F56: 664800 | G56: 32430 | H56: 26889 | I56: 46592 | J56: 65086 | K56: 82538 | L56: 91151 | M56: 106731 | N56: 74016 | O56: 60707 | P56: 22830 | Q56: 22920 | R56: 24324 | AE56: =SUM(F56:AD56) -> 1321014 | AF56: =VLOOKUP($C56,'Tech Pallet'!$A:$I,9,0) -> 225 | AG56: =VLOOKUP($C56,'Tech Pallet'!$A:$H,8,0) -> 0.002832 | AH56: =SUM(G56:R56) -> 656214 | AI56: =SUM(S56:AD56) -> 0 | AJ56: =F56/AF56 -> 2954.6667 | AK56: =SUM(G56:R56)/AF56 -> 2916.5067 | AL56: =SUM(S56:AD56)/AF56 -> 0 | AM56: =G56/$AF56 -> 144.13333 | AN56: =H56/$AF56 -> 119.50667 | AO56: =I56/$AF56 -> 207.07556 | AP56: =J56/$AF56 -> 289.27111 | AQ56: =K56/$AF56 -> 366.83556 | AR56: =L56/$AF56 -> 405.11556 | AS56: =M56/$AF56 -> 474.36 | AT56: =N56/$AF56 -> 328.96 | ... BJ56: =AD56/$AF56 -> 0 | BK56: =F56*AG56 -> 1882.7136 | BL56: =SUM(G56:R56)*AG56 -> 1858.398 | BM56: =SUM(S56:AD56)*AG56 -> 0 | BN56: =G56*$AG56 -> 91.84176 | BO56: =H56*$AG56 -> 76.149648 | BP56: =I56*$AG56 -> 131.94854 | BQ56: =J56*$AG56 -> 184.32355 | BR56: =K56*$AG56 -> 233.74762 | BS56: =L56*$AG56 -> 258.13963 | BT56: =M56*$AG56 -> 302.26219 | BU56: =N56*$AG56 -> 209.61331 | ... CK56: =AD56*$AG56 -> 0
A57: =VLOOKUP($C57,'Tech Pallet'!$A:$J,10,0) -> PIC | B57: =VLOOKUP(C57,'Tech Pallet'!A:I,3,0) -> TALENTI | C57: =VLOOKUP($D57,'DU -UCC'!B:C,2,0) -> 68862496 | D57: 20186852000185 | E57: TAL Alphonso Mango Sorbetto (Df) 8p 1PT | F57: 581670 | G57: 41281 | H57: 45510 | I57: 51525 | J57: 53722 | K57: 57777 | L57: 68355 | M57: 55125 | N57: 46695 | O57: 47280 | P57: 41700 | Q57: 36840 | R57: 40500 | AE57: =SUM(F57:AD57) -> 1167980 | AF57: =VLOOKUP($C57,'Tech Pallet'!$A:$I,9,0) -> 255 | AG57: =VLOOKUP($C57,'Tech Pallet'!$A:$H,8,0) -> 0.003784 | AH57: =SUM(G57:R57) -> 586310 | AI57: =SUM(S57:AD57) -> 0 | AJ57: =F57/AF57 -> 2281.0588 | AK57: =SUM(G57:R57)/AF57 -> 2299.2549 | AL57: =SUM(S57:AD57)/AF57 -> 0 | AM57: =G57/$AF57 -> 161.88627 | AN57: =H57/$AF57 -> 178.47059 | AO57: =I57/$AF57 -> 202.05882 | AP57: =J57/$AF57 -> 210.67451 | AQ57: =K57/$AF57 -> 226.57647 | AR57: =L57/$AF57 -> 268.05882 | AS57: =M57/$AF57 -> 216.17647 | AT57: =N57/$AF57 -> 183.11765 | ... BJ57: =AD57/$AF57 -> 0 | BK57: =F57*AG57 -> 2201.0393 | BL57: =SUM(G57:R57)*AG57 -> 2218.597 | BM57: =SUM(S57:AD57)*AG57 -> 0 | BN57: =G57*$AG57 -> 156.2073 | BO57: =H57*$AG57 -> 172.20984 | BP57: =I57*$AG57 -> 194.9706 | BQ57: =J57*$AG57 -> 203.28405 | BR57: =K57*$AG57 -> 218.62817 | BS57: =L57*$AG57 -> 258.65532 | BT57: =M57*$AG57 -> 208.593 | BU57: =N57*$AG57 -> 176.69388 | ... CK57: =AD57*$AG57 -> 0
A58: =VLOOKUP($C58,'Tech Pallet'!$A:$J,10,0) -> NOV | B58: =VLOOKUP(C58,'Tech Pallet'!A:I,3,0) -> PG | C58: =VLOOKUP($D58,'DU -UCC'!B:C,2,0) -> 64341106 | D58: 10077567085167 | E58: PS Jolly Rancher Pop 6-18PK | F58: 745716 | G58: 31109 | H58: 41665 | I58: 55128 | J58: 60658 | K58: 110519 | L58: 91585 | M58: 75413 | N58: 52702 | O58: 39962 | P58: 28301 | Q58: 29094 | R58: 35553 | AE58: =SUM(F58:AD58) -> 1397405 | AF58: =VLOOKUP($C58,'Tech Pallet'!$A:$I,9,0) -> 130 | AG58: =VLOOKUP($C58,'Tech Pallet'!$A:$H,8,0) -> 0.005268 | AH58: =SUM(G58:R58) -> 651689 | AI58: =SUM(S58:AD58) -> 0 | AJ58: =F58/AF58 -> 5736.2769 | AK58: =SUM(G58:R58)/AF58 -> 5012.9923 | AL58: =SUM(S58:AD58)/AF58 -> 0 | AM58: =G58/$AF58 -> 239.3 | AN58: =H58/$AF58 -> 320.5 | AO58: =I58/$AF58 -> 424.06154 | AP58: =J58/$AF58 -> 466.6 | AQ58: =K58/$AF58 -> 850.14615 | AR58: =L58/$AF58 -> 704.5 | AS58: =M58/$AF58 -> 580.1 | AT58: =N58/$AF58 -> 405.4 | ... BJ58: =AD58/$AF58 -> 0 | BK58: =F58*AG58 -> 3928.4319 | BL58: =SUM(G58:R58)*AG58 -> 3433.0977 | BM58: =SUM(S58:AD58)*AG58 -> 0 | BN58: =G58*$AG58 -> 163.88221 | BO58: =H58*$AG58 -> 219.49122 | BP58: =I58*$AG58 -> 290.4143 | BQ58: =J58*$AG58 -> 319.54634 | BR58: =K58*$AG58 -> 582.21409 | BS58: =L58*$AG58 -> 482.46978 | BT58: =M58*$AG58 -> 397.27568 | BU58: =N58*$AG58 -> 277.63414 | ... CK58: =AD58*$AG58 -> 0
A59: =VLOOKUP($C59,'Tech Pallet'!$A:$J,10,0) -> PIC | B59: =VLOOKUP(C59,'Tech Pallet'!A:I,3,0) -> 48oz | C59: =VLOOKUP($D59,'DU -UCC'!B:C,2,0) -> 64389651 | D59: 10077567003901 | E59: BR Strawberry Shortcake 6 1.5QT | F59: 55 | G59: 11992 | H59: 25915 | I59: 39850 | J59: 59321 | K59: 68877 | L59: 70006 | M59: 71032 | N59: 60927 | O59: 45614 | P59: 37849 | Q59: 50468 | R59: 38412 | AE59: =SUM(F59:AD59) -> 580318 | AF59: =VLOOKUP($C59,'Tech Pallet'!$A:$I,9,0) -> 176 | AG59: =VLOOKUP($C59,'Tech Pallet'!$A:$H,8,0) -> 0.00852 | AH59: =SUM(G59:R59) -> 580263 | AI59: =SUM(S59:AD59) -> 0 | AJ59: =F59/AF59 -> 0.3125 | AK59: =SUM(G59:R59)/AF59 -> 3296.9489 | AL59: =SUM(S59:AD59)/AF59 -> 0 | AM59: =G59/$AF59 -> 68.136364 | AN59: =H59/$AF59 -> 147.24432 | AO59: =I59/$AF59 -> 226.42045 | AP59: =J59/$AF59 -> 337.05114 | AQ59: =K59/$AF59 -> 391.34659 | AR59: =L59/$AF59 -> 397.76136 | AS59: =M59/$AF59 -> 403.59091 | AT59: =N59/$AF59 -> 346.17614 | ... BJ59: =AD59/$AF59 -> 0 | BK59: =F59*AG59 -> 0.4686 | BL59: =SUM(G59:R59)*AG59 -> 4943.8408 | BM59: =SUM(S59:AD59)*AG59 -> 0 | BN59: =G59*$AG59 -> 102.17184 | BO59: =H59*$AG59 -> 220.7958 | BP59: =I59*$AG59 -> 339.522 | BQ59: =J59*$AG59 -> 505.41492 | BR59: =K59*$AG59 -> 586.83204 | BS59: =L59*$AG59 -> 596.45112 | BT59: =M59*$AG59 -> 605.19264 | BU59: =N59*$AG59 -> 519.09804 | ... CK59: =AD59*$AG59 -> 0
A60: =VLOOKUP($C60,'Tech Pallet'!$A:$J,10,0) -> PIC | B60: =VLOOKUP(C60,'Tech Pallet'!A:I,3,0) -> BJ PTS | C60: =VLOOKUP($D60,'DU -UCC'!B:C,2,0) -> 69999267 | D60: 10076840002358 | E60: BJ US-IC-GimmeSmore-8 1PT | F60: 574596 | G60: 33118 | H60: 60510 | I60: 59696 | J60: 52330 | K60: 51477 | L60: 64273 | M60: 58029 | N60: 53027 | O60: 50749 | P60: 42539 | Q60: 42430 | R60: 37768 | AE60: =SUM(F60:AD60) -> 1180542 | AF60: =VLOOKUP($C60,'Tech Pallet'!$A:$I,9,0) -> 240 | AG60: =VLOOKUP($C60,'Tech Pallet'!$A:$H,8,0) -> 0.003784 | AH60: =SUM(G60:R60) -> 605946 | AI60: =SUM(S60:AD60) -> 0 | AJ60: =F60/AF60 -> 2394.15 | AK60: =SUM(G60:R60)/AF60 -> 2524.775 | AL60: =SUM(S60:AD60)/AF60 -> 0 | AM60: =G60/$AF60 -> 137.99167 | AN60: =H60/$AF60 -> 252.125 | AO60: =I60/$AF60 -> 248.73333 | AP60: =J60/$AF60 -> 218.04167 | AQ60: =K60/$AF60 -> 214.4875 | AR60: =L60/$AF60 -> 267.80417 | AS60: =M60/$AF60 -> 241.7875 | AT60: =N60/$AF60 -> 220.94583 | ... BJ60: =AD60/$AF60 -> 0 | BK60: =F60*AG60 -> 2174.2713 | BL60: =SUM(G60:R60)*AG60 -> 2292.8997 | BM60: =SUM(S60:AD60)*AG60 -> 0 | BN60: =G60*$AG60 -> 125.31851 | BO60: =H60*$AG60 -> 228.96984 | BP60: =I60*$AG60 -> 225.88966 | BQ60: =J60*$AG60 -> 198.01672 | BR60: =K60*$AG60 -> 194.78897 | BS60: =L60*$AG60 -> 243.20903 | BT60: =M60*$AG60 -> 219.58174 | BU60: =N60*$AG60 -> 200.65417 | ... CK60: =AD60*$AG60 -> 0
A61: =VLOOKUP($C61,'Tech Pallet'!$A:$J,10,0) -> NOV | B61: =VLOOKUP(C61,'Tech Pallet'!A:I,3,0) -> Yasso Sticks | C61: =VLOOKUP($D61,'DU -UCC'!B:C,2,0) -> 64325512 | D61: 10851035003323 | E61: Yasso Coffee Chocolate Chip 8-4pk | F61: 500809 | G61: 32065 | H61: 45895 | I61: 55745 | J61: 51171 | K61: 51621 | L61: 30218 | M61: 45920 | N61: 71804.01 | O61: 56402 | P61: 32208 | Q61: 35739 | R61: 38796 | AE61: =SUM(F61:AD61) -> 1048393 | AF61: =VLOOKUP($C61,'Tech Pallet'!$A:$I,9,0) -> 187 | AG61: =VLOOKUP($C61,'Tech Pallet'!$A:$H,8,0) -> 0.003312 | AH61: =SUM(G61:R61) -> 547584.01 | AI61: =SUM(S61:AD61) -> 0 | AJ61: =F61/AF61 -> 2678.123 | AK61: =SUM(G61:R61)/AF61 -> 2928.2567 | AL61: =SUM(S61:AD61)/AF61 -> 0 | AM61: =G61/$AF61 -> 171.47059 | AN61: =H61/$AF61 -> 245.42781 | AO61: =I61/$AF61 -> 298.1016 | AP61: =J61/$AF61 -> 273.64171 | AQ61: =K61/$AF61 -> 276.04813 | AR61: =L61/$AF61 -> 161.59358 | AS61: =M61/$AF61 -> 245.5615 | AT61: =N61/$AF61 -> 383.97866 | ... BJ61: =AD61/$AF61 -> 0 | BK61: =F61*AG61 -> 1658.6794 | BL61: =SUM(G61:R61)*AG61 -> 1813.5982 | BM61: =SUM(S61:AD61)*AG61 -> 0 | BN61: =G61*$AG61 -> 106.19928 | BO61: =H61*$AG61 -> 152.00424 | BP61: =I61*$AG61 -> 184.62744 | BQ61: =J61*$AG61 -> 169.47835 | BR61: =K61*$AG61 -> 170.96875 | BS61: =L61*$AG61 -> 100.08202 | BT61: =M61*$AG61 -> 152.08704 | BU61: =N61*$AG61 -> 237.81488 | ... CK61: =AD61*$AG61 -> 0
A62: =VLOOKUP($C62,'Tech Pallet'!$A:$J,10,0) -> NOV | B62: =VLOOKUP(C62,'Tech Pallet'!A:I,3,0) -> Yasso Sticks | C62: =VLOOKUP($D62,'DU -UCC'!B:C,2,0) -> 64325372 | D62: 10851035003248 | E62: Yasso Sea Salt Caramel 8-4pk | F62: 519632 | G62: 30787 | H62: 44471 | I62: 57239 | J62: 42208 | K62: 24701 | L62: 75722 | M62: 57403 | N62: 55649 | O62: 49392 | P62: 36931 | Q62: 33313 | R62: 37111 | AE62: =SUM(F62:AD62) -> 1064559 | AF62: =VLOOKUP($C62,'Tech Pallet'!$A:$I,9,0) -> 187 | AG62: =VLOOKUP($C62,'Tech Pallet'!$A:$H,8,0) -> 0.003312 | AH62: =SUM(G62:R62) -> 544927 | AI62: =SUM(S62:AD62) -> 0 | AJ62: =F62/AF62 -> 2778.7807 | AK62: =SUM(G62:R62)/AF62 -> 2914.0481 | AL62: =SUM(S62:AD62)/AF62 -> 0 | AM62: =G62/$AF62 -> 164.63636 | AN62: =H62/$AF62 -> 237.81283 | AO62: =I62/$AF62 -> 306.09091 | AP62: =J62/$AF62 -> 225.71123 | AQ62: =K62/$AF62 -> 132.09091 | AR62: =L62/$AF62 -> 404.93048 | AS62: =M62/$AF62 -> 306.96791 | AT62: =N62/$AF62 -> 297.58824 | ... BJ62: =AD62/$AF62 -> 0 | BK62: =F62*AG62 -> 1721.0212 | BL62: =SUM(G62:R62)*AG62 -> 1804.7982 | BM62: =SUM(S62:AD62)*AG62 -> 0 | BN62: =G62*$AG62 -> 101.96654 | BO62: =H62*$AG62 -> 147.28795 | BP62: =I62*$AG62 -> 189.57557 | BQ62: =J62*$AG62 -> 139.7929 | BR62: =K62*$AG62 -> 81.809712 | BS62: =L62*$AG62 -> 250.79126 | BT62: =M62*$AG62 -> 190.11874 | BU62: =N62*$AG62 -> 184.30949 | ... CK62: =AD62*$AG62 -> 0
A63: =VLOOKUP($C63,'Tech Pallet'!$A:$J,10,0) -> PIC | B63: =VLOOKUP(C63,'Tech Pallet'!A:I,3,0) -> 48oz | C63: =VLOOKUP($D63,'DU -UCC'!B:C,2,0) -> 69568964 | D63: 10077567281903 | E63: BR NSA VANILLA 6 1.5QT | F63: 587257 | G63: 36313 | H63: 41856 | I63: 50923 | J63: 60739 | K63: 49632 | L63: 65591 | M63: 55128 | N63: 60873 | O63: 43956 | P63: 39229 | Q63: 46028 | R63: 40065 | AE63: =SUM(F63:AD63) -> 1177590 | AF63: =VLOOKUP($C63,'Tech Pallet'!$A:$I,9,0) -> 176 | AG63: =VLOOKUP($C63,'Tech Pallet'!$A:$H,8,0) -> 0.00852 | AH63: =SUM(G63:R63) -> 590333 | AI63: =SUM(S63:AD63) -> 0 | AJ63: =F63/AF63 -> 3336.6875 | AK63: =SUM(G63:R63)/AF63 -> 3354.1648 | AL63: =SUM(S63:AD63)/AF63 -> 0 | AM63: =G63/$AF63 -> 206.32386 | AN63: =H63/$AF63 -> 237.81818 | AO63: =I63/$AF63 -> 289.33523 | AP63: =J63/$AF63 -> 345.10795 | AQ63: =K63/$AF63 -> 282 | AR63: =L63/$AF63 -> 372.67614 | AS63: =M63/$AF63 -> 313.22727 | AT63: =N63/$AF63 -> 345.86932 | ... BJ63: =AD63/$AF63 -> 0 | BK63: =F63*AG63 -> 5003.4296 | BL63: =SUM(G63:R63)*AG63 -> 5029.6372 | BM63: =SUM(S63:AD63)*AG63 -> 0 | BN63: =G63*$AG63 -> 309.38676 | BO63: =H63*$AG63 -> 356.61312 | BP63: =I63*$AG63 -> 433.86396 | BQ63: =J63*$AG63 -> 517.49628 | BR63: =K63*$AG63 -> 422.86464 | BS63: =L63*$AG63 -> 558.83532 | BT63: =M63*$AG63 -> 469.69056 | BU63: =N63*$AG63 -> 518.63796 | ... CK63: =AD63*$AG63 -> 0
A64: =VLOOKUP($C64,'Tech Pallet'!$A:$J,10,0) -> PIC | B64: =VLOOKUP(C64,'Tech Pallet'!A:I,3,0) -> 48oz | C64: =VLOOKUP($D64,'DU -UCC'!B:C,2,0) -> 68737750 | D64: 10077567224801 | E64: BR CO-B Reeses 6 1.5QT | F64: 704075 | G64: 38346 | H64: 47301 | I64: 59994 | J64: 71002 | K64: 68931 | L64: 83237 | M64: 66563 | N64: 64570 | O64: 55954 | P64: 48229 | Q64: 48639 | R64: 45639 | AE64: =SUM(F64:AD64) -> 1402480 | AF64: =VLOOKUP($C64,'Tech Pallet'!$A:$I,9,0) -> 176 | AG64: =VLOOKUP($C64,'Tech Pallet'!$A:$H,8,0) -> 0.00852 | AH64: =SUM(G64:R64) -> 698405 | AI64: =SUM(S64:AD64) -> 0 | AJ64: =F64/AF64 -> 4000.4261 | AK64: =SUM(G64:R64)/AF64 -> 3968.2102 | AL64: =SUM(S64:AD64)/AF64 -> 0 | AM64: =G64/$AF64 -> 217.875 | AN64: =H64/$AF64 -> 268.75568 | AO64: =I64/$AF64 -> 340.875 | AP64: =J64/$AF64 -> 403.42045 | AQ64: =K64/$AF64 -> 391.65341 | AR64: =L64/$AF64 -> 472.9375 | AS64: =M64/$AF64 -> 378.19886 | AT64: =N64/$AF64 -> 366.875 | ... BJ64: =AD64/$AF64 -> 0 | BK64: =F64*AG64 -> 5998.719 | BL64: =SUM(G64:R64)*AG64 -> 5950.4106 | BM64: =SUM(S64:AD64)*AG64 -> 0 | BN64: =G64*$AG64 -> 326.70792 | BO64: =H64*$AG64 -> 403.00452 | BP64: =I64*$AG64 -> 511.14888 | BQ64: =J64*$AG64 -> 604.93704 | BR64: =K64*$AG64 -> 587.29212 | BS64: =L64*$AG64 -> 709.17924 | BT64: =M64*$AG64 -> 567.11676 | BU64: =N64*$AG64 -> 550.1364 | ... CK64: =AD64*$AG64 -> 0
... A78: =VLOOKUP($C78,'Tech Pallet'!$A:$J,10,0) -> NOV | B78: =VLOOKUP(C78,'Tech Pallet'!A:I,3,0) -> Yasso Sticks | C78: =VLOOKUP($D78,'DU -UCC'!B:C,2,0) -> 64325513 | D78: 10851035003446 | E78: Yasso Cookies N Cream 8-4pk | F78: 269818 | G78: 20636 | H78: 27982 | I78: 11684 | J78: 19339 | K78: 34730 | L78: 39289 | M78: 33345 | N78: 36484 | O78: 30762 | P78: 15995 | Q78: 22317 | R78: 30374 | AE78: =SUM(F78:AD78) -> 592755 | AF78: =VLOOKUP($C78,'Tech Pallet'!$A:$I,9,0) -> 187 | AG78: =VLOOKUP($C78,'Tech Pallet'!$A:$H,8,0) -> 0.003312 | AH78: =SUM(G78:R78) -> 322937 | AI78: =SUM(S78:AD78) -> 0 | AJ78: =F78/AF78 -> 1442.877 | AK78: =SUM(G78:R78)/AF78 -> 1726.9358 | AL78: =SUM(S78:AD78)/AF78 -> 0 | AM78: =G78/$AF78 -> 110.35294 | AN78: =H78/$AF78 -> 149.63636 | AO78: =I78/$AF78 -> 62.481283 | AP78: =J78/$AF78 -> 103.41711 | AQ78: =K78/$AF78 -> 185.72193 | AR78: =L78/$AF78 -> 210.1016 | AS78: =M78/$AF78 -> 178.31551 | AT78: =N78/$AF78 -> 195.1016 | ... BJ78: =AD78/$AF78 -> 0 | BK78: =F78*AG78 -> 893.63722 | BL78: =SUM(G78:R78)*AG78 -> 1069.5673 | BM78: =SUM(S78:AD78)*AG78 -> 0 | BN78: =G78*$AG78 -> 68.346432 | BO78: =H78*$AG78 -> 92.676384 | BP78: =I78*$AG78 -> 38.697408 | BQ78: =J78*$AG78 -> 64.050768 | BR78: =K78*$AG78 -> 115.02576 | BS78: =L78*$AG78 -> 130.12517 | BT78: =M78*$AG78 -> 110.43864 | BU78: =N78*$AG78 -> 120.83501 | ... CK78: =AD78*$AG78 -> 0
A79: =VLOOKUP($C79,'Tech Pallet'!$A:$J,10,0) -> NOV | B79: =VLOOKUP(C79,'Tech Pallet'!A:I,3,0) -> Other | C79: =VLOOKUP($D79,'DU -UCC'!B:C,2,0) -> 64973976 | D79: 10840473400115 | E79: BR Reeses Mini Cups 1-12PK | G79: 0 | H79: 0 | I79: 0 | J79: 0 | K79: 0 | L79: 0 | M79: 0 | N79: 0 | O79: 0 | P79: 0 | Q79: 0 | R79: 0 | AE79: =SUM(F79:AD79) -> 0 | AF79: =VLOOKUP($C79,'Tech Pallet'!$A:$I,9,0) -> 190 | AG79: =VLOOKUP($C79,'Tech Pallet'!$A:$H,8,0) -> 0.0010644 | AH79: =SUM(G79:R79) -> 0 | AI79: =SUM(S79:AD79) -> 0 | AJ79: =F79/AF79 -> 0 | AK79: =SUM(G79:R79)/AF79 -> 0 | AL79: =SUM(S79:AD79)/AF79 -> 0 | AM79: =G79/$AF79 -> 0 | AN79: =H79/$AF79 -> 0 | AO79: =I79/$AF79 -> 0 | AP79: =J79/$AF79 -> 0 | AQ79: =K79/$AF79 -> 0 | AR79: =L79/$AF79 -> 0 | AS79: =M79/$AF79 -> 0 | AT79: =N79/$AF79 -> 0 | ... BJ79: =AD79/$AF79 -> 0 | BK79: =F79*AG79 -> 0 | BL79: =SUM(G79:R79)*AG79 -> 0 | BM79: =SUM(S79:AD79)*AG79 -> 0 | BN79: =G79*$AG79 -> 0 | BO79: =H79*$AG79 -> 0 | BP79: =I79*$AG79 -> 0 | BQ79: =J79*$AG79 -> 0 | BR79: =K79*$AG79 -> 0 | BS79: =L79*$AG79 -> 0 | BT79: =M79*$AG79 -> 0 | BU79: =N79*$AG79 -> 0 | ... CK79: =AD79*$AG79 -> 0
A80: =VLOOKUP($C80,'Tech Pallet'!$A:$J,10,0) -> NOV | B80: =VLOOKUP(C80,'Tech Pallet'!A:I,3,0) -> pG | C80: =VLOOKUP($D80,'DU -UCC'!B:C,2,0) -> 64776954 | D80: 10077567001570 | E80: PS Scribblers Natural 6-18PK | F80: 589779 | G80: 31402 | H80: 49445 | I80: 44418 | J80: 53532 | K80: 67346 | L80: 79037 | M80: 64155 | N80: 50557 | O80: 31158 | P80: 17667 | Q80: 19227 | R80: 26217 | AE80: =SUM(F80:AD80) -> 1123940 | AF80: =VLOOKUP($C80,'Tech Pallet'!$A:$I,9,0) -> 130 | AG80: =VLOOKUP($C80,'Tech Pallet'!$A:$H,8,0) -> 0.003834 | AH80: =SUM(G80:R80) -> 534161 | AI80: =SUM(S80:AD80) -> 0 | AJ80: =F80/AF80 -> 4536.7615 | AK80: =SUM(G80:R80)/AF80 -> 4108.9308 | AL80: =SUM(S80:AD80)/AF80 -> 0 | AM80: =G80/$AF80 -> 241.55385 | AN80: =H80/$AF80 -> 380.34615 | AO80: =I80/$AF80 -> 341.67692 | AP80: =J80/$AF80 -> 411.78462 | AQ80: =K80/$AF80 -> 518.04615 | AR80: =L80/$AF80 -> 607.97692 | AS80: =M80/$AF80 -> 493.5 | AT80: =N80/$AF80 -> 388.9 | ... BJ80: =AD80/$AF80 -> 0 | BK80: =F80*AG80 -> 2261.2127 | BL80: =SUM(G80:R80)*AG80 -> 2047.9733 | BM80: =SUM(S80:AD80)*AG80 -> 0 | BN80: =G80*$AG80 -> 120.39527 | BO80: =H80*$AG80 -> 189.57213 | BP80: =I80*$AG80 -> 170.29861 | BQ80: =J80*$AG80 -> 205.24169 | BR80: =K80*$AG80 -> 258.20456 | BS80: =L80*$AG80 -> 303.02786 | BT80: =M80*$AG80 -> 245.97027 | BU80: =N80*$AG80 -> 193.83554 | ... CK80: =AD80*$AG80 -> 0
A81: =VLOOKUP($C81,'Tech Pallet'!$A:$J,10,0) -> NOV | B81: =VLOOKUP(C81,'Tech Pallet'!A:I,3,0) -> EDF | C81: =VLOOKUP($D81,'DU -UCC'!B:C,2,0) -> 68709233 | D81: 10075856011200 | E81: KL SAB RF NSA VANILLA BAR 12-6PK | F81: 426114 | G81: 25524 | H81: 30516 | I81: 46686 | J81: 39287 | K81: 46255 | L81: 57714 | M81: 50041 | N81: 39132 | O81: 33637 | P81: 32868 | Q81: 25116 | R81: 27036 | AE81: =SUM(F81:AD81) -> 879926 | AF81: =VLOOKUP($C81,'Tech Pallet'!$A:$I,9,0) -> 132 | AG81: =VLOOKUP($C81,'Tech Pallet'!$A:$H,8,0) -> 0.008496 | AH81: =SUM(G81:R81) -> 453812 | AI81: =SUM(S81:AD81) -> 0 | AJ81: =F81/AF81 -> 3228.1364 | AK81: =SUM(G81:R81)/AF81 -> 3437.9697 | AL81: =SUM(S81:AD81)/AF81 -> 0 | AM81: =G81/$AF81 -> 193.36364 | AN81: =H81/$AF81 -> 231.18182 | AO81: =I81/$AF81 -> 353.68182 | AP81: =J81/$AF81 -> 297.62879 | AQ81: =K81/$AF81 -> 350.41667 | AR81: =L81/$AF81 -> 437.22727 | AS81: =M81/$AF81 -> 379.09848 | AT81: =N81/$AF81 -> 296.45455 | ... BJ81: =AD81/$AF81 -> 0 | BK81: =F81*AG81 -> 3620.2645 | BL81: =SUM(G81:R81)*AG81 -> 3855.5868 | BM81: =SUM(S81:AD81)*AG81 -> 0 | BN81: =G81*$AG81 -> 216.8519 | BO81: =H81*$AG81 -> 259.26394 | BP81: =I81*$AG81 -> 396.64426 | BQ81: =J81*$AG81 -> 333.78235 | BR81: =K81*$AG81 -> 392.98248 | BS81: =L81*$AG81 -> 490.33814 | BT81: =M81*$AG81 -> 425.14834 | BU81: =N81*$AG81 -> 332.46547 | ... CK81: =AD81*$AG81 -> 0
A82: =VLOOKUP($C82,'Tech Pallet'!$A:$J,10,0) -> NOV | B82: =VLOOKUP(C82,'Tech Pallet'!A:I,3,0) -> Yasso Sticks | C82: =VLOOKUP($D82,'DU -UCC'!B:C,2,0) -> 64325509 | D82: 10850001974575 | E82: Yasso Fudge Chocolate Crunch 8-4pk | F82: 290105 | G82: 19906 | H82: 26450 | I82: 38854 | J82: 35377 | K82: 40171 | L82: 47707 | M82: 46733 | N82: 40841 | O82: 46747 | P82: 28368 | Q82: 29506 | R82: 24340 | AE82: =SUM(F82:AD82) -> 715105 | AF82: =VLOOKUP($C82,'Tech Pallet'!$A:$I,9,0) -> 187 | AG82: =VLOOKUP($C82,'Tech Pallet'!$A:$H,8,0) -> 0.002512 | AH82: =SUM(G82:R82) -> 425000 | AI82: =SUM(S82:AD82) -> 0 | AJ82: =F82/AF82 -> 1551.3636 | AK82: =SUM(G82:R82)/AF82 -> 2272.7273 | AL82: =SUM(S82:AD82)/AF82 -> 0 | AM82: =G82/$AF82 -> 106.4492 | AN82: =H82/$AF82 -> 141.44385 | AO82: =I82/$AF82 -> 207.7754 | AP82: =J82/$AF82 -> 189.18182 | AQ82: =K82/$AF82 -> 214.81818 | AR82: =L82/$AF82 -> 255.11765 | AS82: =M82/$AF82 -> 249.90909 | AT82: =N82/$AF82 -> 218.40107 | ... BJ82: =AD82/$AF82 -> 0 | BK82: =F82*AG82 -> 728.74376 | BL82: =SUM(G82:R82)*AG82 -> 1067.6 | BM82: =SUM(S82:AD82)*AG82 -> 0 | BN82: =G82*$AG82 -> 50.003872 | BO82: =H82*$AG82 -> 66.4424 | BP82: =I82*$AG82 -> 97.601248 | BQ82: =J82*$AG82 -> 88.867024 | BR82: =K82*$AG82 -> 100.90955 | BS82: =L82*$AG82 -> 119.83998 | BT82: =M82*$AG82 -> 117.3933 | BU82: =N82*$AG82 -> 102.59259 | ... CK82: =AD82*$AG82 -> 0
A83: =VLOOKUP($C83,'Tech Pallet'!$A:$J,10,0) -> PIC | B83: =VLOOKUP(C83,'Tech Pallet'!A:I,3,0) -> TALENTI | C83: =VLOOKUP($D83,'DU -UCC'!B:C,2,0) -> 68730257 | D83: 20186852000079 | E83: Talenti Mediterranean Mint 8 1PT | F83: 501218 | G83: 31980 | H83: 38385 | I83: 46472 | J83: 41701 | K83: 48396 | L83: 52620 | M83: 41550 | N83: 37695 | O83: 36600 | P83: 35550 | Q83: 30435 | R83: 29835 | AE83: =SUM(F83:AD83) -> 972437 | AF83: =VLOOKUP($C83,'Tech Pallet'!$A:$I,9,0) -> 255 | AG83: =VLOOKUP($C83,'Tech Pallet'!$A:$H,8,0) -> 0.003785344 | AH83: =SUM(G83:R83) -> 471219 | AI83: =SUM(S83:AD83) -> 0 | AJ83: =F83/AF83 -> 1965.5608 | AK83: =SUM(G83:R83)/AF83 -> 1847.9176 | AL83: =SUM(S83:AD83)/AF83 -> 0 | AM83: =G83/$AF83 -> 125.41176 | AN83: =H83/$AF83 -> 150.52941 | AO83: =I83/$AF83 -> 182.24314 | AP83: =J83/$AF83 -> 163.53333 | AQ83: =K83/$AF83 -> 189.78824 | AR83: =L83/$AF83 -> 206.35294 | AS83: =M83/$AF83 -> 162.94118 | AT83: =N83/$AF83 -> 147.82353 | ... BJ83: =AD83/$AF83 -> 0 | BK83: =F83*AG83 -> 1897.2825 | BL83: =SUM(G83:R83)*AG83 -> 1783.726 | BM83: =SUM(S83:AD83)*AG83 -> 0 | BN83: =G83*$AG83 -> 121.0553 | BO83: =H83*$AG83 -> 145.30043 | BP83: =I83*$AG83 -> 175.91251 | BQ83: =J83*$AG83 -> 157.85263 | BR83: =K83*$AG83 -> 183.19551 | BS83: =L83*$AG83 -> 199.1848 | BT83: =M83*$AG83 -> 157.28104 | BU83: =N83*$AG83 -> 142.68854 | ... CK83: =AD83*$AG83 -> 0
