Workbook

Sheet RR Pivot 25
A3: Source | B3: Part Name | C3: Part Description | D3: Values | E3: Total
A4: GDI | B4: 62714126 | C4: PS OCG SF 6-18PK | D4: Sum of 12/30/2024 | E4: 40002
A5: GDI | B5: 62714126 | C5: PS OCG SF 6-18PK | D5: Sum of 1/6/2025 | E5: 40000
A6: GDI | B6: 62714126 | C6: PS OCG SF 6-18PK | D6: Sum of 1/13/2025 | E6: 0
A7: GDI | B7: 62714126 | C7: PS OCG SF 6-18PK | D7: Sum of 1/20/2025 | E7: 0
A8: GDI | B8: 62714126 | C8: PS OCG SF 6-18PK | D8: Sum of 1/27/2025 | E8: 0
A9: GDI | B9: 62714126 | C9: PS OCG SF 6-18PK | D9: Sum of 2/3/2025 | E9: 0
A10: GDI | B10: 62714126 | C10: PS OCG SF 6-18PK | D10: Sum of 2/10/2025 | E10: 0
A11: GDI | B11: 62714126 | C11: PS OCG SF 6-18PK | D11: Sum of 2/17/2025 | E11: 0
A12: GDI | B12: 62714126 | C12: PS OCG SF 6-18PK | D12: Sum of 2/24/2025 | E12: 0
A13: GDI | B13: 62714126 | C13: PS OCG SF 6-18PK | D13: Sum of 3/3/2025 | E13: 40000
A14: GDI | B14: 62714126 | C14: PS OCG SF 6-18PK | D14: Sum of 3/10/2025 | E14: 40000
A15: GDI | B15: 62714126 | C15: PS OCG SF 6-18PK | D15: Sum of 3/17/2025 | E15: 40000
... A162: GDI | B162: 64366224 | C162: PS Buzz Lightyear IH 6-6PK | D162: Sum of 12/29/2025 | E162: 0
A163: Total Sum of 12/30/2024 | E163: 40002
A164: Total Sum of 1/6/2025 | E164: 40002
A165: Total Sum of 1/13/2025 | E165: 40000
A166: Total Sum of 1/20/2025 | E166: 40000
A167: Total Sum of 1/27/2025 | E167: 40000
A168: Total Sum of 2/3/2025 | E168: 40000
A169: Total Sum of 2/10/2025 | E169: 0
A170: Total Sum of 2/17/2025 | E170: 0
A171: Total Sum of 2/24/2025 | E171: 24192
A172: Total Sum of 3/3/2025 | E172: 104192
A173: Total Sum of 3/10/2025 | E173: 40000
A174: Total Sum of 3/17/2025 | E174: 40000
... A215: Total Sum of 12/29/2025 | E215: 40000

Sheet Sheet2
A1: DU | B1: Site | C1: Qty | D1: Date | E1: Description
A2: 69713190 | B2: Rhino/Hollipac | C2: 21450 | D2: 45607 | E2: BJ US-CD-CCCD-FTNG-8 8z
A3: 69713190 | B3: Rhino/Hollipac | C3: 21450 | D3: 45614 | E3: BJ US-CD-CCCD-FTNG-8 8z
A4: 69713190 | B4: Rhino/Hollipac | C4: 30250 | D4: 45635 | E4: BJ US-CD-CCCD-FTNG-8 8z
A5: 69713190 | B5: Rhino/Hollipac | C5: 30250 | D5: 45642 | E5: BJ US-CD-CCCD-FTNG-8 8z
A6: 69665114 | B6: Rhino/Hollipac | C6: 19440 | D6: 45656 | E6: BJ US-CD-SugarCookieDough-8 8z
A7: 69665115 | B7: Rhino/Hollipac | C7: 16128 | D7: 45558 | E7: BJ US-CD-VCCCD-FTNG-8 8z
A8: 69665115 | B8: Rhino/Hollipac | C8: 12400 | D8: 45565 | E8: BJ US-CD-VCCCD-FTNG-8 8z
A9: 69665115 | B9: Rhino/Hollipac | C9: 7000 | D9: 45579 | E9: BJ US-CD-VCCCD-FTNG-8 8z
A10: 69665115 | B10: Rhino/Hollipac | C10: 14000 | D10: 45642 | E10: BJ US-CD-VCCCD-FTNG-8 8z
A11: 64413477 | B11: Schwann's | C11: 20155 | D11: 45558 | E11: BJ US-IC-AmericoneDream-FTNG-12 4FOZ
A12: 64413477 | B12: Schwann's | C12: 18360 | D12: 45600 | E12: BJ US-IC-AmericoneDream-FTNG-12 4FOZ
A13: 64413477 | B13: Schwann's | C13: 18360 | D13: 45642 | E13: BJ US-IC-AmericoneDream-FTNG-12 4FOZ
... A26: 64413476 | B26: Schwann's | C26: 18360 | D26: 45628 | E26: BJ US-IC-ChocFudgBrownie-FTNG-12 4FOZ
A27: 69653125 | B27: 6706 | C27: 10000 | D27: 45558 | E27: BR Chocolate 6 10CT 3z
A28: 69653125 | B28: 6706 | C28: 10000 | D28: 45614 | E28: BR Chocolate 6 10CT 3z
A29: 69653125 | B29: 6706 | C29: 10000 | D29: 45642 | E29: BR Chocolate 6 10CT 3z
A30: 69653140 | B30: 6706 | C30: 15000 | D30: 45558 | E30: BR Natural Vanilla 6 10CT 3z
A31: 69653140 | B31: 6706 | C31: 15000 | D31: 45579 | E31: BR Natural Vanilla 6 10CT 3z
A32: 69653140 | B32: 6706 | C32: 15000 | D32: 45607 | E32: BR Natural Vanilla 6 10CT 3z
A33: 69653140 | B33: 6706 | C33: 15000 | D33: 45635 | E33: BR Natural Vanilla 6 10CT 3z
A34: 68871220 | B34: 6706 | C34: 30000 | D34: 45593 | E34: BR Vanilla 8 1PT
A35: 64378129 | B35: Corlu | C35: 22800 | D35: 45621 | E35: GH Candy center 8-6pk
A36: 64378129 | B36: Corlu | C36: 2400 | D36: 45628 | E36: GH Candy center 8-6pk
A37: 69687232 | B37: 6706 | C37: 30000 | D37: 45572 | E37: GH Giant Cookies and Cream Cone 1-12PK
A38: 69645145 | B38: 6706 | C38: 30000 | D38: 45565 | E38: GH Giant King Cone 1-12PK
A39: 69645145 | B39: 6706 | C39: 30000 | D39: 45614 | E39: GH Giant King Cone 1-12PK
A40: 69645145 | B40: 6706 | C40: 30000 | D40: 45656 | E40: GH Giant King Cone 1-12PK
A41: 68521425 | B41: 6706 | C41: 633 | D41: 45551 | E41: GH Giant Vanilla Sandwich 1-24BK
A42: 68521425 | B42: 6706 | C42: 25000 | D42: 45565 | E42: GH Giant Vanilla Sandwich 1-24BK
A43: 68521425 | B43: 6706 | C43: 25000 | D43: 45642 | E43: GH Giant Vanilla Sandwich 1-24BK
A44: 68521425 | B44: 6706 | C44: 25000 | D44: 45656 | E44: GH Giant Vanilla Sandwich 1-24BK
A45: 67382713 | B45: St Iria | C45: 21312 | D45: 45656 | E45: GH King Cone Vanilla 1-24PK
A46: 69964648 | B46: Corlu | C46: 23400 | D46: 45558 | E46: KL Cone BDay/ChocCrumble Cake 6-8CT
A47: 69964648 | B47: Corlu | C47: 7800 | D47: 45565 | E47: KL Cone BDay/ChocCrumble Cake 6-8CT
A48: 69964648 | B48: Corlu | C48: 15600 | D48: 45572 | E48: KL Cone BDay/ChocCrumble Cake 6-8CT
A49: 69964648 | B49: Corlu | C49: 15600 | D49: 45579 | E49: KL Cone BDay/ChocCrumble Cake 6-8CT
A50: 69964648 | B50: Corlu | C50: 40620 | D50: 45586 | E50: KL Cone BDay/ChocCrumble Cake 6-8CT
A51: 69964648 | B51: Corlu | C51: 31408 | D51: 45593 | E51: KL Cone BDay/ChocCrumble Cake 6-8CT
A52: 69964648 | B52: Corlu | C52: 5776 | D52: 45600 | E52: KL Cone BDay/ChocCrumble Cake 6-8CT
...

Sheet RR Data
A1: Part Name | B1: Source | C1: Part Name | D1: Part Description | E1: 45551 | F1: =E1+7 -> 45558 | G1: =F1+7 -> 45565 | H1: =G1+7 -> 45572 | I1: =H1+7 -> 45579 | J1: =I1+7 -> 45586 | K1: =J1+7 -> 45593 | L1: =K1+7 -> 45600 | M1: =L1+7 -> 45607 | ... BT1: =BS1+7 -> 46020
A2: 62694394 | B2: =VLOOKUP(A2,Sourcing!A:C,3,0) -> Caivano | C2: 62694394 | D2: MG Non-Dairy Sea Salt Caramel 10-3PK | E2: 0 | F2: 0 | G2: 0 | H2: 0 | I2: 0 | J2: 0 | K2: 0 | L2: 0 | M2: 0 | N2: 0 | O2: 0 | P2: 0 | Q2: 0 | R2: 0 | S2: 0 | T2: 0 | U2: 0 | V2: 500 | W2: 0 | X2: 0 | Y2: 0 | Z2: 0 | AA2: 0 | AB2: 0 | AC2: 0 | AD2: 0 | AE2: 0 | AF2: 0 | AG2: 0 | AH2: 0 | AI2: 0 | AJ2: 0 | AK2: 0 | AL2: 0 | AM2: 0 | AN2: 0 | AO2: 0 | AP2: 0 | AQ2: 0 | AR2: 0 | AS2: 0 | AT2: 500 | AU2: 0 | AV2: 0 | AW2: 0 | AX2: 0 | AY2: 0 | AZ2: 0 | BA2: 0 | BB2: 0 | BC2: 0 | BD2: 0 | BE2: 0 | BF2: 0 | BG2: 0 | BH2: 0 | BI2: 0 | BJ2: 0 | BK2: 0 | BL2: 0 | BM2: 0 | BN2: 0 | BO2: 0 | BP2: 0 | BQ2: 0 | BR2: 0 | BS2: 500
A3: 62694440 | B3: =VLOOKUP(A3,Sourcing!A:C,3,0) -> Caivano | C3: 62694440 | D3: MG Non-Dairy Almond 10-3PK | E3: 0 | F3: 0 | G3: 0 | H3: 0 | I3: 0 | J3: 0 | K3: 0 | L3: 0 | M3: 0 | N3: 0 | O3: 0 | P3: 0 | Q3: 0 | R3: 0 | S3: 0 | T3: 0 | U3: 0 | V3: 0 | W3: 0 | X3: 0 | Y3: 500 | Z3: 0 | AA3: 0 | AB3: 0 | AC3: 0 | AD3: 0 | AE3: 0 | AF3: 0 | AG3: 0 | AH3: 0 | AI3: 500 | AJ3: 0 | AK3: 0 | AL3: 0 | AM3: 0 | AN3: 0 | AO3: 0 | AP3: 0 | AQ3: 0 | AR3: 0 | AS3: 500 | AT3: 0 | AU3: 0 | AV3: 0 | AW3: 0 | AX3: 0 | AY3: 0 | AZ3: 0 | BA3: 0 | BB3: 0 | BC3: 0 | BD3: 0 | BE3: 0 | BF3: 500 | BG3: 0 | BH3: 0 | BI3: 0 | BJ3: 0 | BK3: 0 | BL3: 0 | BM3: 0 | BN3: 0 | BO3: 0 | BP3: 0 | BQ3: 0 | BR3: 0 | BS3: 0
A4: 62714126 | B4: =VLOOKUP(A4,Sourcing!A:C,3,0) -> GDI | C4: 62714126 | D4: PS OCG SF 6-18PK | E4: 0 | F4: 7184 | G4: 0 | H4: 0 | I4: 0 | J4: 0 | K4: 0 | L4: 0 | M4: 2 | N4: 0 | O4: 0 | P4: 0 | Q4: 0 | R4: 0 | S4: 0 | T4: 2 | U4: 0 | V4: 0 | W4: 0 | X4: 0 | Y4: 0 | Z4: 0 | AA4: 0 | AB4: 0 | AC4: 0 | AD4: 0 | AE4: 0 | AF4: 0 | AG4: 0 | AH4: 0 | AI4: 0 | AJ4: 0 | AK4: 0 | AL4: 0 | AM4: 0 | AN4: 0 | AO4: 0 | AP4: 0 | AQ4: 0 | AR4: 0 | AS4: 0 | AT4: 0 | AU4: 0 | AV4: 0 | AW4: 0 | AX4: 0 | AY4: 0 | AZ4: 0 | BA4: 0 | BB4: 0 | BC4: 0 | BD4: 0 | BE4: 0 | BF4: 0 | BG4: 0 | BH4: 0 | BI4: 0 | BJ4: 0 | BK4: 0 | BL4: 0 | BM4: 0 | BN4: 0 | BO4: 0 | BP4: 0 | BQ4: 0 | BR4: 0 | BS4: 0
A5: 62714129 | B5: =VLOOKUP(A5,Sourcing!A:C,3,0) -> GDI | C5: 62714129 | D5: PS OCG 6-18PK | E5: 0 | F5: 3855 | G5: 0 | H5: 0 | I5: 0 | J5: 0 | K5: 0 | L5: 0 | M5: 0 | N5: 0 | O5: 0 | P5: 0 | Q5: 0 | R5: 0 | S5: 0 | T5: 0 | U5: 2 | V5: 0 | W5: 0 | X5: 0 | Y5: 0 | Z5: 0 | AA5: 0 | AB5: 0 | AC5: 0 | AD5: 0 | AE5: 0 | AF5: 0 | AG5: 0 | AH5: 0 | AI5: 0 | AJ5: 0 | AK5: 0 | AL5: 0 | AM5: 0 | AN5: 0 | AO5: 0 | AP5: 0 | AQ5: 0 | AR5: 0 | AS5: 0 | AT5: 0 | AU5: 0 | AV5: 0 | AW5: 0 | AX5: 0 | AY5: 0 | AZ5: 0 | BA5: 0 | BB5: 0 | BC5: 0 | BD5: 0 | BE5: 0 | BF5: 0 | BG5: 0 | BH5: 0 | BI5: 0 | BJ5: 0 | BK5: 0 | BL5: 0 | BM5: 0 | BN5: 0 | BO5: 0 | BP5: 0 | BQ5: 0 | BR5: 0 | BS5: 0
A6: 64365613 | B6: =VLOOKUP(A6,Sourcing!A:C,3,0) -> Incom | C6: 64365613 | D6: PS Spiderman Facepiece 6-6PK | E6: 0 | F6: 0 | G6: 0 | H6: 0 | I6: 0 | J6: 0 | K6: 0 | L6: 0 | M6: 0 | N6: 0 | O6: 77280 | P6: 0 | Q6: 0 | R6: 0 | S6: 0 | T6: 0 | U6: 0 | V6: 0 | W6: 0 | X6: 0 | Y6: 0 | Z6: 11760 | AA6: 41040 | AB6: 41280 | AC6: 41040 | AD6: 47040 | AE6: 30000 | AF6: 35040 | AG6: 34800 | AH6: 50160 | AI6: 7200 | AJ6: 12960 | AK6: 12720 | AL6: 24000 | AM6: 1680 | AN6: 13440 | AO6: 13200 | AP6: 13200 | AQ6: 15120 | AR6: 11040 | AS6: 12960 | AT6: 12720 | AU6: 20160 | AV6: 5520 | AW6: 12720 | AX6: 12960 | AY6: 12720 | AZ6: 12960 | BA6: 13200 | BB6: 13200 | BC6: 13200 | BD6: 17040 | BE6: 9360 | BF6: 12720 | BG6: 12720 | BH6: 22080 | BI6: 0 | BJ6: 0 | BK6: 0 | BL6: 0 | BM6: 0 | BN6: 0 | BO6: 0 | BP6: 0 | BQ6: 0 | BR6: 0 | BS6: 0
A7: 64366224 | B7: =VLOOKUP(A7,Sourcing!A:C,3,0) -> Incom | C7: 64366224 | D7: PS Buzz Lightyear IH 6-6PK | E7: 0 | F7: 0 | G7: 0 | H7: 0 | I7: 0 | J7: 0 | K7: 0 | L7: 0 | M7: 0 | N7: 0 | O7: 66720 | P7: 3360 | Q7: 4560 | R7: 4320 | S7: 6000 | T7: 6240 | U7: 10320 | V7: 480 | W7: 1440 | X7: 1440 | Y7: 2400 | Z7: 1920 | AA7: 6480 | AB7: 6720 | AC7: 6720 | AD7: 7440 | AE7: 720 | AF7: 960 | AG7: 960 | AH7: 1200 | AI7: 6240 | AJ7: 11040 | AK7: 10800 | AL7: 20400 | AM7: 480 | AN7: 3120 | AO7: 3120 | AP7: 3120 | AQ7: 3600 | AR7: 10080 | AS7: 11760 | AT7: 11520 | AU7: 18480 | AV7: 1680 | AW7: 4320 | AX7: 4080 | AY7: 4080 | AZ7: 4080 | BA7: 8880 | BB7: 8640 | BC7: 8880 | BD7: 11280 | BE7: 4080 | BF7: 5520 | BG7: 5520 | BH7: 9360 | BI7: 1200 | BJ7: 4080 | BK7: 4320 | BL7: 4080 | BM7: 4080 | BN7: 3600 | BO7: 3360 | BP7: 3600 | BQ7: 5040 | BR7: 0 | BS7: 0
A8: 64369052 | B8: =VLOOKUP(A8,Sourcing!A:C,3,0) -> Corlu | C8: 64369052 | D8: KL Cone StrwShortcake Van Chillin 6-8CT | E8: 0 | F8: 0 | G8: 0 | H8: 0 | I8: 0 | J8: 0 | K8: 66508 | L8: 69756 | M8: 34656 | N8: 37184 | O8: 34656 | P8: 34656 | Q8: 17328 | R8: 17328 | S8: 0 | T8: 34656 | U8: 23104 | V8: 25992 | W8: 34656 | X8: 57760 | Y8: 8664 | Z8: 2 | AA8: 0 | AB8: 0 | AC8: 0 | AD8: 0 | AE8: 0 | AF8: 0 | AG8: 0 | AH8: 0 | AI8: 0 | AJ8: 0 | AK8: 0 | AL8: 0 | AM8: 0 | AN8: 0 | AO8: 0 | AP8: 0 | AQ8: 3315 | AR8: 22815 | AS8: 18525 | AT8: 16575 | AU8: 17355 | AV8: 23400 | AW8: 14820 | AX8: 10530 | AY8: 13455 | AZ8: 13650 | BA8: 13650 | BB8: 12870 | BC8: 12480 | BD8: 12480 | BE8: 14625 | BF8: 9945 | BG8: 7215 | BH8: 8385 | BI8: 11895 | BJ8: 7020 | BK8: 5655 | BL8: 7800 | BM8: 7800 | BN8: 7995 | BO8: 7410 | BP8: 7410 | BQ8: 7215 | BR8: 9360 | BS8: 4095
A9: 64378129 | B9: =VLOOKUP(A9,Sourcing!A:C,3,0) -> Corlu | C9: 64378129 | D9: GH Candy center 8-6pk | E9: 0 | F9: 0 | G9: 0 | H9: 0 | I9: 0 | J9: 0 | K9: 0 | L9: 0 | M9: 0 | N9: 0 | O9: 22800 | P9: 2400 | Q9: 0 | R9: 0 | S9: 0 | T9: 0 | U9: 0 | V9: 0 | W9: 0 | X9: 0 | Y9: 0 | Z9: 0 | AA9: 0 | AB9: 0 | AC9: 0 | AD9: 25526 | AE9: 0 | AF9: 0 | AG9: 0 | AH9: 0 | AI9: 0 | AJ9: 0 | AK9: 0 | AL9: 0 | AM9: 0 | AN9: 0 | AO9: 0 | AP9: 0 | AQ9: 0 | AR9: 0 | AS9: 0 | AT9: 0 | AU9: 0 | AV9: 25526 | AW9: 0 | AX9: 0 | AY9: 0 | AZ9: 0 | BA9: 0 | BB9: 0 | BC9: 0 | BD9: 0 | BE9: 0 | BF9: 0 | BG9: 0 | BH9: 0 | BI9: 0 | BJ9: 0 | BK9: 0 | BL9: 0 | BM9: 25526 | BN9: 0 | BO9: 0 | BP9: 0 | BQ9: 0 | BR9: 0 | BS9: 0
A10: 64401837 | B10: =VLOOKUP(A10,Sourcing!A:C,3,0) -> Incom | C10: 64401837 | D10: PS Frozen Olaf Facepiece IH 6-6PK | E10: 0 | F10: 0 | G10: 0 | H10: 0 | I10: 0 | J10: 0 | K10: 0 | L10: 0 | M10: 0 | N10: 0 | O10: 0 | P10: 0 | Q10: 0 | R10: 0 | S10: 114960 | T10: 160560 | U10: 160560 | V10: 160560 | W10: 146880 | X10: 112800 | Y10: 112560 | Z10: 112560 | AA10: 84720 | AB10: 14640 | AC10: 14880 | AD10: 14640 | AE10: 14880 | AF10: 1920 | AG10: 0 | AH10: 0 | AI10: 0 | AJ10: 0 | AK10: 0 | AL10: 0 | AM10: 0 | AN10: 0 | AO10: 0 | AP10: 0 | AQ10: 0 | AR10: 0 | AS10: 0 | AT10: 0 | AU10: 0 | AV10: 0 | AW10: 0 | AX10: 0 | AY10: 0 | AZ10: 0 | BA10: 0 | BB10: 0 | BC10: 0 | BD10: 0 | BE10: 0 | BF10: 0 | BG10: 0 | BH10: 0 | BI10: 0 | BJ10: 0 | BK10: 0 | BL10: 0 | BM10: 0 | BN10: 0 | BO10: 0 | BP10: 0 | BQ10: 0 | BR10: 0 | BS10: 0
A11: 64403162 | B11: =VLOOKUP(A11,Sourcing!A:C,3,0) -> Incom | C11: 64403162 | D11: PS Grogu Facepiece IH 6-6PK | E11: 0 | F11: 0 | G11: 5610 | H11: 22000 | I11: 4400 | J11: 0 | K11: 5280 | L11: 0 | M11: 0 | N11: 0 | O11: 0 | P11: 0 | Q11: 0 | R11: 0 | S11: 2 | T11: 0 | U11: 0 | V11: 0 | W11: 0 | X11: 0 | Y11: 0 | Z11: 0 | AA11: 0 | AB11: 0 | AC11: 0 | AD11: 0 | AE11: 0 | AF11: 0 | AG11: 0 | AH11: 0 | AI11: 0 | AJ11: 0 | AK11: 0 | AL11: 0 | AM11: 0 | AN11: 0 | AO11: 0 | AP11: 0 | AQ11: 0 | AR11: 0 | AS11: 0 | AT11: 0 | AU11: 0 | AV11: 0 | AW11: 0 | AX11: 0 | AY11: 0 | AZ11: 0 | BA11: 0 | BB11: 0 | BC11: 0 | BD11: 0 | BE11: 0 | BF11: 0 | BG11: 0 | BH11: 0 | BI11: 0 | BJ11: 0 | BK11: 0 | BL11: 0 | BM11: 0 | BN11: 0 | BO11: 0 | BP11: 0 | BQ11: 0 | BR11: 0 | BS11: 0
A12: 67382713 | B12: =VLOOKUP(A12,Sourcing!A:C,3,0) -> St Iria | C12: 67382713 | D12: GH King Cone Vanilla 1-24PK | E12: 0 | F12: 0 | G12: 0 | H12: 0 | I12: 0 | J12: 0 | K12: 0 | L12: 0 | M12: 0 | N12: 0 | O12: 0 | P12: 0 | Q12: 0 | R12: 0 | S12: 0 | T12: 21312 | U12: 0 | V12: 0 | W12: 0 | X12: 0 | Y12: 0 | Z12: 2 | AA12: 0 | AB12: 0 | AC12: 0 | AD12: 0 | AE12: 0 | AF12: 0 | AG12: 0 | AH12: 0 | AI12: 0 | AJ12: 0 | AK12: 0 | AL12: 0 | AM12: 0 | AN12: 2550 | AO12: 300 | AP12: 1800 | AQ12: 2850 | AR12: 3000 | AS12: 2700 | AT12: 1050 | AU12: 1050 | AV12: 1050 | AW12: 1500 | AX12: 900 | AY12: 1800 | AZ12: 1800 | BA12: 1950 | BB12: 1950 | BC12: 2850 | BD12: 2850 | BE12: 3000 | BF12: 3300 | BG12: 1500 | BH12: 1800 | BI12: 2250 | BJ12: 2700 | BK12: 1050 | BL12: 2400 | BM12: 2250 | BN12: 2250 | BO12: 2250 | BP12: 1200 | BQ12: 1500 | BR12: 1650 | BS12: 1500
A13: 67896936 | B13: =VLOOKUP(A13,Sourcing!A:C,3,0) -> Gloucester | C13: 67896936 | D13: MG ND MINI Variety Pack 6-6PK | E13: 0 | F13: 0 | G13: 0 | H13: 0 | I13: 0 | J13: 0 | K13: 0 | L13: 0 | M13: 0 | N13: 0 | O13: 0 | P13: 0 | Q13: 0 | R13: 0 | S13: 0 | T13: 21312 | U13: 0 | V13: 0 | W13: 0 | X13: 0 | Y13: 0 | Z13: 2 | AA13: 0 | AB13: 0 | AC13: 0 | AD13: 0 | AE13: 0 | AF13: 0 | AG13: 0 | AH13: 0 | AI13: 0 | AJ13: 0 | AK13: 0 | AL13: 0 | AM13: 0 | AN13: 390 | AO13: 195 | AP13: 1365 | AQ13: 1365 | AR13: 1560 | AS13: 2145 | AT13: 780 | AU13: 975 | AV13: 585 | AW13: 1365 | AX13: 585 | AY13: 1755 | AZ13: 1170 | BA13: 1365 | BB13: 1755 | BC13: 2145 | BD13: 2340 | BE13: 2340 | BF13: 2535 | BG13: 975 | BH13: 1560 | BI13: 1950 | BJ13: 1950 | BK13: 585 | BL13: 1950 | BM13: 1950 | BN13: 1755 | BO13: 1560 | BP13: 975 | BQ13: 1365 | BR13: 975 | BS13: 1365
... A44: 64388736 | B44: =VLOOKUP(A44,Sourcing!A:C,3,0) -> 1713 | C44: 64388736 | D44: Yasso Fudge Poppables 10p 6.84flz | E44: 0 | F44: 0 | G44: 0 | H44: 0 | I44: 3200 | J44: 0 | K44: 0 | L44: 0 | M44: 3200 | N44: 0 | O44: 0 | P44: 6400 | Q44: 3200 | R44: 0 | S44: 3200 | T44: 0 | U44: 3200 | V44: 3200 | W44: 3200 | X44: 6400 | Y44: 0 | Z44: 0 | AA44: 0 | AB44: 0 | AC44: 0 | AD44: 0 | AE44: 0 | AF44: 0 | AG44: 3600 | AH44: 0 | AI44: 3600 | AJ44: 3600 | AK44: 0 | AL44: 3600 | AM44: 0 | AN44: 3600 | AO44: 3600 | AP44: 3600 | AQ44: 3600 | AR44: 0 | AS44: 3600 | AT44: 3600 | AU44: 3600 | AV44: 0 | AW44: 3600 | AX44: 3600 | AY44: 0 | AZ44: 3600 | BA44: 3600 | BB44: 0 | BC44: 3600 | BD44: 3600 | BE44: 0 | BF44: 3600 | BG44: 3600 | BH44: 3600 | BI44: 0 | BJ44: 0 | BK44: 3600 | BL44: 0 | BM44: 3600 | BN44: 0 | BO44: 3600 | BP44: 0 | BQ44: 3600 | BR44: 0 | BS44: 0
A45: 64325372 | B45: 1715 | C45: 64325372 | D45: Yasso Sea Salt Caramel 8-4pk | E45: 13125 | F45: 0 | G45: 0 | H45: 0 | I45: 13125 | J45: 0 | K45: 0 | L45: 26250 | M45: 0 | N45: 0 | O45: 26250 | P45: 0 | Q45: 0 | R45: 0 | S45: 0 | T45: 0 | U45: 0 | V45: 0 | W45: 0 | X45: 0 | Y45: 0 | Z45: 0 | AA45: 0 | AB45: 0 | AC45: 0 | AD45: 0 | AE45: 0 | AF45: 0 | AG45: 0 | AH45: 0 | AI45: 0 | AJ45: 0 | AK45: 0 | AL45: 0 | AM45: 0 | AN45: 0 | AO45: 0 | AP45: 0 | AQ45: 0 | AR45: 0 | AS45: 0 | AT45: 0 | AU45: 0 | AV45: 0 | AW45: 0 | AX45: 0 | AY45: 0 | AZ45: 0 | BA45: 0 | BB45: 0 | BC45: 0 | BD45: 0 | BE45: 0 | BF45: 0 | BG45: 0 | BH45: 0 | BI45: 0 | BJ45: 0 | BK45: 0 | BL45: 0 | BM45: 0 | BN45: 0 | BO45: 0 | BP45: 0 | BQ45: 0 | BR45: 0 | BS45: 0 | BT45: 0
A46: 64325486 | B46: 1715 | C46: 64325486 | D46: Yasso Caramel Chocolate Crunch 8-4pk | E46: 0 | F46: 0 | G46: 0 | H46: 0 | I46: 0 | J46: 0 | K46: 38451 | L46: 0 | M46: 0 | N46: 0 | O46: 26250 | P46: 0 | Q46: 0 | R46: 0 | S46: 0 | T46: 0 | U46: 0 | V46: 0 | W46: 0 | X46: 0 | Y46: 0 | Z46: 0 | AA46: 0 | AB46: 0 | AC46: 0 | AD46: 0 | AE46: 0 | AF46: 0 | AG46: 0 | AH46: 0 | AI46: 0 | AJ46: 0 | AK46: 0 | AL46: 0 | AM46: 0 | AN46: 0 | AO46: 0 | AP46: 0 | AQ46: 0 | AR46: 0 | AS46: 0 | AT46: 0 | AU46: 0 | AV46: 0 | AW46: 0 | AX46: 0 | AY46: 0 | AZ46: 0 | BA46: 0 | BB46: 0 | BC46: 0 | BD46: 0 | BE46: 0 | BF46: 0 | BG46: 0 | BH46: 0 | BI46: 0 | BJ46: 0 | BK46: 0 | BL46: 0 | BM46: 0 | BN46: 0 | BO46: 0 | BP46: 0 | BQ46: 0 | BR46: 0 | BS46: 0 | BT46: 0
A47: 64325487 | B47: 1715 | C47: 64325487 | D47: Yasso Mint Chocolate Crunch 8-4pk | E47: 25634 | F47: 0 | G47: 0 | H47: 0 | I47: 0 | J47: 0 | K47: 0 | L47: 0 | M47: 0 | N47: 0 | O47: 13125 | P47: 0 | Q47: 0 | R47: 0 | S47: 0 | T47: 0 | U47: 0 | V47: 0 | W47: 0 | X47: 0 | Y47: 12500 | Z47: 0 | AA47: 0 | AB47: 0 | AC47: 0 | AD47: 0 | AE47: 0 | AF47: 0 | AG47: 0 | AH47: 0 | AI47: 0 | AJ47: 0 | AK47: 0 | AL47: 0 | AM47: 0 | AN47: 0 | AO47: 0 | AP47: 0 | AQ47: 0 | AR47: 0 | AS47: 0 | AT47: 0 | AU47: 0 | AV47: 0 | AW47: 0 | AX47: 0 | AY47: 0 | AZ47: 0 | BA47: 0 | BB47: 0 | BC47: 0 | BD47: 0 | BE47: 0 | BF47: 0 | BG47: 0 | BH47: 0 | BI47: 0 | BJ47: 0 | BK47: 0 | BL47: 0 | BM47: 0 | BN47: 0 | BO47: 0 | BP47: 0 | BQ47: 0 | BR47: 0 | BS47: 0 | BT47: 0
A48: 64325488 | B48: 1715 | C48: 64325488 | D48: Yasso PB Chocolate Crunch 8-4pk | E48: 0 | F48: 0 | G48: 0 | H48: 0 | I48: 0 | J48: 0 | K48: 25634 | L48: 0 | M48: 0 | N48: 0 | O48: 0 | P48: 0 | Q48: 0 | R48: 0 | S48: 0 | T48: 0 | U48: 0 | V48: 0 | W48: 0 | X48: 0 | Y48: 0 | Z48: 0 | AA48: 0 | AB48: 0 | AC48: 0 | AD48: 0 | AE48: 0 | AF48: 0 | AG48: 0 | AH48: 0 | AI48: 0 | AJ48: 0 | AK48: 0 | AL48: 0 | AM48: 0 | AN48: 0 | AO48: 0 | AP48: 0 | AQ48: 0 | AR48: 0 | AS48: 0 | AT48: 0 | AU48: 0 | AV48: 0 | AW48: 0 | AX48: 0 | AY48: 0 | AZ48: 0 | BA48: 0 | BB48: 0 | BC48: 0 | BD48: 0 | BE48: 0 | BF48: 0 | BG48: 0 | BH48: 0 | BI48: 0 | BJ48: 0 | BK48: 0 | BL48: 0 | BM48: 0 | BN48: 0 | BO48: 0 | BP48: 0 | BQ48: 0 | BR48: 0 | BS48: 0 | BT48: 0
A49: 64325492 | B49: 1715 | C49: 64325492 | D49: Yasso Strawberry Chocolate Crunch 8-4pk | E49: 0 | F49: 13125 | G49: 0 | H49: 0 | I49: 0 | J49: 38451 | K49: 0 | L49: 0 | M49: 0 | N49: 0 | O49: 0 | P49: 0 | Q49: 0 | R49: 26250 | S49: 0 | T49: 0 | U49: 0 | V49: 0 | W49: 0 | X49: 0 | Y49: 0 | Z49: 0 | AA49: 0 | AB49: 0 | AC49: 0 | AD49: 0 | AE49: 0 | AF49: 0 | AG49: 0 | AH49: 0 | AI49: 0 | AJ49: 0 | AK49: 0 | AL49: 0 | AM49: 0 | AN49: 0 | AO49: 0 | AP49: 0 | AQ49: 0 | AR49: 0 | AS49: 0 | AT49: 0 | AU49: 0 | AV49: 0 | AW49: 0 | AX49: 0 | AY49: 0 | AZ49: 0 | BA49: 0 | BB49: 0 | BC49: 0 | BD49: 0 | BE49: 0 | BF49: 0 | BG49: 0 | BH49: 0 | BI49: 0 | BJ49: 0 | BK49: 0 | BL49: 0 | BM49: 0 | BN49: 0 | BO49: 0 | BP49: 0 | BQ49: 0 | BR49: 0 | BS49: 0 | BT49: 0
A50: 64325509 | B50: 1715 | C50: 64325509 | D50: Yasso Fudge Chocolate Crunch 8-4pk | E50: 0 | F50: 0 | G50: 0 | H50: 0 | I50: 0 | J50: 0 | K50: 0 | L50: 0 | M50: 0 | N50: 0 | O50: 0 | P50: 0 | Q50: 0 | R50: 0 | S50: 0 | T50: 0 | U50: 0 | V50: 0 | W50: 0 | X50: 0 | Y50: 0 | Z50: 0 | AA50: 0 | AB50: 0 | AC50: 0 | AD50: 0 | AE50: 12500 | AF50: 0 | AG50: 0 | AH50: 0 | AI50: 0 | AJ50: 12500 | AK50: 0 | AL50: 0 | AM50: 0 | AN50: 0 | AO50: 0 | AP50: 0 | AQ50: 0 | AR50: 0 | AS50: 12500 | AT50: 0 | AU50: 0 | AV50: 0 | AW50: 0 | AX50: 12500 | AY50: 0 | AZ50: 0 | BA50: 0 | BB50: 0 | BC50: 0 | BD50: 12500 | BE50: 0 | BF50: 0 | BG50: 0 | BH50: 0 | BI50: 0 | BJ50: 0 | BK50: 12500 | BL50: 0 | BM50: 0 | BN50: 0 | BO50: 0 | BP50: 0 | BQ50: 0 | BR50: 0 | BS50: 0 | BT50: 0
A51: 64325510 | B51: 1715 | C51: 64325510 | D51: Yasso Chocolate Chip Cookie Dough 8-4pk | E51: 19529 | F51: 0 | G51: 0 | H51: 0 | I51: 0 | J51: 26250 | K51: 0 | L51: 0 | M51: 0 | N51: 0 | O51: 0 | P51: 0 | Q51: 0 | R51: 39375 | S51: 0 | T51: 0 | U51: 0 | V51: 0 | W51: 0 | X51: 0 | Y51: 0 | Z51: 0 | AA51: 0 | AB51: 0 | AC51: 12500 | AD51: 0 | AE51: 0 | AF51: 12500 | AG51: 0 | AH51: 0 | AI51: 12500 | AJ51: 0 | AK51: 0 | AL51: 12500 | AM51: 0 | AN51: 12500 | AO51: 0 | AP51: 12500 | AQ51: 0 | AR51: 0 | AS51: 12500 | AT51: 0 | AU51: 12500 | AV51: 0 | AW51: 0 | AX51: 12500 | AY51: 0 | AZ51: 12500 | BA51: 0 | BB51: 0 | BC51: 12500 | BD51: 0 | BE51: 0 | BF51: 12500 | BG51: 0 | BH51: 12500 | BI51: 0 | BJ51: 0 | BK51: 0 | BL51: 12500 | BM51: 0 | BN51: 0 | BO51: 12500 | BP51: 0 | BQ51: 0 | BR51: 0 | BS51: 0 | BT51: 0
A52: 64325512 | B52: 1715 | C52: 64325512 | D52: Yasso Coffee Chocolate Chip 8-4pk | E52: 0 | F52: 0 | G52: 0 | H52: 0 | I52: 0 | J52: 0 | K52: 0 | L52: 0 | M52: 26250 | N52: 0 | O52: 0 | P52: 0 | Q52: 0 | R52: 0 | S52: 0 | T52: 0 | U52: 0 | V52: 0 | W52: 0 | X52: 0 | Y52: 0 | Z52: 0 | AA52: 0 | AB52: 0 | AC52: 0 | AD52: 0 | AE52: 0 | AF52: 0 | AG52: 0 | AH52: 0 | AI52: 0 | AJ52: 0 | AK52: 0 | AL52: 0 | AM52: 0 | AN52: 0 | AO52: 0 | AP52: 0 | AQ52: 0 | AR52: 0 | AS52: 0 | AT52: 0 | AU52: 0 | AV52: 0 | AW52: 0 | AX52: 0 | AY52: 0 | AZ52: 0 | BA52: 0 | BB52: 0 | BC52: 0 | BD52: 0 | BE52: 0 | BF52: 0 | BG52: 0 | BH52: 0 | BI52: 0 | BJ52: 0 | BK52: 0 | BL52: 0 | BM52: 0 | BN52: 0 | BO52: 0 | BP52: 0 | BQ52: 0 | BR52: 0 | BS52: 0 | BT52: 0
A53: 64325513 | B53: 1715 | C53: 64325513 | D53: Yasso Cookies N Cream 8-4pk | E53: 0 | F53: 0 | G53: 0 | H53: 0 | I53: 39375 | J53: 0 | K53: 0 | L53: 0 | M53: 0 | N53: 0 | O53: 0 | P53: 0 | Q53: 0 | R53: 0 | S53: 0 | T53: 0 | U53: 0 | V53: 0 | W53: 0 | X53: 0 | Y53: 0 | Z53: 0 | AA53: 0 | AB53: 0 | AC53: 0 | AD53: 0 | AE53: 0 | AF53: 0 | AG53: 0 | AH53: 12500 | AI53: 0 | AJ53: 0 | AK53: 0 | AL53: 0 | AM53: 12500 | AN53: 0 | AO53: 0 | AP53: 0 | AQ53: 0 | AR53: 0 | AS53: 0 | AT53: 0 | AU53: 12500 | AV53: 0 | AW53: 0 | AX53: 0 | AY53: 0 | AZ53: 0 | BA53: 12500 | BB53: 0 | BC53: 0 | BD53: 0 | BE53: 0 | BF53: 0 | BG53: 0 | BH53: 0 | BI53: 12500 | BJ53: 0 | BK53: 0 | BL53: 0 | BM53: 0 | BN53: 0 | BO53: 0 | BP53: 0 | BQ53: 0 | BR53: 0 | BS53: 0 | BT53: 0
A54: 64325518 | B54: 1715 | C54: 64325518 | D54: Yasso Black Raspberry Chip 8-4pk | E54: 0 | F54: 0 | G54: 0 | H54: 0 | I54: 0 | J54: 0 | K54: 0 | L54: 25634 | M54: 0 | N54: 0 | O54: 0 | P54: 0 | Q54: 0 | R54: 0 | S54: 0 | T54: 0 | U54: 0 | V54: 0 | W54: 0 | X54: 0 | Y54: 0 | Z54: 0 | AA54: 0 | AB54: 0 | AC54: 0 | AD54: 0 | AE54: 0 | AF54: 0 | AG54: 12500 | AH54: 0 | AI54: 0 | AJ54: 0 | AK54: 0 | AL54: 0 | AM54: 0 | AN54: 0 | AO54: 0 | AP54: 0 | AQ54: 0 | AR54: 0 | AS54: 0 | AT54: 0 | AU54: 0 | AV54: 0 | AW54: 0 | AX54: 0 | AY54: 0 | AZ54: 0 | BA54: 0 | BB54: 0 | BC54: 0 | BD54: 0 | BE54: 0 | BF54: 0 | BG54: 0 | BH54: 0 | BI54: 0 | BJ54: 0 | BK54: 0 | BL54: 0 | BM54: 0 | BN54: 0 | BO54: 0 | BP54: 0 | BQ54: 0 | BR54: 0 | BS54: 0 | BT54: 0
A55: 64325523 | B55: 1715 | C55: 64325523 | D55: Yasso Chocolate Fudge Brownie 8-4pk | E55: 0 | F55: 0 | G55: 26250 | H55: 0 | I55: 0 | J55: 0 | K55: 0 | L55: 0 | M55: 0 | N55: 0 | O55: 0 | P55: 0 | Q55: 0 | R55: 0 | S55: 0 | T55: 0 | U55: 0 | V55: 0 | W55: 0 | X55: 0 | Y55: 0 | Z55: 0 | AA55: 0 | AB55: 0 | AC55: 0 | AD55: 0 | AE55: 0 | AF55: 0 | AG55: 0 | AH55: 0 | AI55: 0 | AJ55: 0 | AK55: 0 | AL55: 0 | AM55: 0 | AN55: 0 | AO55: 0 | AP55: 0 | AQ55: 0 | AR55: 0 | AS55: 0 | AT55: 0 | AU55: 0 | AV55: 0 | AW55: 0 | AX55: 0 | AY55: 0 | AZ55: 0 | BA55: 0 | BB55: 0 | BC55: 0 | BD55: 0 | BE55: 0 | BF55: 0 | BG55: 0 | BH55: 0 | BI55: 0 | BJ55: 0 | BK55: 0 | BL55: 0 | BM55: 0 | BN55: 0 | BO55: 0 | BP55: 0 | BQ55: 0 | BR55: 0 | BS55: 0 | BT55: 0
A56: 64325559 | B56: 1715 | C56: 64325559 | D56: Yasso Birthday Cake 8-4pk | E56: 0 | F56: 0 | G56: 20000 | H56: 1 | I56: 0 | J56: 0 | K56: 0 | L56: 12500 | M56: 0 | N56: 0 | O56: 0 | P56: 0 | Q56: 0 | R56: 0 | S56: 0 | T56: 0 | U56: 0 | V56: 0 | W56: 0 | X56: 0 | Y56: 0 | Z56: 0 | AA56: 0 | AB56: 0 | AC56: 0 | AD56: 0 | AE56: 0 | AF56: 0 | AG56: 0 | AH56: 0 | AI56: 0 | AJ56: 0 | AK56: 0 | AL56: 0 | AM56: 0 | AN56: 0 | AO56: 0 | AP56: 0 | AQ56: 0 | AR56: 0 | AS56: 0 | AT56: 0 | AU56: 0 | AV56: 0 | AW56: 0 | AX56: 0 | AY56: 0 | AZ56: 0 | BA56: 0 | BB56: 0 | BC56: 0 | BD56: 0 | BE56: 0 | BF56: 0 | BG56: 0 | BH56: 0 | BI56: 0 | BJ56: 0 | BK56: 0 | BL56: 0 | BM56: 0 | BN56: 0 | BO56: 0 | BP56: 0 | BQ56: 0 | BR56: 0 | BS56: 0 | BT56: 0
... A113: 69687232 | B113: 6706 | C113: 69687232 | D113: GH Giant Cookies and Cream Cone 1-12PK | E113: 0 | F113: 0 | G113: 0 | H113: 30000 | I113: 0 | J113: 0 | K113: 0 | L113: 0 | M113: 0 | N113: 0 | O113: 0 | P113: 0 | Q113: 0 | R113: 0 | S113: 0 | T113: 0 | U113: 0 | V113: 0 | W113: 0 | X113: 0 | Y113: 30000 | Z113: 0 | AA113: 0 | AB113: 0 | AC113: 0 | AD113: 0 | AE113: 0 | AF113: 30000 | AG113: 0 | AH113: 0 | AI113: 0 | AJ113: 0 | AK113: 30000 | AL113: 0 | AM113: 0 | AN113: 0 | AO113: 0 | AP113: 0 | AQ113: 30000 | AR113: 0 | AS113: 0 | AT113: 0 | AU113: 0 | AV113: 0 | AW113: 30000 | AX113: 0 | AY113: 0 | AZ113: 0 | BA113: 0 | BB113: 0 | BC113: 0 | BD113: 0 | BE113: 30000 | BF113: 0 | BG113: 0 | BH113: 0 | BI113: 0 | BJ113: 0 | BK113: 0 | BL113: 0 | BM113: 0 | BN113: 30000 | BO113: 0 | BP113: 0 | BQ113: 0 | BR113: 0 | BS113: 0 | BT113: 0
A114: 62714126 | B114: GDI | C114: 62714126 | D114: PS OCG SF 6-18PK | E114: 15600 | F114: 49400 | G114: 49400 | H114: 44200 | I114: 57200 | J114: 36400 | K114: 40000 | L114: 40000 | M114: 40000 | N114: 0 | O114: 0 | P114: 0 | Q114: 0 | R114: 25000 | S114: 40000 | T114: 40000 | U114: 40000 | V114: 0 | W114: 0 | X114: 0 | Y114: 0 | Z114: 0 | AA114: 0 | AB114: 0 | AC114: 40000 | AD114: 40000 | AE114: 40000 | AF114: 40000 | AG114: 40000 | AH114: 40000 | AI114: 30000 | AJ114: 30000 | AK114: 40000 | AL114: 40000 | AM114: 40000 | AN114: 30000 | AO114: 40000 | AP114: 40000 | AQ114: 40000 | AR114: 30000 | AS114: 0 | AT114: 40000 | AU114: 40000 | AV114: 40000 | AW114: 30000 | AX114: 40000 | AY114: 40000 | AZ114: 40000 | BA114: 30000 | BB114: 40000 | BC114: 40000 | BD114: 40000 | BE114: 30000 | BF114: 43210 | BG114: 40000 | BH114: 40000 | BI114: 40000 | BJ114: 30000 | BK114: 40000 | BL114: 40000 | BM114: 40000 | BN114: 40000 | BO114: 40000 | BP114: 20000 | BQ114: 20000 | BR114: 20000 | BS114: 20000 | BT114: 40000
A115: 62714129 | B115: GDI | C115: 62714129 | D115: PS OCG 6-18PK | E115: 0 | F115: 7800 | G115: 0 | H115: 0 | I115: 0 | J115: 0 | K115: 0 | L115: 0 | M115: 0 | N115: 0 | O115: 20000 | P115: 20000 | Q115: 40000 | R115: 5000 | S115: 0 | T115: 0 | U115: 0 | V115: 40000 | W115: 40000 | X115: 40000 | Y115: 40000 | Z115: 0 | AA115: 0 | AB115: 0 | AC115: 40000 | AD115: 0 | AE115: 0 | AF115: 0 | AG115: 0 | AH115: 0 | AI115: 0 | AJ115: 40000 | AK115: 0 | AL115: 0 | AM115: 0 | AN115: 40000 | AO115: 0 | AP115: 0 | AQ115: 0 | AR115: 20000 | AS115: 40000 | AT115: 0 | AU115: 0 | AV115: 20000 | AW115: 40000 | AX115: 0 | AY115: 0 | AZ115: 20000 | BA115: 40000 | BB115: 0 | BC115: 0 | BD115: 0 | BE115: 40000 | BF115: 5310 | BG115: 0 | BH115: 0 | BI115: 0 | BJ115: 40000 | BK115: 0 | BL115: 0 | BM115: 0 | BN115: 0 | BO115: 40000 | BP115: 0 | BQ115: 0 | BR115: 20000 | BS115: 3000 | BT115: 0
A116: 64366224 | B116: GDI | C116: 64366224 | D116: PS Buzz Lightyear IH 6-6PK | E116: 0 | F116: 0 | G116: 0 | H116: 0 | I116: 0 | J116: 0 | K116: 0 | L116: 0 | M116: 0 | N116: 0 | O116: 0 | P116: 0 | Q116: 24123 | R116: 40018 | S116: 15895 | T116: 0 | U116: 0 | V116: 0 | W116: 0 | X116: 0 | Y116: 0 | Z116: 0 | AA116: 0 | AB116: 24192 | AC116: 24192 | AD116: 0 | AE116: 0 | AF116: 48324 | AG116: 0 | AH116: 0 | AI116: 0 | AJ116: 0 | AK116: 0 | AL116: 0 | AM116: 32256 | AN116: 40420 | AO116: 0 | AP116: 0 | AQ116: 40320 | AR116: 0 | AS116: 0 | AT116: 0 | AU116: 32256 | AV116: 28224 | AW116: 0 | AX116: 0 | AY116: 32256 | AZ116: 0 | BA116: 0 | BB116: 0 | BC116: 0 | BD116: 40320 | BE116: 32256 | BF116: 0 | BG116: 0 | BH116: 0 | BI116: 40320 | BJ116: 40320 | BK116: 0 | BL116: 0 | BM116: 0 | BN116: 0 | BO116: 0 | BP116: 0 | BQ116: 0 | BR116: 16128 | BS116: 24192 | BT116: 0

Sheet Sheet3
A1: Part Name | B1: Part Description | C1: Alternate Part | D1: Segmentation | E1: Figure Name | F1: Figure by Date Past | G1: Figure by Date Week 08-26-24 | H1: Figure by Date Week 09-02-24 | I1: Figure by Date Week 09-09-24 | J1: Figure by Date Week 09-16-24 | K1: Figure by Date Week 09-23-24 | L1: Figure by Date Week 09-30-24 | M1: Figure by Date Week 10-07-24 | N1: Figure by Date Week 10-14-24 | O1: Figure by Date Week 10-21-24 | P1: Figure by Date Week 10-28-24 | Q1: Figure by Date Week 11-04-24 | R1: Figure by Date Week 11-11-24 | S1: Figure by Date Week 11-18-24 | T1: Figure by Date Week 11-25-24 | U1: Figure by Date Week 12-02-24 | V1: Figure by Date Week 12-09-24 | W1: Figure by Date Week 12-16-24 | X1: Figure by Date Week 12-23-24 | Y1: Figure by Date Week 12-30-24 | Z1: Figure by Date Week 01-06-25 | AA1: Figure by Date Week 01-13-25 | AB1: Figure by Date Week 01-20-25 | AC1: Figure by Date Week 01-27-25 | AD1: Figure by Date Week 02-03-25 | AE1: Figure by Date Week 02-10-25 | AF1: Figure by Date Week 02-17-25 | AG1: Figure by Date Week 02-24-25 | AH1: Figure by Date Week 03-03-25 | AI1: Figure by Date Week 03-10-25 | AJ1: Figure by Date Week 03-17-25 | AK1: Figure by Date Week 03-24-25 | AL1: Figure by Date Week 03-31-25 | AM1: Figure by Date Week 04-07-25 | AN1: Figure by Date Week 04-14-25 | AO1: Figure by Date Week 04-21-25 | AP1: Figure by Date Week 04-28-25 | AQ1: Figure by Date Week 05-05-25 | AR1: Figure by Date Week 05-12-25 | AS1: Figure by Date Week 05-19-25 | AT1: Figure by Date Week 05-26-25 | AU1: Figure by Date Week 06-02-25 | AV1: Figure by Date Week 06-09-25 | AW1: Figure by Date Week 06-16-25 | AX1: Figure by Date Week 06-23-25 | AY1: Figure by Date Week 06-30-25 | AZ1: Figure by Date Week 07-07-25 | BA1: Figure by Date Week 07-14-25 | BB1: Figure by Date Week 07-21-25 | BC1: Figure by Date Week 07-28-25 | BD1: Figure by Date Week 08-04-25 | BE1: Figure by Date Week 08-11-25 | BF1: Figure by Date Week 08-18-25 | BG1: Figure by Date Week 08-25-25 | BH1: Figure by Date Week 09-01-25 | BI1: Figure by Date Week 09-08-25 | BJ1: Figure by Date Week 09-15-25 | BK1: Figure by Date Week 09-22-25 | BL1: Figure by Date Week 09-29-25 | BM1: Figure by Date Week 10-06-25 | BN1: Figure by Date Week 10-13-25 | BO1: Figure by Date Week 10-20-25 | BP1: Figure by Date Week 10-27-25 | BQ1: Figure by Date Week 11-03-25 | BR1: Figure by Date Week 11-10-25 | BS1: Figure by Date Week 11-17-25 | BT1: Figure by Date Week 11-24-25 | BU1: Figure by Date Week 12-01-25 | BV1: Figure by Date Week 12-08-25 | BW1: Figure by Date Week 12-15-25 | BX1: Figure by Date Week 12-22-25 | BY1: Figure by Date Week 12-29-25
A2: 62678148 | B2: BJ US-NDO-LightsCaramelAction-8 1PT | C2: 62678148 | D2: B | E2: Sum Of Supply | F2: 240 | G2: 480 | H2: 0 | I2: 0 | J2: 0 | K2: 0 | L2: 0 | M2: 0 | N2: 0 | O2: 0 | P2: 0 | Q2: 0 | R2: 0 | S2: 0 | T2: 0 | U2: 0 | V2: 0 | W2: 0 | X2: 0 | Y2: 0 | Z2: 0 | AA2: 0 | AB2: 0 | AC2: 0 | AD2: 0 | AE2: 0 | AF2: 0 | AG2: 0 | AH2: 0 | AI2: 0 | AJ2: 0 | AK2: 0 | AL2: 0 | AM2: 0 | AN2: 0 | AO2: 0 | AP2: 0 | AQ2: 0 | AR2: 0 | AS2: 0 | AT2: 0 | AU2: 0 | AV2: 0 | AW2: 0 | AX2: 0 | AY2: 0 | AZ2: 0 | BA2: 0 | BB2: 0 | BC2: 0 | BD2: 0 | BE2: 0 | BF2: 0 | BG2: 0 | BH2: 0 | BI2: 0 | BJ2: 0 | BK2: 0 | BL2: 0 | BM2: 0 | BN2: 0 | BO2: 0 | BP2: 0 | BQ2: 0 | BR2: 0 | BS2: 0 | BT2: 0 | BU2: 0 | BV2: 0 | BW2: 0 | BX2: 0 | BY2: 0
A3: 62678151 | B3: BJ US-NDO-PBHalfBaked-8 1PT | C3: 62678151 | D3: B | E3: Sum Of Supply | F3: 0 | G3: 240 | H3: 0 | I3: 0 | J3: 0 | K3: 0 | L3: 0 | M3: 0 | N3: 0 | O3: 0 | P3: 0 | Q3: 0 | R3: 0 | S3: 0 | T3: 0 | U3: 0 | V3: 0 | W3: 0 | X3: 0 | Y3: 0 | Z3: 0 | AA3: 0 | AB3: 0 | AC3: 0 | AD3: 0 | AE3: 0 | AF3: 0 | AG3: 0 | AH3: 0 | AI3: 0 | AJ3: 0 | AK3: 0 | AL3: 0 | AM3: 0 | AN3: 0 | AO3: 0 | AP3: 0 | AQ3: 0 | AR3: 0 | AS3: 0 | AT3: 0 | AU3: 0 | AV3: 0 | AW3: 0 | AX3: 0 | AY3: 0 | AZ3: 0 | BA3: 0 | BB3: 0 | BC3: 0 | BD3: 0 | BE3: 0 | BF3: 0 | BG3: 0 | BH3: 0 | BI3: 0 | BJ3: 0 | BK3: 0 | BL3: 0 | BM3: 0 | BN3: 0 | BO3: 0 | BP3: 0 | BQ3: 0 | BR3: 0 | BS3: 0 | BT3: 0 | BU3: 0 | BV3: 0 | BW3: 0 | BX3: 0 | BY3: 0
A4: 62678152 | B4: BJ US-NDO-OatmealDreamPie-8 1PT | C4: 62678152 | D4: B | E4: Sum Of Supply | F4: 240 | G4: 240 | H4: 0 | I4: 0 | J4: 0 | K4: 0 | L4: 0 | M4: 0 | N4: 0 | O4: 0 | P4: 0 | Q4: 0 | R4: 0 | S4: 0 | T4: 0 | U4: 0 | V4: 0 | W4: 0 | X4: 0 | Y4: 0 | Z4: 0 | AA4: 0 | AB4: 0 | AC4: 0 | AD4: 0 | AE4: 0 | AF4: 0 | AG4: 0 | AH4: 0 | AI4: 0 | AJ4: 0 | AK4: 0 | AL4: 0 | AM4: 0 | AN4: 0 | AO4: 0 | AP4: 0 | AQ4: 0 | AR4: 0 | AS4: 0 | AT4: 0 | AU4: 0 | AV4: 0 | AW4: 0 | AX4: 0 | AY4: 0 | AZ4: 0 | BA4: 0 | BB4: 0 | BC4: 0 | BD4: 0 | BE4: 0 | BF4: 0 | BG4: 0 | BH4: 0 | BI4: 0 | BJ4: 0 | BK4: 0 | BL4: 0 | BM4: 0 | BN4: 0 | BO4: 0 | BP4: 0 | BQ4: 0 | BR4: 0 | BS4: 0 | BT4: 0 | BU4: 0 | BV4: 0 | BW4: 0 | BX4: 0 | BY4: 0
A5: 62689431 | B5: BJ US-IC-Mango-1 2.4GAL | C5: 62689431 | D5: D | E5: Sum Of Supply | F5: 0 | G5: 500 | H5: 0 | I5: 0 | J5: 0 | K5: 0 | L5: 0 | M5: 0 | N5: 0 | O5: 0 | P5: 0 | Q5: 0 | R5: 0 | S5: 0 | T5: 0 | U5: 0 | V5: 0 | W5: 0 | X5: 0 | Y5: 0 | Z5: 0 | AA5: 0 | AB5: 0 | AC5: 0 | AD5: 0 | AE5: 0 | AF5: 0 | AG5: 0 | AH5: 0 | AI5: 0 | AJ5: 0 | AK5: 0 | AL5: 0 | AM5: 0 | AN5: 0 | AO5: 0 | AP5: 0 | AQ5: 0 | AR5: 0 | AS5: 0 | AT5: 0 | AU5: 0 | AV5: 0 | AW5: 0 | AX5: 0 | AY5: 0 | AZ5: 0 | BA5: 0 | BB5: 0 | BC5: 0 | BD5: 0 | BE5: 0 | BF5: 0 | BG5: 0 | BH5: 0 | BI5: 0 | BJ5: 0 | BK5: 0 | BL5: 0 | BM5: 0 | BN5: 0 | BO5: 0 | BP5: 0 | BQ5: 0 | BR5: 0 | BS5: 0 | BT5: 0 | BU5: 0 | BV5: 0 | BW5: 0 | BX5: 0 | BY5: 0
A6: 62694394 | B6: MG Non-Dairy Sea Salt Caramel 10-3PK | C6: 62694394 | D6: C | E6: Import Supply | F6: 61 | G6: 0 | H6: 8884 | I6: 0 | J6: 0 | K6: 0 | L6: 0 | M6: 0 | N6: 0 | O6: 0 | P6: 0 | Q6: 0 | R6: 0 | S6: 0 | T6: 0 | U6: 0 | V6: 0 | W6: 0 | X6: 0 | Y6: 0 | Z6: 0 | AA6: 0 | AB6: 0 | AC6: 0 | AD6: 0 | AE6: 0 | AF6: 0 | AG6: 0 | AH6: 0 | AI6: 0 | AJ6: 0 | AK6: 0 | AL6: 0 | AM6: 0 | AN6: 0 | AO6: 0 | AP6: 0 | AQ6: 0 | AR6: 0 | AS6: 0 | AT6: 0 | AU6: 0 | AV6: 0 | AW6: 0 | AX6: 0 | AY6: 0 | AZ6: 0 | BA6: 0 | BB6: 0 | BC6: 0 | BD6: 0 | BE6: 0 | BF6: 0 | BG6: 0 | BH6: 0 | BI6: 0 | BJ6: 0 | BK6: 0 | BL6: 0 | BM6: 0 | BN6: 0 | BO6: 0 | BP6: 0 | BQ6: 0 | BR6: 0 | BS6: 0 | BT6: 0 | BU6: 0 | BV6: 0 | BW6: 0 | BX6: 0 | BY6: 0
A7: 62694394 | B7: MG Non-Dairy Sea Salt Caramel 10-3PK | C7: 62694394 | D7: C | E7: Sum Of Supply | F7: 61 | G7: 0 | H7: 8884 | I7: 0 | J7: 0 | K7: 0 | L7: 0 | M7: 0 | N7: 0 | O7: 0 | P7: 0 | Q7: 0 | R7: 0 | S7: 0 | T7: 0 | U7: 0 | V7: 0 | W7: 0 | X7: 0 | Y7: 0 | Z7: 0 | AA7: 0 | AB7: 0 | AC7: 0 | AD7: 0 | AE7: 0 | AF7: 0 | AG7: 0 | AH7: 0 | AI7: 0 | AJ7: 0 | AK7: 0 | AL7: 0 | AM7: 0 | AN7: 0 | AO7: 0 | AP7: 0 | AQ7: 0 | AR7: 0 | AS7: 0 | AT7: 0 | AU7: 0 | AV7: 0 | AW7: 0 | AX7: 0 | AY7: 0 | AZ7: 0 | BA7: 0 | BB7: 0 | BC7: 0 | BD7: 0 | BE7: 0 | BF7: 0 | BG7: 0 | BH7: 0 | BI7: 0 | BJ7: 0 | BK7: 0 | BL7: 0 | BM7: 0 | BN7: 0 | BO7: 0 | BP7: 0 | BQ7: 0 | BR7: 0 | BS7: 0 | BT7: 0 | BU7: 0 | BV7: 0 | BW7: 0 | BX7: 0 | BY7: 0
A8: 62694440 | B8: MG Non-Dairy Almond 10-3PK | C8: 62694440 | D8: C | E8: Import Supply | F8: 1 | G8: 0 | H8: 3855 | I8: 0 | J8: 0 | K8: 0 | L8: 0 | M8: 0 | N8: 0 | O8: 0 | P8: 0 | Q8: 0 | R8: 0 | S8: 0 | T8: 0 | U8: 0 | V8: 0 | W8: 0 | X8: 0 | Y8: 0 | Z8: 0 | AA8: 0 | AB8: 0 | AC8: 0 | AD8: 0 | AE8: 0 | AF8: 0 | AG8: 0 | AH8: 0 | AI8: 0 | AJ8: 0 | AK8: 0 | AL8: 0 | AM8: 0 | AN8: 0 | AO8: 0 | AP8: 0 | AQ8: 0 | AR8: 0 | AS8: 0 | AT8: 0 | AU8: 0 | AV8: 0 | AW8: 0 | AX8: 0 | AY8: 0 | AZ8: 0 | BA8: 0 | BB8: 0 | BC8: 0 | BD8: 0 | BE8: 0 | BF8: 0 | BG8: 0 | BH8: 0 | BI8: 0 | BJ8: 0 | BK8: 0 | BL8: 0 | BM8: 0 | BN8: 0 | BO8: 0 | BP8: 0 | BQ8: 0 | BR8: 0 | BS8: 0 | BT8: 0 | BU8: 0 | BV8: 0 | BW8: 0 | BX8: 0 | BY8: 0
A9: 62694440 | B9: MG Non-Dairy Almond 10-3PK | C9: 62694440 | D9: C | E9: Sum Of Supply | F9: 1 | G9: 0 | H9: 3855 | I9: 0 | J9: 0 | K9: 0 | L9: 0 | M9: 0 | N9: 0 | O9: 0 | P9: 0 | Q9: 0 | R9: 0 | S9: 0 | T9: 0 | U9: 0 | V9: 0 | W9: 0 | X9: 0 | Y9: 0 | Z9: 0 | AA9: 0 | AB9: 0 | AC9: 0 | AD9: 0 | AE9: 0 | AF9: 0 | AG9: 0 | AH9: 0 | AI9: 0 | AJ9: 0 | AK9: 0 | AL9: 0 | AM9: 0 | AN9: 0 | AO9: 0 | AP9: 0 | AQ9: 0 | AR9: 0 | AS9: 0 | AT9: 0 | AU9: 0 | AV9: 0 | AW9: 0 | AX9: 0 | AY9: 0 | AZ9: 0 | BA9: 0 | BB9: 0 | BC9: 0 | BD9: 0 | BE9: 0 | BF9: 0 | BG9: 0 | BH9: 0 | BI9: 0 | BJ9: 0 | BK9: 0 | BL9: 0 | BM9: 0 | BN9: 0 | BO9: 0 | BP9: 0 | BQ9: 0 | BR9: 0 | BS9: 0 | BT9: 0 | BU9: 0 | BV9: 0 | BW9: 0 | BX9: 0 | BY9: 0
A10: 62697528 | B10: BJ US-NDO-Milk+Cookies-8 1PT | C10: 62697528 | D10: B | E10: Sum Of Supply | F10: 240 | G10: 240 | H10: 0 | I10: 0 | J10: 0 | K10: 0 | L10: 0 | M10: 0 | N10: 0 | O10: 0 | P10: 0 | Q10: 0 | R10: 0 | S10: 0 | T10: 0 | U10: 0 | V10: 0 | W10: 0 | X10: 0 | Y10: 0 | Z10: 0 | AA10: 0 | AB10: 0 | AC10: 0 | AD10: 0 | AE10: 0 | AF10: 0 | AG10: 0 | AH10: 0 | AI10: 0 | AJ10: 0 | AK10: 0 | AL10: 0 | AM10: 0 | AN10: 0 | AO10: 0 | AP10: 0 | AQ10: 0 | AR10: 0 | AS10: 0 | AT10: 0 | AU10: 0 | AV10: 0 | AW10: 0 | AX10: 0 | AY10: 0 | AZ10: 0 | BA10: 0 | BB10: 0 | BC10: 0 | BD10: 0 | BE10: 0 | BF10: 0 | BG10: 0 | BH10: 0 | BI10: 0 | BJ10: 0 | BK10: 0 | BL10: 0 | BM10: 0 | BN10: 0 | BO10: 0 | BP10: 0 | BQ10: 0 | BR10: 0 | BS10: 0 | BT10: 0 | BU10: 0 | BV10: 0 | BW10: 0 | BX10: 0 | BY10: 0
A11: 62697530 | B11: BJ US-NDO-COR-BananasFoster-8 1PT | C11: 62697530 | D11: C | E11: Sum Of Supply | F11: 720 | G11: 0 | H11: 0 | I11: 0 | J11: 0 | K11: 0 | L11: 0 | M11: 0 | N11: 0 | O11: 0 | P11: 0 | Q11: 0 | R11: 0 | S11: 0 | T11: 0 | U11: 0 | V11: 0 | W11: 0 | X11: 0 | Y11: 0 | Z11: 0 | AA11: 0 | AB11: 0 | AC11: 0 | AD11: 0 | AE11: 0 | AF11: 0 | AG11: 0 | AH11: 0 | AI11: 0 | AJ11: 0 | AK11: 0 | AL11: 0 | AM11: 0 | AN11: 0 | AO11: 0 | AP11: 0 | AQ11: 0 | AR11: 0 | AS11: 0 | AT11: 0 | AU11: 0 | AV11: 0 | AW11: 0 | AX11: 0 | AY11: 0 | AZ11: 0 | BA11: 0 | BB11: 0 | BC11: 0 | BD11: 0 | BE11: 0 | BF11: 0 | BG11: 0 | BH11: 0 | BI11: 0 | BJ11: 0 | BK11: 0 | BL11: 0 | BM11: 0 | BN11: 0 | BO11: 0 | BP11: 0 | BQ11: 0 | BR11: 0 | BS11: 0 | BT11: 0 | BU11: 0 | BV11: 0 | BW11: 0 | BX11: 0 | BY11: 0
A12: 62698497 | B12: GH Reeses Bar Club 1-24PK | C12: 62698497 | D12: I | E12: Sum Of Supply | F12: 1800 | G12: 3720 | H12: 0 | I12: 0 | J12: 0 | K12: 0 | L12: 0 | M12: 0 | N12: 0 | O12: 0 | P12: 0 | Q12: 0 | R12: 0 | S12: 0 | T12: 0 | U12: 0 | V12: 0 | W12: 0 | X12: 0 | Y12: 0 | Z12: 0 | AA12: 0 | AB12: 0 | AC12: 0 | AD12: 0 | AE12: 0 | AF12: 0 | AG12: 0 | AH12: 0 | AI12: 0 | AJ12: 0 | AK12: 0 | AL12: 0 | AM12: 0 | AN12: 0 | AO12: 0 | AP12: 0 | AQ12: 0 | AR12: 0 | AS12: 0 | AT12: 0 | AU12: 0 | AV12: 0 | AW12: 0 | AX12: 0 | AY12: 0 | AZ12: 0 | BA12: 0 | BB12: 0 | BC12: 0 | BD12: 0 | BE12: 0 | BF12: 0 | BG12: 0 | BH12: 0 | BI12: 0 | BJ12: 0 | BK12: 0 | BL12: 0 | BM12: 0 | BN12: 0 | BO12: 0 | BP12: 0 | BQ12: 0 | BR12: 0 | BS12: 0 | BT12: 0 | BU12: 0 | BV12: 0 | BW12: 0 | BX12: 0 | BY12: 0
A13: 62714126 | B13: PS OCG SF 6-18PK | C13: 62714126 | D13: A | E13: Import Supply | F13: 39000 | G13: 20800 | H13: 52000 | I13: 41600 | J13: 96200 | K13: 20800 | L13: 0 | M13: 0 | N13: 0 | O13: 0 | P13: 0 | Q13: 0 | R13: 0 | S13: 0 | T13: 0 | U13: 0 | V13: 0 | W13: 0 | X13: 0 | Y13: 0 | Z13: 0 | AA13: 0 | AB13: 0 | AC13: 0 | AD13: 0 | AE13: 0 | AF13: 0 | AG13: 0 | AH13: 0 | AI13: 0 | AJ13: 0 | AK13: 0 | AL13: 0 | AM13: 0 | AN13: 0 | AO13: 0 | AP13: 0 | AQ13: 0 | AR13: 0 | AS13: 0 | AT13: 0 | AU13: 0 | AV13: 0 | AW13: 0 | AX13: 0 | AY13: 0 | AZ13: 0 | BA13: 0 | BB13: 0 | BC13: 0 | BD13: 0 | BE13: 0 | BF13: 0 | BG13: 0 | BH13: 0 | BI13: 0 | BJ13: 0 | BK13: 0 | BL13: 0 | BM13: 0 | BN13: 0 | BO13: 0 | BP13: 0 | BQ13: 0 | BR13: 0 | BS13: 0 | BT13: 0 | BU13: 0 | BV13: 0 | BW13: 0 | BX13: 0 | BY13: 0
... A52: 64326407 | B52: Yasso Coffee Poppables 10-6.84flz | C52: 64326407 | D52: I | E52: Sum Of Supply | F52: 0 | G52: 0 | H52: 0 | I52: 16000 | J52: 0 | K52: 0 | L52: 0 | M52: 0 | N52: 0 | O52: 0 | P52: 0 | Q52: 0 | R52: 0 | S52: 0 | T52: 0 | U52: 0 | V52: 0 | W52: 0 | X52: 0 | Y52: 0 | Z52: 0 | AA52: 0 | AB52: 0 | AC52: 0 | AD52: 0 | AE52: 0 | AF52: 0 | AG52: 0 | AH52: 0 | AI52: 0 | AJ52: 0 | AK52: 0 | AL52: 0 | AM52: 0 | AN52: 0 | AO52: 0 | AP52: 0 | AQ52: 0 | AR52: 0 | AS52: 0 | AT52: 0 | AU52: 0 | AV52: 0 | AW52: 0 | AX52: 0 | AY52: 0 | AZ52: 0 | BA52: 0 | BB52: 0 | BC52: 0 | BD52: 0 | BE52: 0 | BF52: 0 | BG52: 0 | BH52: 0 | BI52: 0 | BJ52: 0 | BK52: 0 | BL52: 0 | BM52: 0 | BN52: 0 | BO52: 0 | BP52: 0 | BQ52: 0 | BR52: 0 | BS52: 0 | BT52: 0 | BU52: 0 | BV52: 0 | BW52: 0 | BX52: 0 | BY52: 0
A53: 64327184 | B53: YSO Mint Chocolate Chip Club 1-12pk | C53: 64327184 | E53: Sum Of Supply | F53: 0 | G53: 0 | H53: 86970 | I53: 0 | J53: 0 | K53: 0 | L53: 0 | M53: 0 | N53: 0 | O53: 0 | P53: 0 | Q53: 0 | R53: 0 | S53: 0 | T53: 0 | U53: 0 | V53: 0 | W53: 0 | X53: 0 | Y53: 0 | Z53: 0 | AA53: 0 | AB53: 0 | AC53: 0 | AD53: 0 | AE53: 0 | AF53: 0 | AG53: 0 | AH53: 0 | AI53: 0 | AJ53: 0 | AK53: 0 | AL53: 0 | AM53: 0 | AN53: 0 | AO53: 0 | AP53: 0 | AQ53: 0 | AR53: 0 | AS53: 0 | AT53: 0 | AU53: 0 | AV53: 0 | AW53: 0 | AX53: 0 | AY53: 0 | AZ53: 0 | BA53: 0 | BB53: 0 | BC53: 0 | BD53: 0 | BE53: 0 | BF53: 0 | BG53: 0 | BH53: 0 | BI53: 0 | BJ53: 0 | BK53: 0 | BL53: 0 | BM53: 0 | BN53: 0 | BO53: 0 | BP53: 0 | BQ53: 0 | BR53: 0 | BS53: 0 | BT53: 0 | BU53: 0 | BV53: 0 | BW53: 0 | BX53: 0 | BY53: 0
A54: 64328806 | B54: KL Reeses SW 6-4PK | C54: 64328806 | D54: A | E54: Sum Of Supply | F54: 9 | G54: 0 | H54: 0 | I54: 0 | J54: 0 | K54: 0 | L54: 0 | M54: 0 | N54: 0 | O54: 0 | P54: 0 | Q54: 0 | R54: 0 | S54: 0 | T54: 0 | U54: 0 | V54: 0 | W54: 0 | X54: 0 | Y54: 0 | Z54: 0 | AA54: 0 | AB54: 0 | AC54: 0 | AD54: 0 | AE54: 0 | AF54: 0 | AG54: 0 | AH54: 0 | AI54: 0 | AJ54: 0 | AK54: 0 | AL54: 0 | AM54: 0 | AN54: 0 | AO54: 0 | AP54: 0 | AQ54: 0 | AR54: 0 | AS54: 0 | AT54: 0 | AU54: 0 | AV54: 0 | AW54: 0 | AX54: 0 | AY54: 0 | AZ54: 0 | BA54: 0 | BB54: 0 | BC54: 0 | BD54: 0 | BE54: 0 | BF54: 0 | BG54: 0 | BH54: 0 | BI54: 0 | BJ54: 0 | BK54: 0 | BL54: 0 | BM54: 0 | BN54: 0 | BO54: 0 | BP54: 0 | BQ54: 0 | BR54: 0 | BS54: 0 | BT54: 0 | BU54: 0 | BV54: 0 | BW54: 0 | BX54: 0 | BY54: 0
A55: 64331551 | B55: MG Double Caramel OOH 1-12BK | C55: 64331551 | D55: A | E55: Sum Of Supply | F55: 169 | G55: 314 | H55: 0 | I55: 0 | J55: 0 | K55: 0 | L55: 0 | M55: 0 | N55: 0 | O55: 0 | P55: 0 | Q55: 0 | R55: 0 | S55: 0 | T55: 0 | U55: 0 | V55: 0 | W55: 0 | X55: 0 | Y55: 0 | Z55: 0 | AA55: 0 | AB55: 0 | AC55: 0 | AD55: 0 | AE55: 0 | AF55: 0 | AG55: 0 | AH55: 0 | AI55: 0 | AJ55: 0 | AK55: 0 | AL55: 0 | AM55: 0 | AN55: 0 | AO55: 0 | AP55: 0 | AQ55: 0 | AR55: 0 | AS55: 0 | AT55: 0 | AU55: 0 | AV55: 0 | AW55: 0 | AX55: 0 | AY55: 0 | AZ55: 0 | BA55: 0 | BB55: 0 | BC55: 0 | BD55: 0 | BE55: 0 | BF55: 0 | BG55: 0 | BH55: 0 | BI55: 0 | BJ55: 0 | BK55: 0 | BL55: 0 | BM55: 0 | BN55: 0 | BO55: 0 | BP55: 0 | BQ55: 0 | BR55: 0 | BS55: 0 | BT55: 0 | BU55: 0 | BV55: 0 | BW55: 0 | BX55: 0 | BY55: 0
A56: 64334438 | B56: Talenti Cold Brew Coffee Sorbetto 8 1PT | C56: 64334438 | D56: B | E56: Sum Of Supply | F56: 510 | G56: 765 | H56: 0 | I56: 0 | J56: 0 | K56: 0 | L56: 0 | M56: 0 | N56: 0 | O56: 0 | P56: 0 | Q56: 0 | R56: 0 | S56: 0 | T56: 0 | U56: 0 | V56: 0 | W56: 0 | X56: 0 | Y56: 0 | Z56: 0 | AA56: 0 | AB56: 0 | AC56: 0 | AD56: 0 | AE56: 0 | AF56: 0 | AG56: 0 | AH56: 0 | AI56: 0 | AJ56: 0 | AK56: 0 | AL56: 0 | AM56: 0 | AN56: 0 | AO56: 0 | AP56: 0 | AQ56: 0 | AR56: 0 | AS56: 0 | AT56: 0 | AU56: 0 | AV56: 0 | AW56: 0 | AX56: 0 | AY56: 0 | AZ56: 0 | BA56: 0 | BB56: 0 | BC56: 0 | BD56: 0 | BE56: 0 | BF56: 0 | BG56: 0 | BH56: 0 | BI56: 0 | BJ56: 0 | BK56: 0 | BL56: 0 | BM56: 0 | BN56: 0 | BO56: 0 | BP56: 0 | BQ56: 0 | BR56: 0 | BS56: 0 | BT56: 0 | BU56: 0 | BV56: 0 | BW56: 0 | BX56: 0 | BY56: 0
A57: 64341106 | B57: PS Jolly Rancher Pop 6-18PK | C57: 69778792 | D57: A | E57: Sum Of Supply | F57: 650 | G57: 2600 | H57: 0 | I57: 0 | J57: 0 | K57: 0 | L57: 0 | M57: 0 | N57: 0 | O57: 0 | P57: 0 | Q57: 0 | R57: 0 | S57: 0 | T57: 0 | U57: 0 | V57: 0 | W57: 0 | X57: 0 | Y57: 0 | Z57: 0 | AA57: 0 | AB57: 0 | AC57: 0 | AD57: 0 | AE57: 0 | AF57: 0 | AG57: 0 | AH57: 0 | AI57: 0 | AJ57: 0 | AK57: 0 | AL57: 0 | AM57: 0 | AN57: 0 | AO57: 0 | AP57: 0 | AQ57: 0 | AR57: 0 | AS57: 0 | AT57: 0 | AU57: 0 | AV57: 0 | AW57: 0 | AX57: 0 | AY57: 0 | AZ57: 0 | BA57: 0 | BB57: 0 | BC57: 0 | BD57: 0 | BE57: 0 | BF57: 0 | BG57: 0 | BH57: 0 | BI57: 0 | BJ57: 0 | BK57: 0 | BL57: 0 | BM57: 0 | BN57: 0 | BO57: 0 | BP57: 0 | BQ57: 0 | BR57: 0 | BS57: 0 | BT57: 0 | BU57: 0 | BV57: 0 | BW57: 0 | BX57: 0 | BY57: 0
A58: 64341962 | B58: BR Chocolate Truffle 6 1.5QT | C58: 64341962 | D58: A | E58: Sum Of Supply | F58: 352 | G58: 1936 | H58: 0 | I58: 0 | J58: 0 | K58: 0 | L58: 0 | M58: 0 | N58: 0 | O58: 0 | P58: 0 | Q58: 0 | R58: 0 | S58: 0 | T58: 0 | U58: 0 | V58: 0 | W58: 0 | X58: 0 | Y58: 0 | Z58: 0 | AA58: 0 | AB58: 0 | AC58: 0 | AD58: 0 | AE58: 0 | AF58: 0 | AG58: 0 | AH58: 0 | AI58: 0 | AJ58: 0 | AK58: 0 | AL58: 0 | AM58: 0 | AN58: 0 | AO58: 0 | AP58: 0 | AQ58: 0 | AR58: 0 | AS58: 0 | AT58: 0 | AU58: 0 | AV58: 0 | AW58: 0 | AX58: 0 | AY58: 0 | AZ58: 0 | BA58: 0 | BB58: 0 | BC58: 0 | BD58: 0 | BE58: 0 | BF58: 0 | BG58: 0 | BH58: 0 | BI58: 0 | BJ58: 0 | BK58: 0 | BL58: 0 | BM58: 0 | BN58: 0 | BO58: 0 | BP58: 0 | BQ58: 0 | BR58: 0 | BS58: 0 | BT58: 0 | BU58: 0 | BV58: 0 | BW58: 0 | BX58: 0 | BY58: 0
A59: 64343267 | B59: BJ US-PUP-PumpkinCookie 108p 4FOZ | C59: 64343267 | D59: I | E59: Sum Of Supply | F59: 597 | G59: 0 | H59: 0 | I59: 0 | J59: 0 | K59: 0 | L59: 0 | M59: 0 | N59: 0 | O59: 0 | P59: 0 | Q59: 0 | R59: 0 | S59: 0 | T59: 0 | U59: 0 | V59: 0 | W59: 0 | X59: 0 | Y59: 0 | Z59: 0 | AA59: 0 | AB59: 0 | AC59: 0 | AD59: 0 | AE59: 0 | AF59: 0 | AG59: 0 | AH59: 0 | AI59: 0 | AJ59: 0 | AK59: 0 | AL59: 0 | AM59: 0 | AN59: 0 | AO59: 0 | AP59: 0 | AQ59: 0 | AR59: 0 | AS59: 0 | AT59: 0 | AU59: 0 | AV59: 0 | AW59: 0 | AX59: 0 | AY59: 0 | AZ59: 0 | BA59: 0 | BB59: 0 | BC59: 0 | BD59: 0 | BE59: 0 | BF59: 0 | BG59: 0 | BH59: 0 | BI59: 0 | BJ59: 0 | BK59: 0 | BL59: 0 | BM59: 0 | BN59: 0 | BO59: 0 | BP59: 0 | BQ59: 0 | BR59: 0 | BS59: 0 | BT59: 0 | BU59: 0 | BV59: 0 | BW59: 0 | BX59: 0 | BY59: 0
A60: 64343704 | B60: BJ US-PUP-PB Pretzel 108p 4FOZ | C60: 64343704 | D60: I | E60: Sum Of Supply | F60: 640 | G60: 0 | H60: 0 | I60: 0 | J60: 0 | K60: 0 | L60: 0 | M60: 0 | N60: 0 | O60: 0 | P60: 0 | Q60: 0 | R60: 0 | S60: 0 | T60: 0 | U60: 0 | V60: 0 | W60: 0 | X60: 0 | Y60: 0 | Z60: 0 | AA60: 0 | AB60: 0 | AC60: 0 | AD60: 0 | AE60: 0 | AF60: 0 | AG60: 0 | AH60: 0 | AI60: 0 | AJ60: 0 | AK60: 0 | AL60: 0 | AM60: 0 | AN60: 0 | AO60: 0 | AP60: 0 | AQ60: 0 | AR60: 0 | AS60: 0 | AT60: 0 | AU60: 0 | AV60: 0 | AW60: 0 | AX60: 0 | AY60: 0 | AZ60: 0 | BA60: 0 | BB60: 0 | BC60: 0 | BD60: 0 | BE60: 0 | BF60: 0 | BG60: 0 | BH60: 0 | BI60: 0 | BJ60: 0 | BK60: 0 | BL60: 0 | BM60: 0 | BN60: 0 | BO60: 0 | BP60: 0 | BQ60: 0 | BR60: 0 | BS60: 0 | BT60: 0 | BU60: 0 | BV60: 0 | BW60: 0 | BX60: 0 | BY60: 0
A61: 64346612 | B61: BJ US-PUP-PumpkinCookie 6-4PK | C61: 64346612 | D61: B | E61: Sum Of Supply | F61: 10170 | G61: 6300 | H61: 0 | I61: 0 | J61: 0 | K61: 0 | L61: 0 | M61: 0 | N61: 0 | O61: 0 | P61: 0 | Q61: 0 | R61: 0 | S61: 0 | T61: 0 | U61: 0 | V61: 0 | W61: 0 | X61: 0 | Y61: 0 | Z61: 0 | AA61: 0 | AB61: 0 | AC61: 0 | AD61: 0 | AE61: 0 | AF61: 0 | AG61: 0 | AH61: 0 | AI61: 0 | AJ61: 0 | AK61: 0 | AL61: 0 | AM61: 0 | AN61: 0 | AO61: 0 | AP61: 0 | AQ61: 0 | AR61: 0 | AS61: 0 | AT61: 0 | AU61: 0 | AV61: 0 | AW61: 0 | AX61: 0 | AY61: 0 | AZ61: 0 | BA61: 0 | BB61: 0 | BC61: 0 | BD61: 0 | BE61: 0 | BF61: 0 | BG61: 0 | BH61: 0 | BI61: 0 | BJ61: 0 | BK61: 0 | BL61: 0 | BM61: 0 | BN61: 0 | BO61: 0 | BP61: 0 | BQ61: 0 | BR61: 0 | BS61: 0 | BT61: 0 | BU61: 0 | BV61: 0 | BW61: 0 | BX61: 0 | BY61: 0
A62: 64346613 | B62: BJ US-PUP-PB Pretzel 6-4PK | C62: 64346613 | D62: B | E62: Sum Of Supply | F62: 7224 | G62: 1222 | H62: 0 | I62: 0 | J62: 0 | K62: 0 | L62: 0 | M62: 0 | N62: 0 | O62: 0 | P62: 0 | Q62: 0 | R62: 0 | S62: 0 | T62: 0 | U62: 0 | V62: 0 | W62: 0 | X62: 0 | Y62: 0 | Z62: 0 | AA62: 0 | AB62: 0 | AC62: 0 | AD62: 0 | AE62: 0 | AF62: 0 | AG62: 0 | AH62: 0 | AI62: 0 | AJ62: 0 | AK62: 0 | AL62: 0 | AM62: 0 | AN62: 0 | AO62: 0 | AP62: 0 | AQ62: 0 | AR62: 0 | AS62: 0 | AT62: 0 | AU62: 0 | AV62: 0 | AW62: 0 | AX62: 0 | AY62: 0 | AZ62: 0 | BA62: 0 | BB62: 0 | BC62: 0 | BD62: 0 | BE62: 0 | BF62: 0 | BG62: 0 | BH62: 0 | BI62: 0 | BJ62: 0 | BK62: 0 | BL62: 0 | BM62: 0 | BN62: 0 | BO62: 0 | BP62: 0 | BQ62: 0 | BR62: 0 | BS62: 0 | BT62: 0 | BU62: 0 | BV62: 0 | BW62: 0 | BX62: 0 | BY62: 0
A63: 64356482 | B63: MG Mini Double Caramel RFA 1(3) 6PK | C63: 64356482 | D63: I | E63: Sum Of Supply | F63: 92 | G63: 25360 | H63: 0 | I63: 0 | J63: 0 | K63: 0 | L63: 0 | M63: 0 | N63: 0 | O63: 0 | P63: 0 | Q63: 0 | R63: 0 | S63: 0 | T63: 0 | U63: 0 | V63: 0 | W63: 0 | X63: 0 | Y63: 0 | Z63: 0 | AA63: 0 | AB63: 0 | AC63: 0 | AD63: 0 | AE63: 0 | AF63: 0 | AG63: 0 | AH63: 0 | AI63: 0 | AJ63: 0 | AK63: 0 | AL63: 0 | AM63: 0 | AN63: 0 | AO63: 0 | AP63: 0 | AQ63: 0 | AR63: 0 | AS63: 0 | AT63: 0 | AU63: 0 | AV63: 0 | AW63: 0 | AX63: 0 | AY63: 0 | AZ63: 0 | BA63: 0 | BB63: 0 | BC63: 0 | BD63: 0 | BE63: 0 | BF63: 0 | BG63: 0 | BH63: 0 | BI63: 0 | BJ63: 0 | BK63: 0 | BL63: 0 | BM63: 0 | BN63: 0 | BO63: 0 | BP63: 0 | BQ63: 0 | BR63: 0 | BS63: 0 | BT63: 0 | BU63: 0 | BV63: 0 | BW63: 0 | BX63: 0 | BY63: 0
A64: 64365613 | B64: PS Spiderman Facepiece 6-6PK | C64: 64365613 | E64: Import Supply | F64: 0 | G64: 0 | H64: 0 | I64: 0 | J64: 0 | K64: 0 | L64: 0 | M64: 0 | N64: 0 | O64: 0 | P64: 195 | Q64: 0 | R64: 0 | S64: 0 | T64: 0 | U64: 0 | V64: 0 | W64: 0 | X64: 0 | Y64: 0 | Z64: 0 | AA64: 0 | AB64: 0 | AC64: 0 | AD64: 0 | AE64: 0 | AF64: 0 | AG64: 0 | AH64: 0 | AI64: 0 | AJ64: 0 | AK64: 0 | AL64: 0 | AM64: 0 | AN64: 0 | AO64: 0 | AP64: 0 | AQ64: 0 | AR64: 0 | AS64: 0 | AT64: 0 | AU64: 0 | AV64: 0 | AW64: 0 | AX64: 0 | AY64: 0 | AZ64: 0 | BA64: 0 | BB64: 0 | BC64: 0 | BD64: 0 | BE64: 0 | BF64: 0 | BG64: 0 | BH64: 0 | BI64: 0 | BJ64: 0 | BK64: 0 | BL64: 0 | BM64: 0 | BN64: 0 | BO64: 0 | BP64: 0 | BQ64: 0 | BR64: 0 | BS64: 0 | BT64: 0 | BU64: 0 | BV64: 0 | BW64: 0 | BX64: 0 | BY64: 0
A65: 64365613 | B65: PS Spiderman Facepiece 6-6PK | C65: 64365613 | E65: Sum Of Supply | F65: 0 | G65: 0 | H65: 0 | I65: 0 | J65: 0 | K65: 0 | L65: 0 | M65: 0 | N65: 0 | O65: 0 | P65: 195 | Q65: 0 | R65: 0 | S65: 0 | T65: 0 | U65: 0 | V65: 0 | W65: 0 | X65: 0 | Y65: 0 | Z65: 0 | AA65: 0 | AB65: 0 | AC65: 0 | AD65: 0 | AE65: 0 | AF65: 0 | AG65: 0 | AH65: 0 | AI65: 0 | AJ65: 0 | AK65: 0 | AL65: 0 | AM65: 0 | AN65: 0 | AO65: 0 | AP65: 0 | AQ65: 0 | AR65: 0 | AS65: 0 | AT65: 0 | AU65: 0 | AV65: 0 | AW65: 0 | AX65: 0 | AY65: 0 | AZ65: 0 | BA65: 0 | BB65: 0 | BC65: 0 | BD65: 0 | BE65: 0 | BF65: 0 | BG65: 0 | BH65: 0 | BI65: 0 | BJ65: 0 | BK65: 0 | BL65: 0 | BM65: 0 | BN65: 0 | BO65: 0 | BP65: 0 | BQ65: 0 | BR65: 0 | BS65: 0 | BT65: 0 | BU65: 0 | BV65: 0 | BW65: 0 | BX65: 0 | BY65: 0
A66: 64368273 | B66: BJ US-IC-ChurnOutTheVote-8 1PT LTD | C66: 64368273 | D66: A | E66: Sum Of Supply | F66: 240 | G66: 1200 | H66: 0 | I66: 0 | J66: 0 | K66: 0 | L66: 0 | M66: 0 | N66: 0 | O66: 0 | P66: 0 | Q66: 0 | R66: 0 | S66: 0 | T66: 0 | U66: 0 | V66: 0 | W66: 0 | X66: 0 | Y66: 0 | Z66: 0 | AA66: 0 | AB66: 0 | AC66: 0 | AD66: 0 | AE66: 0 | AF66: 0 | AG66: 0 | AH66: 0 | AI66: 0 | AJ66: 0 | AK66: 0 | AL66: 0 | AM66: 0 | AN66: 0 | AO66: 0 | AP66: 0 | AQ66: 0 | AR66: 0 | AS66: 0 | AT66: 0 | AU66: 0 | AV66: 0 | AW66: 0 | AX66: 0 | AY66: 0 | AZ66: 0 | BA66: 0 | BB66: 0 | BC66: 0 | BD66: 0 | BE66: 0 | BF66: 0 | BG66: 0 | BH66: 0 | BI66: 0 | BJ66: 0 | BK66: 0 | BL66: 0 | BM66: 0 | BN66: 0 | BO66: 0 | BP66: 0 | BQ66: 0 | BR66: 0 | BS66: 0 | BT66: 0 | BU66: 0 | BV66: 0 | BW66: 0 | BX66: 0 | BY66: 0
A67: 64378129 | B67: GH Candy center 8-6pk | C67: 64378129 | D67: I | E67: Import Supply | F67: 0 | G67: 7810 | H67: 0 | I67: 0 | J67: 5610 | K67: 0 | L67: 0 | M67: 0 | N67: 0 | O67: 0 | P67: 0 | Q67: 0 | R67: 0 | S67: 0 | T67: 0 | U67: 0 | V67: 0 | W67: 0 | X67: 0 | Y67: 0 | Z67: 0 | AA67: 0 | AB67: 0 | AC67: 0 | AD67: 0 | AE67: 0 | AF67: 0 | AG67: 0 | AH67: 0 | AI67: 0 | AJ67: 0 | AK67: 0 | AL67: 0 | AM67: 0 | AN67: 0 | AO67: 0 | AP67: 0 | AQ67: 0 | AR67: 0 | AS67: 0 | AT67: 0 | AU67: 0 | AV67: 0 | AW67: 0 | AX67: 0 | AY67: 0 | AZ67: 0 | BA67: 0 | BB67: 0 | BC67: 0 | BD67: 0 | BE67: 0 | BF67: 0 | BG67: 0 | BH67: 0 | BI67: 0 | BJ67: 0 | BK67: 0 | BL67: 0 | BM67: 0 | BN67: 0 | BO67: 0 | BP67: 0 | BQ67: 0 | BR67: 0 | BS67: 0 | BT67: 0 | BU67: 0 | BV67: 0 | BW67: 0 | BX67: 0 | BY67: 0
A68: 64378129 | B68: GH Candy center 8-6pk | C68: 64378129 | D68: I | E68: Sum Of Supply | F68: 0 | G68: 7810 | H68: 0 | I68: 0 | J68: 5610 | K68: 0 | L68: 0 | M68: 0 | N68: 0 | O68: 0 | P68: 0 | Q68: 0 | R68: 0 | S68: 0 | T68: 0 | U68: 0 | V68: 0 | W68: 0 | X68: 0 | Y68: 0 | Z68: 0 | AA68: 0 | AB68: 0 | AC68: 0 | AD68: 0 | AE68: 0 | AF68: 0 | AG68: 0 | AH68: 0 | AI68: 0 | AJ68: 0 | AK68: 0 | AL68: 0 | AM68: 0 | AN68: 0 | AO68: 0 | AP68: 0 | AQ68: 0 | AR68: 0 | AS68: 0 | AT68: 0 | AU68: 0 | AV68: 0 | AW68: 0 | AX68: 0 | AY68: 0 | AZ68: 0 | BA68: 0 | BB68: 0 | BC68: 0 | BD68: 0 | BE68: 0 | BF68: 0 | BG68: 0 | BH68: 0 | BI68: 0 | BJ68: 0 | BK68: 0 | BL68: 0 | BM68: 0 | BN68: 0 | BO68: 0 | BP68: 0 | BQ68: 0 | BR68: 0 | BS68: 0 | BT68: 0 | BU68: 0 | BV68: 0 | BW68: 0 | BX68: 0 | BY68: 0
A69: 64388734 | B69: Yasso Creamy Pineapple Coconut 8-4pk | C69: 64388734 | E69: Sum Of Supply | F69: 0 | G69: 13125 | H69: 0 | I69: 0 | J69: 0 | K69: 0 | L69: 0 | M69: 0 | N69: 0 | O69: 0 | P69: 0 | Q69: 0 | R69: 0 | S69: 0 | T69: 0 | U69: 0 | V69: 0 | W69: 0 | X69: 0 | Y69: 0 | Z69: 0 | AA69: 0 | AB69: 0 | AC69: 0 | AD69: 0 | AE69: 0 | AF69: 0 | AG69: 0 | AH69: 0 | AI69: 0 | AJ69: 0 | AK69: 0 | AL69: 0 | AM69: 0 | AN69: 0 | AO69: 0 | AP69: 0 | AQ69: 0 | AR69: 0 | AS69: 0 | AT69: 0 | AU69: 0 | AV69: 0 | AW69: 0 | AX69: 0 | AY69: 0 | AZ69: 0 | BA69: 0 | BB69: 0 | BC69: 0 | BD69: 0 | BE69: 0 | BF69: 0 | BG69: 0 | BH69: 0 | BI69: 0 | BJ69: 0 | BK69: 0 | BL69: 0 | BM69: 0 | BN69: 0 | BO69: 0 | BP69: 0 | BQ69: 0 | BR69: 0 | BS69: 0 | BT69: 0 | BU69: 0 | BV69: 0 | BW69: 0 | BX69: 0 | BY69: 0
A70: 64388735 | B70: Yasso Cherry Chocolate Crunch 8-4pk | C70: 64388735 | E70: Sum Of Supply | F70: 0 | G70: 13125 | H70: 0 | I70: 0 | J70: 0 | K70: 0 | L70: 0 | M70: 0 | N70: 0 | O70: 0 | P70: 0 | Q70: 0 | R70: 0 | S70: 0 | T70: 0 | U70: 0 | V70: 0 | W70: 0 | X70: 0 | Y70: 0 | Z70: 0 | AA70: 0 | AB70: 0 | AC70: 0 | AD70: 0 | AE70: 0 | AF70: 0 | AG70: 0 | AH70: 0 | AI70: 0 | AJ70: 0 | AK70: 0 | AL70: 0 | AM70: 0 | AN70: 0 | AO70: 0 | AP70: 0 | AQ70: 0 | AR70: 0 | AS70: 0 | AT70: 0 | AU70: 0 | AV70: 0 | AW70: 0 | AX70: 0 | AY70: 0 | AZ70: 0 | BA70: 0 | BB70: 0 | BC70: 0 | BD70: 0 | BE70: 0 | BF70: 0 | BG70: 0 | BH70: 0 | BI70: 0 | BJ70: 0 | BK70: 0 | BL70: 0 | BM70: 0 | BN70: 0 | BO70: 0 | BP70: 0 | BQ70: 0 | BR70: 0 | BS70: 0 | BT70: 0 | BU70: 0 | BV70: 0 | BW70: 0 | BX70: 0 | BY70: 0
A71: 64388736 | B71: Yasso Fudge Poppables 10p 6.84flz | C71: 64388736 | E71: Sum Of Supply | F71: 0 | G71: 4500 | H71: 0 | I71: 0 | J71: 0 | K71: 0 | L71: 0 | M71: 0 | N71: 0 | O71: 0 | P71: 0 | Q71: 0 | R71: 0 | S71: 0 | T71: 0 | U71: 0 | V71: 0 | W71: 0 | X71: 0 | Y71: 0 | Z71: 0 | AA71: 0 | AB71: 0 | AC71: 0 | AD71: 0 | AE71: 0 | AF71: 0 | AG71: 0 | AH71: 0 | AI71: 0 | AJ71: 0 | AK71: 0 | AL71: 0 | AM71: 0 | AN71: 0 | AO71: 0 | AP71: 0 | AQ71: 0 | AR71: 0 | AS71: 0 | AT71: 0 | AU71: 0 | AV71: 0 | AW71: 0 | AX71: 0 | AY71: 0 | AZ71: 0 | BA71: 0 | BB71: 0 | BC71: 0 | BD71: 0 | BE71: 0 | BF71: 0 | BG71: 0 | BH71: 0 | BI71: 0 | BJ71: 0 | BK71: 0 | BL71: 0 | BM71: 0 | BN71: 0 | BO71: 0 | BP71: 0 | BQ71: 0 | BR71: 0 | BS71: 0 | BT71: 0 | BU71: 0 | BV71: 0 | BW71: 0 | BX71: 0 | BY71: 0
A72: 64407917 | B72: BJ US-IC CCCD 6(3) 1PT | C72: 64407917 | D72: I | E72: Sum Of Supply | F72: 2015 | G72: 8000 | H72: 0 | I72: 0 | J72: 0 | K72: 0 | L72: 0 | M72: 0 | N72: 0 | O72: 0 | P72: 0 | Q72: 0 | R72: 0 | S72: 0 | T72: 0 | U72: 0 | V72: 0 | W72: 0 | X72: 0 | Y72: 0 | Z72: 0 | AA72: 0 | AB72: 0 | AC72: 0 | AD72: 0 | AE72: 0 | AF72: 0 | AG72: 0 | AH72: 0 | AI72: 0 | AJ72: 0 | AK72: 0 | AL72: 0 | AM72: 0 | AN72: 0 | AO72: 0 | AP72: 0 | AQ72: 0 | AR72: 0 | AS72: 0 | AT72: 0 | AU72: 0 | AV72: 0 | AW72: 0 | AX72: 0 | AY72: 0 | AZ72: 0 | BA72: 0 | BB72: 0 | BC72: 0 | BD72: 0 | BE72: 0 | BF72: 0 | BG72: 0 | BH72: 0 | BI72: 0 | BJ72: 0 | BK72: 0 | BL72: 0 | BM72: 0 | BN72: 0 | BO72: 0 | BP72: 0 | BQ72: 0 | BR72: 0 | BS72: 0 | BT72: 0 | BU72: 0 | BV72: 0 | BW72: 0 | BX72: 0 | BY72: 0
A73: 64409312 | B73: Holanda Chemisse Pineapple 8-4pk | C73: 64409312 | E73: Sum Of Supply | F73: 0 | G73: 0 | H73: 0 | I73: 0 | J73: 0 | K73: 0 | L73: 0 | M73: 0 | N73: 0 | O73: 0 | P73: 20760 | Q73: 0 | R73: 0 | S73: 0 | T73: 0 | U73: 0 | V73: 0 | W73: 0 | X73: 0 | Y73: 0 | Z73: 0 | AA73: 0 | AB73: 0 | AC73: 0 | AD73: 0 | AE73: 0 | AF73: 0 | AG73: 0 | AH73: 0 | AI73: 0 | AJ73: 0 | AK73: 0 | AL73: 0 | AM73: 0 | AN73: 0 | AO73: 0 | AP73: 0 | AQ73: 0 | AR73: 0 | AS73: 0 | AT73: 0 | AU73: 0 | AV73: 0 | AW73: 0 | AX73: 0 | AY73: 0 | AZ73: 0 | BA73: 0 | BB73: 0 | BC73: 0 | BD73: 0 | BE73: 0 | BF73: 0 | BG73: 0 | BH73: 0 | BI73: 0 | BJ73: 0 | BK73: 0 | BL73: 0 | BM73: 0 | BN73: 0 | BO73: 0 | BP73: 0 | BQ73: 0 | BR73: 0 | BS73: 0 | BT73: 0 | BU73: 0 | BV73: 0 | BW73: 0 | BX73: 0 | BY73: 0
A74: 64409314 | B74: Holanda Chemisse Strawberry 8-4pk | C74: 64409314 | E74: Sum Of Supply | F74: 0 | G74: 0 | H74: 0 | I74: 0 | J74: 0 | K74: 0 | L74: 0 | M74: 0 | N74: 0 | O74: 0 | P74: 20760 | Q74: 0 | R74: 0 | S74: 0 | T74: 0 | U74: 0 | V74: 0 | W74: 0 | X74: 0 | Y74: 0 | Z74: 0 | AA74: 0 | AB74: 0 | AC74: 0 | AD74: 0 | AE74: 0 | AF74: 0 | AG74: 0 | AH74: 0 | AI74: 0 | AJ74: 0 | AK74: 0 | AL74: 0 | AM74: 0 | AN74: 0 | AO74: 0 | AP74: 0 | AQ74: 0 | AR74: 0 | AS74: 0 | AT74: 0 | AU74: 0 | AV74: 0 | AW74: 0 | AX74: 0 | AY74: 0 | AZ74: 0 | BA74: 0 | BB74: 0 | BC74: 0 | BD74: 0 | BE74: 0 | BF74: 0 | BG74: 0 | BH74: 0 | BI74: 0 | BJ74: 0 | BK74: 0 | BL74: 0 | BM74: 0 | BN74: 0 | BO74: 0 | BP74: 0 | BQ74: 0 | BR74: 0 | BS74: 0 | BT74: 0 | BU74: 0 | BV74: 0 | BW74: 0 | BX74: 0 | BY74: 0
A75: 67278338 | B75: BJ SORV-SRB-Lemonade-1 8.95L | C75: 67278338 | D75: D | E75: Sum Of Supply | F75: 0 | G75: 0 | H75: 0 | I75: 0 | J75: 125 | K75: 0 | L75: 0 | M75: 0 | N75: 0 | O75: 0 | P75: 0 | Q75: 0 | R75: 0 | S75: 0 | T75: 0 | U75: 0 | V75: 0 | W75: 0 | X75: 0 | Y75: 0 | Z75: 0 | AA75: 0 | AB75: 0 | AC75: 0 | AD75: 0 | AE75: 0 | AF75: 0 | AG75: 0 | AH75: 0 | AI75: 0 | AJ75: 0 | AK75: 0 | AL75: 0 | AM75: 0 | AN75: 0 | AO75: 0 | AP75: 0 | AQ75: 0 | AR75: 0 | AS75: 0 | AT75: 0 | AU75: 0 | AV75: 0 | AW75: 0 | AX75: 0 | AY75: 0 | AZ75: 0 | BA75: 0 | BB75: 0 | BC75: 0 | BD75: 0 | BE75: 0 | BF75: 0 | BG75: 0 | BH75: 0 | BI75: 0 | BJ75: 0 | BK75: 0 | BL75: 0 | BM75: 0 | BN75: 0 | BO75: 0 | BP75: 0 | BQ75: 0 | BR75: 0 | BS75: 0 | BT75: 0 | BU75: 0 | BV75: 0 | BW75: 0 | BX75: 0 | BY75: 0
