Workbook
Name \P: #REF!
Name \P: #REF!
Name __bas8: #REF!
Name __bas8: #REF!
Name _10QRY_OCTCD_SUMMARY: #REF!
Name _10QRY_OCTCD_SUMMARY: #REF!
Name _10QRY_OCTST_SUMMARY: #REF!
Name _10QRY_OCTST_SUMMARY: #REF!
Name _1a_qr_CD_standard_rate_per_case: #REF!
Name _2007AC_Q1_Shipped_Paid_CD: #REF!
Name _2007AC_Q1_Shipped_Paid_ST: #REF!
Name _2a_qr_ST_rate_per_standard_case: #REF!
Name _6QRY_JUNCD_SUMMARY: #REF!
Name _6QRY_JUNST_SUMMARY: #REF!
Name _8QRY_AUGCD_SUMMARY: #REF!
Name _8QRY_AUGST_SUMMARY: #REF!
Name _9QRY_SEPCD_SUMMARY: #REF!
Name _9QRY_SEPST_SUMMARY: #REF!
Name _ACC0320: #REF!
Name _BAL0320: #REF!
Name _BAL0344: #REF!
Name _BAL0348: #REF!
Name _BAL0360: #REF!
Name _BAL0361: #REF!
Name _BAL0367: #REF!
Name _BAL0370: #REF!
Name _BAL0375: #REF!
Name _BAL0384: #REF!
Name _BAL0385: #REF!
Name _BAL0386: #REF!
Name _BAL0387: #REF!
Name _BAL0388: #REF!
Name _BAL0395: #REF!
Name _bal0397: #REF!
Name _BAL0399: #REF!
Name _BAL0400: #REF!
Name _BAL0810: #REF!
Name _BAL0811: #REF!
Name _BAL0815: #REF!
Name _BAL6791: #REF!
Name _bas8: #REF!
Name _BLA0811: #REF!
Name _top15: #REF!
Name _top15: #REF!
Name aaa: #REF!
Name aaa: #REF!
Name ACTUAL_RATE: #REF!
Name ACTUAL_RATE: #REF!
Name Adjustment: #REF!
Name Adjustment: #REF!
Name agdump: #REF!
Name agedump: #REF!
Name agencydump: #REF!
Name AGENCYLY: #REF!
Name AGENCYPLAN: #REF!
Name AllocationTable: #REF!
Name Americas_Apr: #REF!
Name Americas_Aug: #REF!
Name Americas_Backlog_Apr: #REF!
Name Americas_Backlog_Aug: #REF!

Sheet Recap
C2: M Phys CS | G2: Growth vs YAG | J2: Weight of Total
B3: Supply | D3: 2024 | E3: 2025 | F3: 2026 | G3: 2025 | H3: 2026 | J3: 2024 | K3: 2025 | L3: 2026
C4: VT | D4: =('Cases post Attain'!#REF!+'Cases post Attain'!#REF!)/1000000 -> #REF! | E4: =('Cases post Attain'!Q14+'Cases post Attain'!Q22)/1000000 -> 23.132218 | F4: =('Cases post Attain'!P14+'Cases post Attain'!P22)/1000000 -> 23.460657 | G4: =E4/D4-1 -> #REF! | H4: =F4/E4-1 -> 0.014198304 | J4: =D4/D$11 -> #REF! | K4: =E4/E$11 -> 0.20370898 | L4: =F4/F$11 -> 0.20629004
C5: SIK | D5: ='Cases post Attain'!#REF!/1000000 -> #REF! | E5: ='Cases post Attain'!Q41/1000000 -> 41.684951 | F5: ='Cases post Attain'!P41/1000000 -> 41.70427 | G5: =E5/D5-1 -> #REF! | H5: =F5/E5-1 -> 0.00046344022 | J5: =D5/D$11 -> #REF! | K5: =E5/E$11 -> 0.36708969 | L5: =F5/F$11 -> 0.36670651
C6: COV | D6: ='Cases post Attain'!#REF!/1000000 -> #REF! | E6: ='Cases post Attain'!Q53/1000000 -> 21.663802 | F6: ='Cases post Attain'!P53/1000000 -> 21.551506 | G6: =E6/D6-1 -> #REF! | H6: =F6/E6-1 -> -0.0051836022 | J6: =D6/D$11 -> #REF! | K6: =E6/E$11 -> 0.19077768 | L6: =F6/F$11 -> 0.18950284
C7: Total UL Sites | D7: =SUM(D4:D6) -> #REF! | E7: =SUM(E4:E6) -> 86.480972 | F7: =SUM(F4:F6) -> 86.716432 | G7: =E7/D7-1 -> #REF! | H7: =F7/E7-1 -> 0.0027226823 | J7: =D7/D$11 -> #REF! | K7: =E7/E$11 -> 0.76157636 | L7: =F7/F$11 -> 0.76249939
C8: SIM | D8: ='Cases post Attain'!#REF!/1000000 -> #REF! | E8: ='Cases post Attain'!Q185/1000000 -> 1.050083 | F8: ='Cases post Attain'!P185/1000000 -> 1.3736613 | G8: =E8/D8-1 -> #REF! | H8: =F8/E8-1 -> 0.30814547 | J8: =D8/D$11 -> #REF! | K8: =E8/E$11 -> 0.0092473335 | L8: =F8/F$11 -> 0.012078633
C9: Imports | D9: ='Cases post Attain'!#REF!/1000000 -> #REF! | E9: ='Cases post Attain'!Q186/1000000 -> 6.4899841 | F9: ='Cases post Attain'!P186/1000000 -> 6.7847887 | G9: =E9/D9-1 -> #REF! | H9: =F9/E9-1 -> 0.045424559 | J9: =D9/D$11 -> #REF! | K9: =E9/E$11 -> 0.05715267 | L9: =F9/F$11 -> 0.059658789
C10: CM | D10: ='Cases post Attain'!#REF!/1000000 -> #REF! | E10: ='Cases post Attain'!Q184/1000000 -> 19.534182 | F10: ='Cases post Attain'!P184/1000000 -> 18.851677 | G10: =E10/D10-1 -> #REF! | H10: =F10/E10-1 -> -0.034939041 | J10: =D10/D$11 -> #REF! | K10: =E10/E$11 -> 0.17202364 | L10: =F10/F$11 -> 0.16576319
C11: Total UL | D11: =SUM(D7:D10) -> #REF! | E11: =SUM(E7:E10) -> 113.55522 | F11: =SUM(F7:F10) -> 113.72656 | G11: =E11/D11-1 -> #REF! | H11: =F11/E11-1 -> 0.0015088481
B13: Demand | D13: 110.04314 | E13: 114.37354 | F13: 115.02552 | G13: =E13/D13-1 -> 0.039351813 | H13: =F13/E13-1 -> 0.0057004547
C15: Litons | G15: Growth vs YAG | J15: Weight of Total
B16: Supply | D16: 2024 | E16: 2025 | F16: 2026 | G16: 2025 | H16: 2026 | J16: 2024 | K16: 2025 | L16: 2026
C17: VT | D17: ='Litons Post Attain'!X14+'Litons Post Attain'!X22 -> 104785.87 | E17: ='Litons Post Attain'!Q14+'Litons Post Attain'!Q22 -> 90219.037 | F17: ='Litons Post Attain'!P14+'Litons Post Attain'!P22 -> 91781.613 | G17: =E17/D17-1 -> -0.13901523 | H17: =F17/E17-1 -> 0.017319805 | J17: =D17/D$24 -> 0.19226184 | K17: =E17/E$24 -> 0.16642088 | L17: =F17/F$24 -> 0.16881117
C18: SIK | D18: ='Litons Post Attain'!X41 -> 205930.96 | E18: ='Litons Post Attain'!Q41 -> 205006.34 | F18: ='Litons Post Attain'!P41 -> 203978.38 | G18: =E18/D18-1 -> -0.0044899845 | H18: =F18/E18-1 -> -0.0050142644 | J18: =D18/D$24 -> 0.37784356 | K18: =E18/E$24 -> 0.37816115 | L18: =F18/F$24 -> 0.37517133
C19: COV | D19: ='Litons Post Attain'!X53 -> 165582.14 | E19: ='Litons Post Attain'!Q53 -> 166103.48 | F19: ='Litons Post Attain'!P53 -> 164699.16 | G19: =E19/D19-1 -> 0.0031485448 | H19: =F19/E19-1 -> -0.0084544979 | J19: =D19/D$24 -> 0.30381127 | K19: =E19/E$24 -> 0.30639973 | L19: =F19/F$24 -> 0.30292624
C20: Total UL Sites | D20: =SUM(D17:D19) -> 476298.97 | E20: =SUM(E17:E19) -> 461328.86 | F20: =SUM(F17:F19) -> 460459.16 | G20: =E20/D20-1 -> -0.031430083 | H20: =F20/E20-1 -> -0.0018852093 | J20: =D20/D$24 -> 0.87391667 | K20: =E20/E$24 -> 0.85098176 | L20: =F20/F$24 -> 0.84690874
C21: SIM | D21: ='Litons Post Attain'!X185 -> 2692.3499 | E21: ='Litons Post Attain'!Q185 -> 6089.5978 | F21: ='Litons Post Attain'!P185 -> 7235.8502 | G21: =E21/D21-1 -> 1.2618152 | H21: =F21/E21-1 -> 0.18823123 | J21: =D21/D$24 -> 0.0049399423 | K21: =E21/E$24 -> 0.011233064 | L21: =F21/F$24 -> 0.013308683
C22: Imports | D22: ='Litons Post Attain'!X186 -> 25084.336 | E22: ='Litons Post Attain'!Q186 -> 20341.501 | F22: ='Litons Post Attain'!P186 -> 21261.39 | G22: =E22/D22-1 -> -0.18907556 | H22: =F22/E22-1 -> 0.045222262 | J22: =D22/D$24 -> 0.046024915 | K22: =E22/E$24 -> 0.037522575 | L22: =F22/F$24 -> 0.039105438
C23: CM | D23: ='Litons Post Attain'!X184 -> 40940.802 | E23: ='Litons Post Attain'!Q184 -> 54353.729 | F23: ='Litons Post Attain'!P184 -> 54737.552 | G23: =E23/D23-1 -> 0.32761759 | H23: =F23/E23-1 -> 0.0070615826 | J23: =D23/D$24 -> 0.075118469 | K23: =E23/E$24 -> 0.1002626 | L23: =F23/F$24 -> 0.10067714
C24: Total UL | D24: =SUM(D20:D23) -> 545016.46 | E24: =SUM(E20:E23) -> 542113.69 | F24: =SUM(F20:F23) -> 543693.95 | G24: =E24/D24-1 -> -0.0053260347 | H24: =F24/E24-1 -> 0.0029150031
B26: Demand | D26: 545782.12 | E26: 558648.09 | F26: 554103.58 | G26: =E26/D26-1 -> 0.023573437 | H26: =F26/E26-1 -> -0.0081348248
E29: =(E7*1000000) -> 86480972
E30: =E20/E29 -> 0.0053344551

Sheet Sup-Dmd
D3: Column Labels
D4: CM | G4: Import | J4: SIM | M4: UL | U4: 2026
C5: Row Labels | D5: Sum of 2024 MRF12 | E5: Sum of 2025 MRF8 | F5: Sum of 2026 MRF8 | G5: Sum of 2024 MRF12 | H5: Sum of 2025 MRF8 | I5: Sum of 2026 MRF8 | J5: Sum of 2024 MRF12 | K5: Sum of 2025 MRF8 | L5: Sum of 2026 MRF8 | M5: Sum of 2024 MRF12 | N5: Sum of 2025 MRF8 | O5: Sum of 2026 MRF8 | S5: SIM | T5: UL | U5: CM | V5: Import | W5: SIM | X5: UL
C6: 2.4 Gal | M6: 496558 | N6: 483586 | O6: 526240 | S6: =J6/F6-1 -> #DIV/0! | T6: =K6/G6-1 -> #DIV/0! | U6: =L6/H6-1 -> #DIV/0! | V6: =M6/I6-1 -> #DIV/0! | W6: =N6/J6-1 -> #DIV/0! | X6: =O6/K6-1 -> #DIV/0! | Y6: Course Correct Inventory in 2025
C7: 48oz | K7: 0 | L7: 0 | M7: 25940115 | N7: 25174238 | O7: 25596140 | S7: =J7/F7-1 -> #DIV/0! | T7: =K7/G7-1 -> #DIV/0! | U7: =L7/H7-1 -> #DIV/0! | V7: =M7/I7-1 -> #DIV/0! | W7: =N7/J7-1 -> #DIV/0! | X7: =O7/K7-1 -> #DIV/0! | Y7: Price Increase in 26' -9% Growth
C8: B&J Cups | D8: 428282.4 | E8: 1197580 | F8: 1060263 | M8: 951586 | N8: 0 | O8: 0 | S8: =J8/F8-1 -> -1 | T8: =K8/G8-1 -> #DIV/0! | U8: =L8/H8-1 -> #DIV/0! | V8: =M8/I8-1 -> #DIV/0! | W8: =N8/J8-1 -> #DIV/0! | X8: =O8/K8-1 -> #DIV/0! | Y8: Only 1% growth
C9: BJ Bars | E9: 190000 | F9: 1987500 | M9: 0 | N9: 0 | O9: 0 | S9: =J9/F9-1 -> -1 | T9: =K9/G9-1 -> #DIV/0! | U9: =L9/H9-1 -> #DIV/0! | V9: =M9/I9-1 -> #DIV/0! | W9: =N9/J9-1 -> #DIV/0! | X9: =O9/K9-1 -> #DIV/0! | Y9: Run All out till Sept, then must reduce
C10: BJ PTS | E10: 607165 | F10: 0 | J10: 306662 | K10: 115851 | L10: 0 | M10: 26084291 | N10: 25610872 | O10: 24125674 | S10: =J10/F10-1 -> #DIV/0! | T10: =K10/G10-1 -> #DIV/0! | U10: =L10/H10-1 -> #DIV/0! | V10: =M10/I10-1 -> #DIV/0! | W10: =N10/J10-1 -> 82.514984 | X10: =O10/K10-1 -> 207.24744
C11: Dough Bites | D11: 414132 | E11: 472047 | F11: 338000 | S11: =J11/F11-1 -> -1 | T11: =K11/G11-1 -> #DIV/0! | U11: =L11/H11-1 -> #DIV/0! | V11: =M11/I11-1 -> #DIV/0! | W11: =N11/J11-1 -> #DIV/0! | X11: =O11/K11-1 -> #DIV/0!
C12: EDF | M12: 4730331 | N12: 4886903 | O12: 4799210 | S12: =J12/F12-1 -> #DIV/0! | T12: =K12/G12-1 -> #DIV/0! | U12: =L12/H12-1 -> #DIV/0! | V12: =M12/I12-1 -> #DIV/0! | W12: =N12/J12-1 -> #DIV/0! | X12: =O12/K12-1 -> #DIV/0!
C13: EFW | J13: 277747 | K13: 0 | L13: 210808.32 | M13: 1279479 | N13: 429288 | O13: 0 | S13: =J13/F13-1 -> #DIV/0! | T13: =K13/G13-1 -> #DIV/0! | U13: =L13/H13-1 -> #DIV/0! | V13: =M13/I13-1 -> #DIV/0! | W13: =N13/J13-1 -> 0.54560805 | X13: =O13/K13-1 -> #DIV/0!
C14: ESS | D14: 1152694 | E14: 2139398 | F14: 2441304 | H14: 0 | I14: 0 | J14: 153328 | K14: 366132.4 | L14: 417273.6 | M14: 1566148 | N14: 0 | O14: 0 | S14: =J14/F14-1 -> -0.93719422 | T14: =K14/G14-1 -> #DIV/0! | U14: =L14/H14-1 -> #DIV/0! | V14: =M14/I14-1 -> #DIV/0! | W14: =N14/J14-1 -> -1 | X14: =O14/K14-1 -> -1
C15: Facepieces | G15: 3277504 | H15: 4737327 | I15: 3860663 | S15: =J15/F15-1 -> #DIV/0! | T15: =K15/G15-1 -> -1 | U15: =L15/H15-1 -> -1 | V15: =M15/I15-1 -> -1 | W15: =N15/J15-1 -> #DIV/0! | X15: =O15/K15-1 -> #DIV/0!
C16: KL Mini Cones | G16: 988955 | H16: 741961 | I16: 638158 | S16: =J16/F16-1 -> #DIV/0! | T16: =K16/G16-1 -> -1 | U16: =L16/H16-1 -> -1 | V16: =M16/I16-1 -> -1 | W16: =N16/J16-1 -> #DIV/0! | X16: =O16/K16-1 -> #DIV/0!
C17: MBG | M17: 3656088 | N17: 3863294 | O17: 2789300 | S17: =J17/F17-1 -> #DIV/0! | T17: =K17/G17-1 -> #DIV/0! | U17: =L17/H17-1 -> #DIV/0! | V17: =M17/I17-1 -> #DIV/0! | W17: =N17/J17-1 -> #DIV/0! | X17: =O17/K17-1 -> #DIV/0!
C18: MG Sticks | G18: 215076 | H18: 108582 | I18: 0 | J18: 75496 | K18: 8403 | L18: 0 | M18: 6269673 | N18: 6988063.5 | O18: 6048195 | S18: =J18/F18-1 -> #DIV/0! | T18: =K18/G18-1 -> -0.96093009 | U18: =L18/H18-1 -> -1 | V18: =M18/I18-1 -> #DIV/0! | W18: =N18/J18-1 -> 91.562036 | X18: =O18/K18-1 -> 718.76615
C19: Other | D19: 1646147 | E19: 761236 | F19: 873302.14 | G19: 92423 | H19: 218262 | I19: 329856 | M19: 168964 | N19: 358927 | O19: 472340 | S19: =J19/F19-1 -> -1 | T19: =K19/G19-1 -> -1 | U19: =L19/H19-1 -> -1 | V19: =M19/I19-1 -> -0.48776436 | W19: =N19/J19-1 -> #DIV/0! | X19: =O19/K19-1 -> #DIV/0!
C20: PG | G20: 1676859 | H20: 3133646.9 | I20: 1490517.9 | J20: 11427 | K20: 17358 | L20: 0 | M20: 2414254 | N20: 5053318.5 | O20: 5361705 | S20: =J20/F20-1 -> #DIV/0! | T20: =K20/G20-1 -> -0.9896485 | U20: =L20/H20-1 -> -1 | V20: =M20/I20-1 -> 0.6197417 | W20: =N20/J20-1 -> 441.22617 | X20: =O20/K20-1 -> 307.88956
C21: SP1 | D21: 229128 | E21: 8521 | F21: 0 | M21: 3347105.6 | N21: 3907336 | O21: 4073579 | S21: =J21/F21-1 -> #DIV/0! | T21: =K21/G21-1 -> #DIV/0! | U21: =L21/H21-1 -> #DIV/0! | V21: =M21/I21-1 -> #DIV/0! | W21: =N21/J21-1 -> #DIV/0! | X21: =O21/K21-1 -> #DIV/0!
C22: TALENTI | M22: 11399511 | N22: 10546374 | O22: 11003808 | S22: =J22/F22-1 -> #DIV/0! | T22: =K22/G22-1 -> #DIV/0! | U22: =L22/H22-1 -> #DIV/0! | V22: =M22/I22-1 -> #DIV/0! | W22: =N22/J22-1 -> #DIV/0! | X22: =O22/K22-1 -> #DIV/0!
C23: Yasso Poppables | D23: 335233 | E23: 489248 | F23: 417600 | S23: =J23/F23-1 -> -1 | T23: =K23/G23-1 -> #DIV/0! | U23: =L23/H23-1 -> #DIV/0! | V23: =M23/I23-1 -> #DIV/0! | W23: =N23/J23-1 -> #DIV/0! | X23: =O23/K23-1 -> #DIV/0!
C24: Yasso Sandwich | D24: 168614 | E24: 156824 | F24: 169253.5 | S24: =J24/F24-1 -> -1 | T24: =K24/G24-1 -> #DIV/0! | U24: =L24/H24-1 -> #DIV/0! | V24: =M24/I24-1 -> #DIV/0! | W24: =N24/J24-1 -> #DIV/0! | X24: =O24/K24-1 -> #DIV/0!
C25: Yasso Sticks | D25: 7019764 | E25: 7905382.8 | F25: 7006250 | M25: 441482 | N25: 1474098 | O25: 3855100 | S25: =J25/F25-1 -> -1 | T25: =K25/G25-1 -> #DIV/0! | U25: =L25/H25-1 -> #DIV/0! | V25: =M25/I25-1 -> #DIV/0! | W25: =N25/J25-1 -> #DIV/0! | X25: =O25/K25-1 -> #DIV/0!
C26: YS PTS | E26: 238415 | F26: 0 | M26: 0 | N26: 75000 | O26: 1680000 | S26: =J26/F26-1 -> #DIV/0! | T26: =K26/G26-1 -> #DIV/0! | U26: =L26/H26-1 -> #DIV/0! | V26: =M26/I26-1 -> #DIV/0! | W26: =N26/J26-1 -> #DIV/0! | X26: =O26/K26-1 -> #DIV/0!
C27: Yasso Club | D27: 1931563 | E27: 2821581 | F27: 2142284.2 | S27: =J27/F27-1 -> -1 | T27: =K27/G27-1 -> #DIV/0! | U27: =L27/H27-1 -> #DIV/0! | V27: =M27/I27-1 -> #DIV/0! | W27: =N27/J27-1 -> #DIV/0! | X27: =O27/K27-1 -> #DIV/0!
C28: Grand Total | D28: 13325557 | E28: 16987398 | F28: 16435757 | G28: 6250817 | H28: 8939778.8 | I28: 6319194.9 | J28: 824660 | K28: 507744.4 | L28: 628081.92 | M28: 88745585 | N28: 88851298 | O28: 90331291 | S28: =J28/F28-1 -> -0.94982525 | T28: =K28/G28-1 -> -0.91877151 | U28: =L28/H28-1 -> -0.92974301 | V28: =M28/I28-1 -> 13.043812 | W28: =N28/J28-1 -> 106.74295 | X28: =O28/K28-1 -> 176.90702
C32: Type | D32: (Multiple Items)
G33: Demand | J33: Demand | L33: Suppl | N33: Supp vs Dem
C34: Row Labels | D34: Sum of 2024 MRF12 | E34: Sum of 2025 MRF8 | F34: Sum of 2026 MRF8 | G34: 2024 | H34: 2025 | I34: 2026 | J34: 2025 | K34: 2026 | L34: 2025 | M34: 2026 | N34: 25 | O34: 26
B35: Cases | C35: 48oz | D35: 25940115 | E35: 25174238 | F35: 25596140 | G35: =VLOOKUP($C35,#REF!,2,0) -> #REF! | H35: =VLOOKUP($C35,#REF!,3,0) -> #REF! | I35: =VLOOKUP($C35,#REF!,4,0) -> #REF! | J35: =H35/G35-1 -> #REF! | K35: =I35/H35-1 -> #REF! | L35: =E35/D35-1 -> -0.029524811 | M35: =F35/E35-1 -> 0.016759276 | N35: =E35/H35-1 -> #REF! | O35: =F35/I35-1 -> #REF! | P35: Short in 25'
C36: BJ PTS | D36: 26390953 | E36: 26333888 | F36: 24125674 | G36: =VLOOKUP($C36,#REF!,2,0) -> #REF! | H36: =VLOOKUP($C36,#REF!,3,0) -> #REF! | I36: =VLOOKUP($C36,#REF!,4,0) -> #REF! | J36: =H36/G36-1 -> #REF! | K36: =I36/H36-1 -> #REF! | L36: =E36/D36-1 -> -0.002162288 | M36: =F36/E36-1 -> -0.083854456 | N36: =E36/H36-1 -> #REF! | O36: =F36/I36-1 -> #REF!
C37: TALENTI | D37: 11399511 | E37: 10546374 | F37: 11003808 | G37: =VLOOKUP($C37,#REF!,2,0) -> #REF! | H37: =VLOOKUP($C37,#REF!,3,0) -> #REF! | I37: =VLOOKUP($C37,#REF!,4,0) -> #REF! | J37: =H37/G37-1 -> #REF! | K37: =I37/H37-1 -> #REF! | L37: =E37/D37-1 -> -0.074839752 | M37: =F37/E37-1 -> 0.04337358 | N37: =E37/H37-1 -> #REF! | O37: =F37/I37-1 -> #REF! | P37: Course correction in 25'
C38: Yasso Sticks | D38: 7461246 | E38: 9379480.8 | F38: 10861350 | G38: =VLOOKUP($C38,#REF!,2,0) -> #REF! | H38: =VLOOKUP($C38,#REF!,3,0) -> #REF! | I38: =VLOOKUP($C38,#REF!,4,0) -> #REF! | J38: =H38/G38-1 -> #REF! | K38: =I38/H38-1 -> #REF! | L38: =E38/D38-1 -> 0.25709308 | M38: =F38/E38-1 -> 0.15799054 | N38: =E38/H38-1 -> #REF! | O38: =F38/I38-1 -> #REF!
C39: PG | D39: 4102540 | E39: 8204323.3 | F39: 6852222.9 | G39: =VLOOKUP($C39,#REF!,2,0) -> #REF! | H39: =VLOOKUP($C39,#REF!,3,0) -> #REF! | I39: =VLOOKUP($C39,#REF!,4,0) -> #REF! | J39: =H39/G39-1 -> #REF! | K39: =I39/H39-1 -> #REF! | L39: =E39/D39-1 -> 0.99981557 | M39: =F39/E39-1 -> -0.16480341 | N39: =E39/H39-1 -> #REF! | O39: =F39/I39-1 -> #REF!
C40: MG Sticks | D40: 6560245 | E40: 7105048.5 | F40: 6048195 | G40: =VLOOKUP($C40,#REF!,2,0) -> #REF! | H40: =VLOOKUP($C40,#REF!,3,0) -> #REF! | I40: =VLOOKUP($C40,#REF!,4,0) -> #REF! | J40: =H40/G40-1 -> #REF! | K40: =I40/H40-1 -> #REF! | L40: =E40/D40-1 -> 0.083046212 | M40: =F40/E40-1 -> -0.14874684 | N40: =E40/H40-1 -> #REF! | O40: =F40/I40-1 -> #REF!
C41: EDF | D41: 4730331 | E41: 4886903 | F41: 4799210 | G41: =VLOOKUP($C41,#REF!,2,0) -> #REF! | H41: =VLOOKUP($C41,#REF!,3,0) -> #REF! | I41: =VLOOKUP($C41,#REF!,4,0) -> #REF! | J41: =H41/G41-1 -> #REF! | K41: =I41/H41-1 -> #REF! | L41: =E41/D41-1 -> 0.033099586 | M41: =F41/E41-1 -> -0.017944494 | N41: =E41/H41-1 -> #REF! | O41: =F41/I41-1 -> #REF!
C42: SP1 | D42: 3576233.6 | E42: 3915857 | F42: 4073579 | G42: =VLOOKUP($C42,#REF!,2,0) -> #REF! | H42: =VLOOKUP($C42,#REF!,3,0) -> #REF! | I42: =VLOOKUP($C42,#REF!,4,0) -> #REF! | J42: =H42/G42-1 -> #REF! | K42: =I42/H42-1 -> #REF! | L42: =E42/D42-1 -> 0.094966792 | M42: =F42/E42-1 -> 0.040277782 | N42: =E42/H42-1 -> #REF! | O42: =F42/I42-1 -> #REF!
C43: Facepieces | D43: 3277504 | E43: 4737327 | F43: 3860663 | G43: =VLOOKUP($C43,#REF!,2,0) -> #REF! | H43: =VLOOKUP($C43,#REF!,3,0) -> #REF! | I43: =VLOOKUP($C43,#REF!,4,0) -> #REF! | J43: =H43/G43-1 -> #REF! | K43: =I43/H43-1 -> #REF! | L43: =E43/D43-1 -> 0.44540693 | M43: =F43/E43-1 -> -0.18505456 | N43: =E43/H43-1 -> #REF! | O43: =F43/I43-1 -> #REF!
C44: ESS | D44: 2872170 | E44: 2505530.4 | F44: 2858577.6 | G44: =VLOOKUP($C44,#REF!,2,0) -> #REF! | H44: =VLOOKUP($C44,#REF!,3,0) -> #REF! | I44: =VLOOKUP($C44,#REF!,4,0) -> #REF! | J44: =H44/G44-1 -> #REF! | K44: =I44/H44-1 -> #REF! | L44: =E44/D44-1 -> -0.12765247 | M44: =F44/E44-1 -> 0.14090717 | N44: =E44/H44-1 -> #REF! | O44: =F44/I44-1 -> #REF!
C45: MBG | D45: 3656088 | E45: 3863294 | F45: 2789300 | G45: =VLOOKUP($C45,#REF!,2,0) -> #REF! | H45: =VLOOKUP($C45,#REF!,3,0) -> #REF! | I45: =VLOOKUP($C45,#REF!,4,0) -> #REF! | J45: =H45/G45-1 -> #REF! | K45: =I45/H45-1 -> #REF! | L45: =E45/D45-1 -> 0.056674238 | M45: =F45/E45-1 -> -0.27799955 | N45: =E45/H45-1 -> #REF! | O45: =F45/I45-1 -> #REF!
...

Sheet Recap2
B2: Tonnage Recap
F3: Vs Prior
C4: MRF1 | D4: MRF2 | E4: MRF3 | F4: Litons | G4: %
B5: SIK | C5: 203 | D5: 205 | E5: ='Litons Post Attain'!P167/1000 -> 203.97838 | F5: =E5-D5 -> -1.0216206 | G5: =E5/D5-1 -> -0.0049835152
B6: COV | C6: 161 | D6: 166 | E6: ='Litons Post Attain'!P168/1000 -> 164.69916 | F6: =E6-D6 -> -1.3008368 | G6: =E6/D6-1 -> -0.0078363664
B7: VT | C7: 89 | D7: 90 | E7: ='Litons Post Attain'!P169/1000 -> 91.781613 | F7: =E7-D7 -> 1.7816133 | G7: =E7/D7-1 -> 0.019795704
B8: UL Sites | C8: 454 | D8: 461 | E8: ='Litons Post Attain'!P170/1000 -> 460.45916 | F8: =E8-D8 -> -0.5408441 | G8: =E8/D8-1 -> -0.0011731976
B9: CM | C9: 48 | D9: 54 | E9: ='Litons Post Attain'!P184/1000 -> 54.737552 | F9: =E9-D9 -> 0.7375524 | G9: =E9/D9-1 -> 0.013658378
B10: Import | C10: 26.028 | D10: =SUM('Litons Post Attain'!Q185:Q186)/1000 -> 26.431099 | E10: =SUM('Litons Post Attain'!P185:P186)/1000 -> 28.49724 | F10: =E10-D10 -> 2.0661412 | G10: =E10/D10-1 -> 0.078170838
B11: Total UL | C11: =SUM(C8:C10) -> 528.028 | D11: =SUM(D8:D10) -> 541.4311 | E11: =SUM(E8:E10) -> 543.69395 | F11: =E11-D11 -> 2.2628495 | G11: =E11/D11-1 -> 0.0041793858
B14: Pallet Positions
C15: Peak | D15: EOY | E15: Notes
B16: 2025 | C16: 113 | D16: 98
B17: 2026 LV | C17: 135 | D17: 95 | E17: With CM, Intransit, & Club volume we would be at 126 internally, just above 124
B20: Inventory
B21: 2025 | C21: 68.3
C22: MRF1 | D22: MRF2 | E22: MRF3
B23: Demand | C23: 530 | D23: 528 | E23: 527
B24: Suppl | C24: =C11 -> 528.028 | D24: =D11 -> 541.4311 | E24: =E11 -> 543.69395
B25: SCC's | C25: 1459 | D25: 1532 | E25: 1530
B26: 2026 | C26: 65.1 | D26: 75.2 | E26: 75.1
B27: vs YAG | C27: =C26-C21 -> -3.2 | D27: =D26-C21 -> 6.9 | E27: =E26-C21 -> 6.8
B28: Notes | C28: Error in calculation in MRF1

Sheet Cases post Attain
D1: 110 | E1: 110 | F1: 120 | G1: =SUM(D1:F1) -> 340 | H1: =G1*4 -> 1360
H2: =G1*3.5 -> 1190
B3: PLANT | C3: STA ALBANS | R3: Vs YAG | T3: Commentary
A4: Tech Rollup | B4: PLANT | C4: Row Labels | D4: Jan | E4: Feb | F4: Mar | G4: Apr | H4: May | I4: Jun | J4: Jul | K4: Aug | L4: Sep | M4: Oct | N4: Nov | O4: Dec | P4: 2026 MRF3 | Q4: 2026 MRF2 | R4: Difference | S4: % change | T4: Commentary | U4: 2025 Final
A5: 2.4 Gal | B5: 5914 | C5: 2.4 Gal | D5: =SUMIFS('2026'!$L:$L,'2026'!$J:$J,$B5&$C5,'2026'!$O:$O,D$4) -> 40870 | E5: =SUMIFS('2026'!$L:$L,'2026'!$J:$J,$B5&$C5,'2026'!$O:$O,E$4) -> 84448 | F5: =SUMIFS('2026'!$L:$L,'2026'!$J:$J,$B5&$C5,'2026'!$O:$O,F$4) -> 63514 | G5: =SUMIFS('2026'!$L:$L,'2026'!$J:$J,$B5&$C5,'2026'!$O:$O,G$4) -> 63648 | H5: =SUMIFS('2026'!$L:$L,'2026'!$J:$J,$B5&$C5,'2026'!$O:$O,H$4) -> 95999 | I5: =SUMIFS('2026'!$L:$L,'2026'!$J:$J,$B5&$C5,'2026'!$O:$O,I$4) -> 27404 | J5: =SUMIFS('2026'!$L:$L,'2026'!$J:$J,$B5&$C5,'2026'!$O:$O,J$4) -> 50830 | K5: =SUMIFS('2026'!$L:$L,'2026'!$J:$J,$B5&$C5,'2026'!$O:$O,K$4) -> 53040 | ... O5: =SUMIFS('2026'!$L:$L,'2026'!$J:$J,$B5&$C5,'2026'!$O:$O,O$4) -> 0 | P5: =SUM(D5:O5) -> 566385 | Q5: 504816.4 | R5: =P5-Q5 -> 61568.6 | S5: =IF(ISERROR(R5/Q5),"",R5/Q5) -> 0.12196236 | T5: Deman | U5: 469585
A6: Other | B6: 5914 | C6: Quarts | D6: =SUMIFS('2026'!$L:$L,'2026'!$J:$J,$B6&$C6,'2026'!$O:$O,D$4) -> 0 | E6: =SUMIFS('2026'!$L:$L,'2026'!$J:$J,$B6&$C6,'2026'!$O:$O,E$4) -> 0 | F6: =SUMIFS('2026'!$L:$L,'2026'!$J:$J,$B6&$C6,'2026'!$O:$O,F$4) -> 0 | G6: =SUMIFS('2026'!$L:$L,'2026'!$J:$J,$B6&$C6,'2026'!$O:$O,G$4) -> 0 | H6: =SUMIFS('2026'!$L:$L,'2026'!$J:$J,$B6&$C6,'2026'!$O:$O,H$4) -> 0 | I6: =SUMIFS('2026'!$L:$L,'2026'!$J:$J,$B6&$C6,'2026'!$O:$O,I$4) -> 0 | J6: =SUMIFS('2026'!$L:$L,'2026'!$J:$J,$B6&$C6,'2026'!$O:$O,J$4) -> 0 | K6: =SUMIFS('2026'!$L:$L,'2026'!$J:$J,$B6&$C6,'2026'!$O:$O,K$4) -> 0 | ... O6: =SUMIFS('2026'!$L:$L,'2026'!$J:$J,$B6&$C6,'2026'!$O:$O,O$4) -> 0 | P6: =SUM(D6:O6) -> 0 | Q6: 0 | R6: =P6-Q6 -> 0 | S6: =IF(ISERROR(R6/Q6),"",R6/Q6) | T6: Demand & Being Discontinued | U6: 321236
A7: BJ PTS | B7: 5914 | C7: PTS Exports | D7: =SUMIFS('2026'!$L:$L,'2026'!$J:$J,$B7&$C7,'2026'!$O:$O,D$4) -> 56422 | E7: =SUMIFS('2026'!$L:$L,'2026'!$J:$J,$B7&$C7,'2026'!$O:$O,E$4) -> 0 | F7: =SUMIFS('2026'!$L:$L,'2026'!$J:$J,$B7&$C7,'2026'!$O:$O,F$4) -> 76571 | G7: =SUMIFS('2026'!$L:$L,'2026'!$J:$J,$B7&$C7,'2026'!$O:$O,G$4) -> 32832 | H7: =SUMIFS('2026'!$L:$L,'2026'!$J:$J,$B7&$C7,'2026'!$O:$O,H$4) -> 62784 | I7: =SUMIFS('2026'!$L:$L,'2026'!$J:$J,$B7&$C7,'2026'!$O:$O,I$4) -> 0 | J7: =SUMIFS('2026'!$L:$L,'2026'!$J:$J,$B7&$C7,'2026'!$O:$O,J$4) -> 0 | K7: =SUMIFS('2026'!$L:$L,'2026'!$J:$J,$B7&$C7,'2026'!$O:$O,K$4) -> 0 | ... O7: =SUMIFS('2026'!$L:$L,'2026'!$J:$J,$B7&$C7,'2026'!$O:$O,O$4) -> 0 | P7: =SUM(D7:O7) -> 228609 | Q7: 147967.6 | R7: =P7-Q7 -> 80641.4 | S7: =IF(ISERROR(R7/Q7),"",R7/Q7) -> 0.54499363 | U7: 446691
A8: B&J Cups | B8: 5914 | C8: Cup Exports | D8: =SUMIFS('2026'!$L:$L,'2026'!$J:$J,$B8&$C8,'2026'!$O:$O,D$4) -> 0 | E8: =SUMIFS('2026'!$L:$L,'2026'!$J:$J,$B8&$C8,'2026'!$O:$O,E$4) -> 0 | F8: =SUMIFS('2026'!$L:$L,'2026'!$J:$J,$B8&$C8,'2026'!$O:$O,F$4) -> 0 | G8: =SUMIFS('2026'!$L:$L,'2026'!$J:$J,$B8&$C8,'2026'!$O:$O,G$4) -> 0 | H8: =SUMIFS('2026'!$L:$L,'2026'!$J:$J,$B8&$C8,'2026'!$O:$O,H$4) -> 0 | I8: =SUMIFS('2026'!$L:$L,'2026'!$J:$J,$B8&$C8,'2026'!$O:$O,I$4) -> 0 | J8: =SUMIFS('2026'!$L:$L,'2026'!$J:$J,$B8&$C8,'2026'!$O:$O,J$4) -> 0 | K8: =SUMIFS('2026'!$L:$L,'2026'!$J:$J,$B8&$C8,'2026'!$O:$O,K$4) -> 0 | ... O8: =SUMIFS('2026'!$L:$L,'2026'!$J:$J,$B8&$C8,'2026'!$O:$O,O$4) -> 0 | P8: =SUM(D8:O8) -> 0 | Q8: 0 | S8: =IF(ISERROR(R8/Q8),"",R8/Q8) | U8: 0
A9: 2.4 Gal | B9: 5914 | C9: Bulk Exports | D9: =SUMIFS('2026'!$L:$L,'2026'!$J:$J,$B9&$C9,'2026'!$O:$O,D$4) -> 0 | E9: =SUMIFS('2026'!$L:$L,'2026'!$J:$J,$B9&$C9,'2026'!$O:$O,E$4) -> 0 | F9: =SUMIFS('2026'!$L:$L,'2026'!$J:$J,$B9&$C9,'2026'!$O:$O,F$4) -> 0 | G9: =SUMIFS('2026'!$L:$L,'2026'!$J:$J,$B9&$C9,'2026'!$O:$O,G$4) -> 0 | H9: =SUMIFS('2026'!$L:$L,'2026'!$J:$J,$B9&$C9,'2026'!$O:$O,H$4) -> 0 | I9: =SUMIFS('2026'!$L:$L,'2026'!$J:$J,$B9&$C9,'2026'!$O:$O,I$4) -> 0 | J9: =SUMIFS('2026'!$L:$L,'2026'!$J:$J,$B9&$C9,'2026'!$O:$O,J$4) -> 0 | K9: =SUMIFS('2026'!$L:$L,'2026'!$J:$J,$B9&$C9,'2026'!$O:$O,K$4) -> 0 | ... O9: =SUMIFS('2026'!$L:$L,'2026'!$J:$J,$B9&$C9,'2026'!$O:$O,O$4) -> 0 | P9: =SUM(D9:O9) -> 0 | Q9: 0 | S9: =IF(ISERROR(R9/Q9),"",R9/Q9) | U9: 0
A10: B&J Cups | B10: 5914 | C10: B&J Cups | D10: =SUMIFS('2026'!$L:$L,'2026'!$J:$J,$B10&$C10,'2026'!$O:$O,D$4) -> 0 | E10: =SUMIFS('2026'!$L:$L,'2026'!$J:$J,$B10&$C10,'2026'!$O:$O,E$4) -> 0 | F10: =SUMIFS('2026'!$L:$L,'2026'!$J:$J,$B10&$C10,'2026'!$O:$O,F$4) -> 0 | G10: =SUMIFS('2026'!$L:$L,'2026'!$J:$J,$B10&$C10,'2026'!$O:$O,G$4) -> 0 | H10: =SUMIFS('2026'!$L:$L,'2026'!$J:$J,$B10&$C10,'2026'!$O:$O,H$4) -> 0 | I10: =SUMIFS('2026'!$L:$L,'2026'!$J:$J,$B10&$C10,'2026'!$O:$O,I$4) -> 0 | J10: =SUMIFS('2026'!$L:$L,'2026'!$J:$J,$B10&$C10,'2026'!$O:$O,J$4) -> 0 | K10: =SUMIFS('2026'!$L:$L,'2026'!$J:$J,$B10&$C10,'2026'!$O:$O,K$4) -> 0 | ... O10: =SUMIFS('2026'!$L:$L,'2026'!$J:$J,$B10&$C10,'2026'!$O:$O,O$4) -> 0 | P10: =SUM(D10:O10) -> 0 | Q10: 0 | R10: =P10-Q10 -> 0 | S10: =IF(ISERROR(R10/Q10),"",R10/Q10) | U10: 0
A11: B&J Cups | B11: 5914 | C11: B&J Dog Treat | D11: =SUMIFS('2026'!$L:$L,'2026'!$J:$J,$B11&$C11,'2026'!$O:$O,D$4) -> 0 | E11: =SUMIFS('2026'!$L:$L,'2026'!$J:$J,$B11&$C11,'2026'!$O:$O,E$4) -> 0 | F11: =SUMIFS('2026'!$L:$L,'2026'!$J:$J,$B11&$C11,'2026'!$O:$O,F$4) -> 0 | G11: =SUMIFS('2026'!$L:$L,'2026'!$J:$J,$B11&$C11,'2026'!$O:$O,G$4) -> 0 | H11: =SUMIFS('2026'!$L:$L,'2026'!$J:$J,$B11&$C11,'2026'!$O:$O,H$4) -> 0 | I11: =SUMIFS('2026'!$L:$L,'2026'!$J:$J,$B11&$C11,'2026'!$O:$O,I$4) -> 0 | J11: =SUMIFS('2026'!$L:$L,'2026'!$J:$J,$B11&$C11,'2026'!$O:$O,J$4) -> 0 | K11: =SUMIFS('2026'!$L:$L,'2026'!$J:$J,$B11&$C11,'2026'!$O:$O,K$4) -> 0 | ... O11: =SUMIFS('2026'!$L:$L,'2026'!$J:$J,$B11&$C11,'2026'!$O:$O,O$4) -> 0 | P11: =SUM(D11:O11) -> 0 | Q11: 0 | R11: =P11-Q11 -> 0 | S11: =IF(ISERROR(R11/Q11),"",R11/Q11) | U11: 0
A12: SP1 | B12: 5914 | C12: PTS - BR | D12: =SUMIFS('2026'!$L:$L,'2026'!$J:$J,$B12&$C12,'2026'!$O:$O,D$4) -> 0 | E12: =SUMIFS('2026'!$L:$L,'2026'!$J:$J,$B12&$C12,'2026'!$O:$O,E$4) -> 0 | F12: =SUMIFS('2026'!$L:$L,'2026'!$J:$J,$B12&$C12,'2026'!$O:$O,F$4) -> 0 | G12: =SUMIFS('2026'!$L:$L,'2026'!$J:$J,$B12&$C12,'2026'!$O:$O,G$4) -> 0 | H12: =SUMIFS('2026'!$L:$L,'2026'!$J:$J,$B12&$C12,'2026'!$O:$O,H$4) -> 0 | I12: =SUMIFS('2026'!$L:$L,'2026'!$J:$J,$B12&$C12,'2026'!$O:$O,I$4) -> 0 | J12: =SUMIFS('2026'!$L:$L,'2026'!$J:$J,$B12&$C12,'2026'!$O:$O,J$4) -> 0 | K12: =SUMIFS('2026'!$L:$L,'2026'!$J:$J,$B12&$C12,'2026'!$O:$O,K$4) -> 0 | ... O12: =SUMIFS('2026'!$L:$L,'2026'!$J:$J,$B12&$C12,'2026'!$O:$O,O$4) -> 0 | P12: =SUM(D12:O12) -> 0 | Q12: 0 | S12: =IF(ISERROR(R12/Q12),"",R12/Q12) | U12: 0
A13: BJ PTS | B13: 5914 | C13: BJ PTS | D13: =SUMIFS('2026'!$L:$L,'2026'!$J:$J,$B13&$C13,'2026'!$O:$O,D$4) -> 1069362 | E13: =SUMIFS('2026'!$L:$L,'2026'!$J:$J,$B13&$C13,'2026'!$O:$O,E$4) -> 1516469 | F13: =SUMIFS('2026'!$L:$L,'2026'!$J:$J,$B13&$C13,'2026'!$O:$O,F$4) -> 1784134.4 | G13: =SUMIFS('2026'!$L:$L,'2026'!$J:$J,$B13&$C13,'2026'!$O:$O,G$4) -> 1248718 | H13: =SUMIFS('2026'!$L:$L,'2026'!$J:$J,$B13&$C13,'2026'!$O:$O,H$4) -> 1009508 | I13: =SUMIFS('2026'!$L:$L,'2026'!$J:$J,$B13&$C13,'2026'!$O:$O,I$4) -> 1203110.4 | J13: =SUMIFS('2026'!$L:$L,'2026'!$J:$J,$B13&$C13,'2026'!$O:$O,J$4) -> 1266432 | K13: =SUMIFS('2026'!$L:$L,'2026'!$J:$J,$B13&$C13,'2026'!$O:$O,K$4) -> 1393075.2 | ... O13: =SUMIFS('2026'!$L:$L,'2026'!$J:$J,$B13&$C13,'2026'!$O:$O,O$4) -> 1106265.6 | P13: =SUM(D13:O13) -> 15236204 | Q13: 15379174 | R13: =P13-Q13 -> -142969.6 | S13: =IF(ISERROR(R13/Q13),"",R13/Q13) -> -0.0092963121 | U13: 15309960
C14: Total St. Albans | D14: =SUM(D5:D13) -> 1166654 | E14: =SUM(E5:E13) -> 1600917 | F14: =SUM(F5:F13) -> 1924219.4 | G14: =SUM(G5:G13) -> 1345198 | H14: =SUM(H5:H13) -> 1168291 | I14: =SUM(I5:I13) -> 1230514.4 | J14: =SUM(J5:J13) -> 1317262 | K14: =SUM(K5:K13) -> 1446115.2 | ... O14: =SUM(O5:O13) -> 1106265.6 | P14: =SUM(D14:O14) -> 16031198 | Q14: 16031958 | R14: =SUM(R5:R13) -> -759.6 | S14: =IF(ISERROR(R14/Q14),"",R14/Q14) -> -4.7380364e-05 | U14: 16547472
D15: =SUM(D13,D7) -> 1125784 | E15: =SUM(E13,E7) -> 1516469 | F15: =SUM(F13,F7) -> 1860705.4 | G15: =SUM(G13,G7) -> 1281550 | H15: =SUM(H13,H7) -> 1072292 | I15: =SUM(I13,I7) -> 1203110.4 | J15: =SUM(J13,J7) -> 1266432 | K15: =SUM(K13,K7) -> 1393075.2 | ... O15: =SUM(O13,O7) -> 1106265.6
C16: WATERBURY | R16: Vs Last Cycle | T16: Commentary
C17: Row Labels | D17: Jan | E17: Feb | F17: Mar | G17: Apr | H17: May | I17: Jun | J17: Jul | K17: Aug | L17: Sep | M17: Oct | N17: Nov | O17: Dec | P17: =P$4 -> 2026 MRF3 | Q17: 2026 MRF2 | R17: =R$4 -> Difference | S17: =S$4 -> % change | U17: 2025 Final
A18: Other | B18: 5911 | C18: 1 Gal | D18: =SUMIFS('2026'!$L:$L,'2026'!$J:$J,$B18&$C18,'2026'!$O:$O,D$4) -> 0 | E18: =SUMIFS('2026'!$L:$L,'2026'!$J:$J,$B18&$C18,'2026'!$O:$O,E$4) -> 0 | F18: =SUMIFS('2026'!$L:$L,'2026'!$J:$J,$B18&$C18,'2026'!$O:$O,F$4) -> 0 | G18: =SUMIFS('2026'!$L:$L,'2026'!$J:$J,$B18&$C18,'2026'!$O:$O,G$4) -> 0 | H18: =SUMIFS('2026'!$L:$L,'2026'!$J:$J,$B18&$C18,'2026'!$O:$O,H$4) -> 0 | I18: =SUMIFS('2026'!$L:$L,'2026'!$J:$J,$B18&$C18,'2026'!$O:$O,I$4) -> 0 | J18: =SUMIFS('2026'!$L:$L,'2026'!$J:$J,$B18&$C18,'2026'!$O:$O,J$4) -> 0 | K18: =SUMIFS('2026'!$L:$L,'2026'!$J:$J,$B18&$C18,'2026'!$O:$O,K$4) -> 0 | ... O18: =SUMIFS('2026'!$L:$L,'2026'!$J:$J,$B18&$C18,'2026'!$O:$O,O$4) -> 0 | P18: =SUM(D18:O18) -> 0 | Q18: 0 | S18: =IF(ISERROR(R18/Q18),"",R18/Q18) | U18: 0
A19: Other | B19: 5911 | C19: QTS | D19: =SUMIFS('2026'!$L:$L,'2026'!$J:$J,$B19&$C19,'2026'!$O:$O,D$4) -> 0 | E19: =SUMIFS('2026'!$L:$L,'2026'!$J:$J,$B19&$C19,'2026'!$O:$O,E$4) -> 0 | F19: =SUMIFS('2026'!$L:$L,'2026'!$J:$J,$B19&$C19,'2026'!$O:$O,F$4) -> 0 | G19: =SUMIFS('2026'!$L:$L,'2026'!$J:$J,$B19&$C19,'2026'!$O:$O,G$4) -> 0 | H19: =SUMIFS('2026'!$L:$L,'2026'!$J:$J,$B19&$C19,'2026'!$O:$O,H$4) -> 0 | I19: =SUMIFS('2026'!$L:$L,'2026'!$J:$J,$B19&$C19,'2026'!$O:$O,I$4) -> 0 | J19: =SUMIFS('2026'!$L:$L,'2026'!$J:$J,$B19&$C19,'2026'!$O:$O,J$4) -> 0 | K19: =SUMIFS('2026'!$L:$L,'2026'!$J:$J,$B19&$C19,'2026'!$O:$O,K$4) -> 0 | ... O19: =SUMIFS('2026'!$L:$L,'2026'!$J:$J,$B19&$C19,'2026'!$O:$O,O$4) -> 0 | P19: =SUM(D19:O19) -> 0 | Q19: 0 | S19: =IF(ISERROR(R19/Q19),"",R19/Q19) | U19: 0
A20: BJ PTS | B20: 5911 | C20: PTS Exports | D20: =SUMIFS('2026'!$L:$L,'2026'!$J:$J,$B20&$C20,'2026'!$O:$O,D$4) -> 11510 | E20: =SUMIFS('2026'!$L:$L,'2026'!$J:$J,$B20&$C20,'2026'!$O:$O,E$4) -> 8824 | F20: =SUMIFS('2026'!$L:$L,'2026'!$J:$J,$B20&$C20,'2026'!$O:$O,F$4) -> 13545 | G20: =SUMIFS('2026'!$L:$L,'2026'!$J:$J,$B20&$C20,'2026'!$O:$O,G$4) -> 11520 | H20: =SUMIFS('2026'!$L:$L,'2026'!$J:$J,$B20&$C20,'2026'!$O:$O,H$4) -> 0 | I20: =SUMIFS('2026'!$L:$L,'2026'!$J:$J,$B20&$C20,'2026'!$O:$O,I$4) -> 0 | J20: =SUMIFS('2026'!$L:$L,'2026'!$J:$J,$B20&$C20,'2026'!$O:$O,J$4) -> 0 | K20: =SUMIFS('2026'!$L:$L,'2026'!$J:$J,$B20&$C20,'2026'!$O:$O,K$4) -> 0 | ... O20: =SUMIFS('2026'!$L:$L,'2026'!$J:$J,$B20&$C20,'2026'!$O:$O,O$4) -> 0 | P20: =SUM(D20:O20) -> 45399 | Q20: 46254 | R20: =P20-Q20 -> -855 | S20: =IF(ISERROR(R20/Q20),"",R20/Q20) -> -0.018484888 | U20: 271877
A21: BJ PTS | B21: 5911 | C21: BJ PTS | D21: =SUMIFS('2026'!$L:$L,'2026'!$J:$J,$B21&$C21,'2026'!$O:$O,D$4) -> 626144 | E21: =SUMIFS('2026'!$L:$L,'2026'!$J:$J,$B21&$C21,'2026'!$O:$O,E$4) -> 736400 | F21: =SUMIFS('2026'!$L:$L,'2026'!$J:$J,$B21&$C21,'2026'!$O:$O,F$4) -> 941614 | G21: =SUMIFS('2026'!$L:$L,'2026'!$J:$J,$B21&$C21,'2026'!$O:$O,G$4) -> 702620 | H21: =SUMIFS('2026'!$L:$L,'2026'!$J:$J,$B21&$C21,'2026'!$O:$O,H$4) -> 783750 | I21: =SUMIFS('2026'!$L:$L,'2026'!$J:$J,$B21&$C21,'2026'!$O:$O,I$4) -> 721920 | J21: =SUMIFS('2026'!$L:$L,'2026'!$J:$J,$B21&$C21,'2026'!$O:$O,J$4) -> 763611.43 | K21: =SUMIFS('2026'!$L:$L,'2026'!$J:$J,$B21&$C21,'2026'!$O:$O,K$4) -> 768000 | ... O21: =SUMIFS('2026'!$L:$L,'2026'!$J:$J,$B21&$C21,'2026'!$O:$O,O$4) -> 400000 | P21: =SUM(D21:O21) -> 7384059.4 | Q21: 7054006.6 | R21: =P21-Q21 -> 330052.86 | S21: =IF(ISERROR(R21/Q21),"",R21/Q21) -> 0.046789417 | U21: 8237828
C22: Total Waterbury | D22: =SUM(D18:D21) -> 637654 | E22: =SUM(E18:E21) -> 745224 | F22: =SUM(F18:F21) -> 955159 | G22: =SUM(G18:G21) -> 714140 | H22: =SUM(H18:H21) -> 783750 | I22: =SUM(I18:I21) -> 721920 | J22: =SUM(J18:J21) -> 763611.43 | K22: =SUM(K18:K21) -> 768000 | ... P22: =SUM(P18:P21) -> 7429458.4 | Q22: 7100260.6 | R22: =SUM(R18:R21) -> 329197.86 | S22: =IF(ISERROR(R22/Q22),"",R22/Q22) -> 0.046364194 | U22: 8509705
C24: SIKESTON | R24: Vs Last Cycle | T24: Commentary
C25: Row Labels | D25: Jan | E25: Feb | F25: Mar | G25: Apr | H25: May | I25: Jun | J25: Jul | K25: Aug | L25: Sep | M25: Oct | N25: Nov | O25: Dec | P25: =P$4 -> 2026 MRF3 | Q25: 2026 MRF2 | R25: =R$4 -> Difference | S25: =S$4 -> % change | U25: 2025 Final
A26: 48oz | B26: 2904 | C26: 48oz | D26: =SUMIFS('2026'!$L:$L,'2026'!$J:$J,$B26&$C26,'2026'!$O:$O,D$4) -> 907813 | E26: =SUMIFS('2026'!$L:$L,'2026'!$J:$J,$B26&$C26,'2026'!$O:$O,E$4) -> 1057884 | F26: =SUMIFS('2026'!$L:$L,'2026'!$J:$J,$B26&$C26,'2026'!$O:$O,F$4) -> 1317294.1 | G26: =SUMIFS('2026'!$L:$L,'2026'!$J:$J,$B26&$C26,'2026'!$O:$O,G$4) -> 1118647 | H26: =SUMIFS('2026'!$L:$L,'2026'!$J:$J,$B26&$C26,'2026'!$O:$O,H$4) -> 983240 | I26: =SUMIFS('2026'!$L:$L,'2026'!$J:$J,$B26&$C26,'2026'!$O:$O,I$4) -> 985241.42 | J26: =SUMIFS('2026'!$L:$L,'2026'!$J:$J,$B26&$C26,'2026'!$O:$O,J$4) -> 1021731.8 | K26: =SUMIFS('2026'!$L:$L,'2026'!$J:$J,$B26&$C26,'2026'!$O:$O,K$4) -> 1094712.7 | ... O26: =SUMIFS('2026'!$L:$L,'2026'!$J:$J,$B26&$C26,'2026'!$O:$O,O$4) -> 646771.84 | P26: =SUM(D26:O26) -> 11581679 | Q26: 11630678 | R26: =P26-Q26 -> -48999.723 | S26: =IF(ISERROR(R26/Q26),"",R26/Q26) -> -0.004212972 | T26: =P26/46 -> 251775.62 | U26: 12284789
A27: EDF | B27: 2904 | C27: EDF | D27: =SUMIFS('2026'!$L:$L,'2026'!$J:$J,$B27&$C27,'2026'!$O:$O,D$4) -> 44810 | E27: =SUMIFS('2026'!$L:$L,'2026'!$J:$J,$B27&$C27,'2026'!$O:$O,E$4) -> 55315 | F27: =SUMIFS('2026'!$L:$L,'2026'!$J:$J,$B27&$C27,'2026'!$O:$O,F$4) -> 85838.48 | G27: =SUMIFS('2026'!$L:$L,'2026'!$J:$J,$B27&$C27,'2026'!$O:$O,G$4) -> 72576 | H27: =SUMIFS('2026'!$L:$L,'2026'!$J:$J,$B27&$C27,'2026'!$O:$O,H$4) -> 62208 | I27: =SUMIFS('2026'!$L:$L,'2026'!$J:$J,$B27&$C27,'2026'!$O:$O,I$4) -> 0 | J27: =SUMIFS('2026'!$L:$L,'2026'!$J:$J,$B27&$C27,'2026'!$O:$O,J$4) -> 0 | K27: =SUMIFS('2026'!$L:$L,'2026'!$J:$J,$B27&$C27,'2026'!$O:$O,K$4) -> 0 | ... O27: =SUMIFS('2026'!$L:$L,'2026'!$J:$J,$B27&$C27,'2026'!$O:$O,O$4) -> 0 | P27: =SUM(D27:O27) -> 320747.48 | Q27: 358058.64 | R27: =P27-Q27 -> -37311.16 | S27: =IF(ISERROR(R27/Q27),"",R27/Q27) -> -0.10420405 | U27: 799237
A28: BJ Bars | B28: 2904 | C28: BJ Bars | D28: =SUMIFS('2026'!$L:$L,'2026'!$J:$J,$B28&$C28,'2026'!$O:$O,D$4) -> 0 | E28: =SUMIFS('2026'!$L:$L,'2026'!$J:$J,$B28&$C28,'2026'!$O:$O,E$4) -> 0 | F28: =SUMIFS('2026'!$L:$L,'2026'!$J:$J,$B28&$C28,'2026'!$O:$O,F$4) -> 0 | G28: =SUMIFS('2026'!$L:$L,'2026'!$J:$J,$B28&$C28,'2026'!$O:$O,G$4) -> 0 | H28: =SUMIFS('2026'!$L:$L,'2026'!$J:$J,$B28&$C28,'2026'!$O:$O,H$4) -> 0 | I28: =SUMIFS('2026'!$L:$L,'2026'!$J:$J,$B28&$C28,'2026'!$O:$O,I$4) -> 0 | J28: =SUMIFS('2026'!$L:$L,'2026'!$J:$J,$B28&$C28,'2026'!$O:$O,J$4) -> 0 | K28: =SUMIFS('2026'!$L:$L,'2026'!$J:$J,$B28&$C28,'2026'!$O:$O,K$4) -> 0 | ... O28: =SUMIFS('2026'!$L:$L,'2026'!$J:$J,$B28&$C28,'2026'!$O:$O,O$4) -> 0 | P28: =SUM(D28:O28) -> 0 | Q28: 0 | S28: =IF(ISERROR(R28/Q28),"",R28/Q28) | U28: 0
A29: Other | B29: 2904 | C29: Other | D29: =SUMIFS('2026'!$L:$L,'2026'!$J:$J,$B29&$C29,'2026'!$O:$O,D$4) -> 0 | E29: =SUMIFS('2026'!$L:$L,'2026'!$J:$J,$B29&$C29,'2026'!$O:$O,E$4) -> 85224 | F29: =SUMIFS('2026'!$L:$L,'2026'!$J:$J,$B29&$C29,'2026'!$O:$O,F$4) -> 15 | G29: =SUMIFS('2026'!$L:$L,'2026'!$J:$J,$B29&$C29,'2026'!$O:$O,G$4) -> 40320 | H29: =SUMIFS('2026'!$L:$L,'2026'!$J:$J,$B29&$C29,'2026'!$O:$O,H$4) -> 63360 | I29: =SUMIFS('2026'!$L:$L,'2026'!$J:$J,$B29&$C29,'2026'!$O:$O,I$4) -> 0 | J29: =SUMIFS('2026'!$L:$L,'2026'!$J:$J,$B29&$C29,'2026'!$O:$O,J$4) -> 16703.85 | K29: =SUMIFS('2026'!$L:$L,'2026'!$J:$J,$B29&$C29,'2026'!$O:$O,K$4) -> 22271.8 | ... O29: =SUMIFS('2026'!$L:$L,'2026'!$J:$J,$B29&$C29,'2026'!$O:$O,O$4) -> 22271.8 | P29: =SUM(D29:O29) -> 315543.55 | Q29: 281009.5 | R29: =P29-Q29 -> 34534.05 | S29: =IF(ISERROR(R29/Q29),"",R29/Q29) -> 0.12289282 | U29: 0
A30: MBG | B30: 2904 | C30: MBG | D30: =SUMIFS('2026'!$L:$L,'2026'!$J:$J,$B30&$C30,'2026'!$O:$O,D$4) -> 55878 | E30: =SUMIFS('2026'!$L:$L,'2026'!$J:$J,$B30&$C30,'2026'!$O:$O,E$4) -> 76823 | F30: =SUMIFS('2026'!$L:$L,'2026'!$J:$J,$B30&$C30,'2026'!$O:$O,F$4) -> 81797.88 | G30: =SUMIFS('2026'!$L:$L,'2026'!$J:$J,$B30&$C30,'2026'!$O:$O,G$4) -> 92832 | H30: =SUMIFS('2026'!$L:$L,'2026'!$J:$J,$B30&$C30,'2026'!$O:$O,H$4) -> 69120 | I30: =SUMIFS('2026'!$L:$L,'2026'!$J:$J,$B30&$C30,'2026'!$O:$O,I$4) -> 80750 | J30: =SUMIFS('2026'!$L:$L,'2026'!$J:$J,$B30&$C30,'2026'!$O:$O,J$4) -> 92862.5 | K30: =SUMIFS('2026'!$L:$L,'2026'!$J:$J,$B30&$C30,'2026'!$O:$O,K$4) -> 88825 | ... O30: =SUMIFS('2026'!$L:$L,'2026'!$J:$J,$B30&$C30,'2026'!$O:$O,O$4) -> 0 | P30: =SUM(D30:O30) -> 808463.38 | Q30: 806336.32 | R30: =P30-Q30 -> 2127.06 | S30: =IF(ISERROR(R30/Q30),"",R30/Q30) -> 0.0026379315 | U30: 745276
A31: MG Sticks | B31: 2904 | C31: MG Sticks | D31: =SUMIFS('2026'!$L:$L,'2026'!$J:$J,$B31&$C31,'2026'!$O:$O,D$4) -> 543661 | E31: =SUMIFS('2026'!$L:$L,'2026'!$J:$J,$B31&$C31,'2026'!$O:$O,E$4) -> 675319 | F31: =SUMIFS('2026'!$L:$L,'2026'!$J:$J,$B31&$C31,'2026'!$O:$O,F$4) -> 705455 | G31: =SUMIFS('2026'!$L:$L,'2026'!$J:$J,$B31&$C31,'2026'!$O:$O,G$4) -> 955824 | H31: =SUMIFS('2026'!$L:$L,'2026'!$J:$J,$B31&$C31,'2026'!$O:$O,H$4) -> 839424 | I31: =SUMIFS('2026'!$L:$L,'2026'!$J:$J,$B31&$C31,'2026'!$O:$O,I$4) -> 694925 | J31: =SUMIFS('2026'!$L:$L,'2026'!$J:$J,$B31&$C31,'2026'!$O:$O,J$4) -> 711075 | K31: =SUMIFS('2026'!$L:$L,'2026'!$J:$J,$B31&$C31,'2026'!$O:$O,K$4) -> 676875 | ... O31: =SUMIFS('2026'!$L:$L,'2026'!$J:$J,$B31&$C31,'2026'!$O:$O,O$4) -> 0 | P31: =SUM(D31:O31) -> 6511133 | Q31: 6678576 | R31: =P31-Q31 -> -167442.96 | S31: =IF(ISERROR(R31/Q31),"",R31/Q31) -> -0.025071656 | U31: 7080128
A32: MG Sticks | B32: 2904 | C32: TAL NV | D32: =SUMIFS('2026'!$L:$L,'2026'!$J:$J,$B32&$C32,'2026'!$O:$O,D$4) -> 0 | E32: =SUMIFS('2026'!$L:$L,'2026'!$J:$J,$B32&$C32,'2026'!$O:$O,E$4) -> 0 | F32: =SUMIFS('2026'!$L:$L,'2026'!$J:$J,$B32&$C32,'2026'!$O:$O,F$4) -> 0 | G32: =SUMIFS('2026'!$L:$L,'2026'!$J:$J,$B32&$C32,'2026'!$O:$O,G$4) -> 0 | H32: =SUMIFS('2026'!$L:$L,'2026'!$J:$J,$B32&$C32,'2026'!$O:$O,H$4) -> 0 | I32: =SUMIFS('2026'!$L:$L,'2026'!$J:$J,$B32&$C32,'2026'!$O:$O,I$4) -> 0 | J32: =SUMIFS('2026'!$L:$L,'2026'!$J:$J,$B32&$C32,'2026'!$O:$O,J$4) -> 0 | K32: =SUMIFS('2026'!$L:$L,'2026'!$J:$J,$B32&$C32,'2026'!$O:$O,K$4) -> 0 | ... O32: =SUMIFS('2026'!$L:$L,'2026'!$J:$J,$B32&$C32,'2026'!$O:$O,O$4) -> 0 | P32: =SUM(D32:O32) -> 0 | Q32: 0 | R32: =P32-Q32 -> 0 | S32: =IF(ISERROR(R32/Q32),"",R32/Q32) | U32: 120379
A33: Yasso Sticks | B33: 2904 | C33: Yasso Sticks | D33: =SUMIFS('2026'!$L:$L,'2026'!$J:$J,$B33&$C33,'2026'!$O:$O,D$4) -> 313143 | E33: =SUMIFS('2026'!$L:$L,'2026'!$J:$J,$B33&$C33,'2026'!$O:$O,E$4) -> 380320 | F33: =SUMIFS('2026'!$L:$L,'2026'!$J:$J,$B33&$C33,'2026'!$O:$O,F$4) -> 294111 | G33: =SUMIFS('2026'!$L:$L,'2026'!$J:$J,$B33&$C33,'2026'!$O:$O,G$4) -> 296208 | H33: =SUMIFS('2026'!$L:$L,'2026'!$J:$J,$B33&$C33,'2026'!$O:$O,H$4) -> 288000 | I33: =SUMIFS('2026'!$L:$L,'2026'!$J:$J,$B33&$C33,'2026'!$O:$O,I$4) -> 275310 | J33: =SUMIFS('2026'!$L:$L,'2026'!$J:$J,$B33&$C33,'2026'!$O:$O,J$4) -> 285142.5 | K33: =SUMIFS('2026'!$L:$L,'2026'!$J:$J,$B33&$C33,'2026'!$O:$O,K$4) -> 304807.5 | ... O33: =SUMIFS('2026'!$L:$L,'2026'!$J:$J,$B33&$C33,'2026'!$O:$O,O$4) -> 265477.5 | P33: =SUM(D33:O33) -> 3528449.5 | Q33: 3402261.5 | R33: =P33-Q33 -> 126188 | S33: =IF(ISERROR(R33/Q33),"",R33/Q33) -> 0.037089448 | U33: 1294124
A34: SP1 | B34: 2904 | C34: PTS | D34: =SUMIFS('2026'!$L:$L,'2026'!$J:$J,$B34&$C34,'2026'!$O:$O,D$4) -> 22671 | E34: =SUMIFS('2026'!$L:$L,'2026'!$J:$J,$B34&$C34,'2026'!$O:$O,E$4) -> 0 | F34: =SUMIFS('2026'!$L:$L,'2026'!$J:$J,$B34&$C34,'2026'!$O:$O,F$4) -> 69122.16 | G34: =SUMIFS('2026'!$L:$L,'2026'!$J:$J,$B34&$C34,'2026'!$O:$O,G$4) -> 0 | H34: =SUMIFS('2026'!$L:$L,'2026'!$J:$J,$B34&$C34,'2026'!$O:$O,H$4) -> 66528 | I34: =SUMIFS('2026'!$L:$L,'2026'!$J:$J,$B34&$C34,'2026'!$O:$O,I$4) -> 43690.388 | J34: =SUMIFS('2026'!$L:$L,'2026'!$J:$J,$B34&$C34,'2026'!$O:$O,J$4) -> 48544.875 | K34: =SUMIFS('2026'!$L:$L,'2026'!$J:$J,$B34&$C34,'2026'!$O:$O,K$4) -> 53399.363 | ... O34: =SUMIFS('2026'!$L:$L,'2026'!$J:$J,$B34&$C34,'2026'!$O:$O,O$4) -> 22500 | P34: =SUM(D34:O34) -> 506263.81 | Q34: 507623.88 | R34: =P34-Q34 -> -1360.0722 | S34: =IF(ISERROR(R34/Q34),"",R34/Q34) -> -0.0026792912 | U34: 366575
A35: BJ PTS | B35: 2904 | C35: BJ PTS | D35: =SUMIFS('2026'!$L:$L,'2026'!$J:$J,$B35&$C35,'2026'!$O:$O,D$4) -> 146152 | E35: =SUMIFS('2026'!$L:$L,'2026'!$J:$J,$B35&$C35,'2026'!$O:$O,E$4) -> 35832 | F35: =SUMIFS('2026'!$L:$L,'2026'!$J:$J,$B35&$C35,'2026'!$O:$O,F$4) -> 323036.25 | G35: =SUMIFS('2026'!$L:$L,'2026'!$J:$J,$B35&$C35,'2026'!$O:$O,G$4) -> 235125 | H35: =SUMIFS('2026'!$L:$L,'2026'!$J:$J,$B35&$C35,'2026'!$O:$O,H$4) -> 136800 | I35: =SUMIFS('2026'!$L:$L,'2026'!$J:$J,$B35&$C35,'2026'!$O:$O,I$4) -> 211212 | J35: =SUMIFS('2026'!$L:$L,'2026'!$J:$J,$B35&$C35,'2026'!$O:$O,J$4) -> 189960 | K35: =SUMIFS('2026'!$L:$L,'2026'!$J:$J,$B35&$C35,'2026'!$O:$O,K$4) -> 0 | ... O35: =SUMIFS('2026'!$L:$L,'2026'!$J:$J,$B35&$C35,'2026'!$O:$O,O$4) -> 0 | P35: =SUM(D35:O35) -> 1281833.2 | Q35: 1405397 | R35: =P35-Q35 -> -123563.75 | S35: =IF(ISERROR(R35/Q35),"",R35/Q35) -> -0.087920886 | U35: 1488407
A36: SP1 | B36: 2904 | C36: Sundaes | D36: =SUMIFS('2026'!$L:$L,'2026'!$J:$J,$B36&$C36,'2026'!$O:$O,D$4) -> 33616 | E36: =SUMIFS('2026'!$L:$L,'2026'!$J:$J,$B36&$C36,'2026'!$O:$O,E$4) -> 81737 | F36: =SUMIFS('2026'!$L:$L,'2026'!$J:$J,$B36&$C36,'2026'!$O:$O,F$4) -> 45972 | G36: =SUMIFS('2026'!$L:$L,'2026'!$J:$J,$B36&$C36,'2026'!$O:$O,G$4) -> 110880 | H36: =SUMIFS('2026'!$L:$L,'2026'!$J:$J,$B36&$C36,'2026'!$O:$O,H$4) -> 149688 | I36: =SUMIFS('2026'!$L:$L,'2026'!$J:$J,$B36&$C36,'2026'!$O:$O,I$4) -> 95017.104 | J36: =SUMIFS('2026'!$L:$L,'2026'!$J:$J,$B36&$C36,'2026'!$O:$O,J$4) -> 105574.56 | K36: =SUMIFS('2026'!$L:$L,'2026'!$J:$J,$B36&$C36,'2026'!$O:$O,K$4) -> 116132.02 | ... O36: =SUMIFS('2026'!$L:$L,'2026'!$J:$J,$B36&$C36,'2026'!$O:$O,O$4) -> 90000 | P36: =SUM(D36:O36) -> 1113929.6 | Q36: 1147570 | R36: =P36-Q36 -> -33640.371 | S36: =IF(ISERROR(R36/Q36),"",R36/Q36) -> -0.029314439 | U36: 961930
A37: YS PTS | B37: 2904 | C37: YS PTS | D37: =SUMIFS('2026'!$L:$L,'2026'!$J:$J,$B37&$C37,'2026'!$O:$O,D$4) -> -344 | E37: =SUMIFS('2026'!$L:$L,'2026'!$J:$J,$B37&$C37,'2026'!$O:$O,E$4) -> 121156 | F37: =SUMIFS('2026'!$L:$L,'2026'!$J:$J,$B37&$C37,'2026'!$O:$O,F$4) -> -15 | G37: =SUMIFS('2026'!$L:$L,'2026'!$J:$J,$B37&$C37,'2026'!$O:$O,G$4) -> 0 | H37: =SUMIFS('2026'!$L:$L,'2026'!$J:$J,$B37&$C37,'2026'!$O:$O,H$4) -> 0 | I37: =SUMIFS('2026'!$L:$L,'2026'!$J:$J,$B37&$C37,'2026'!$O:$O,I$4) -> 40500 | J37: =SUMIFS('2026'!$L:$L,'2026'!$J:$J,$B37&$C37,'2026'!$O:$O,J$4) -> 75000 | K37: =SUMIFS('2026'!$L:$L,'2026'!$J:$J,$B37&$C37,'2026'!$O:$O,K$4) -> 215000 | ... O37: =SUMIFS('2026'!$L:$L,'2026'!$J:$J,$B37&$C37,'2026'!$O:$O,O$4) -> 160000 | P37: =SUM(D37:O37) -> 1196297 | Q37: 733461.12 | R37: =P37-Q37 -> 462835.88 | S37: =IF(ISERROR(R37/Q37),"",R37/Q37) -> 0.63102988 | U37: 77109
A38: SP1 | B38: 2904 | C38: Topped | D38: =SUMIFS('2026'!$L:$L,'2026'!$J:$J,$B38&$C38,'2026'!$O:$O,D$4) -> 121965 | E38: =SUMIFS('2026'!$L:$L,'2026'!$J:$J,$B38&$C38,'2026'!$O:$O,E$4) -> 162834 | F38: =SUMIFS('2026'!$L:$L,'2026'!$J:$J,$B38&$C38,'2026'!$O:$O,F$4) -> 211985 | G38: =SUMIFS('2026'!$L:$L,'2026'!$J:$J,$B38&$C38,'2026'!$O:$O,G$4) -> 193248 | H38: =SUMIFS('2026'!$L:$L,'2026'!$J:$J,$B38&$C38,'2026'!$O:$O,H$4) -> 120384 | I38: =SUMIFS('2026'!$L:$L,'2026'!$J:$J,$B38&$C38,'2026'!$O:$O,I$4) -> 144960.99 | J38: =SUMIFS('2026'!$L:$L,'2026'!$J:$J,$B38&$C38,'2026'!$O:$O,J$4) -> 161067.76 | K38: =SUMIFS('2026'!$L:$L,'2026'!$J:$J,$B38&$C38,'2026'!$O:$O,K$4) -> 177174.54 | ... O38: =SUMIFS('2026'!$L:$L,'2026'!$J:$J,$B38&$C38,'2026'!$O:$O,O$4) -> 193500 | P38: =SUM(D38:O38) -> 1929094.7 | Q38: 2043949.4 | R38: =P38-Q38 -> -114854.76 | S38: =IF(ISERROR(R38/Q38),"",R38/Q38) -> -0.056192563 | U38: 2182170
A39: TALENTI | B39: 2904 | C39: TALENTI | D39: =SUMIFS('2026'!$L:$L,'2026'!$J:$J,$B39&$C39,'2026'!$O:$O,D$4) -> 787404 | E39: =SUMIFS('2026'!$L:$L,'2026'!$J:$J,$B39&$C39,'2026'!$O:$O,E$4) -> 936622 | F39: =SUMIFS('2026'!$L:$L,'2026'!$J:$J,$B39&$C39,'2026'!$O:$O,F$4) -> 1043191.2 | G39: =SUMIFS('2026'!$L:$L,'2026'!$J:$J,$B39&$C39,'2026'!$O:$O,G$4) -> 1240608 | H39: =SUMIFS('2026'!$L:$L,'2026'!$J:$J,$B39&$C39,'2026'!$O:$O,H$4) -> 912864 | I39: =SUMIFS('2026'!$L:$L,'2026'!$J:$J,$B39&$C39,'2026'!$O:$O,I$4) -> 1000719.4 | J39: =SUMIFS('2026'!$L:$L,'2026'!$J:$J,$B39&$C39,'2026'!$O:$O,J$4) -> 1000719.4 | K39: =SUMIFS('2026'!$L:$L,'2026'!$J:$J,$B39&$C39,'2026'!$O:$O,K$4) -> 1107939.3 | ... O39: =SUMIFS('2026'!$L:$L,'2026'!$J:$J,$B39&$C39,'2026'!$O:$O,O$4) -> 678950.95 | P39: =SUM(D39:O39) -> 11044130 | Q39: 11023727 | R39: =P39-Q39 -> 20402.886 | S39: =IF(ISERROR(R39/Q39),"",R39/Q39) -> 0.0018508156 | U39: 10467549
A40: PG | B40: 2904 | C40: PG | D40: =SUMIFS('2026'!$L:$L,'2026'!$J:$J,$B40&$C40,'2026'!$O:$O,D$4) -> 82580 | E40: =SUMIFS('2026'!$L:$L,'2026'!$J:$J,$B40&$C40,'2026'!$O:$O,E$4) -> 118064 | F40: =SUMIFS('2026'!$L:$L,'2026'!$J:$J,$B40&$C40,'2026'!$O:$O,F$4) -> 110940 | G40: =SUMIFS('2026'!$L:$L,'2026'!$J:$J,$B40&$C40,'2026'!$O:$O,G$4) -> 137088 | H40: =SUMIFS('2026'!$L:$L,'2026'!$J:$J,$B40&$C40,'2026'!$O:$O,H$4) -> 134784 | I40: =SUMIFS('2026'!$L:$L,'2026'!$J:$J,$B40&$C40,'2026'!$O:$O,I$4) -> 172900 | J40: =SUMIFS('2026'!$L:$L,'2026'!$J:$J,$B40&$C40,'2026'!$O:$O,J$4) -> 186675 | K40: =SUMIFS('2026'!$L:$L,'2026'!$J:$J,$B40&$C40,'2026'!$O:$O,K$4) -> 190950 | ... O40: =SUMIFS('2026'!$L:$L,'2026'!$J:$J,$B40&$C40,'2026'!$O:$O,O$4) -> 0 | P40: =SUM(D40:O40) -> 1566706 | Q40: 1666302.6 | R40: =P40-Q40 -> -99596.6 | S40: =IF(ISERROR(R40/Q40),"",R40/Q40) -> -0.059771016 | U40: 1801702
C41: Total Sikeston | D41: =SUM(D26:D40) -> 3059349 | E41: =SUM(E26:E40) -> 3787130 | F41: =SUM(F26:F40) -> 4288743.1 | G41: =SUM(G26:G40) -> 4493356 | H41: =SUM(H26:H40) -> 3826400 | I41: =SUM(I26:I40) -> 3745226.3 | J41: =SUM(J26:J40) -> 3895057.2 | K41: =SUM(K26:K40) -> 4048087.2 | ... P41: =SUM(P26:P40) -> 41704270 | Q41: 41684951 | R41: =SUM(R26:R40) -> 19318.483 | S41: =IF(ISERROR(R41/Q41),"",R41/Q41) -> 0.00046344022 | U41: 39669375
...

Sheet Litons Post Attain
C3: STA ALBANS
A4: Tech Rollup | B4: Plant | C4: Row Labels | D4: Jan | E4: Feb | F4: Mar | G4: Apr | H4: May | I4: Jun | J4: Jul | K4: Aug | L4: Sep | M4: Oct | N4: Nov | O4: Dec | P4: 2026 MRF3 | Q4: 2026 MRF2 | R4: Difference | S4: % change | T4: Commentary | U4: 2025 Final | V4: 2025 MRF8 | W4: 2025 MRF7 | X4: 2024 MRF12 | Y4: Vs YAG MRF8 | Z4: VS YA | AA4: Type | AB4: 2026 MRF7
A5: 2.4 Gal | B5: 5914 | C5: 2.4 Gal | D5: =SUMIFS('2026'!$M:$M,'2026'!$J:$J,$B5&$C5,'2026'!$O:$O,D$4) -> 371.29852 | E5: =SUMIFS('2026'!$M:$M,'2026'!$J:$J,$B5&$C5,'2026'!$O:$O,E$4) -> 767.1967 | F5: =SUMIFS('2026'!$M:$M,'2026'!$J:$J,$B5&$C5,'2026'!$O:$O,F$4) -> 577.01471 | G5: =SUMIFS('2026'!$M:$M,'2026'!$J:$J,$B5&$C5,'2026'!$O:$O,G$4) -> 578.23283 | H5: =SUMIFS('2026'!$M:$M,'2026'!$J:$J,$B5&$C5,'2026'!$O:$O,H$4) -> 874.45591 | I5: =SUMIFS('2026'!$M:$M,'2026'!$J:$J,$B5&$C5,'2026'!$O:$O,I$4) -> 248.96257 | J5: =SUMIFS('2026'!$M:$M,'2026'!$J:$J,$B5&$C5,'2026'!$O:$O,J$4) -> 461.78331 | K5: =SUMIFS('2026'!$M:$M,'2026'!$J:$J,$B5&$C5,'2026'!$O:$O,K$4) -> 481.861 | ... O5: =SUMIFS('2026'!$M:$M,'2026'!$J:$J,$B5&$C5,'2026'!$O:$O,O$4) -> 0 | P5: =SUM(D5:O5) -> 5147.8471 | Q5: 4586.1812 | R5: =P5-Q5 -> 561.66588 | S5: =IF(ISERROR(R5/Q5),"",R5/Q5) -> 0.12246919 | U5: 4266.1069 | V5: 4393.3133 | W5: 4725.0633 | X5: 4511.154 | Y5: =P5/V5-1 -> 0.17174595 | Z5: =P5-V5 -> 754.53378 | AA5: UL | AB5: 4780.8133
A6: Other | B6: 5914 | C6: Quarts | D6: =SUMIFS('2026'!$M:$M,'2026'!$J:$J,$B6&$C6,'2026'!$O:$O,D$4) -> 0 | E6: =SUMIFS('2026'!$M:$M,'2026'!$J:$J,$B6&$C6,'2026'!$O:$O,E$4) -> 0 | F6: =SUMIFS('2026'!$M:$M,'2026'!$J:$J,$B6&$C6,'2026'!$O:$O,F$4) -> 0 | G6: =SUMIFS('2026'!$M:$M,'2026'!$J:$J,$B6&$C6,'2026'!$O:$O,G$4) -> 0 | H6: =SUMIFS('2026'!$M:$M,'2026'!$J:$J,$B6&$C6,'2026'!$O:$O,H$4) -> 0 | I6: =SUMIFS('2026'!$M:$M,'2026'!$J:$J,$B6&$C6,'2026'!$O:$O,I$4) -> 0 | J6: =SUMIFS('2026'!$M:$M,'2026'!$J:$J,$B6&$C6,'2026'!$O:$O,J$4) -> 0 | K6: =SUMIFS('2026'!$M:$M,'2026'!$J:$J,$B6&$C6,'2026'!$O:$O,K$4) -> 0 | ... O6: =SUMIFS('2026'!$M:$M,'2026'!$J:$J,$B6&$C6,'2026'!$O:$O,O$4) -> 0 | P6: =SUM(D6:O6) -> 0 | Q6: 0 | R6: =P6-Q6 -> 0 | S6: =IF(ISERROR(R6/Q6),"",R6/Q6) | U6: 1595.9004 | V6: 1783.1493 | W6: 2310.8503 | X6: 839.41315 | Y6: =P6/V6-1 -> -1 | Z6: =P6-V6 -> -1783.1493 | AA6: UL | AB6: 2346.5851
A7: BJ PTS | B7: 5914 | C7: PTS Exports | D7: =SUMIFS('2026'!$M:$M,'2026'!$J:$J,$B7&$C7,'2026'!$O:$O,D$4) -> 209.90622 | E7: =SUMIFS('2026'!$M:$M,'2026'!$J:$J,$B7&$C7,'2026'!$O:$O,E$4) -> 0 | F7: =SUMIFS('2026'!$M:$M,'2026'!$J:$J,$B7&$C7,'2026'!$O:$O,F$4) -> 281.91622 | G7: =SUMIFS('2026'!$M:$M,'2026'!$J:$J,$B7&$C7,'2026'!$O:$O,G$4) -> 120.29645 | H7: =SUMIFS('2026'!$M:$M,'2026'!$J:$J,$B7&$C7,'2026'!$O:$O,H$4) -> 234.0798 | I7: =SUMIFS('2026'!$M:$M,'2026'!$J:$J,$B7&$C7,'2026'!$O:$O,I$4) -> 0 | J7: =SUMIFS('2026'!$M:$M,'2026'!$J:$J,$B7&$C7,'2026'!$O:$O,J$4) -> 0 | K7: =SUMIFS('2026'!$M:$M,'2026'!$J:$J,$B7&$C7,'2026'!$O:$O,K$4) -> 0 | ... O7: =SUMIFS('2026'!$M:$M,'2026'!$J:$J,$B7&$C7,'2026'!$O:$O,O$4) -> 0 | P7: =SUM(D7:O7) -> 846.19869 | Q7: 546.61954 | R7: =P7-Q7 -> 299.57915 | S7: =IF(ISERROR(R7/Q7),"",R7/Q7) -> 0.5480579 | U7: 1649.0903 | V7: 1861.0493 | W7: 1431.4722 | X7: 1311.5092 | Y7: =P7/V7-1 -> -0.54531097 | Z7: =P7-V7 -> -1014.8506 | AA7: UL | AB7: 0
A8: B&J Cups | B8: 5914 | C8: Cup Exports | D8: =SUMIFS('2026'!$M:$M,'2026'!$J:$J,$B8&$C8,'2026'!$O:$O,D$4) -> 0 | E8: =SUMIFS('2026'!$M:$M,'2026'!$J:$J,$B8&$C8,'2026'!$O:$O,E$4) -> 0 | F8: =SUMIFS('2026'!$M:$M,'2026'!$J:$J,$B8&$C8,'2026'!$O:$O,F$4) -> 0 | G8: =SUMIFS('2026'!$M:$M,'2026'!$J:$J,$B8&$C8,'2026'!$O:$O,G$4) -> 0 | H8: =SUMIFS('2026'!$M:$M,'2026'!$J:$J,$B8&$C8,'2026'!$O:$O,H$4) -> 0 | I8: =SUMIFS('2026'!$M:$M,'2026'!$J:$J,$B8&$C8,'2026'!$O:$O,I$4) -> 0 | J8: =SUMIFS('2026'!$M:$M,'2026'!$J:$J,$B8&$C8,'2026'!$O:$O,J$4) -> 0 | K8: =SUMIFS('2026'!$M:$M,'2026'!$J:$J,$B8&$C8,'2026'!$O:$O,K$4) -> 0 | ... O8: =SUMIFS('2026'!$M:$M,'2026'!$J:$J,$B8&$C8,'2026'!$O:$O,O$4) -> 0 | P8: =SUM(D8:O8) -> 0 | Q8: 0 | R8: =P8-Q8 -> 0 | S8: =IF(ISERROR(R8/Q8),"",R8/Q8) | U8: 0 | V8: 0 | W8: 0 | X8: 66.42864 | Y8: =P8/V8-1 -> #DIV/0! | Z8: =P8-V8 -> 0 | AA8: UL | AB8: 0
A9: 2.4 Gal | B9: 5914 | C9: Bulk Exports | D9: =SUMIFS('2026'!$M:$M,'2026'!$J:$J,$B9&$C9,'2026'!$O:$O,D$4) -> 0 | E9: =SUMIFS('2026'!$M:$M,'2026'!$J:$J,$B9&$C9,'2026'!$O:$O,E$4) -> 0 | F9: =SUMIFS('2026'!$M:$M,'2026'!$J:$J,$B9&$C9,'2026'!$O:$O,F$4) -> 0 | G9: =SUMIFS('2026'!$M:$M,'2026'!$J:$J,$B9&$C9,'2026'!$O:$O,G$4) -> 0 | H9: =SUMIFS('2026'!$M:$M,'2026'!$J:$J,$B9&$C9,'2026'!$O:$O,H$4) -> 0 | I9: =SUMIFS('2026'!$M:$M,'2026'!$J:$J,$B9&$C9,'2026'!$O:$O,I$4) -> 0 | J9: =SUMIFS('2026'!$M:$M,'2026'!$J:$J,$B9&$C9,'2026'!$O:$O,J$4) -> 0 | K9: =SUMIFS('2026'!$M:$M,'2026'!$J:$J,$B9&$C9,'2026'!$O:$O,K$4) -> 0 | ... O9: =SUMIFS('2026'!$M:$M,'2026'!$J:$J,$B9&$C9,'2026'!$O:$O,O$4) -> 0 | P9: =SUM(D9:O9) -> 0 | Q9: 0 | R9: =P9-Q9 -> 0 | S9: =IF(ISERROR(R9/Q9),"",R9/Q9) | U9: 0 | V9: 0 | W9: 0 | X9: 0 | Y9: =P9/V9-1 -> #DIV/0! | Z9: =P9-V9 -> 0 | AA9: UL | AB9: 0
A10: B&J Cups | B10: 5914 | C10: B&J Cups | D10: =SUMIFS('2026'!$M:$M,'2026'!$J:$J,$B10&$C10,'2026'!$O:$O,D$4) -> 0 | E10: =SUMIFS('2026'!$M:$M,'2026'!$J:$J,$B10&$C10,'2026'!$O:$O,E$4) -> 0 | F10: =SUMIFS('2026'!$M:$M,'2026'!$J:$J,$B10&$C10,'2026'!$O:$O,F$4) -> 0 | G10: =SUMIFS('2026'!$M:$M,'2026'!$J:$J,$B10&$C10,'2026'!$O:$O,G$4) -> 0 | H10: =SUMIFS('2026'!$M:$M,'2026'!$J:$J,$B10&$C10,'2026'!$O:$O,H$4) -> 0 | I10: =SUMIFS('2026'!$M:$M,'2026'!$J:$J,$B10&$C10,'2026'!$O:$O,I$4) -> 0 | J10: =SUMIFS('2026'!$M:$M,'2026'!$J:$J,$B10&$C10,'2026'!$O:$O,J$4) -> 0 | K10: =SUMIFS('2026'!$M:$M,'2026'!$J:$J,$B10&$C10,'2026'!$O:$O,K$4) -> 0 | ... O10: =SUMIFS('2026'!$M:$M,'2026'!$J:$J,$B10&$C10,'2026'!$O:$O,O$4) -> 0 | P10: =SUM(D10:O10) -> 0 | Q10: 0 | R10: =P10-Q10 -> 0 | S10: =IF(ISERROR(R10/Q10),"",R10/Q10) | U10: 0 | V10: 0 | W10: 0 | X10: 1215.7807 | Y10: =P10/V10-1 -> #DIV/0! | Z10: =P10-V10 -> 0 | AA10: UL | AB10: 0
A11: B&J Cups | B11: 5914 | C11: B&J Dog Treat | D11: =SUMIFS('2026'!$M:$M,'2026'!$J:$J,$B11&$C11,'2026'!$O:$O,D$4) -> 0 | E11: =SUMIFS('2026'!$M:$M,'2026'!$J:$J,$B11&$C11,'2026'!$O:$O,E$4) -> 0 | F11: =SUMIFS('2026'!$M:$M,'2026'!$J:$J,$B11&$C11,'2026'!$O:$O,F$4) -> 0 | G11: =SUMIFS('2026'!$M:$M,'2026'!$J:$J,$B11&$C11,'2026'!$O:$O,G$4) -> 0 | H11: =SUMIFS('2026'!$M:$M,'2026'!$J:$J,$B11&$C11,'2026'!$O:$O,H$4) -> 0 | I11: =SUMIFS('2026'!$M:$M,'2026'!$J:$J,$B11&$C11,'2026'!$O:$O,I$4) -> 0 | J11: =SUMIFS('2026'!$M:$M,'2026'!$J:$J,$B11&$C11,'2026'!$O:$O,J$4) -> 0 | K11: =SUMIFS('2026'!$M:$M,'2026'!$J:$J,$B11&$C11,'2026'!$O:$O,K$4) -> 0 | ... O11: =SUMIFS('2026'!$M:$M,'2026'!$J:$J,$B11&$C11,'2026'!$O:$O,O$4) -> 0 | P11: =SUM(D11:O11) -> 0 | Q11: 0 | R11: =P11-Q11 -> 0 | S11: =IF(ISERROR(R11/Q11),"",R11/Q11) | U11: 0 | V11: 0 | W11: 0 | X11: 90.575711 | Y11: =P11/V11-1 -> #DIV/0! | Z11: =P11-V11 -> 0 | AA11: UL | AB11: 0
A12: SP1 | B12: 5914 | C12: PTS - BR | D12: =SUMIFS('2026'!$M:$M,'2026'!$J:$J,$B12&$C12,'2026'!$O:$O,D$4) -> 0 | E12: =SUMIFS('2026'!$M:$M,'2026'!$J:$J,$B12&$C12,'2026'!$O:$O,E$4) -> 0 | F12: =SUMIFS('2026'!$M:$M,'2026'!$J:$J,$B12&$C12,'2026'!$O:$O,F$4) -> 0 | G12: =SUMIFS('2026'!$M:$M,'2026'!$J:$J,$B12&$C12,'2026'!$O:$O,G$4) -> 0 | H12: =SUMIFS('2026'!$M:$M,'2026'!$J:$J,$B12&$C12,'2026'!$O:$O,H$4) -> 0 | I12: =SUMIFS('2026'!$M:$M,'2026'!$J:$J,$B12&$C12,'2026'!$O:$O,I$4) -> 0 | J12: =SUMIFS('2026'!$M:$M,'2026'!$J:$J,$B12&$C12,'2026'!$O:$O,J$4) -> 0 | K12: =SUMIFS('2026'!$M:$M,'2026'!$J:$J,$B12&$C12,'2026'!$O:$O,K$4) -> 0 | ... O12: =SUMIFS('2026'!$M:$M,'2026'!$J:$J,$B12&$C12,'2026'!$O:$O,O$4) -> 0 | P12: =SUM(D12:O12) -> 0 | Q12: 0 | R12: =P12-Q12 -> 0 | S12: =IF(ISERROR(R12/Q12),"",R12/Q12) | U12: 0 | V12: 0 | W12: 0 | X12: 0 | Y12: =P12/V12-1 -> #DIV/0! | Z12: =P12-V12 -> 0 | AA12: UL | AB12: 0
A13: BJ PTS | B13: 5914 | C13: BJ PTS | D13: =SUMIFS('2026'!$M:$M,'2026'!$J:$J,$B13&$C13,'2026'!$O:$O,D$4) -> 4047.3508 | E13: =SUMIFS('2026'!$M:$M,'2026'!$J:$J,$B13&$C13,'2026'!$O:$O,E$4) -> 5739.5715 | F13: =SUMIFS('2026'!$M:$M,'2026'!$J:$J,$B13&$C13,'2026'!$O:$O,F$4) -> 6752.8084 | G13: =SUMIFS('2026'!$M:$M,'2026'!$J:$J,$B13&$C13,'2026'!$O:$O,G$4) -> 4725.9196 | H13: =SUMIFS('2026'!$M:$M,'2026'!$J:$J,$B13&$C13,'2026'!$O:$O,H$4) -> 3820.7458 | I13: =SUMIFS('2026'!$M:$M,'2026'!$J:$J,$B13&$C13,'2026'!$O:$O,I$4) -> 4554.1867 | J13: =SUMIFS('2026'!$M:$M,'2026'!$J:$J,$B13&$C13,'2026'!$O:$O,J$4) -> 4793.8808 | K13: =SUMIFS('2026'!$M:$M,'2026'!$J:$J,$B13&$C13,'2026'!$O:$O,K$4) -> 5273.2688 | ... O13: =SUMIFS('2026'!$M:$M,'2026'!$J:$J,$B13&$C13,'2026'!$O:$O,O$4) -> 4187.5959 | P13: =SUM(D13:O13) -> 57670.686 | Q13: 58212.488 | R13: =P13-Q13 -> -541.80203 | S13: =IF(ISERROR(R13/Q13),"",R13/Q13) -> -0.0093073162 | U13: 57943.937 | V13: 56361.537 | W13: 56669.026 | X13: 64060.535 | Y13: =P13/V13-1 -> 0.023227697 | Z13: =P13-V13 -> 1309.1487 | AA13: UL | AB13: 56967.889
C14: Total St. Albans | D14: =SUM(D5:D13) -> 4628.5556 | E14: =SUM(E5:E13) -> 6506.7682 | F14: =SUM(F5:F13) -> 7611.7393 | G14: =SUM(G5:G13) -> 5424.4489 | H14: =SUM(H5:H13) -> 4929.2815 | I14: =SUM(I5:I13) -> 4803.1493 | J14: =SUM(J5:J13) -> 5255.6641 | K14: =SUM(K5:K13) -> 5755.1299 | ... P14: =SUM(P5:P13) -> 63664.731 | Q14: 63345.288 | R14: =SUM(R5:R13) -> 319.44301 | S14: =IF(ISERROR(R14/Q14),"",R14/Q14) -> 0.0050428851 | T14: 3 lines 24.7% | U14: 65455.035 | V14: 64399.049 | W14: 65136.412 | X14: 72095.396 | Y14: =P14/V14-1 -> -0.011402613 | Z14: =P14-V14 -> -734.31746 | AB14: 64095.288
C16: WATERBURY | R16: Vs PV | T16: Commentary
C17: Row Labels | D17: Jan | E17: Feb | F17: Mar | G17: Apr | H17: May | I17: Jun | J17: Jul | K17: Aug | L17: Sep | M17: Oct | N17: Nov | O17: Dec | P17: =P$4 -> 2026 MRF3 | Q17: 2026 MRF2 | R17: =R$4 -> Difference | S17: =S$4 -> % change | U17: 2025 Final | V17: 2025 MRF8 | W17: 2025 MRF7 | X17: 2024 MRF12 | AB17: 2026 MRF7
A18: Other | B18: 5911 | C18: 1 Gal | D18: =SUMIFS('2026'!$M:$M,'2026'!$J:$J,$B18&$C18,'2026'!$O:$O,D$4) -> 0 | E18: =SUMIFS('2026'!$M:$M,'2026'!$J:$J,$B18&$C18,'2026'!$O:$O,E$4) -> 0 | F18: =SUMIFS('2026'!$M:$M,'2026'!$J:$J,$B18&$C18,'2026'!$O:$O,F$4) -> 0 | G18: =SUMIFS('2026'!$M:$M,'2026'!$J:$J,$B18&$C18,'2026'!$O:$O,G$4) -> 0 | H18: =SUMIFS('2026'!$M:$M,'2026'!$J:$J,$B18&$C18,'2026'!$O:$O,H$4) -> 0 | I18: =SUMIFS('2026'!$M:$M,'2026'!$J:$J,$B18&$C18,'2026'!$O:$O,I$4) -> 0 | J18: =SUMIFS('2026'!$M:$M,'2026'!$J:$J,$B18&$C18,'2026'!$O:$O,J$4) -> 0 | K18: =SUMIFS('2026'!$M:$M,'2026'!$J:$J,$B18&$C18,'2026'!$O:$O,K$4) -> 0 | ... O18: =SUMIFS('2026'!$M:$M,'2026'!$J:$J,$B18&$C18,'2026'!$O:$O,O$4) -> 0 | P18: =SUM(D18:O18) -> 0 | Q18: 0 | R18: =P18-Q18 -> 0 | S18: =IF(ISERROR(R18/Q18),"",R18/Q18) | U18: 0 | V18: 0 | W18: 0 | X18: 0 | Y18: =P18/V18-1 -> #DIV/0! | Z18: =P18-V18 -> 0 | AA18: UL | AB18: 0
A19: Other | B19: 5911 | C19: QTS | D19: =SUMIFS('2026'!$M:$M,'2026'!$J:$J,$B19&$C19,'2026'!$O:$O,D$4) -> 0 | E19: =SUMIFS('2026'!$M:$M,'2026'!$J:$J,$B19&$C19,'2026'!$O:$O,E$4) -> 0 | F19: =SUMIFS('2026'!$M:$M,'2026'!$J:$J,$B19&$C19,'2026'!$O:$O,F$4) -> 0 | G19: =SUMIFS('2026'!$M:$M,'2026'!$J:$J,$B19&$C19,'2026'!$O:$O,G$4) -> 0 | H19: =SUMIFS('2026'!$M:$M,'2026'!$J:$J,$B19&$C19,'2026'!$O:$O,H$4) -> 0 | I19: =SUMIFS('2026'!$M:$M,'2026'!$J:$J,$B19&$C19,'2026'!$O:$O,I$4) -> 0 | J19: =SUMIFS('2026'!$M:$M,'2026'!$J:$J,$B19&$C19,'2026'!$O:$O,J$4) -> 0 | K19: =SUMIFS('2026'!$M:$M,'2026'!$J:$J,$B19&$C19,'2026'!$O:$O,K$4) -> 0 | ... O19: =SUMIFS('2026'!$M:$M,'2026'!$J:$J,$B19&$C19,'2026'!$O:$O,O$4) -> 0 | P19: =SUM(D19:O19) -> 0 | Q19: 0 | R19: =P19-Q19 -> 0 | S19: =IF(ISERROR(R19/Q19),"",R19/Q19) | U19: 0 | V19: 0 | W19: 0 | X19: 0 | Y19: =P19/V19-1 -> #DIV/0! | Z19: =P19-V19 -> 0 | AA19: UL | AB19: 0
A20: BJ PTS | B20: 5911 | C20: PTS Exports | D20: =SUMIFS('2026'!$M:$M,'2026'!$J:$J,$B20&$C20,'2026'!$O:$O,D$4) -> 40.48396 | E20: =SUMIFS('2026'!$M:$M,'2026'!$J:$J,$B20&$C20,'2026'!$O:$O,E$4) -> 33.390016 | F20: =SUMIFS('2026'!$M:$M,'2026'!$J:$J,$B20&$C20,'2026'!$O:$O,F$4) -> 51.25428 | G20: =SUMIFS('2026'!$M:$M,'2026'!$J:$J,$B20&$C20,'2026'!$O:$O,G$4) -> 40.59648 | H20: =SUMIFS('2026'!$M:$M,'2026'!$J:$J,$B20&$C20,'2026'!$O:$O,H$4) -> 0 | I20: =SUMIFS('2026'!$M:$M,'2026'!$J:$J,$B20&$C20,'2026'!$O:$O,I$4) -> 0 | J20: =SUMIFS('2026'!$M:$M,'2026'!$J:$J,$B20&$C20,'2026'!$O:$O,J$4) -> 0 | K20: =SUMIFS('2026'!$M:$M,'2026'!$J:$J,$B20&$C20,'2026'!$O:$O,K$4) -> 0 | ... O20: =SUMIFS('2026'!$M:$M,'2026'!$J:$J,$B20&$C20,'2026'!$O:$O,O$4) -> 0 | P20: =SUM(D20:O20) -> 165.72474 | Q20: 171.95526 | R20: =P20-Q20 -> -6.23052 | U20: 1016.0536 | V20: 1978.4506 | W20: 1709.5618 | X20: 1079.6825 | Y20: =P20/V20-1 -> -0.91623509 | Z20: =P20-V20 -> -1812.7258 | AA20: UL | AB20: 0
A21: BJ PTS | B21: 5911 | C21: BJ PTS | D21: =SUMIFS('2026'!$M:$M,'2026'!$J:$J,$B21&$C21,'2026'!$O:$O,D$4) -> 2370.1704 | E21: =SUMIFS('2026'!$M:$M,'2026'!$J:$J,$B21&$C21,'2026'!$O:$O,E$4) -> 2787.5273 | F21: =SUMIFS('2026'!$M:$M,'2026'!$J:$J,$B21&$C21,'2026'!$O:$O,F$4) -> 3564.3061 | G21: =SUMIFS('2026'!$M:$M,'2026'!$J:$J,$B21&$C21,'2026'!$O:$O,G$4) -> 2659.6373 | H21: =SUMIFS('2026'!$M:$M,'2026'!$J:$J,$B21&$C21,'2026'!$O:$O,H$4) -> 2966.7634 | I21: =SUMIFS('2026'!$M:$M,'2026'!$J:$J,$B21&$C21,'2026'!$O:$O,I$4) -> 2732.7155 | J21: =SUMIFS('2026'!$M:$M,'2026'!$J:$J,$B21&$C21,'2026'!$O:$O,J$4) -> 2890.5319 | K21: =SUMIFS('2026'!$M:$M,'2026'!$J:$J,$B21&$C21,'2026'!$O:$O,K$4) -> 2907.1442 | ... O21: =SUMIFS('2026'!$M:$M,'2026'!$J:$J,$B21&$C21,'2026'!$O:$O,O$4) -> 1514.1376 | P21: =SUM(D21:O21) -> 27951.157 | Q21: 26701.794 | R21: =P21-Q21 -> 1249.3636 | S21: =IF(ISERROR(R21/Q21),"",R21/Q21) -> 0.046789501 | T21: Still assuming 10 weeks down | U21: 31182.785 | V21: 31464.71 | W21: 30988.984 | X21: 31610.79 | Y21: =P21/V21-1 -> -0.11166647 | Z21: =P21-V21 -> -3513.5532 | AA21: UL | AB21: 30472.322
