Workbook

Sheet Sites
B3: 1419
B4: 3989
B5: 3983
B6: 3984
B7: 3961
B8: 3962
B9: 6706
B10: 2600
B11: 3985
B12: 3938
B13: 1461
B14: 1712
... B22: 6765

Sheet TMICC
A1: Material | B1: Plant | C1: Quantity | D1: Pstng Date | E1: Description | F1: Ver. | G1: CA is for US | H1: Purch.Doc.
A2: 64315721 | B2: 1352 | C2: 22 | D2: 46076 | E2: BR CS Chocolate Peanut Butter 6 1.5QT | F2: S4 | G2: =VLOOKUP($A2,'CA-US List'!$A:$C,3,0) -> #N/A
A3: 64315721 | B3: 1352 | C3: 3344 | D3: 46077 | E3: BR CS Chocolate Peanut Butter 6 1.5QT | F3: S4 | G3: =VLOOKUP($A3,'CA-US List'!$A:$C,3,0) -> #N/A
A4: 64315721 | B4: 1352 | C4: 7920 | D4: 46078 | E4: BR CS Chocolate Peanut Butter 6 1.5QT | F4: S4 | G4: =VLOOKUP($A4,'CA-US List'!$A:$C,3,0) -> #N/A
A5: 64315721 | B5: 1352 | C5: 3001 | D5: 46077 | E5: BR CS Chocolate Peanut Butter 6 1.5QT | F5: S4 | G5: =VLOOKUP($A5,'CA-US List'!$A:$C,3,0) -> #N/A
A6: 64315721 | B6: 1352 | C6: 3872 | D6: 46076 | E6: BR CS Chocolate Peanut Butter 6 1.5QT | F6: S4 | G6: =VLOOKUP($A6,'CA-US List'!$A:$C,3,0) -> #N/A
A7: 64315721 | B7: 1352 | C7: 11 | D7: 46078 | E7: BR CS Chocolate Peanut Butter 6 1.5QT | F7: S4 | G7: =VLOOKUP($A7,'CA-US List'!$A:$C,3,0) -> #N/A
A8: 64315721 | B8: 1352 | C8: 0 | D8: 46079 | E8: BR CS Chocolate Peanut Butter 6 1.5QT | F8: S4 | G8: =VLOOKUP($A8,'CA-US List'!$A:$C,3,0) -> #N/A
A9: 64315721 | B9: 1352 | C9: 176 | D9: 46079 | E9: BR CS Chocolate Peanut Butter 6 1.5QT | F9: S4 | G9: =VLOOKUP($A9,'CA-US List'!$A:$C,3,0) -> #N/A
A10: 64315721 | B10: 1352 | C10: 478 | D10: 46078 | E10: BR CS Chocolate Peanut Butter 6 1.5QT | F10: S4 | G10: =VLOOKUP($A10,'CA-US List'!$A:$C,3,0) -> #N/A
A11: 64315721 | B11: 1352 | C11: 4414 | D11: 46079 | E11: BR CS Chocolate Peanut Butter 6 1.5QT | F11: S4 | G11: =VLOOKUP($A11,'CA-US List'!$A:$C,3,0) -> #N/A
A12: 64341967 | B12: 1352 | C12: 4045 | D12: 46102 | E12: BR CHOC Peanut Butter 6 1.5QT | F12: S4 | G12: =VLOOKUP($A12,'CA-US List'!$A:$C,3,0) -> #N/A
A13: 64341967 | B13: 1352 | C13: 4909 | D13: 46103 | E13: BR CHOC Peanut Butter 6 1.5QT | F13: S4 | G13: =VLOOKUP($A13,'CA-US List'!$A:$C,3,0) -> #N/A
... A1156: 68821728 | B1156: 2904 | C1156: -9 | D1156: 46100 | E1156: BR Rocky Road 6 1.5QT | F1156: SS3 | G1156: =VLOOKUP($A1156,'CA-US List'!$A:$C,3,0) -> #N/A
A1157: 68821728 | B1157: 2904 | C1157: 4282 | D1157: 46089 | E1157: BR Rocky Road 6 1.5QT | G1157: =VLOOKUP($A1157,'CA-US List'!$A:$C,3,0) -> #N/A
A1158: 68821734 | B1158: 2904 | C1158: 704 | D1158: 46097 | E1158: BR Vanilla Chocolate 6 1.5QT | F1158: SS1 | G1158: =VLOOKUP($A1158,'CA-US List'!$A:$C,3,0) -> #N/A
A1159: 68821734 | B1159: 2904 | C1159: 9680 | D1159: 46097 | E1159: BR Vanilla Chocolate 6 1.5QT | F1159: SS1 | G1159: =VLOOKUP($A1159,'CA-US List'!$A:$C,3,0) -> #N/A
A1160: 68821734 | B1160: 2904 | C1160: 8448 | D1160: 46098 | E1160: BR Vanilla Chocolate 6 1.5QT | F1160: SS1 | G1160: =VLOOKUP($A1160,'CA-US List'!$A:$C,3,0) -> #N/A
A1161: 68821734 | B1161: 2904 | C1161: 12320 | D1161: 46098 | E1161: BR Vanilla Chocolate 6 1.5QT | F1161: SS1 | G1161: =VLOOKUP($A1161,'CA-US List'!$A:$C,3,0) -> #N/A
A1162: 68821734 | B1162: 2904 | C1162: 5199 | D1162: 46099 | E1162: BR Vanilla Chocolate 6 1.5QT | F1162: SS1 | G1162: =VLOOKUP($A1162,'CA-US List'!$A:$C,3,0) -> #N/A
A1163: 68821734 | B1163: 2904 | C1163: 176 | D1163: 46099 | E1163: BR Vanilla Chocolate 6 1.5QT | F1163: SS1 | G1163: =VLOOKUP($A1163,'CA-US List'!$A:$C,3,0) -> #N/A
A1164: 68821734 | B1164: 2904 | C1164: 4048 | D1164: 46100 | E1164: BR Vanilla Chocolate 6 1.5QT | F1164: SS1 | G1164: =VLOOKUP($A1164,'CA-US List'!$A:$C,3,0) -> #N/A
A1165: 68821734 | B1165: 2904 | C1165: 13200 | D1165: 46100 | E1165: BR Vanilla Chocolate 6 1.5QT | F1165: SS1 | G1165: =VLOOKUP($A1165,'CA-US List'!$A:$C,3,0) -> #N/A
A1166: 68821734 | B1166: 2904 | C1166: 11385 | D1166: 46101 | E1166: BR Vanilla Chocolate 6 1.5QT | F1166: SS1 | G1166: =VLOOKUP($A1166,'CA-US List'!$A:$C,3,0) -> #N/A
A1167: 68821734 | B1167: 2904 | C1167: 9328 | D1167: 46101 | E1167: BR Vanilla Chocolate 6 1.5QT | F1167: SS1 | G1167: =VLOOKUP($A1167,'CA-US List'!$A:$C,3,0) -> #N/A
A1168: 68821734 | B1168: 2904 | C1168: 25 | D1168: 46102 | E1168: BR Vanilla Chocolate 6 1.5QT | F1168: SS1 | G1168: =VLOOKUP($A1168,'CA-US List'!$A:$C,3,0) -> #N/A
A1169: 68821735 | B1169: 2904 | C1169: 6864 | D1169: 46090 | E1169: BR Lactose Free Vanilla 6 1.5QT | F1169: SS3 | G1169: =VLOOKUP($A1169,'CA-US List'!$A:$C,3,0) -> #N/A
... A1790: 84164939 | B1790: 5914 | C1790: 2341 | D1790: 46100 | E1790: BJ US-IC-SweetCrm+Cookies-FTNG-1 2.4G | F1790: 01 | G1790: =VLOOKUP($A1790,'CA-US List'!$A:$C,3,0) -> #N/A

Sheet Sheet1
A1: 64315721 | B1: 1352 | C1: 22 | D1: 46076 | E1: =VLOOKUP($A1,Sheet4!$A:$B,2,0) -> BR CS Chocolate Peanut Butter 6 1.5QT | F1: S4
A2: 64315721 | B2: 1352 | C2: 3344 | D2: 46077 | E2: =VLOOKUP($A2,Sheet4!$A:$B,2,0) -> BR CS Chocolate Peanut Butter 6 1.5QT | F2: S4
A3: 64315721 | B3: 1352 | C3: 7920 | D3: 46078 | E3: =VLOOKUP($A3,Sheet4!$A:$B,2,0) -> BR CS Chocolate Peanut Butter 6 1.5QT | F3: S4
A4: 64315721 | B4: 1352 | C4: 3001 | D4: 46077 | E4: =VLOOKUP($A4,Sheet4!$A:$B,2,0) -> BR CS Chocolate Peanut Butter 6 1.5QT | F4: S4
A5: 64315721 | B5: 1352 | C5: 3872 | D5: 46076 | E5: =VLOOKUP($A5,Sheet4!$A:$B,2,0) -> BR CS Chocolate Peanut Butter 6 1.5QT | F5: S4
A6: 64315721 | B6: 1352 | C6: 11 | D6: 46078 | E6: =VLOOKUP($A6,Sheet4!$A:$B,2,0) -> BR CS Chocolate Peanut Butter 6 1.5QT | F6: S4
A7: 64315721 | B7: 1352 | C7: 0 | D7: 46079 | E7: =VLOOKUP($A7,Sheet4!$A:$B,2,0) -> BR CS Chocolate Peanut Butter 6 1.5QT | F7: S4
A8: 64315721 | B8: 1352 | C8: 176 | D8: 46079 | E8: =VLOOKUP($A8,Sheet4!$A:$B,2,0) -> BR CS Chocolate Peanut Butter 6 1.5QT | F8: S4
A9: 64315721 | B9: 1352 | C9: 478 | D9: 46078 | E9: =VLOOKUP($A9,Sheet4!$A:$B,2,0) -> BR CS Chocolate Peanut Butter 6 1.5QT | F9: S4
A10: 64315721 | B10: 1352 | C10: 4414 | D10: 46079 | E10: =VLOOKUP($A10,Sheet4!$A:$B,2,0) -> BR CS Chocolate Peanut Butter 6 1.5QT | F10: S4
A11: 64341967 | B11: 1352 | C11: 4045 | D11: 46102 | E11: =VLOOKUP($A11,Sheet4!$A:$B,2,0) -> BR CHOC Peanut Butter 6 1.5QT | F11: S4
A12: 64341967 | B12: 1352 | C12: 4909 | D12: 46103 | E12: =VLOOKUP($A12,Sheet4!$A:$B,2,0) -> BR CHOC Peanut Butter 6 1.5QT | F12: S4
... A1155: 68821728 | B1155: 2904 | C1155: -9 | D1155: 46100 | E1155: =VLOOKUP($A1155,Sheet4!$A:$B,2,0) -> BR Rocky Road 6 1.5QT | F1155: SS3
A1156: 68821728 | B1156: 2904 | C1156: 4282 | D1156: 46089 | E1156: =VLOOKUP($A1156,Sheet4!$A:$B,2,0) -> BR Rocky Road 6 1.5QT
A1157: 68821734 | B1157: 2904 | C1157: 704 | D1157: 46097 | E1157: =VLOOKUP($A1157,Sheet4!$A:$B,2,0) -> BR Vanilla Chocolate 6 1.5QT | F1157: SS1
A1158: 68821734 | B1158: 2904 | C1158: 9680 | D1158: 46097 | E1158: =VLOOKUP($A1158,Sheet4!$A:$B,2,0) -> BR Vanilla Chocolate 6 1.5QT | F1158: SS1
A1159: 68821734 | B1159: 2904 | C1159: 8448 | D1159: 46098 | E1159: =VLOOKUP($A1159,Sheet4!$A:$B,2,0) -> BR Vanilla Chocolate 6 1.5QT | F1159: SS1
A1160: 68821734 | B1160: 2904 | C1160: 12320 | D1160: 46098 | E1160: =VLOOKUP($A1160,Sheet4!$A:$B,2,0) -> BR Vanilla Chocolate 6 1.5QT | F1160: SS1
A1161: 68821734 | B1161: 2904 | C1161: 5199 | D1161: 46099 | E1161: =VLOOKUP($A1161,Sheet4!$A:$B,2,0) -> BR Vanilla Chocolate 6 1.5QT | F1161: SS1
A1162: 68821734 | B1162: 2904 | C1162: 176 | D1162: 46099 | E1162: =VLOOKUP($A1162,Sheet4!$A:$B,2,0) -> BR Vanilla Chocolate 6 1.5QT | F1162: SS1
A1163: 68821734 | B1163: 2904 | C1163: 4048 | D1163: 46100 | E1163: =VLOOKUP($A1163,Sheet4!$A:$B,2,0) -> BR Vanilla Chocolate 6 1.5QT | F1163: SS1
A1164: 68821734 | B1164: 2904 | C1164: 13200 | D1164: 46100 | E1164: =VLOOKUP($A1164,Sheet4!$A:$B,2,0) -> BR Vanilla Chocolate 6 1.5QT | F1164: SS1
A1165: 68821734 | B1165: 2904 | C1165: 11385 | D1165: 46101 | E1165: =VLOOKUP($A1165,Sheet4!$A:$B,2,0) -> BR Vanilla Chocolate 6 1.5QT | F1165: SS1
A1166: 68821734 | B1166: 2904 | C1166: 9328 | D1166: 46101 | E1166: =VLOOKUP($A1166,Sheet4!$A:$B,2,0) -> BR Vanilla Chocolate 6 1.5QT | F1166: SS1
A1167: 68821734 | B1167: 2904 | C1167: 25 | D1167: 46102 | E1167: =VLOOKUP($A1167,Sheet4!$A:$B,2,0) -> BR Vanilla Chocolate 6 1.5QT | F1167: SS1
A1168: 68821735 | B1168: 2904 | C1168: 6864 | D1168: 46090 | E1168: =VLOOKUP($A1168,Sheet4!$A:$B,2,0) -> BR Lactose Free Vanilla 6 1.5QT | F1168: SS3
... A2074: 84164939 | B2074: 5914 | C2074: 2341 | D2074: 46100 | E2074: =VLOOKUP($A2074,Sheet4!$A:$B,2,0) -> BJ US-IC-SweetCrm+Cookies-FTNG-1 2.4G | F2074: 01

Sheet CM Info
A1: Material | B1: Plant | C1: Goods Receipt Quantity | D1: Goods Receipt Date | E1: Description | F1: Plnt | G1: Vendor | H1: Vendor Name | I1: Goods Supplier | J1: GS Name
A2: 64976846 | B2: 1717 | C2: 28282 | D2: 46078 | E2: Yasso Strawberry Chocolate Crunch 8-4pk | F2: 1717 | G2: 51655114 | H2: Caspers Ice Cream LLC | I2: 51655114 | J2: Caspers Ice Cream LLC
A3: 64976851 | B3: 1717 | C3: 19571 | D3: 46083 | E3: Yasso Caramel Chocolate Crunch 8-4pk | F3: 1717 | G3: 51655114 | H3: Caspers Ice Cream LLC | I3: 51655114 | J3: Caspers Ice Cream LLC
A4: 64976847 | B4: 1717 | C4: 50055 | D4: 46094 | E4: Yasso Vanilla Chocolate Crunch 8-4pk | F4: 1717 | G4: 51655114 | H4: Caspers Ice Cream LLC | I4: 51655114 | J4: Caspers Ice Cream LLC
A5: 65489676 | B5: 1717 | C5: 17846 | D5: 46100 | E5: GH King Cone GINT Cookies and CRM 1-12PK | F5: 1717 | G5: 51655114 | H5: Caspers Ice Cream LLC | I5: 51655114 | J5: Caspers Ice Cream LLC
A6: 65489677 | B6: 1717 | C6: 13923 | D6: 46102 | E6: GH King Cone Giant VAN CHOC 1-12PK | F6: 1717 | G6: 51655114 | H6: Caspers Ice Cream LLC | I6: 51655114 | J6: Caspers Ice Cream LLC
A7: 64958128 | B7: 1717 | C7: 32843 | D7: 46104 | E7: Yasso Mint Chocolate Chip 8-4pk | F7: 1717 | G7: 51655114 | H7: Caspers Ice Cream LLC | I7: 51655114 | J7: Caspers Ice Cream LLC
A8: 65489677 | B8: 1717 | C8: 5746 | D8: 46105 | E8: GH King Cone Giant VAN CHOC 1-12PK | F8: 1717 | G8: 51655114 | H8: Caspers Ice Cream LLC | I8: 51655114 | J8: Caspers Ice Cream LLC
A9: 64955741 | B9: 1715 | C9: 22379 | D9: 46078 | E9: Yasso Pistachio 8-4pk | F9: 1715 | G9: 51655117 | H9: DFA Belvidere IL | I9: 51655117 | J9: DFA Belvidere IL
A10: 64958126 | B10: 1715 | C10: 10043 | D10: 46079 | E10: Yasso Black Raspberry Chip 8-4pk | F10: 1715 | G10: 51655117 | H10: DFA Belvidere IL | I10: 51655117 | J10: DFA Belvidere IL
A11: 64955561 | B11: 1715 | C11: 17722 | D11: 46084 | E11: Yasso Creamy Pineapple Coconut 8-4pk | F11: 1715 | G11: 51655117 | H11: DFA Belvidere IL | I11: 51655117 | J11: DFA Belvidere IL
A12: 64955741 | B12: 1715 | C12: 23702 | D12: 46086 | E12: Yasso Pistachio 8-4pk | F12: 1715 | G12: 51655117 | H12: DFA Belvidere IL | I12: 51655117 | J12: DFA Belvidere IL
A13: 64955559 | B13: 1715 | C13: 21008 | D13: 46087 | E13: Yasso Strawberries n Cream 8-4pk | F13: 1715 | G13: 51655117 | H13: DFA Belvidere IL | I13: 51655117 | J13: DFA Belvidere IL
... A17: 64955743 | B17: 1715 | C17: 19406 | D17: 46104 | E17: Yasso Peanut Butter Chip 8-4pk | F17: 1715 | G17: 51655117 | H17: DFA Belvidere IL | I17: 51655117 | J17: DFA Belvidere IL
A18: 62714126 | B18: GDI | C18: 2600 | D18: 46076 | E18: PS OCG SF 6-18PK | F18: 1419 | G18: 51146194 | H18: GELATO D ITALIA S P A | I18: 51146194 | J18: GELATO D ITALIA S P A
A19: 64833353 | B19: GDI | C19: 2600 | D19: 46076 | E19: PS SF Tropical 6-18PK | F19: 1419 | G19: 51146194 | H19: GELATO D ITALIA S P A | I19: 51146194 | J19: GELATO D ITALIA S P A
A20: 64833353 | B20: GDI | C20: 2600 | D20: 46076 | E20: PS SF Tropical 6-18PK | F20: 1419 | G20: 51146194 | H20: GELATO D ITALIA S P A | I20: 51146194 | J20: GELATO D ITALIA S P A
A21: 62714126 | B21: GDI | C21: 2600 | D21: 46078 | E21: PS OCG SF 6-18PK | F21: 1419 | G21: 51146194 | H21: GELATO D ITALIA S P A | I21: 51146194 | J21: GELATO D ITALIA S P A
A22: 64833353 | B22: GDI | C22: 2600 | D22: 46080 | E22: PS SF Tropical 6-18PK | F22: 3989 | G22: 51146194 | H22: GELATO D ITALIA S P A | I22: 51146194 | J22: GELATO D ITALIA S P A
A23: 64833353 | B23: GDI | C23: 2600 | D23: 46083 | E23: PS SF Tropical 6-18PK | F23: 3989 | G23: 51146194 | H23: GELATO D ITALIA S P A | I23: 51146194 | J23: GELATO D ITALIA S P A
A24: 64833353 | B24: GDI | C24: 2600 | D24: 46083 | E24: PS SF Tropical 6-18PK | F24: 3989 | G24: 51146194 | H24: GELATO D ITALIA S P A | I24: 51146194 | J24: GELATO D ITALIA S P A
A25: 64833353 | B25: GDI | C25: 2600 | D25: 46083 | E25: PS SF Tropical 6-18PK | F25: 3989 | G25: 51146194 | H25: GELATO D ITALIA S P A | I25: 51146194 | J25: GELATO D ITALIA S P A
A26: 64833353 | B26: GDI | C26: 2600 | D26: 46084 | E26: PS SF Tropical 6-18PK | F26: 3989 | G26: 51146194 | H26: GELATO D ITALIA S P A | I26: 51146194 | J26: GELATO D ITALIA S P A
A27: 62714126 | B27: GDI | C27: 2600 | D27: 46087 | E27: PS OCG SF 6-18PK | F27: 1419 | G27: 51146194 | H27: GELATO D ITALIA S P A | I27: 51146194 | J27: GELATO D ITALIA S P A
A28: 62714126 | B28: GDI | C28: 2600 | D28: 46087 | E28: PS OCG SF 6-18PK | F28: 1419 | G28: 51146194 | H28: GELATO D ITALIA S P A | I28: 51146194 | J28: GELATO D ITALIA S P A
A29: 62714126 | B29: GDI | C29: 2600 | D29: 46087 | E29: PS OCG SF 6-18PK | F29: 1419 | G29: 51146194 | H29: GELATO D ITALIA S P A | I29: 51146194 | J29: GELATO D ITALIA S P A
... A104: 64960643 | B104: GDI | C104: 3400 | D104: 46105 | E104: PS Orange Regular IH 6-12pk | F104: 1419 | G104: 51146194 | H104: GELATO D ITALIA S P A | I104: 51146194 | J104: GELATO D ITALIA S P A
A105: 64988054 | B105: 1716 | C105: 24253 | D105: 46077 | E105: BJ US-Bar-Caramel Blondie 8-4pk | F105: 1716 | G105: 51655250 | H105: Hudsonville Creamery and Ice Cream | I105: 51655250 | J105: Hudsonville Creamery and Ice Cream
A106: 64988053 | B106: 1716 | C106: 24276 | D106: 46077 | E106: BJ US-Bar-PB Pretzel 8-4pk | F106: 1716 | G106: 51655250 | H106: Hudsonville Creamery and Ice Cream | I106: 51655250 | J106: Hudsonville Creamery and Ice Cream
A107: 64987232 | B107: 1716 | C107: 24778 | D107: 46077 | E107: BJ US-Bar-CHOCFUDGBrownie 8-4pk | F107: 1716 | G107: 51655250 | H107: Hudsonville Creamery and Ice Cream | I107: 51655250 | J107: Hudsonville Creamery and Ice Cream
A108: 64975613 | B108: 1716 | C108: 48560 | D108: 46077 | E108: Yasso Chocolate Chip Cookie Dough 8-14z | F108: 1716 | G108: 51655250 | H108: Hudsonville Creamery and Ice Cream | I108: 51655250 | J108: Hudsonville Creamery and Ice Cream
A109: 64975614 | B109: 1716 | C109: 95637 | D109: 46077 | E109: Yasso Fudge Brownie 8-14z | F109: 1716 | G109: 51655250 | H109: Hudsonville Creamery and Ice Cream | I109: 51655250 | J109: Hudsonville Creamery and Ice Cream
A110: 64958129 | B110: 1716 | C110: 7117 | D110: 46079 | E110: Yasso Chocolate Chip Cookie Dough 8-4pk | F110: 1716 | G110: 51655250 | H110: Hudsonville Creamery and Ice Cream | I110: 51655250 | J110: Hudsonville Creamery and Ice Cream
A111: 64975616 | B111: 1716 | C111: 62924 | D111: 46079 | E111: Yasso Mint Chocolate Chip 8-14z | F111: 1716 | G111: 51655250 | H111: Hudsonville Creamery and Ice Cream | I111: 51655250 | J111: Hudsonville Creamery and Ice Cream
A112: 64999073 | B112: 1716 | C112: 46482 | D112: 46083 | E112: Yasso Cookies n Cream 8-14z | F112: 1716 | G112: 51655250 | H112: Hudsonville Creamery and Ice Cream | I112: 51655250 | J112: Hudsonville Creamery and Ice Cream
A113: 64999042 | B113: 1716 | C113: 13758 | D113: 46085 | E113: Yasso Coffee Chocolate Chip 8-14z | F113: 1716 | G113: 51655250 | H113: Hudsonville Creamery and Ice Cream | I113: 51655250 | J113: Hudsonville Creamery and Ice Cream
A114: 64987233 | B114: 1716 | C114: 15090 | D114: 46086 | E114: BJ US-Bar-StrawberryCHSCAKE 8-4pk | F114: 1716 | G114: 51655250 | H114: Hudsonville Creamery and Ice Cream | I114: 51655250 | J114: Hudsonville Creamery and Ice Cream
A115: 64988054 | B115: 1716 | C115: 31084 | D115: 46086 | E115: BJ US-Bar-Caramel Blondie 8-4pk | F115: 1716 | G115: 51655250 | H115: Hudsonville Creamery and Ice Cream | I115: 51655250 | J115: Hudsonville Creamery and Ice Cream
A116: 64975614 | B116: 1716 | C116: 11520 | D116: 46087 | E116: Yasso Fudge Brownie 8-14z | F116: 1716 | G116: 51655250 | H116: Hudsonville Creamery and Ice Cream | I116: 51655250 | J116: Hudsonville Creamery and Ice Cream
... A131: 64989109 | B131: 6765 | C131: 5847 | D131: 46099 | E131: BR Natural Vanilla 6 10CT 3z | F131: 6765 | G131: 51714298 | H131: Ice Cream Specialties Inc | I131: 51714298 | J131: Ice Cream Specialties Inc
...

Sheet Sheet4
A1: Material | B1: Description | C1: Ind. Std Desc. | D1: Material Type | E1: X-DChain status | F1: Valid from | G1: EAN/UPC | H1: Created On | I1: Last Change | J1: Changed by
A2: 62678148 | B2: BJ US-NDO-LightsCaramelAction-8 1PT | C2: NA | D2: FERT | E2: 20 | F2: 45273 | G2: 10076840003928 | H2: 45044 | I2: 46064 | J2: PUJARI_B705
A3: 62678153 | B3: BJ US-NDO-TonightDough-8 1PT | C3: NA | D3: FERT | E3: 20 | F3: 45273 | G3: 10076840002884 | H3: 45044 | I3: 46061 | J3: PUJARI_B705
A4: 62697528 | B4: BJ US-NDO-Milk+Cookies-8 1PT | C4: NA | D4: FERT | E4: 20 | F4: 45328 | G4: 10076840002280 | H4: 45078 | I4: 46064 | J4: PUJARI_B705
A5: 62697529 | B5: BJ US-NDO-COR-KaramelSutra-8 1PT | C5: NA | D5: FERT | E5: 20 | F5: 45414 | G5: 10076840002891 | H5: 45078 | I5: 46055 | J5: PUJARI_B705
A6: 62697531 | B6: BJ US-NDO-MintChocCookie-8 1PT | C6: NA | D6: FERT | E6: 20 | F6: 45435 | G6: 10076840002273 | H6: 45078 | I6: 46023 | J6: BATCH_FI
A7: 62711311 | B7: MG Cookie Duet 1-12BK | C7: NA | D7: FERT | E7: 20 | F7: 45471 | G7: 10058779143005 | H7: 45085 | I7: 46041 | J7: BPMCEREMOTE
A8: 62711316 | B8: MG Almond 1-12BK | C8: NA | D8: FERT | E8: 20 | F8: 45348 | G8: 10058779133716 | H8: 45085 | I8: 46041 | J8: BPMCEREMOTE
A9: 62711330 | B9: MG Classic 1-12BK | C9: NA | D9: FERT | E9: 20 | F9: 45348 | G9: 10058779143623 | H9: 45085 | I9: 46041 | J9: BPMCEREMOTE
A10: 62711372 | B10: MG Mini Almond 6-4PK | C10: NA | D10: FERT | E10: 20 | F10: 45418 | G10: 10058779203075 | H10: 45085 | I10: 46042 | J10: BPMCEREMOTE
A11: 62711373 | B11: MG Mini Double Caramel 6-4PK | C11: NA | D11: FERT | E11: 20 | F11: 45446 | G11: 10058779203068 | H11: 45085 | I11: 46041 | J11: BPMCEREMOTE
A12: 62712615 | B12: MG Almond 12-3PK | C12: NA | D12: FERT | E12: 20 | F12: 45379 | G12: 10058779133457 | H12: 45086 | I12: 46042 | J12: BPMCEREMOTE
A13: 62712623 | B13: MG Double Caramel 12-3PK | C13: NA | D13: FERT | E13: 20 | F13: 45446 | G13: 10058779597020 | H13: 45086 | I13: 46041 | J13: BPMCEREMOTE
... A287: 84164937 | B287: BJ US-IC-ChubbyHubby-8 1PT | C287: NA | D287: FERT | E287: 20 | F287: 42767 | G287: 10076840100122 | H287: 42380 | I287: 46101 | J287: HAUG_T001

Sheet Sheet3
A1: 62694914 | B1: MG Almond Bar 1-12PK
A2: 64330596 | B2: MG Mini Double Caramel Bar 6-6PK
A3: 64330611 | B3: MG Double Caramel Bar 8-3PK
A4: 64341106 | B4: PS Jolly Rancher Pop 6-18PK
A5: 64341962 | B5: BR Chocolate Truffle 6 1.5QT
A6: 64341967 | B6: BR CHOC Peanut Butter 6 1.5QT
A7: 64341968 | B7: BR CO-B SNICKERS 6 1.5QT
A8: 64369043 | B8: TAL ND LYR CHOC Fudge Brownie 8 323.1g
A9: 64369046 | B9: TAL LYR Snickerdoodle 8p 326.7g
A10: 64373718 | B10: BR Smores 6 1.5QT
A11: 64389650 | B11: BR CS Rocky Road 6p 1.5QT
A12: 64389651 | B12: BR Strawberry Shortcake 6 1.5QT
... A120: 84164937 | B120: BJ US-IC-ChubbyHubby-8 1PT

Sheet CA-US List
A1: 68214423 | C1: US
A2: 68214422 | C2: US
A3: 68401152 | C3: US
A4: 68214424 | C4: US
A5: 68401149 | C5: US
A6: 67270387 | C6: US
A7: 67270386 | C7: US
A8: 67270381 | C8: US
A9: 64380012 | C9: US
A10: 64380013 | C10: US
C11: US
A12: 69716749 | B12: BJ US-IC-ChocTherapy-FTNG-8 1PT | C12: US
A13: 69716745 | B13: BJ US-IC-PBHalfBaked-8 1 PT | C13: US
A14: 69716746 | B14: BJ US-IC-TonightDough-8 1PT | C14: US
A15: 69716748 | B15: BJ US-IC-ChocFudgBrownie-FTNG-8 1PT | C15: US
A16: 69716747 | B16: BJ US-IC-MintChocolateChance-8 1PT | C16: US
A17: 62754606 | B17: BJ US-IC AmericoneDream-FTNG-8 1PT | C17: US
A18: 62754607 | B18: BJ US-IC-ChurrayForChurros-8 1PT | C18: US
A19: 64874631 | B19: KL Cookies and Creme IC SW 6-4PK | C19: US
A20: 64874633 | B20: KL Cookies and Creme SW 1-24BK 4.5z | C20: US
A21: 64875812 | B21: KL Vanilla Sandwich 8-6 PK | C21: US
A22: 64331551 | C22: US
A23: 64874631 | C23: US

Sheet Sheet5
A1: Material | B1: Plnt | C1: Goods Receipt Quantity | D1: Goods Receipt Date | E1: Description | F1: Plnt | G1: Vendor | H1: Vendor Name | I1: Goods Supplier | J1: GS Name | K1: Purch.Doc.
A2: 62714126 | B2: GDI | C2: 2600 | D2: 46027 | E2: PS OCG SF 6-18PK | F2: 1419 | G2: 51146194 | H2: GELATO D ITALIA S P A | I2: 51146194 | J2: GELATO D ITALIA S P A | K2: 4506572791
A3: 62714126 | B3: GDI | C3: 2600 | D3: 46028 | E3: PS OCG SF 6-18PK | F3: 1419 | G3: 51146194 | H3: GELATO D ITALIA S P A | I3: 51146194 | J3: GELATO D ITALIA S P A | K3: 4506572787
A4: 62714126 | B4: GDI | C4: 2600 | D4: 46028 | E4: PS OCG SF 6-18PK | F4: 1419 | G4: 51146194 | H4: GELATO D ITALIA S P A | I4: 51146194 | J4: GELATO D ITALIA S P A | K4: 4506572790
A5: 62714126 | B5: GDI | C5: 2600 | D5: 46028 | E5: PS OCG SF 6-18PK | F5: 1419 | G5: 51146194 | H5: GELATO D ITALIA S P A | I5: 51146194 | J5: GELATO D ITALIA S P A | K5: 4506572792
A6: 69665113 | B6: Rhino | C6: 6656 | D6: 46028 | E6: BJ US-CD-CCCD-FTNG-8 8z | F6: 1419 | G6: 50015356 | H6: RHINO FOODS INC USE V#2018125 FOR | I6: 50015356 | J6: RHINO FOODS INC USE V#2018125 FOR | K6: 4506610616
A7: 62714126 | B7: GDI | C7: 2600 | D7: 46029 | E7: PS OCG SF 6-18PK | F7: 1419 | G7: 51146194 | H7: GELATO D ITALIA S P A | I7: 51146194 | J7: GELATO D ITALIA S P A | K7: 4506572796
A8: 64833353 | B8: GDI | C8: 2600 | D8: 46029 | E8: PS SF Tropical 6-18PK | F8: 1419 | G8: 51146194 | H8: GELATO D ITALIA S P A | I8: 51146194 | J8: GELATO D ITALIA S P A | K8: 4506572807
A9: 64833353 | B9: GDI | C9: 2600 | D9: 46029 | E9: PS SF Tropical 6-18PK | F9: 1419 | G9: 51146194 | H9: GELATO D ITALIA S P A | I9: 51146194 | J9: GELATO D ITALIA S P A | K9: 4506572808
A10: 64833353 | B10: GDI | C10: 2600 | D10: 46029 | E10: PS SF Tropical 6-18PK | F10: 1419 | G10: 51146194 | H10: GELATO D ITALIA S P A | I10: 51146194 | J10: GELATO D ITALIA S P A | K10: 4506572810
A11: 64833353 | B11: GDI | C11: 2600 | D11: 46030 | E11: PS SF Tropical 6-18PK | F11: 1419 | G11: 51146194 | H11: GELATO D ITALIA S P A | I11: 51146194 | J11: GELATO D ITALIA S P A | K11: 4506572809
A12: 64833353 | B12: GDI | C12: 2600 | D12: 46030 | E12: PS SF Tropical 6-18PK | F12: 1419 | G12: 51146194 | H12: GELATO D ITALIA S P A | I12: 51146194 | J12: GELATO D ITALIA S P A | K12: 4506572812
A13: 62714126 | B13: GDI | C13: 2600 | D13: 46030 | E13: PS OCG SF 6-18PK | F13: 1419 | G13: 51146194 | H13: GELATO D ITALIA S P A | I13: 51146194 | J13: GELATO D ITALIA S P A | K13: 4506578511
... A88: 64341108 | B88: Incom | C88: 4200 | D88: 46050 | E88: PS SpongeBob Facepiece 1-20PK | F88: 1419 | G88: 51083022 | H88: Incom doo | I88: 51083022 | J88: Incom doo | K88: 4506565327
A89: 64978550 | B89: 1712 | C89: 11440 | D89: 46031 | E89: GH Almond Joy Candy Bar 8-6PK | F89: 1712 | G89: 50579936 | H89: SCHWANS FOOD SERVICE INC | I89: 50579936 | J89: SCHWANS FOOD SERVICE INC | K89: 4506574044
A90: 64413478 | B90: 1712 | C90: 19956 | D90: 46031 | E90: BJ US-IC-ChocChpCookDgh-FTNG-12 4FOZ | F90: 1712 | G90: 50579936 | H90: SCHWANS FOOD SERVICE INC | I90: 50579936 | J90: SCHWANS FOOD SERVICE INC | K90: 4506574043
A91: 64804361 | B91: 1712 | C91: 697 | D91: 46034 | E91: BJ US-PUP-Pumpkincoockie 108p 4flz | F91: 1712 | G91: 50579936 | H91: SCHWANS FOOD SERVICE INC | I91: 50579936 | J91: SCHWANS FOOD SERVICE INC | K91: 4506602802
A92: 64804365 | B92: 1712 | C92: 4981 | D92: 46038 | E92: BJ US-PUP-PB Pretzel 6-4PK | F92: 1712 | G92: 50579936 | H92: SCHWANS FOOD SERVICE INC | I92: 50579936 | J92: SCHWANS FOOD SERVICE INC | K92: 4506625183
A93: 64875812 | B93: 1712 | C93: 9353 | D93: 46038 | E93: KL Vanilla Sandwich 8-6 PK | F93: 1712 | G93: 50579936 | H93: SCHWANS FOOD SERVICE INC | I93: 50579936 | J93: SCHWANS FOOD SERVICE INC | K93: 4506602804
A94: 64874636 | B94: 1712 | C94: 14731 | D94: 46038 | E94: BR Smores SW 6-4ct | F94: 1712 | G94: 50579936 | H94: SCHWANS FOOD SERVICE INC | I94: 50579936 | J94: SCHWANS FOOD SERVICE INC | K94: 4506602803
A95: 64376316 | B95: 1712 | C95: 119771 | D95: 46038 | E95: Yasso Cookies n Cream Club 1-15pk | F95: 1712 | G95: 50579936 | H95: SCHWANS FOOD SERVICE INC | I95: 50579936 | J95: SCHWANS FOOD SERVICE INC | K95: 4506572220
A96: 64328806 | B96: 1712 | C96: 33867 | D96: 46041 | E96: KL Reeses SW 6-4PK | F96: 1712 | G96: 50579936 | H96: SCHWANS FOOD SERVICE INC | I96: 50579936 | J96: SCHWANS FOOD SERVICE INC | K96: 4506611533
A97: 64413476 | B97: 1712 | C97: 33517 | D97: 46044 | E97: BJ US-IC-ChocFudgBrownie-FTNG-12 4FOZ | F97: 1712 | G97: 50579936 | H97: SCHWANS FOOD SERVICE INC | I97: 50579936 | J97: SCHWANS FOOD SERVICE INC | K97: 4506632748
A98: 64326407 | B98: 1713 | C98: 99 | D98: 46042 | E98: Yasso Coffee Poppables 10-6.84flz | F98: 1713 | G98: 51657100 | H98: CooLab Foods LLC | I98: 51657100 | J98: CooLab Foods LLC | K98: 4506606174
A99: 64976848 | B99: 1715 | C99: 15119 | D99: 46024 | E99: Yasso Fudge Chocolate Crunch 8-4pk | F99: 1715 | G99: 51655117 | H99: DFA Belvidere IL | I99: 51655117 | J99: DFA Belvidere IL | K99: 4506560447
A100: 64958122 | B100: 1715 | C100: 4950 | D100: 46029 | E100: Yasso Sea Salt Caramel 8-4pk | F100: 1715 | G100: 51655117 | H100: DFA Belvidere IL | I100: 51655117 | J100: DFA Belvidere IL | K100: 4506545130
... A140: 64851294 | B140: 3985 | C140: 97898 | D140: 46045 | E140: COR RSC MG Mini Double Caramel 18ct Club | F140: 3985 | G140: 50016156 | H140: PACKAGING CORPORATION OF AMERICA | I140: 50016156 | J140: PACKAGING CORPORATION OF AMERICA | K140: 4506588929
A141: 64833353 | B141: GDI | C141: 2600 | D141: 46024 | E141: PS SF Tropical 6-18PK | F141: 3989 | G141: 51146194 | H141: GELATO D ITALIA S P A | I141: 51146194 | J141: GELATO D ITALIA S P A | K141: 4506555165
A142: 62714126 | B142: GDI | C142: 2600 | D142: 46027 | E142: PS OCG SF 6-18PK | F142: 3989 | G142: 51146194 | H142: GELATO D ITALIA S P A | I142: 51146194 | J142: GELATO D ITALIA S P A | K142: 4506563424
A143: 62714126 | B143: GDI | C143: 2600 | D143: 46027 | E143: PS OCG SF 6-18PK | F143: 3989 | G143: 51146194 | H143: GELATO D ITALIA S P A | I143: 51146194 | J143: GELATO D ITALIA S P A | K143: 4506563425
A144: 62714126 | B144: GDI | C144: 2600 | D144: 46028 | E144: PS OCG SF 6-18PK | F144: 3989 | G144: 51146194 | H144: GELATO D ITALIA S P A | I144: 51146194 | J144: GELATO D ITALIA S P A | K144: 4506546104
A145: 62714126 | B145: GDI | C145: 2600 | D145: 46028 | E145: PS OCG SF 6-18PK | F145: 3989 | G145: 51146194 | H145: GELATO D ITALIA S P A | I145: 51146194 | J145: GELATO D ITALIA S P A | K145: 4506546107
A146: 62714126 | B146: GDI | C146: 2600 | D146: 46028 | E146: PS OCG SF 6-18PK | F146: 3989 | G146: 51146194 | H146: GELATO D ITALIA S P A | I146: 51146194 | J146: GELATO D ITALIA S P A | K146: 4506562612
A147: 62714126 | B147: GDI | C147: 2600 | D147: 46028 | E147: PS OCG SF 6-18PK | F147: 3989 | G147: 51146194 | H147: GELATO D ITALIA S P A | I147: 51146194 | J147: GELATO D ITALIA S P A | K147: 4506563419
A148: 62714126 | B148: GDI | C148: 2600 | D148: 46028 | E148: PS OCG SF 6-18PK | F148: 3989 | G148: 51146194 | H148: GELATO D ITALIA S P A | I148: 51146194 | J148: GELATO D ITALIA S P A | K148: 4506563420
A149: 62714126 | B149: GDI | C149: 2600 | D149: 46028 | E149: PS OCG SF 6-18PK | F149: 3989 | G149: 51146194 | H149: GELATO D ITALIA S P A | I149: 51146194 | J149: GELATO D ITALIA S P A | K149: 4506563422
A150: 62714126 | B150: GDI | C150: 2600 | D150: 46028 | E150: PS OCG SF 6-18PK | F150: 3989 | G150: 51146194 | H150: GELATO D ITALIA S P A | I150: 51146194 | J150: GELATO D ITALIA S P A | K150: 4506563426
A151: 64833353 | B151: GDI | C151: 2600 | D151: 46028 | E151: PS SF Tropical 6-18PK | F151: 3989 | G151: 51146194 | H151: GELATO D ITALIA S P A | I151: 51146194 | J151: GELATO D ITALIA S P A | K151: 4506573714
A152: 62714126 | B152: GDI | C152: 2599 | D152: 46029 | E152: PS OCG SF 6-18PK | F152: 3989 | G152: 51146194 | H152: GELATO D ITALIA S P A | I152: 51146194 | J152: GELATO D ITALIA S P A | K152: 4506563417
... A197: 64341108 | B197: Incom | C197: 4200 | D197: 46045 | E197: PS SpongeBob Facepiece 1-20PK | F197: 3989 | G197: 51083022 | H197: Incom doo | I197: 51083022 | J197: Incom doo | K197: 4506565315
...
