Workbook

Sheet CM Info

Sheet MBEWH Pivot
A2: ValA | B2: (All) | S2: ValA | T2: (Multiple Items)
J3: Tech | K3: (All) | N3: Tech | O3: (All)
A4: Row Labels | B4: Sum of TotalStock | C4: Sum of Total Val. | F4: WAC | S4: Row Labels | T4: Sum of TotalStock | U4: Sum of Total Val.
A5: 48oz | B5: 3375504 | C5: 36461707 | D5: =C5/1.1238 -> 32445014 | E5: =C5/B5 -> 10.801856 | F5: =D5/B5 -> 9.6119022 | G5: Diff | J5: Row Labels | K5: Sum of TotalStock | L5: Sum of Total Val. | N5: Row Labels | O5: Sum of TotalStock | P5: Sum of Total Val. | Q5: Sum of Pallets | S5: Grand Total | V5: =U5/1.08499 -> 0 | Y5: Tech | Z5: (All)
A6: BJ PTS | B6: 2981431 | C6: 36844982 | D6: =C6/1.1238 -> 32786067 | E6: =C6/B6 -> 12.358154 | F6: =D6/B6 -> 10.996755 | J6: 1419 | K6: 4635340 | L6: 56188829 | M6: =L6/1.08499 -> 51787416 | N6: (blank) | V6: =U6/1.08499 -> 0
A7: Facepieces | B7: 2331198 | C7: 14075000 | D7: =C7/1.1238 -> 12524471 | E7: =C7/B7 -> 6.0376684 | F7: =D7/B7 -> 5.3725471 | J7: 2300 | K7: 3126948 | L7: 35934366 | M7: =L7/1.08499 -> 33119537 | N7: 6706 | O7: 3092 | P7: 74208 | Q7: 26 | V7: =U7/1.08499 -> 0 | Y7: Row Labels | Z7: Sum of TotalStock | AA7: Sum of Total Val.
A8: Yasso Sticks | B8: 2024260.5 | C8: 23859946 | D8: =C8/1.1238 -> 21231488 | E8: =C8/B8 -> 11.786994 | F8: =D8/B8 -> 10.488515 | G8: Diff | J8: 2400 | K8: 0 | L8: 0 | M8: =L8/1.08499 -> 0 | N8: 1715 | O8: 42980 | P8: 532117.14 | Q8: 263 | V8: =U8/1.08499 -> 0 | Y8: Grand Total
A9: Talenti | B9: 1856781 | C9: 20474460 | D9: =C9/1.1238 -> 18218953 | E9: =C9/B9 -> 11.026858 | F9: =D9/B9 -> 9.8121175 | J9: 3989 | K9: 7850360 | L9: 1.0154849e+08 | M9: =L9/1.08499 -> 93593939 | N9: 1716 | O9: 243606 | P9: 3085408 | Q9: 1227 | V9: =U9/1.08499 -> 0
A10: MG Sticks | B10: 1778594.2 | C10: 21883734 | D10: =C10/1.1238 -> 19472979 | E10: =C10/B10 -> 12.30395 | F10: =D10/B10 -> 10.948523 | J10: 5914 | K10: 92065 | L10: 1013930 | M10: =L10/1.08499 -> 934506.27 | N10: 1714 | O10: 189 | P10: 1608.75 | Q10: 1 | V10: =U10/1.08499 -> 0
A11: PG | B11: 1608992 | C11: 19147308 | D11: =C11/1.1238 -> 17038003 | E11: =C11/B11 -> 11.900188 | F11: =D11/B11 -> 10.58924 | J11: 1406 | K11: 1119301 | L11: 11384764 | M11: =L11/1.08499 -> 10492967 | N11: 1713 | O11: 10917 | P11: 194049.5 | Q11: 56 | V11: =U11/1.08499 -> 0
A12: EDF | B12: 1090251 | C12: 24804023 | D12: =C12/1.1238 -> 22071564 | E12: =C12/B12 -> 22.750746 | F12: =D12/B12 -> 20.244479 | J12: 1471 | K12: 2004213 | L12: 18349015 | M12: =L12/1.08499 -> 16911691 | N12: 1712 | O12: 643520 | P12: 4128145.1 | Q12: 1415 | V12: =U12/1.08499 -> 0
A13: SP1 | B13: 765536 | C13: 8962852.6 | D13: =C13/1.1238 -> 7975487.3 | E13: =C13/B13 -> 11.707944 | F13: =D13/B13 -> 10.418174 | J13: 2904 | K13: 56973 | L13: 566646.05 | M13: =L13/1.08499 -> 522259.24 | N13: 1717 | O13: 41130 | P13: 503785.89 | Q13: 248 | V13: =U13/1.08499 -> 0
A14: Yasso Club | B14: 746096 | C14: 4713344.3 | D14: =C14/1.1238 -> 4194113.1 | E14: =C14/B14 -> 6.3173429 | F14: =D14/B14 -> 5.6214121 | J14: 1352 | K14: 185157 | L14: 2615161.9 | M14: =L14/1.08499 -> 2410309.7 | N14: 6757 | O14: 25089 | P14: 420351.08 | Q14: 247 | V14: =U14/1.08499 -> 0
A15: MBG | B15: 510706 | C15: 6443437.7 | D15: =C15/1.1238 -> 5733616.1 | E15: =C15/B15 -> 12.616726 | F15: =D15/B15 -> 11.226843 | J15: 5911 | K15: 23782 | L15: 230168.67 | M15: =L15/1.08499 -> 212138.98 | N15: 6764 | O15: 91147 | P15: 823631.78 | Q15: 282 | V15: =U15/1.08499 -> 0
A16: B&J Cups | B16: 467697 | C16: 4843051.5 | D16: =C16/1.1238 -> 4309531.5 | E16: =C16/B16 -> 10.355105 | F16: =D16/B16 -> 9.2143663 | J16: 3985 | K16: 100905.75 | L16: 1252699.6 | M16: =L16/1.08499 -> 1154572.5 | N16: 6765 | O16: 5379 | P16: 45426.03 | Q16: 20 | V16: =U16/1.08499 -> 0
A17: YS PTS | B17: 426103 | C17: 4119513.1 | D17: =C17/1.1238 -> 3665699.5 | E17: =C17/B17 -> 9.6678809 | F17: =D17/B17 -> 8.6028483 | J17: 1439 | K17: 2179089 | L17: 27955579 | M17: =L17/1.08499 -> 25765748 | N17: Grand Total | O17: 1107049 | P17: 9808731.3 | Q17: 3785 | V17: =U17/1.08499 -> 0
A18: ESS | B18: 297291 | C18: 5114961.3 | D18: =C18/1.1238 -> 4551487.2 | E18: =C18/B18 -> 17.205234 | F18: =D18/B18 -> 15.309872 | J18: Grand Total | K18: 21374134 | L18: 2.5703965e+08 | V18: =U18/1.08499 -> 0
A19: KL Mini Cones | B19: 281969 | C19: 4695811.9 | D19: =C19/1.1238 -> 4178512.1 | E19: =C19/B19 -> 16.653646 | F19: =D19/B19 -> 14.819048 | V19: =U19/1.08499 -> 0
A20: BJ Bars | B20: 269196 | C20: 4588851.2 | D20: =C20/1.1238 -> 4083334.4 | E20: =C20/B20 -> 17.046506 | F20: =D20/B20 -> 15.16863 | V20: =U20/1.08499 -> 0
A21: Repack Items | B21: 213581 | C21: 2665181.1 | D21: =C21/1.1238 -> 2371579.5 | E21: =C21/B21 -> 12.47855 | F21: =D21/B21 -> 11.103888 | V21: =U21/1.08499 -> 0
A22: Other | B22: 213370 | C22: 2854406.8 | D22: =C22/1.1238 -> 2539959.8 | E22: =C22/B22 -> 13.377733 | F22: =D22/B22 -> 11.904016 | V22: =U22/1.08499 -> 0
A23: 2.4 Gal | B23: 187395 | C23: 5823295.1 | D23: =C23/1.1238 -> 5181789.5 | E23: =C23/B23 -> 31.074976 | F23: =D23/B23 -> 27.651696 | T23: =GETPIVOTDATA("Sum of TotalStock",$S$4)+GETPIVOTDATA("Sum of TotalStock",$A$4) -> 22481183 | V23: =U23/1.08499 -> 0
A24: GH Cones | B24: 145347 | C24: 1355717.4 | D24: =C24/1.1238 -> 1206368.9 | E24: =C24/B24 -> 9.3274535 | F24: =D24/B24 -> 8.299923
A25: Giant Vanilla Sandwich | B25: 143400 | C25: 1315584.4 | D25: =C25/1.1238 -> 1170657 | E25: =C25/B25 -> 9.1742287 | F25: =D25/B25 -> 8.1635777 | P25: =P22/1.08499 -> 0
A26: Quarts | B26: 108499 | C26: 2545715.9 | D26: =C26/1.1238 -> 2265274.9 | E26: =C26/B26 -> 23.463036 | F26: =D26/B26 -> 20.878302
A27: Dough Bites | B27: 97824 | C27: 1433186.5 | D27: =C27/1.1238 -> 1275303.9 | E27: =C27/B27 -> 14.650663 | F27: =D27/B27 -> 13.036718 | K27: Phys Cs (M) | L27: 20.279 | M27: 20.28
A28: Yasso Sandwich | B28: 91290 | C28: 1221591.5 | D28: =C28/1.1238 -> 1087018.6 | E28: =C28/B28 -> 13.381438 | F28: =D28/B28 -> 11.907313 | K28: WAC | L28: =E32 -> 13.775721 | M28: 10.6 | N28: =L28-M28 -> 3.1757209
A29: BR Minicups | B29: 86537 | C29: 1947733.2 | D29: =C29/1.1238 -> 1733167.1 | E29: =C29/B29 -> 22.50752 | F29: =D29/B29 -> 20.028048 | K29: FG Pre Derecog | L29: =L27*L28 -> 279.35784 | M29: =M27*M28 -> 214.968 | N29: =N28*M27 -> 64.40362
A30: Yasso Poppables | B30: 85293 | C30: 1548909.1 | D30: =C30/1.1238 -> 1378278.2 | E30: =C30/B30 -> 18.159862 | F30: =D30/B30 -> 16.159336 | G30: =C30+P17 -> 11357640 | H30: =G30/B30 -> 133.16029 | K30: CM Derecog | L30: -8.3 | M30: -8.3
A31: BR Pts New | B31: 83001 | C31: 544340.61 | D31: =C31/1.08499 -> 501701.04 | E31: =C31/B31 -> 6.5582416 | F31: =D31/B31 -> 6.044518 | H31: =H30/1.1238 -> 118.49109 | K31: Final FG | L31: =SUM(L29:L30) -> 271.05784 | M31: =SUM(M29:M30) -> 206.668 | Q31: ValA | R31: (Multiple Items)
A32: EFW | B32: 79919 | C32: 1100941.8 | D32: =C32/1.08499 -> 1014702.3 | E32: =C32/B32 -> 13.775721 | F32: =D32/B32 -> 12.696634 | K32: NFG | L32: 36.5 | M32: 36.5
A33: GH "Candy" | B33: 79524 | C33: 1109385.9 | D33: =C33/1.08499 -> 1022484.9 | E33: =C33/B33 -> 13.950328 | F33: =D33/B33 -> 12.857564 | K33: Other | L33: 25 | M33: 25 | Q33: Row Labels | R33: Sum of TotalStock | S33: Sum of Total Val. | T33: Sum of Pallets
A34: Yasso Cups | B34: 54335 | C34: 346187.04 | D34: =C34/1.08499 -> 319069.34 | E34: =C34/B34 -> 6.3713452 | F34: =D34/B34 -> 5.8722617 | K34: Total | L34: =SUM(L31:L33) -> 332.55784 | M34: =SUM(M31:M33) -> 268.168 | Q34: Yasso Club | R34: 608341 | S34: 3719807.4 | T34: 1268 | U34: =R34/240 -> 2534.7542
A35: Canada | B35: 262 | C35: 3217.97 | D35: =C35/1.08499 -> 2965.8983 | E35: =C35/B35 -> 12.282328 | F35: =D35/B35 -> 11.320223 | Q35: YS PTS | R35: 137271 | S35: 1416370.6 | T35: 576
A36: (blank) | D36: =C36/1.08499 -> 0 | E36: =C36/B36 -> #DIV/0! | F36: =D36/B36 -> #DIV/0! | Q36: Yasso Sticks | R36: 114223 | S36: 1458531.4 | T36: 701
A37: Grand Total | B37: 22481183 | C37: 2.6684838e+08 | D37: =C37/1.08499 -> 2.4594547e+08 | E37: =C37/B37 -> 11.869855 | F37: =D37/B37 -> 10.940059 | Q37: Giant Vanilla Sandwich | R37: 91147 | S37: 823631.78 | T37: 282
Q38: BJ Bars | R38: 73806 | S38: 1227157.6 | T38: 450
B39: =SUM(B21:B22,B24:B26,B29,B31,B33:B34) -> 1127594 | Q39: B&J Cups | R39: 26730 | S39: 276130.22 | T39: 85
B40: =B37-B14 -> 21735087 | Q40: ESS | R40: 18624 | S40: 354926.09 | T40: 162
Q41: Yasso Sandwich | R41: 11642 | S41: 142137.06 | T41: 121
...

Sheet MBEWH-Actuals
A1: Material | B1: ValA | C1: Val. Type | D1: Year | E1: Pe | F1: Prc | G1: ValCl | H1: TotalStock | I1: Total Val. | J1: MvAvgPrice | K1: Std price | L1: per | M1: Value | N1: Tot.SP val | O1: Tech | P1: Description | Q1: Brand | R1: Per pallet | S1: Pallets
A2: 17090 | B2: 1419 | D2: 2026 | E2: 02 | F2: V | G2: ZA03 | H2: 230 | I2: 24643.01 | J2: 107143.52 | K2: 103514.08 | L2: 1000 | M2: 24643.01 | N2: 0 | O2: =VLOOKUP($A2,'Roll up tech'!$A:$C,3,0) -> 2.4 Gal | P2: =VLOOKUP($A2,'Roll up tech'!$A:$C,2,0) -> BJ Choc Chk Ckie Btr 6 6 LB | Q2: =LEFT(P2,2) -> BJ | R2: =VLOOKUP(A2,'Per Pallet'!A:C,3,0) -> 50 | S2: =ROUNDUP(H2/R2,0) -> 5
A3: 17090 | B3: 1439 | D3: 2026 | E3: 02 | F3: V | G3: ZA03 | H3: 63 | I3: 7049.93 | J3: 111903.65 | K3: 103514.08 | L3: 1000 | M3: 7049.93 | N3: 0 | O3: =VLOOKUP($A3,'Roll up tech'!$A:$C,3,0) -> 2.4 Gal | P3: =VLOOKUP($A3,'Roll up tech'!$A:$C,2,0) -> BJ Choc Chk Ckie Btr 6 6 LB | Q3: =LEFT(P3,2) -> BJ | R3: =VLOOKUP(A3,'Per Pallet'!A:C,3,0) -> 50 | S3: =ROUNDUP(H3/R3,0) -> 2
A4: 17090 | B4: 2300 | D4: 2026 | E4: 02 | F4: V | G4: ZA03 | H4: 233 | I4: 25250.23 | J4: 108370.09 | K4: 104374.89 | L4: 1000 | M4: 25250.23 | N4: 0 | O4: =VLOOKUP($A4,'Roll up tech'!$A:$C,3,0) -> 2.4 Gal | P4: =VLOOKUP($A4,'Roll up tech'!$A:$C,2,0) -> BJ Choc Chk Ckie Btr 6 6 LB | Q4: =LEFT(P4,2) -> BJ | R4: =VLOOKUP(A4,'Per Pallet'!A:C,3,0) -> 50 | S4: =ROUNDUP(H4/R4,0) -> 5
A5: 17090 | B5: 3989 | D5: 2026 | E5: 02 | F5: V | G5: ZA03 | H5: 39 | I5: 4201.31 | J5: 107725.9 | K5: 104788.67 | L5: 1000 | M5: 4201.31 | N5: 0 | O5: =VLOOKUP($A5,'Roll up tech'!$A:$C,3,0) -> 2.4 Gal | P5: =VLOOKUP($A5,'Roll up tech'!$A:$C,2,0) -> BJ Choc Chk Ckie Btr 6 6 LB | Q5: =LEFT(P5,2) -> BJ | R5: =VLOOKUP(A5,'Per Pallet'!A:C,3,0) -> 50 | S5: =ROUNDUP(H5/R5,0) -> 1
A6: 17093 | B6: 1419 | D6: 2026 | E6: 02 | F6: V | G6: ZA03 | H6: 5 | I6: 530.51 | J6: 106102 | K6: 107466.77 | L6: 1000 | M6: 530.51 | N6: 0 | O6: =VLOOKUP($A6,'Roll up tech'!$A:$C,3,0) -> 2.4 Gal | P6: =VLOOKUP($A6,'Roll up tech'!$A:$C,2,0) -> BJ Nat Fdg Brwni Btr 6 6 LB | Q6: =LEFT(P6,2) -> BJ | R6: =VLOOKUP(A6,'Per Pallet'!A:C,3,0) -> 50 | S6: =ROUNDUP(H6/R6,0) -> 1
A7: 17093 | B7: 1439 | D7: 2026 | E7: 02 | F7: V | G7: ZA03 | H7: 37 | I7: 4061.57 | J7: 109772.16 | K7: 107466.77 | L7: 1000 | M7: 4061.57 | N7: 0 | O7: =VLOOKUP($A7,'Roll up tech'!$A:$C,3,0) -> 2.4 Gal | P7: =VLOOKUP($A7,'Roll up tech'!$A:$C,2,0) -> BJ Nat Fdg Brwni Btr 6 6 LB | Q7: =LEFT(P7,2) -> BJ | R7: =VLOOKUP(A7,'Per Pallet'!A:C,3,0) -> 50 | S7: =ROUNDUP(H7/R7,0) -> 1
A8: 17093 | B8: 2300 | D8: 2026 | E8: 02 | F8: V | G8: ZA03 | H8: 269 | I8: 28796.29 | J8: 107049.41 | K8: 107266.11 | L8: 1000 | M8: 28796.29 | N8: 0 | O8: =VLOOKUP($A8,'Roll up tech'!$A:$C,3,0) -> 2.4 Gal | P8: =VLOOKUP($A8,'Roll up tech'!$A:$C,2,0) -> BJ Nat Fdg Brwni Btr 6 6 LB | Q8: =LEFT(P8,2) -> BJ | R8: =VLOOKUP(A8,'Per Pallet'!A:C,3,0) -> 50 | S8: =ROUNDUP(H8/R8,0) -> 6
A9: 17093 | B9: 3989 | D9: 2026 | E9: 02 | F9: V | G9: ZA03 | H9: 260 | I9: 27722.15 | J9: 106623.65 | K9: 107358.41 | L9: 1000 | M9: 27722.15 | N9: 0 | O9: =VLOOKUP($A9,'Roll up tech'!$A:$C,3,0) -> 2.4 Gal | P9: =VLOOKUP($A9,'Roll up tech'!$A:$C,2,0) -> BJ Nat Fdg Brwni Btr 6 6 LB | Q9: =LEFT(P9,2) -> BJ | R9: =VLOOKUP(A9,'Per Pallet'!A:C,3,0) -> 50 | S9: =ROUNDUP(H9/R9,0) -> 6
A10: 62678148 | B10: 1419 | D10: 2026 | E10: 02 | F10: V | G10: ZA03 | H10: 4665 | I10: 52934.63 | J10: 11347.19 | K10: 11844.7 | L10: 1000 | M10: 52934.63 | N10: 0 | O10: =VLOOKUP($A10,'Roll up tech'!$A:$C,3,0) -> BJ PTS | P10: =VLOOKUP($A10,'Roll up tech'!$A:$C,2,0) -> BJ US-NDO-LightsCaramelAction-8 1PT | Q10: =LEFT(P10,2) -> BJ | R10: =VLOOKUP(A10,'Per Pallet'!A:C,3,0) -> 240 | S10: =ROUNDUP(H10/R10,0) -> 20
A11: 62678148 | B11: 1439 | D11: 2026 | E11: 02 | F11: V | G11: ZA03 | H11: 5857 | I11: 71827.5 | J11: 12263.53 | K11: 12398.75 | L11: 1000 | M11: 71827.5 | N11: 0 | O11: =VLOOKUP($A11,'Roll up tech'!$A:$C,3,0) -> BJ PTS | P11: =VLOOKUP($A11,'Roll up tech'!$A:$C,2,0) -> BJ US-NDO-LightsCaramelAction-8 1PT | Q11: =LEFT(P11,2) -> BJ | R11: =VLOOKUP(A11,'Per Pallet'!A:C,3,0) -> 240 | S11: =ROUNDUP(H11/R11,0) -> 25
A12: 62678148 | B12: 2300 | D12: 2026 | E12: 02 | F12: V | G12: ZA03 | H12: 2272 | I12: 26403.24 | J12: 11621.14 | K12: 11876.32 | L12: 1000 | M12: 26403.24 | N12: 0 | O12: =VLOOKUP($A12,'Roll up tech'!$A:$C,3,0) -> BJ PTS | P12: =VLOOKUP($A12,'Roll up tech'!$A:$C,2,0) -> BJ US-NDO-LightsCaramelAction-8 1PT | Q12: =LEFT(P12,2) -> BJ | R12: =VLOOKUP(A12,'Per Pallet'!A:C,3,0) -> 240 | S12: =ROUNDUP(H12/R12,0) -> 10
A13: 62678148 | B13: 3989 | D13: 2026 | E13: 02 | F13: V | G13: ZA03 | H13: 7477 | I13: 86271.51 | J13: 11538.25 | K13: 11921.96 | L13: 1000 | M13: 86271.51 | N13: 0 | O13: =VLOOKUP($A13,'Roll up tech'!$A:$C,3,0) -> BJ PTS | P13: =VLOOKUP($A13,'Roll up tech'!$A:$C,2,0) -> BJ US-NDO-LightsCaramelAction-8 1PT | Q13: =LEFT(P13,2) -> BJ | R13: =VLOOKUP(A13,'Per Pallet'!A:C,3,0) -> 240 | S13: =ROUNDUP(H13/R13,0) -> 32
... A2276: 84172951 | B2276: 1419 | D2276: 2026 | E2276: 02 | F2276: V | G2276: ZA03 | H2276: 15 | I2276: 193.42 | J2276: 12894.67 | K2276: 10681.49 | L2276: 1000 | M2276: 193.42 | N2276: 0 | O2276: =VLOOKUP($A2276,'Roll up tech'!$A:$C,3,0) -> BJ PTS | P2276: =VLOOKUP($A2276,'Roll up tech'!$A:$C,2,0) -> BJ R01-COR-BrwnieBttr-8 458ML | Q2276: =LEFT(P2276,2) -> BJ | R2276: =VLOOKUP(A2276,'Per Pallet'!A:C,3,0) -> 250 | S2276: =ROUNDUP(H2276/R2276,0) -> 1

Sheet Sheet4
A1: 64804394
A2: 64903296
A3: 64955741
A4: 64967299
A5: 64967300
A6: 64976849
A7: 64976850
A8: 64979407
A9: 64987232
A10: 64988053
A11: 64988055
A12: 64988057
A13: 69983248

Sheet Sites
D1: Incl | E1: Site | F1: Name
D2: Y | E2: 1352
D3: y | E3: 1406 | R3: 1352
D4: y | E4: 1419 | R4: 1406
D5: No | E5: 1423 | R5: 1419
D6: Y | E6: 1439 | F6: Tulare | R6: 1423
D7: Y | E7: 1471 | R7: 1439
D8: No | E8: 1542 | R8: 1471
D9: Y | E9: 1712 | F9: Schwann's | R9: 1542
D10: Y | E10: 1713 | F10: Coolab | R10: 1712
D11: Y | E11: 1714 | F11: Deliciosa | R11: 1713
D12: Y | E12: 1715 | F12: DFA | R12: 1714 | T12: 80
D13: Y | E13: 1716 | F13: Hudsonville | R13: 1715 | T13: 319
D14: Y | E14: 1717 | F14: Casper | R14: 1716 | T14: =T12/T13 -> 0.2507837
D15: No | E15: 2201 | L15: 480 | R15: 1717
D16: Y | E16: 2300 | L16: =L15*13 -> 6240 | R16: 2201
D17: No | E17: 2400 | R17: 2300
D18: Y | E18: 2904 | R18: 2400
D19: Y | K19: 100.9 | R19: 2904
D20: Y
D21: Y
D22: No | E22: 3962
D23: No | E23: 3984 | R23: 3962
D24: y | E24: 3985 | R24: 3984
D25: y | E25: 3989 | Q25: =4/11 -> 0.36363636 | R25: 3985
D26: y | Q26: =2/11 -> 0.18181818 | R26: 3989
D27: y | E27: 5911
D28: y | E28: 5914 | R28: 5911
D29: y | E29: 6706 | F29: Schwann's | K29: 2 | R29: 5914
D30: y | E30: 6757 | F30: OIC | K30: =K19-K29 -> 98.9 | R30: 6706
D31: Y | E31: 6764 | F31: ICS | R31: 6757
D32: no | E32: 6765 | F32: ICS | O32: Cuneyt | R32: 6764
O33: Korhan | R33: 6765
E35: 3217 | F35: CA
E36: 3250 | F36: CA
E37: 3910 | F37: CA
E38: 4074 | F38: CA

Sheet Sheet1

Sheet Roll up tech
A1: DU | B1: DU Description | C1: Rollup Tech
A2: 62714126 | B2: PS OCG SF 6-18PK | C2: PG
A3: 64341108 | B3: PS SpongeBob Facepiece 1-20PK | C3: Facepieces
A4: 68689251 | B4: KL Original Vanilla Bar 12-6PK | C4: EDF
A5: 64376316 | B5: Yasso Cookies n Cream Club 1-15pk | C5: Yasso Club
A6: 64365613 | B6: PS Spiderman Facepiece 6-6PK | C6: Facepieces
A7: 64958128 | B7: Yasso Mint Chocolate Chip 8-4pk | C7: Yasso Sticks
A8: 64771676 | B8: PS SpongeBob Facepiece IH 6-6PK | C8: Facepieces
A9: 68851107 | B9: BR NAT Vanilla 6-1.5QT | C9: 48oz
A10: 64327161 | B10: YSO Mint Chocolate Chip Club 1-15pk | C10: Yasso Club
A11: 69725082 | B11: PS OCG 6-18PK | C11: PG
A12: 64771677 | B12: PS Minions Facepiece IH 6-6PK | C12: Facepieces
A13: 68850683 | B13: BR Homemade Vanilla 6-1.5QT | C13: 48oz
... A587: 69610112 | B587: BJ SORV-IC-ChocolatePBChunk-1 8.95L | C587: 2.4 Gal
J3215: 68867756 | K3215: Talenti Roman Raspberry SORB 8 1PT
J3216: 68726916 | K3216: Talenti Roman Raspberry SORB 8 1PT

Sheet Per Pallet
A1: DU | B1: DU Description | C1: Per Pallet
A2: 68915160 | B2: HOLANDA MAGNUM DARK 8X3X90ML | C2: 210
A3: 68737751 | B3: GH WWE Sandwich 6-4PK | C3: 264
A4: 68890247 | B4: BR Dulce de Leche 6 1.5QT | C4: 176
A5: 69549219 | B5: MG Double Gold Caramel 1-12PK | C5: 493
A6: 68709148 | B6: GH Reese Bar 8-6PK | C6: 154
A7: 68115480 | B7: MG Mini Classic RFA 1(3) 6pk | C7: 222
A8: 68661485 | B8: KL Chocolate Shake Club 1-15CT | C8: 306
A9: 69727314 | B9: PS OCG SF 6-18PK | C9: 130
A10: 68927904 | B10: HOLANDA MAGNUM MINI CLAS MPK 6X6X55ML | C10: 160
A11: 68659824 | B11: HOLANDA MAGNUM MINI CLAS MPK 6X6X55ML | C11: 160
A12: 67895459 | B12: MG RUBY MINI 6-6PK | C12: 162
A13: 84160322 | B13: BR CHOCOLATE 6 10ct 3z | C13: 120
... A243: 67934984 | B243: PS Spiderman Facepiece 1-18PK | C243: 304
A244: 68670703 | B244: PS Spiderman Facepiece 1-18PK | C244: #N/A
A245: 69704149 | B245: PS Spiderman Facepiece 1-20pk | C245: 210
A246: 69665113 | B246: 69665113-BJ US-CD-CCCD-FTNG-8 8z | C246: 256
A247: 69665114 | B247: 69665114-BJ US-CD-SugarCookieDough-8 8z | C247: 256
A248: 69665115 | B248: 69665115-BJ US-CD-VCCCD-FTNG-8 8z | C248: 256
A249: 84147607 | B249: PS Shots Strawberry/Lemon 1-24BK WIP | C249: 126
A250: 67825129 | B250: BJ US-PS Candy Bar Pie 1-24PK WIP | C250: 322
A251: 67964162 | B251: BJ US-CD-CCCD-FTNG-8 8z | C251: 195
A252: 68264515 | B252: BJ US-CD-CHOC CCCD Dough-8 8z | C252: 195
A253: 67964164 | B253: BJ US-CD-PBCD-FTNG-8 8z | C253: 195
A254: 68654218 | B254: BJ US-CD-PBMix-8 8z | C254: 256
A255: 68709811 | B255: BJ US-CD-SeasonalSugarCookie-8 8z | C255: 195
A256: 68354599 | B256: BJ US-CD-SugarCookieDough-8 8z | C256: 195
... A291: 84144694 | B291: MG Mini Almond RFA 6-6PK | C291: 176
A292: 12345678 | B292: MG Mini Almond RFA 6-6PK MX | C292: #N/A
A293: 12345678 | B293: MG Mini Almond RFA 6-6PK MX | C293: #N/A
A294: 84119329 | B294: MG Mini Classic 6-6PK | C294: 176
A295: 84137357 | B295: MG Mini Classic 6-6PK | C295: 176
A296: 84144693 | B296: MG Mini Classic RFA 6-6PK | C296: 176
A297: 68472241 | B297: MG Mini Classic RFA 6-6PK | C297: 160
A298: 87654321 | B298: MG Mini Classic RFA 6-6PK MX | C298: #N/A
A299: 87654321 | B299: MG Mini Classic RFA 6-6PK MX | C299: #N/A
A300: 87654321 | B300: MG Mini Classic RFA 6-6PK MX | C300: #N/A
A301: 84136987 | B301: MG Mini Classic/Almond/White VP 6-6PK | C301: 176
A302: 84144696 | B302: MG Mini Classic/Almond/WhiteVP RFA 6-6PK | C302: 176
A303: 84167199 | B303: MG Mini Classic/Almond/WhiteVP RFA 6-6PK | C303: 176
...

Sheet Descriptions
A1: Material | B1: Description | C1: Ind. Std Desc. | D1: Material Type | E1: X-DChain status | F1: Valid from | G1: Created On | H1: EAN/UPC | I1: Old matl number | J1: Created by | K1: Last Change | L1: Base Unit | M1: Changed by | N1: Prod.allocation | O1: Valid to | P1: Division
A2: 17090 | B2: BJ Choc Chk Ckie Btr 6 6 LB | C2: IGLOO | D2: FERT | E2: 20 | F2: 39720 | G2: 40730 | H2: 10076840870902 | J2: DATACON1 | K2: 45205 | L2: CS | M2: PRAVEEN_P705 | P2: 11
A3: 17093 | B3: BJ Nat Fdg Brwni Btr 6 6 LB | C3: IGLOO | D3: FERT | E3: 20 | F3: 39721 | G3: 40730 | H3: 10076840870933 | J3: DATACON1 | K3: 45205 | L3: CS | M3: PRAVEEN_P705 | P3: 11
A4: 62697527 | B4: BJ US-NDO-ChangetheWhirled-8 1PT | C4: NA | D4: FERT | E4: 1 | F4: 45289 | G4: 45078 | H4: 10076840002976 | J4: BPMCEREMOTE | K4: 45206 | L4: CS | M4: NPD_ROBO_806 | P4: 11
A5: 62697529 | B5: BJ US-NDO-COR-KaramelSutra-8 1PT | C5: NA | D5: FERT | E5: 1 | F5: 45289 | G5: 45078 | H5: 10076840002891 | J5: BPMCEREMOTE | K5: 45206 | L5: CS | M5: NPD_ROBO_806 | P5: 11
A6: 62697530 | B6: BJ US-NDO-COR-BananasFoster-8 1PT | C6: NA | D6: FERT | E6: 1 | F6: 45289 | G6: 45078 | H6: 10076840003386 | J6: BPMCEREMOTE | K6: 45206 | L6: CS | M6: NPD_ROBO_806 | P6: 11
A7: 64313602 | B7: BR Vanilla 8 1PT | C7: NA | D7: FERT | E7: 1 | F7: 45313 | G7: 45205 | H7: 10077567274738 | J7: BPMCEREMOTE | K7: 45205 | L7: CS | M7: PRAVEEN_P705 | P7: 11
A8: 64313605 | B8: BR Cookies and Cream 8 1PT | C8: GMO | D8: FERT | E8: 1 | F8: 45313 | G8: 45205 | H8: 10077567275056 | J8: BPMCEREMOTE | K8: 45208 | L8: CS | M8: BPMCEREMOTE | P8: 11
A9: 64314592 | B9: BR Reese PB Cup 8 1PT | C9: GMO | D9: FERT | E9: 1 | F9: 45313 | G9: 45208 | H9: 10077567275063 | J9: BPMCEREMOTE | K9: 45208 | L9: CS | M9: BPMCEREMOTE | P9: 11
A10: 64314609 | B10: BR HA Cookies and Cream 8 1PT | C10: GMO | D10: FERT | E10: 1 | F10: 45313 | G10: 45208 | H10: 10077567275056 | J10: BPMCEREMOTE | K10: 45208 | L10: CS | M10: BPMCEREMOTE | P10: 11
A11: 64314618 | B11: BR Reeses Pieces 8 1PT | C11: NA | D11: FERT | E11: 1 | F11: 45313 | G11: 45208 | H11: 10077567003741 | J11: BPMCEREMOTE | K11: 45208 | L11: CS | M11: BPMCEREMOTE | P11: 11
A12: 67135545 | B12: KL BAR MINT CHOCOLATE CHIP 8-4PK | C12: NA | D12: FERT | E12: 41 | F12: 44963 | G12: 42629 | H12: 10058779209091 | J12: BPMCEREMOTE | K12: 45200 | L12: CS | M12: ZEPEDA_E007 | P12: 11
A13: 67135546 | B13: KL BAR KRUNCH 8-4PK | C13: NA | D13: FERT | E13: 41 | F13: 44883 | G13: 42629 | H13: 10058779209077 | J13: BPMCEREMOTE | K13: 45200 | L13: CS | M13: ESCALAN_C004 | P13: 11
... A150: 67466462 | B150: PS OCG 6-18PK | C150: NA | D150: FERT | E150: 20 | F150: 43458 | G150: 43090 | H150: 10077567001549 | J150: BPMCEREMOTE | K150: 45200 | L150: CS | M150: ESCALAN_C004 | P150: 11
A151: 67466490 | B151: PS Rainbow 6-18PK | C151: NA | D151: FERT | E151: 32 | F151: 44826 | G151: 43090 | H151: 10077567001556 | J151: BPMCEREMOTE | K151: 45205 | L151: CS | M151: PRAVEEN_P705 | N151: 67466490-605 | P151: 11
A152: 67466492 | B152: PS OCG SF 6-18PK | C152: NA | D152: FERT | E152: 20 | F152: 43458 | G152: 43090 | H152: 10077567001563 | J152: BPMCEREMOTE | K152: 45200 | L152: CS | M152: MORA_M035 | P152: 11
A153: 67466496 | B153: PS Fudgesicle NSA 6-18PK | C153: NA | D153: FERT | E153: 41 | F153: 45194 | G153: 43090 | H153: 10077567001587 | J153: BPMCEREMOTE | K153: 45200 | L153: CS | M153: MORA_M035 | P153: 11
A154: 67466605 | B154: MG Double Caramel 1-9PK WIP | C154: NA | D154: FERT | E154: 2 | F154: 43144 | G154: 43091 | H154: 10077567263152 | J154: BPMCEREMOTE | K154: 45200 | L154: CS | M154: ESCALAN_C004 | P154: 11
A155: 67473912 | B155: BJ AMET-IC-PhishFood-FTNG-8 458ML | C155: NA | D155: FERT | E155: 23 | F155: 43238 | G155: 43105 | H155: 10076840100986 | J155: BPMCEREMOTE | K155: 45200 | L155: CS | M155: MORA_M035 | P155: 11
A156: 67473913 | B156: BJ SORV-IC-PhishFood-8 458ML | C156: NA | D156: FERT | E156: 23 | F156: 43238 | G156: 43105 | H156: 10076840473202 | J156: BPMCEREMOTE | K156: 45200 | L156: CS | M156: KRISHNAN_B | P156: 11
A157: 67473917 | B157: BJ R01-LIC-CHOCOAFFAIR-8 458ML | C157: NA | D157: FERT | E157: 41 | F157: 44692 | G157: 43105 | H157: 10076840001726 | J157: BPMCEREMOTE | K157: 45200 | L157: CS | M157: MORA_M035 | P157: 11
A158: 67473921 | B158: St Albans IC Trial DU | C158: NA | D158: FERT | E158: 2 | F158: 43160 | G158: 43109 | H158: 10076840001733 | J158: BPMCEREMOTE | K158: 45151 | L158: CS | M158: KRISHNAN_B | P158: 11
A159: 67475447 | B159: BJ R01-LIC-CHOCOAFFAIR-8 458ML RP | C159: NA | D159: FERT | E159: 41 | F159: 44692 | G159: 43109 | H159: 10076840001726 | J159: BPMCEREMOTE | K159: 45200 | L159: CS | M159: ESCALAN_C004 | P159: 11
A160: 67476456 | B160: PS SF OCG 1-32PK | C160: NA | D160: FERT | E160: 32 | F160: 45016 | G160: 43111 | H160: 10077567478846 | J160: BPMCEREMOTE | K160: 45205 | L160: CS | M160: PRAVEEN_P705 | P160: 11
A161: 67476457 | B161: PS OCG 6-12 PK | C161: NA | D161: FERT | E161: 41 | F161: 44965 | G161: 43111 | H161: 10077567098204 | J161: BPMCEREMOTE | K161: 45151 | L161: CS | M161: KRISHNAN_B | P161: 11
A162: 67476560 | B162: PS FIrecracker 6-18PK | C162: NA | D162: FERT | E162: 20 | F162: 43617 | G162: 43111 | H162: 10077567274424 | J162: BPMCEREMOTE | K162: 45200 | L162: CS | M162: ESCALAN_C004 | P162: 11
A163: 67491117 | B163: BJ US-ND-PBHalfBaked-8 1PT | C163: NA | D163: FERT | E163: 32 | F163: 45196 | G163: 43126 | H163: 10076840000668 | J163: BPMCEREMOTE | K163: 45200 | L163: CS | M163: ESCALAN_C004 | P163: 11
... A228: 67694743 | B228: TAL Roman Raspberry Sorbetto (Df) 8p 1PT | C228: NA | D228: FERT | E228: 41 | F228: 44025 | G228: 43357 | H228: 20186852000161 | J228: BPMCEREMOTE | K228: 45200 | L228: CS | M228: ESCALAN_C004 | P228: 11
A229: 67699683 | B229: TAL ROM RASPBERRY SORBETTO 1 4.75QT WIP | C229: NA | D229: FERT | E229: 2 | F229: 43477 | G229: 43364 | H229: 10076840002242 | I229: 007684000224 | J229: BPMCEREMOTE | K229: 45200 | L229: CS | M229: ESCALAN_C004 | P229: 11
A230: 67716185 | B230: PS Rainbow Sponge Bob 12 - 10PK 47ML | C230: NA | D230: FERT | E230: 41 | F230: 44824 | G230: 43381 | H230: 10058779462526 | J230: BPMCEREMOTE | K230: 45200 | L230: CS | M230: ESCALAN_C004 | P230: 11
A231: 67716186 | B231: PS FIRECRACKER 12-12PK | C231: NA | D231: FERT | E231: 41 | F231: 44908 | G231: 43381 | H231: 10058779772427 | J231: BPMCEREMOTE | K231: 45200 | L231: CS | M231: ESCALAN_C004 | P231: 11
A232: 67716187 | B232: PS SUPER SICLE FIRECRCKR OOH CDA 1-24BK | C232: NA | D232: FERT | E232: 41 | F232: 44824 | G232: 43381 | H232: 10058779313880 | J232: BPMCEREMOTE | K232: 45200 | L232: CS | M232: ESCALAN_C004 | P232: 11
A233: 67718868 | B233: KL MINT CHOC CHIP 12-6PK | C233: NA | D233: FERT | E233: 41 | F233: 44812 | G233: 43383 | H233: 10075856139010 | J233: BPMCEREMOTE | K233: 45200 | L233: CS | M233: ESCALAN_C004 | P233: 11
A234: 67722258 | B234: BR OREO 8 1PT | C234: GMO | D234: FERT | E234: 41 | F234: 44638 | G234: 43385 | H234: 10077567275056 | J234: BPMCEREMOTE | K234: 45200 | L234: CS | M234: ESCALAN_C004 | P234: 11
A235: 67722259 | B235: BR HA OREO 8 1PT | C235: GMO | D235: FERT | E235: 41 | F235: 44683 | G235: 43385 | H235: 10077567275056 | J235: BPMCEREMOTE | K235: 45200 | L235: CS | M235: ESCALAN_C004 | P235: 11
A236: 67722286 | B236: PS BIG STICK C-P 4-24BK | C236: NA | D236: FERT | E236: 32 | F236: 44638 | G236: 43385 | H236: 10077567404418 | J236: BPMCEREMOTE | K236: 45151 | L236: CS | M236: KRISHNAN_B | P236: 11
A237: 67722287 | B237: PS Rainbow 5 Flavor Stacked Pop 6-12PK | C237: NA | D237: FERT | E237: 41 | F237: 44812 | G237: 43385 | H237: 10077567085198 | J237: BPMCEREMOTE | K237: 45151 | L237: CS | M237: KRISHNAN_B | P237: 11
A238: 67722289 | B238: PS Big Stick Red/White/Blue 4-24PK | C238: NA | D238: FERT | E238: 32 | F238: 44652 | G238: 43385 | H238: 10077567596670 | J238: BPMCEREMOTE | K238: 45205 | L238: CS | M238: PRAVEEN_P705 | P238: 11
A239: 67722290 | B239: PS LICK A COLOR 4-24PK | C239: NA | D239: FERT | E239: 41 | F239: 44965 | G239: 43385 | H239: 10077567020809 | J239: BPMCEREMOTE | K239: 45200 | L239: CS | M239: LARA_M001 | P239: 11
A240: 67722291 | B240: PS POP UPS/ORANGE 1-24PK | C240: NA | D240: FERT | E240: 32 | F240: 44802 | G240: 43385 | H240: 10077567003123 | J240: BPMCEREMOTE | K240: 45200 | L240: CS | M240: LARA_M001 | P240: 11
...

Sheet Direction
C2: Go to SAP transaction | D2: Z0SWT0039
B3: Actual | C3: Pull MBEWH table in SAP | D3: MBEWH
C4: Input US Site | D4: See Sites Tab
C5: Valuation Class field | D5: ZA03
C6: Input Year & Period (aka Month)
C7: Copy & Paste into Colum A-N
C8: Ensure formula in O-Q are all way down, etc
C9: If missing any rollup tech's, add on rollup tech tab

Sheet WAC
D11: Jan | E11: Feb | F11: Mar | G11: Apr | H11: May | I11: Jun | J11: Jul | K11: Aug | L11: Sep | M11: Oct | N11: Nov | O11: Dec
C12: 2021 | D12: 9.46 | E12: 9.36 | F12: 9.2 | G12: 9.03 | H12: 9.1 | I12: 9.36 | J12: 9.73 | K12: 9.85 | L12: 9.92 | M12: 10.07 | N12: 10.08 | O12: 10.6
C13: 2022 | D13: 10.89 | E13: 10.45 | F13: 10.66 | G13: 10.83 | H13: 10.63 | I13: 10.8 | J13: 10.97 | K13: 11.13 | L13: 11.25 | M13: 11.53 | N13: 11.84 | O13: 12.58
C14: 2023 | D14: 12.67 | E14: 12.64 | F14: 12.5 | G14: 12.36 | H14: 12.31 | I14: 12.34 | J14: 12.24 | K14: 11.99 | L14: 12.09 | M14: 12.2 | N14: 12.27 | O14: 12.84
C15: 2024 | D15: 12.23 | E15: 11.978 | F15: 11.534 | G15: 11.449 | H15: 11.266 | I15: 11.243 | J15: 11.234 | K15: 11.17 | L15: 11.413 | M15: 11.23 | N15: 11.4 | O15: 11.6

Sheet NFG INFO
I1: =SUBTOTAL(9,I3:I8133) -> 3300676 | J1: =I1/1.08499 -> 3042125.7
A2: Material | B2: ValA | C2: Val. Type | D2: Year | E2: Pe | F2: Prc | G2: ValCl | H2: TotalStock | I2: Total Val. | J2: MvAvgPrice | K2: Std price | L2: per | M2: Value | N2: Tot.SP val
A3: 12655 | B3: 1352 | D3: 2025 | E3: 12 | F3: S | G3: ZA01 | H3: 0 | I3: 0 | J3: 7497.93 | K3: 7997.02 | L3: 1000 | M3: 0 | N3: 0
A4: 12655 | B4: 2904 | D4: 2025 | E4: 12 | F4: V | G4: ZA01 | H4: 650 | I4: 4564.79 | J4: 7022.75 | K4: 7458.99 | L4: 1000 | M4: 4564.79 | N4: 0
A5: 50443 | B5: 1352 | D5: 2025 | E5: 12 | F5: S | G5: ZA04 | H5: 0 | I5: 0 | J5: 0 | K5: 1988.04 | L5: 1000 | M5: 0 | N5: 0
A6: 50443 | B6: 2904 | D6: 2025 | E6: 12 | F6: V | G6: ZA04 | H6: 4874.18 | I6: 22593.92 | J6: 4635.43 | K6: 4515.45 | L6: 1000 | M6: 22593.92 | N6: 0
A7: 50465 | B7: 1352 | D7: 2025 | E7: 12 | F7: V | G7: ZA04 | H7: 15296.121 | I7: 62245.97 | J7: 4069.4 | K7: 4211.68 | L7: 1000 | M7: 62245.97 | N7: 0
A8: 50465 | B8: 2904 | D8: 2025 | E8: 12 | F8: V | G8: ZA04 | H8: 8720.044 | I8: 39423.53 | J8: 4521.02 | K8: 4260.94 | L8: 1000 | M8: 39423.53 | N8: 0
A9: 50465 | B9: 3910 | D9: 2025 | E9: 12 | F9: V | G9: ZA04 | H9: 2214.5 | I9: 9826.58 | J9: 4437.38 | K9: 4179.83 | L9: 1000 | M9: 9826.58 | N9: 0
A10: 52170 | B10: 5914 | D10: 2025 | E10: 12 | F10: S | G10: ZA04 | H10: 0 | I10: 0 | J10: 160.98 | K10: 174.88 | L10: 1000 | M10: 0 | N10: 0
A11: 52171 | B11: 5914 | D11: 2025 | E11: 12 | F11: S | G11: ZA04 | H11: 0 | I11: 0 | J11: 181.03 | K11: 196.66 | L11: 1000 | M11: 0 | N11: 0
A12: 52900 | B12: 1352 | D12: 2025 | E12: 12 | F12: S | G12: ZA04 | H12: 0 | I12: 0 | J12: 14743.27 | K12: 15097.13 | L12: 1000 | M12: 0 | N12: 0
A13: 52900 | B13: 3910 | D13: 2025 | E13: 12 | F13: S | G13: ZA04 | H13: 0 | I13: 0 | J13: 15085.2 | K13: 15214.93 | L13: 1000 | M13: 0 | N13: 0
A14: 53725 | B14: 1352 | D14: 2025 | E14: 12 | F14: V | G14: ZA04 | H14: 865.352 | I14: 14518.77 | J14: 16777.88 | K14: 18059.02 | L14: 1000 | M14: 14518.77 | N14: 0
... A8133: 87004130P | B8133: 5914 | D8133: 2025 | E8133: 12 | F8133: S | G8133: ZA02 | H8133: 0 | I8133: 0 | J8133: 164.27 | K8133: 2152.1 | L8133: 1000 | M8133: 0 | N8133: 0
